Workbook
Name ID: "ffd3c754-87db-4290-be14-baeec74b153c"
Name ID: "d9833f41-ff4f-4edb-a348-fa5525b33f7f"
Name ID: "48c92c0b-6614-47b6-bc06-edf950ad7eca"
Name ID: "d93ed13a-8e7b-4c6f-b6b3-f42d2e192d2c"
Name ID: "06c35546-e1ea-4f14-840a-995aaed84db4"
Name ID: "a7abdd59-af78-4b30-80f7-65ae2464b716"
Name ID: "b748b396-170f-44a6-bae3-f99a0c51799f"
Name ID: "db02b9b5-88b3-4d4b-a27a-3155df7c60dc"
Name ID: "c5636b4e-3fe7-49a1-bfef-3ebbeb1fa61d"
Name ID: "e71144bd-e222-46f5-8d7c-fe5101f2bc7d"
Name ID_1: "9c7c4969-7e77-4d19-a2b5-78f5e7d15ad4"
Name ID_1: "d93ed13a-8e7b-4c6f-b6b3-f42d2e192d2c"
Name ID_1: "81799d31-f9c1-4594-9c17-e303897ae98a"
Name ID_1_1: "81799d31-f9c1-4594-9c17-e303897ae98a"
Name ID_1_1: "9c7c4969-7e77-4d19-a2b5-78f5e7d15ad4"
Name ID_1_1_1: "81799d31-f9c1-4594-9c17-e303897ae98a"

Sheet Cognos_Office_Connection_Cache

Sheet Home

Sheet Summary  - Fx
A1: Cubo
A2: CONS_VC:DFS.200.KPIs
A3: CONS_VC:DFS.100.Profit_and_loss
A4: CONS_VC:DFS.140.Indirect_Cash_Flow
A5: CONS_VC:DFS.180.Gross_Debt
A6: CONS_VC:REV.100.Revenue_Consolidated
A8: Ano
A11: Mês
A12: =_xll.SUBNM("CONS_VC:ALL.D.Month",,"Total YTD","MEMBER_NAME") -> Total YTD
A13: =_xll.SUBNM("CONS_VC:ALL.D.Month",,"Year","MEMBER_NAME") -> Year
A16: Versão
A22: Currency
A23: =_xll.SUBNM("CONS_VC:ALL.D.Currency","","BRL Conv.") -> BRL Conv.
A24: =_xll.SUBNM("CONS_VC:ALL.D.Currency","","USD Conv.") -> USD Conv.
A25: =_xll.SUBNM("CONS_VC:ALL.D.Currency","","EUR Conv.") -> EUR Conv.
A28: Region
A29: =_xll.SUBNM("CONS_VC:ALL.D.Region","","Global") -> Global
A30: VCBR
A31: VCNA
A32: VCEAA
A33: VCLATAM
A35: Produto
A36: =_xll.SUBNM("CONS_VC:ALL.D.Products","","Total Products") -> Total Products
A38: Accounts_PNL
A39: Net Profit
A41: Accounts_ICF
A42: Change in cash
A45: DFS.100.Profil_and_Loss
A46: Global EBITDA Month | B46: Formato
A47: {=_xll.DBR($A$3,Summary!$S$6,Summary!$U$6,Summary!$M$6,$A$23,$A$29,$A$36,"EBITDA","Total Value")} -> #VALUE! | B47: ="R$ "& ROUND(A47,0) & " M" -> #VALUE!
A48: {=IFERROR((_xll.DBR($A$3,Summary!$S$6,Summary!$U$6,Summary!$M$6,$A$23,$A$29,$A$36,"EBITDA","Total Value") - _xll.DBR($A$3,Summary!$S$6,Summary!$U$6,Summary!$O$6,$A$23,$A$29,$A$36,"EBITDA","Total Value"))/ _xll.DBR($A$3,Summary!$S$6,Summary!$U$6,Summary!$O$6,$A$23,$A$29,$A$36,"EBITDA","Total Value"),0) &"%" & " vs. Budget"} -> 0% vs. Budget
A50: Global EBITDA YTD | B50: Formato
A51: {=_xll.DBR($A$3,Summary!$S$6,$A$12,Summary!$M$6,$A$23,$A$29,$A$36,"EBITDA","Total Value")} -> #VALUE! | B51: ="R$ "& ROUND(A51,0) & " M" -> #VALUE!
A52: {=IFERROR((_xll.DBR($A$3,Summary!$S$6,$A$12,Summary!$M$6,$A$23,$A$29,$A$36,"EBITDA","Total Value") - _xll.DBR($A$3,Summary!$S$6,$A$12,Summary!$O$6,$A$23,$A$29,$A$36,"EBITDA","Total Value"))/ _xll.DBR($A$3,Summary!$S$6,$A$12,Summary!$O$6,$A$23,$A$29,$A$36,"EBITDA","Total Value"),0) &"%" & " vs. Budget"} -> 0% vs. Budget
A54: Global EBITDA Full Year | B54: Formato
A55: {=_xll.DBR($A$3,Summary!$S$6,$A$13,Summary!$M$6,$A$23,$A$29,$A$36,"EBITDA","Total Value")} -> #VALUE! | B55: ="R$ "& ROUND(A55,0) & " M" -> #VALUE!
A56: {=IFERROR((_xll.DBR($A$3,Summary!$S$6,$A$13,Summary!$M$6,$A$23,$A$29,$A$36,"EBITDA","Total Value") - _xll.DBR($A$3,Summary!$S$6,$A$13,Summary!$O$6,$A$23,$A$29,$A$36,"EBITDA","Total Value"))/ _xll.DBR($A$3,Summary!$S$6,$A$13,Summary!$O$6,$A$23,$A$29,$A$36,"EBITDA","Total Value"),0) &"%" & " vs. Budget"} -> 0% vs. Budget
A58: Regions | B58: Formato
A59: VCBR
A60: {=_xll.DBR($A$3,Summary!$S$6,Summary!$U$6,Summary!$K$6,$A$23,$A$30,$A$36,"EBITDA","Total Value")} -> #VALUE! | B60: L300
...

Sheet Summary
B1: Summary - Regions EBITDA
D6: =_xll.SUBNM("CONS_VC_PRD:ALL.D.Region","","Global") -> #N/A | K6: =_xll.SUBNM("CONS_VC_PRD:ALL.D.Version","Sys.Report","L300","Descrição") -> #N/A | M6: =_xll.SUBNM("CONS_VC_PRD:ALL.D.Version",,"RF","Descrição") -> #N/A | O6: Budget | S6: =_xll.SUBNM("CONS_VC_PRD:ALL.D.Year","","2025") -> #N/A | U6: =_xll.SUBNM("CONS_VC_PRD:ALL.D.Month","sys_picklist","Jan","DESC") -> #N/A
D8: Month
J9: VCBR (BRL)
F12: ='Summary - Fx'!B47 -> #VALUE!
G14: ='Summary - Fx'!A48 -> 0% vs. Budget
J15: VCNA (USD)
D17: YTD
F22: ='Summary - Fx'!B51 -> #VALUE! | J22: VCEA (EUR)
G24: ='Summary - Fx'!A52 -> 0% vs. Budget
D29: Full Year
J30: VCLatam (USD)
F35: ='Summary - Fx'!B55 -> #VALUE!
G37: ='Summary - Fx'!A56 -> 0% vs. Budget

Sheet Cement Volumes & Prices - Fx
A1: CONS_VC:REV.100.Revenue_Consolidated
A2: ='Cement Volumes & Prices'!$T$6 -> #N/A
A4: =_xll.SUBNM("CONS_VC:ALL.D.Market","","Total Market") -> Total Market
A6: =_xll.SUBNM("CONS_VC:ALL.D.Currency","Default","BRL","MEMBER_NAME") -> BRL | C6: Jan | D6: Feb | E6: Mar | F6: Apr | G6: May | H6: Jun | I6: Jul | J6: Aug | K6: Sep | L6: Oct | M6: Nov | N6: Dec
A7: =_xll.SUBNM("CONS_VC:ALL.D.Region","Default","VCBR","MEMBER_NAME") -> VCBR | B7: ='Cement Volumes & Prices'!$V$6 -> #N/A | C7: =_xll.DBRW($A$1,$A$2,C$6,$B7,$A6,$A7,'Cement Volumes & Prices'!$D$6,$A$4,$A8) -> #VALUE! | D7: =_xll.DBRW($A$1,$A$2,D$6,$B7,$A6,$A7,'Cement Volumes & Prices'!$D$6,$A$4,$A8) -> #VALUE! | E7: =_xll.DBRW($A$1,$A$2,E$6,$B7,$A6,$A7,'Cement Volumes & Prices'!$D$6,$A$4,$A8) -> #VALUE! | F7: =_xll.DBRW($A$1,$A$2,F$6,$B7,$A6,$A7,'Cement Volumes & Prices'!$D$6,$A$4,$A8) -> #VALUE! | G7: =_xll.DBRW($A$1,$A$2,G$6,$B7,$A6,$A7,'Cement Volumes & Prices'!$D$6,$A$4,$A8) -> #VALUE! | H7: =_xll.DBRW($A$1,$A$2,H$6,$B7,$A6,$A7,'Cement Volumes & Prices'!$D$6,$A$4,$A8) -> #VALUE! | I7: =_xll.DBRW($A$1,$A$2,I$6,$B7,$A6,$A7,'Cement Volumes & Prices'!$D$6,$A$4,$A8) -> #VALUE! | J7: =_xll.DBRW($A$1,$A$2,J$6,$B7,$A6,$A7,'Cement Volumes & Prices'!$D$6,$A$4,$A8) -> #VALUE! | ... N7: =_xll.DBRW($A$1,$A$2,N$6,$B7,$A6,$A7,'Cement Volumes & Prices'!$D$6,$A$4,$A8) -> #VALUE!
A8: =_xll.SUBNM("CONS_VC:REV.M.100.Revenue_Consolidated","Default","Sales Volume [kt]") -> Sales Volume [kt] | B8: ='Cement Volumes & Prices'!$X$6 -> #N/A | C8: =_xll.DBRW($A$1,$A$2,C$6,$B8,$A6,$A7,'Cement Volumes & Prices'!$D$6,$A$4,$A8) -> #VALUE! | D8: =_xll.DBRW($A$1,$A$2,D$6,$B8,$A6,$A7,'Cement Volumes & Prices'!$D$6,$A$4,$A8) -> #VALUE! | E8: =_xll.DBRW($A$1,$A$2,E$6,$B8,$A6,$A7,'Cement Volumes & Prices'!$D$6,$A$4,$A8) -> #VALUE! | F8: =_xll.DBRW($A$1,$A$2,F$6,$B8,$A6,$A7,'Cement Volumes & Prices'!$D$6,$A$4,$A8) -> #VALUE! | G8: =_xll.DBRW($A$1,$A$2,G$6,$B8,$A6,$A7,'Cement Volumes & Prices'!$D$6,$A$4,$A8) -> #VALUE! | H8: =_xll.DBRW($A$1,$A$2,H$6,$B8,$A6,$A7,'Cement Volumes & Prices'!$D$6,$A$4,$A8) -> #VALUE! | I8: =_xll.DBRW($A$1,$A$2,I$6,$B8,$A6,$A7,'Cement Volumes & Prices'!$D$6,$A$4,$A8) -> #VALUE! | J8: =_xll.DBRW($A$1,$A$2,J$6,$B8,$A6,$A7,'Cement Volumes & Prices'!$D$6,$A$4,$A8) -> #VALUE! | ... N8: =_xll.DBRW($A$1,$A$2,N$6,$B8,$A6,$A7,'Cement Volumes & Prices'!$D$6,$A$4,$A8) -> #VALUE!
A10: =_xll.SUBNM("CONS_VC:ALL.D.Currency","Default","USD","MEMBER_NAME") -> USD | C10: Jan | D10: Feb | E10: Mar | F10: Apr | G10: May | H10: Jun | I10: Jul | J10: Aug | K10: Sep | L10: Oct | M10: Nov | N10: Dec
A11: =_xll.SUBNM("CONS_VC:ALL.D.Region","Default","VCNA","MEMBER_NAME") -> VCNA | B11: ='Cement Volumes & Prices'!$V$6 -> #N/A | C11: =_xll.DBRW($A$1,$A$2,C$6,$B11,$A10,$A11,'Cement Volumes & Prices'!$D$6,$A$4,$A12) -> #VALUE! | D11: =_xll.DBRW($A$1,$A$2,D$6,$B11,$A10,$A11,'Cement Volumes & Prices'!$D$6,$A$4,$A12) -> #VALUE! | E11: =_xll.DBRW($A$1,$A$2,E$6,$B11,$A10,$A11,'Cement Volumes & Prices'!$D$6,$A$4,$A12) -> #VALUE! | F11: =_xll.DBRW($A$1,$A$2,F$6,$B11,$A10,$A11,'Cement Volumes & Prices'!$D$6,$A$4,$A12) -> #VALUE! | G11: =_xll.DBRW($A$1,$A$2,G$6,$B11,$A10,$A11,'Cement Volumes & Prices'!$D$6,$A$4,$A12) -> #VALUE! | H11: =_xll.DBRW($A$1,$A$2,H$6,$B11,$A10,$A11,'Cement Volumes & Prices'!$D$6,$A$4,$A12) -> #VALUE! | I11: =_xll.DBRW($A$1,$A$2,I$6,$B11,$A10,$A11,'Cement Volumes & Prices'!$D$6,$A$4,$A12) -> #VALUE! | J11: =_xll.DBRW($A$1,$A$2,J$6,$B11,$A10,$A11,'Cement Volumes & Prices'!$D$6,$A$4,$A12) -> #VALUE! | ... N11: =_xll.DBRW($A$1,$A$2,N$6,$B11,$A10,$A11,'Cement Volumes & Prices'!$D$6,$A$4,$A12) -> #VALUE!
A12: =_xll.SUBNM("CONS_VC:REV.M.100.Revenue_Consolidated","Default","Sales Volume [kt]") -> Sales Volume [kt] | B12: ='Cement Volumes & Prices'!$X$6 -> #N/A | C12: =_xll.DBRW($A$1,$A$2,C$6,$B12,$A10,$A11,'Cement Volumes & Prices'!$D$6,$A$4,$A12) -> #VALUE! | D12: =_xll.DBRW($A$1,$A$2,D$6,$B12,$A10,$A11,'Cement Volumes & Prices'!$D$6,$A$4,$A12) -> #VALUE! | E12: =_xll.DBRW($A$1,$A$2,E$6,$B12,$A10,$A11,'Cement Volumes & Prices'!$D$6,$A$4,$A12) -> #VALUE! | F12: =_xll.DBRW($A$1,$A$2,F$6,$B12,$A10,$A11,'Cement Volumes & Prices'!$D$6,$A$4,$A12) -> #VALUE! | G12: =_xll.DBRW($A$1,$A$2,G$6,$B12,$A10,$A11,'Cement Volumes & Prices'!$D$6,$A$4,$A12) -> #VALUE! | H12: =_xll.DBRW($A$1,$A$2,H$6,$B12,$A10,$A11,'Cement Volumes & Prices'!$D$6,$A$4,$A12) -> #VALUE! | I12: =_xll.DBRW($A$1,$A$2,I$6,$B12,$A10,$A11,'Cement Volumes & Prices'!$D$6,$A$4,$A12) -> #VALUE! | J12: =_xll.DBRW($A$1,$A$2,J$6,$B12,$A10,$A11,'Cement Volumes & Prices'!$D$6,$A$4,$A12) -> #VALUE! | ... N12: =_xll.DBRW($A$1,$A$2,N$6,$B12,$A10,$A11,'Cement Volumes & Prices'!$D$6,$A$4,$A12) -> #VALUE!
A14: =_xll.SUBNM("CONS_VC:ALL.D.Currency","Default","EUR","MEMBER_NAME") -> EUR | C14: Jan | D14: Feb | E14: Mar | F14: Apr | G14: May | H14: Jun | I14: Jul | J14: Aug | K14: Sep | L14: Oct | M14: Nov | N14: Dec
A15: =_xll.SUBNM("CONS_VC:ALL.D.Region","Default","VCEAA","MEMBER_NAME") -> VCEAA | B15: ='Cement Volumes & Prices'!$V$6 -> #N/A | C15: =_xll.DBRW($A$1,$A$2,C$6,$B15,$A14,$A15,'Cement Volumes & Prices'!$D$6,$A$4,$A16) -> #VALUE! | D15: =_xll.DBRW($A$1,$A$2,D$6,$B15,$A14,$A15,'Cement Volumes & Prices'!$D$6,$A$4,$A16) -> #VALUE! | E15: =_xll.DBRW($A$1,$A$2,E$6,$B15,$A14,$A15,'Cement Volumes & Prices'!$D$6,$A$4,$A16) -> #VALUE! | F15: =_xll.DBRW($A$1,$A$2,F$6,$B15,$A14,$A15,'Cement Volumes & Prices'!$D$6,$A$4,$A16) -> #VALUE! | G15: =_xll.DBRW($A$1,$A$2,G$6,$B15,$A14,$A15,'Cement Volumes & Prices'!$D$6,$A$4,$A16) -> #VALUE! | H15: =_xll.DBRW($A$1,$A$2,H$6,$B15,$A14,$A15,'Cement Volumes & Prices'!$D$6,$A$4,$A16) -> #VALUE! | I15: =_xll.DBRW($A$1,$A$2,I$6,$B15,$A14,$A15,'Cement Volumes & Prices'!$D$6,$A$4,$A16) -> #VALUE! | J15: =_xll.DBRW($A$1,$A$2,J$6,$B15,$A14,$A15,'Cement Volumes & Prices'!$D$6,$A$4,$A16) -> #VALUE! | ... N15: =_xll.DBRW($A$1,$A$2,N$6,$B15,$A14,$A15,'Cement Volumes & Prices'!$D$6,$A$4,$A16) -> #VALUE!
A16: =_xll.SUBNM("CONS_VC:REV.M.100.Revenue_Consolidated","Default","Sales Volume [kt]") -> Sales Volume [kt] | B16: ='Cement Volumes & Prices'!$X$6 -> #N/A | C16: =_xll.DBRW($A$1,$A$2,C$6,$B16,$A14,$A15,'Cement Volumes & Prices'!$D$6,$A$4,$A16) -> #VALUE! | D16: =_xll.DBRW($A$1,$A$2,D$6,$B16,$A14,$A15,'Cement Volumes & Prices'!$D$6,$A$4,$A16) -> #VALUE! | E16: =_xll.DBRW($A$1,$A$2,E$6,$B16,$A14,$A15,'Cement Volumes & Prices'!$D$6,$A$4,$A16) -> #VALUE! | F16: =_xll.DBRW($A$1,$A$2,F$6,$B16,$A14,$A15,'Cement Volumes & Prices'!$D$6,$A$4,$A16) -> #VALUE! | G16: =_xll.DBRW($A$1,$A$2,G$6,$B16,$A14,$A15,'Cement Volumes & Prices'!$D$6,$A$4,$A16) -> #VALUE! | H16: =_xll.DBRW($A$1,$A$2,H$6,$B16,$A14,$A15,'Cement Volumes & Prices'!$D$6,$A$4,$A16) -> #VALUE! | I16: =_xll.DBRW($A$1,$A$2,I$6,$B16,$A14,$A15,'Cement Volumes & Prices'!$D$6,$A$4,$A16) -> #VALUE! | J16: =_xll.DBRW($A$1,$A$2,J$6,$B16,$A14,$A15,'Cement Volumes & Prices'!$D$6,$A$4,$A16) -> #VALUE! | ... N16: =_xll.DBRW($A$1,$A$2,N$6,$B16,$A14,$A15,'Cement Volumes & Prices'!$D$6,$A$4,$A16) -> #VALUE!
A18: =_xll.SUBNM("CONS_VC:ALL.D.Currency","Default","USD","MEMBER_NAME") -> USD | C18: Jan | D18: Feb | E18: Mar | F18: Apr | G18: May | H18: Jun | I18: Jul | J18: Aug | K18: Sep | L18: Oct | M18: Nov | N18: Dec
A19: =_xll.SUBNM("CONS_VC:ALL.D.Region","Default","VCLATAM Incl. AVEL","MEMBER_NAME") -> VCLATAM Incl. AVEL | B19: ='Cement Volumes & Prices'!$V$6 -> #N/A | C19: =_xll.DBRW($A$1,$A$2,C$6,$B19,$A18,$A19,'Cement Volumes & Prices'!$D$6,$A$4,$A20) -> #VALUE! | D19: =_xll.DBRW($A$1,$A$2,D$6,$B19,$A18,$A19,'Cement Volumes & Prices'!$D$6,$A$4,$A20) -> #VALUE! | E19: =_xll.DBRW($A$1,$A$2,E$6,$B19,$A18,$A19,'Cement Volumes & Prices'!$D$6,$A$4,$A20) -> #VALUE! | F19: =_xll.DBRW($A$1,$A$2,F$6,$B19,$A18,$A19,'Cement Volumes & Prices'!$D$6,$A$4,$A20) -> #VALUE! | G19: =_xll.DBRW($A$1,$A$2,G$6,$B19,$A18,$A19,'Cement Volumes & Prices'!$D$6,$A$4,$A20) -> #VALUE! | H19: =_xll.DBRW($A$1,$A$2,H$6,$B19,$A18,$A19,'Cement Volumes & Prices'!$D$6,$A$4,$A20) -> #VALUE! | I19: =_xll.DBRW($A$1,$A$2,I$6,$B19,$A18,$A19,'Cement Volumes & Prices'!$D$6,$A$4,$A20) -> #VALUE! | J19: =_xll.DBRW($A$1,$A$2,J$6,$B19,$A18,$A19,'Cement Volumes & Prices'!$D$6,$A$4,$A20) -> #VALUE! | ... N19: =_xll.DBRW($A$1,$A$2,N$6,$B19,$A18,$A19,'Cement Volumes & Prices'!$D$6,$A$4,$A20) -> #VALUE!
A20: =_xll.SUBNM("CONS_VC:REV.M.100.Revenue_Consolidated","Default","Sales Volume [kt]") -> Sales Volume [kt] | B20: ='Cement Volumes & Prices'!$X$6 -> #N/A | C20: =_xll.DBRW($A$1,$A$2,C$6,$B20,$A18,$A19,'Cement Volumes & Prices'!$D$6,$A$4,$A20) -> #VALUE! | D20: =_xll.DBRW($A$1,$A$2,D$6,$B20,$A18,$A19,'Cement Volumes & Prices'!$D$6,$A$4,$A20) -> #VALUE! | E20: =_xll.DBRW($A$1,$A$2,E$6,$B20,$A18,$A19,'Cement Volumes & Prices'!$D$6,$A$4,$A20) -> #VALUE! | F20: =_xll.DBRW($A$1,$A$2,F$6,$B20,$A18,$A19,'Cement Volumes & Prices'!$D$6,$A$4,$A20) -> #VALUE! | G20: =_xll.DBRW($A$1,$A$2,G$6,$B20,$A18,$A19,'Cement Volumes & Prices'!$D$6,$A$4,$A20) -> #VALUE! | H20: =_xll.DBRW($A$1,$A$2,H$6,$B20,$A18,$A19,'Cement Volumes & Prices'!$D$6,$A$4,$A20) -> #VALUE! | I20: =_xll.DBRW($A$1,$A$2,I$6,$B20,$A18,$A19,'Cement Volumes & Prices'!$D$6,$A$4,$A20) -> #VALUE! | J20: =_xll.DBRW($A$1,$A$2,J$6,$B20,$A18,$A19,'Cement Volumes & Prices'!$D$6,$A$4,$A20) -> #VALUE! | ... N20: =_xll.DBRW($A$1,$A$2,N$6,$B20,$A18,$A19,'Cement Volumes & Prices'!$D$6,$A$4,$A20) -> #VALUE!
A23: =_xll.SUBNM("CONS_VC:ALL.D.Currency","Default","BRL","MEMBER_NAME") -> BRL | C23: Jan | D23: Feb | E23: Mar | F23: Apr | G23: May | H23: Jun | I23: Jul | J23: Aug | K23: Sep | L23: Oct | M23: Nov | N23: Dec
A24: =_xll.SUBNM("CONS_VC:ALL.D.Region","Default","VCBR","MEMBER_NAME") -> VCBR | B24: ='Cement Volumes & Prices'!$V$6 -> #N/A | C24: =_xll.DBRW($A$1,$A$2,C$6,$B24,$A23,$A24,'Cement Volumes & Prices'!$D$6,$A$4,$A25) -> #VALUE! | D24: =_xll.DBRW($A$1,$A$2,D$6,$B24,$A23,$A24,'Cement Volumes & Prices'!$D$6,$A$4,$A25) -> #VALUE! | E24: =_xll.DBRW($A$1,$A$2,E$6,$B24,$A23,$A24,'Cement Volumes & Prices'!$D$6,$A$4,$A25) -> #VALUE! | F24: =_xll.DBRW($A$1,$A$2,F$6,$B24,$A23,$A24,'Cement Volumes & Prices'!$D$6,$A$4,$A25) -> #VALUE! | G24: =_xll.DBRW($A$1,$A$2,G$6,$B24,$A23,$A24,'Cement Volumes & Prices'!$D$6,$A$4,$A25) -> #VALUE! | H24: =_xll.DBRW($A$1,$A$2,H$6,$B24,$A23,$A24,'Cement Volumes & Prices'!$D$6,$A$4,$A25) -> #VALUE! | I24: =_xll.DBRW($A$1,$A$2,I$6,$B24,$A23,$A24,'Cement Volumes & Prices'!$D$6,$A$4,$A25) -> #VALUE! | J24: =_xll.DBRW($A$1,$A$2,J$6,$B24,$A23,$A24,'Cement Volumes & Prices'!$D$6,$A$4,$A25) -> #VALUE! | ... N24: =_xll.DBRW($A$1,$A$2,N$6,$B24,$A23,$A24,'Cement Volumes & Prices'!$D$6,$A$4,$A25) -> #VALUE!
A25: =_xll.SUBNM("CONS_VC:REV.M.100.Revenue_Consolidated","Default","Price Premium [$/ton]") -> Price Premium [$/ton] | B25: ='Cement Volumes & Prices'!$X$6 -> #N/A | C25: =_xll.DBRW($A$1,$A$2,C$6,$B25,$A23,$A24,'Cement Volumes & Prices'!$D$6,$A$4,$A25) -> #VALUE! | D25: =_xll.DBRW($A$1,$A$2,D$6,$B25,$A23,$A24,'Cement Volumes & Prices'!$D$6,$A$4,$A25) -> #VALUE! | E25: =_xll.DBRW($A$1,$A$2,E$6,$B25,$A23,$A24,'Cement Volumes & Prices'!$D$6,$A$4,$A25) -> #VALUE! | F25: =_xll.DBRW($A$1,$A$2,F$6,$B25,$A23,$A24,'Cement Volumes & Prices'!$D$6,$A$4,$A25) -> #VALUE! | G25: =_xll.DBRW($A$1,$A$2,G$6,$B25,$A23,$A24,'Cement Volumes & Prices'!$D$6,$A$4,$A25) -> #VALUE! | H25: =_xll.DBRW($A$1,$A$2,H$6,$B25,$A23,$A24,'Cement Volumes & Prices'!$D$6,$A$4,$A25) -> #VALUE! | I25: =_xll.DBRW($A$1,$A$2,I$6,$B25,$A23,$A24,'Cement Volumes & Prices'!$D$6,$A$4,$A25) -> #VALUE! | J25: =_xll.DBRW($A$1,$A$2,J$6,$B25,$A23,$A24,'Cement Volumes & Prices'!$D$6,$A$4,$A25) -> #VALUE! | ... N25: =_xll.DBRW($A$1,$A$2,N$6,$B25,$A23,$A24,'Cement Volumes & Prices'!$D$6,$A$4,$A25) -> #VALUE!
A27: =_xll.SUBNM("CONS_VC:ALL.D.Currency","Default","USD","MEMBER_NAME") -> USD | C27: Jan | D27: Feb | E27: Mar | F27: Apr | G27: May | H27: Jun | I27: Jul | J27: Aug | K27: Sep | L27: Oct | M27: Nov | N27: Dec
A28: =_xll.SUBNM("CONS_VC:ALL.D.Region","Default","VCNA","MEMBER_NAME") -> VCNA | B28: ='Cement Volumes & Prices'!$V$6 -> #N/A | C28: =_xll.DBRW($A$1,$A$2,C$6,$B28,$A27,$A28,'Cement Volumes & Prices'!$D$6,$A$4,$A29) -> #VALUE! | D28: =_xll.DBRW($A$1,$A$2,D$6,$B28,$A27,$A28,'Cement Volumes & Prices'!$D$6,$A$4,$A29) -> #VALUE! | E28: =_xll.DBRW($A$1,$A$2,E$6,$B28,$A27,$A28,'Cement Volumes & Prices'!$D$6,$A$4,$A29) -> #VALUE! | F28: =_xll.DBRW($A$1,$A$2,F$6,$B28,$A27,$A28,'Cement Volumes & Prices'!$D$6,$A$4,$A29) -> #VALUE! | G28: =_xll.DBRW($A$1,$A$2,G$6,$B28,$A27,$A28,'Cement Volumes & Prices'!$D$6,$A$4,$A29) -> #VALUE! | H28: =_xll.DBRW($A$1,$A$2,H$6,$B28,$A27,$A28,'Cement Volumes & Prices'!$D$6,$A$4,$A29) -> #VALUE! | I28: =_xll.DBRW($A$1,$A$2,I$6,$B28,$A27,$A28,'Cement Volumes & Prices'!$D$6,$A$4,$A29) -> #VALUE! | J28: =_xll.DBRW($A$1,$A$2,J$6,$B28,$A27,$A28,'Cement Volumes & Prices'!$D$6,$A$4,$A29) -> #VALUE! | ... N28: =_xll.DBRW($A$1,$A$2,N$6,$B28,$A27,$A28,'Cement Volumes & Prices'!$D$6,$A$4,$A29) -> #VALUE!
A29: =_xll.SUBNM("CONS_VC:REV.M.100.Revenue_Consolidated","Default","Price Premium [$/ton]") -> Price Premium [$/ton] | B29: ='Cement Volumes & Prices'!$X$6 -> #N/A | C29: =_xll.DBRW($A$1,$A$2,C$6,$B29,$A27,$A28,'Cement Volumes & Prices'!$D$6,$A$4,$A29) -> #VALUE! | D29: =_xll.DBRW($A$1,$A$2,D$6,$B29,$A27,$A28,'Cement Volumes & Prices'!$D$6,$A$4,$A29) -> #VALUE! | E29: =_xll.DBRW($A$1,$A$2,E$6,$B29,$A27,$A28,'Cement Volumes & Prices'!$D$6,$A$4,$A29) -> #VALUE! | F29: =_xll.DBRW($A$1,$A$2,F$6,$B29,$A27,$A28,'Cement Volumes & Prices'!$D$6,$A$4,$A29) -> #VALUE! | G29: =_xll.DBRW($A$1,$A$2,G$6,$B29,$A27,$A28,'Cement Volumes & Prices'!$D$6,$A$4,$A29) -> #VALUE! | H29: =_xll.DBRW($A$1,$A$2,H$6,$B29,$A27,$A28,'Cement Volumes & Prices'!$D$6,$A$4,$A29) -> #VALUE! | I29: =_xll.DBRW($A$1,$A$2,I$6,$B29,$A27,$A28,'Cement Volumes & Prices'!$D$6,$A$4,$A29) -> #VALUE! | J29: =_xll.DBRW($A$1,$A$2,J$6,$B29,$A27,$A28,'Cement Volumes & Prices'!$D$6,$A$4,$A29) -> #VALUE! | ... N29: =_xll.DBRW($A$1,$A$2,N$6,$B29,$A27,$A28,'Cement Volumes & Prices'!$D$6,$A$4,$A29) -> #VALUE!
A31: =_xll.SUBNM("CONS_VC:ALL.D.Currency","Default","EUR","MEMBER_NAME") -> EUR | C31: Jan | D31: Feb | E31: Mar | F31: Apr | G31: May | H31: Jun | I31: Jul | J31: Aug | K31: Sep | L31: Oct | M31: Nov | N31: Dec
A32: =_xll.SUBNM("CONS_VC:ALL.D.Region","Default","VCEAA","MEMBER_NAME") -> VCEAA | B32: ='Cement Volumes & Prices'!$V$6 -> #N/A | C32: =_xll.DBRW($A$1,$A$2,C$6,$B32,$A31,$A32,'Cement Volumes & Prices'!$D$6,$A$4,$A33) -> #VALUE! | D32: =_xll.DBRW($A$1,$A$2,D$6,$B32,$A31,$A32,'Cement Volumes & Prices'!$D$6,$A$4,$A33) -> #VALUE! | E32: =_xll.DBRW($A$1,$A$2,E$6,$B32,$A31,$A32,'Cement Volumes & Prices'!$D$6,$A$4,$A33) -> #VALUE! | F32: =_xll.DBRW($A$1,$A$2,F$6,$B32,$A31,$A32,'Cement Volumes & Prices'!$D$6,$A$4,$A33) -> #VALUE! | G32: =_xll.DBRW($A$1,$A$2,G$6,$B32,$A31,$A32,'Cement Volumes & Prices'!$D$6,$A$4,$A33) -> #VALUE! | H32: =_xll.DBRW($A$1,$A$2,H$6,$B32,$A31,$A32,'Cement Volumes & Prices'!$D$6,$A$4,$A33) -> #VALUE! | I32: =_xll.DBRW($A$1,$A$2,I$6,$B32,$A31,$A32,'Cement Volumes & Prices'!$D$6,$A$4,$A33) -> #VALUE! | J32: =_xll.DBRW($A$1,$A$2,J$6,$B32,$A31,$A32,'Cement Volumes & Prices'!$D$6,$A$4,$A33) -> #VALUE! | ... N32: =_xll.DBRW($A$1,$A$2,N$6,$B32,$A31,$A32,'Cement Volumes & Prices'!$D$6,$A$4,$A33) -> #VALUE!
A33: =_xll.SUBNM("CONS_VC:REV.M.100.Revenue_Consolidated","Default","Price Premium [$/ton]") -> Price Premium [$/ton] | B33: ='Cement Volumes & Prices'!$X$6 -> #N/A | C33: =_xll.DBRW($A$1,$A$2,C$6,$B33,$A31,$A32,'Cement Volumes & Prices'!$D$6,$A$4,$A33) -> #VALUE! | D33: =_xll.DBRW($A$1,$A$2,D$6,$B33,$A31,$A32,'Cement Volumes & Prices'!$D$6,$A$4,$A33) -> #VALUE! | E33: =_xll.DBRW($A$1,$A$2,E$6,$B33,$A31,$A32,'Cement Volumes & Prices'!$D$6,$A$4,$A33) -> #VALUE! | F33: =_xll.DBRW($A$1,$A$2,F$6,$B33,$A31,$A32,'Cement Volumes & Prices'!$D$6,$A$4,$A33) -> #VALUE! | G33: =_xll.DBRW($A$1,$A$2,G$6,$B33,$A31,$A32,'Cement Volumes & Prices'!$D$6,$A$4,$A33) -> #VALUE! | H33: =_xll.DBRW($A$1,$A$2,H$6,$B33,$A31,$A32,'Cement Volumes & Prices'!$D$6,$A$4,$A33) -> #VALUE! | I33: =_xll.DBRW($A$1,$A$2,I$6,$B33,$A31,$A32,'Cement Volumes & Prices'!$D$6,$A$4,$A33) -> #VALUE! | J33: =_xll.DBRW($A$1,$A$2,J$6,$B33,$A31,$A32,'Cement Volumes & Prices'!$D$6,$A$4,$A33) -> #VALUE! | ... N33: =_xll.DBRW($A$1,$A$2,N$6,$B33,$A31,$A32,'Cement Volumes & Prices'!$D$6,$A$4,$A33) -> #VALUE!
A35: =_xll.SUBNM("CONS_VC:ALL.D.Currency","Default","USD","MEMBER_NAME") -> USD | C35: Jan | D35: Feb | E35: Mar | F35: Apr | G35: May | H35: Jun | I35: Jul | J35: Aug | K35: Sep | L35: Oct | M35: Nov | N35: Dec
A36: =_xll.SUBNM("CONS_VC:ALL.D.Region","Default","VCLATAM Incl. AVEL","MEMBER_NAME") -> VCLATAM Incl. AVEL | B36: ='Cement Volumes & Prices'!$V$6 -> #N/A | C36: =_xll.DBRW($A$1,$A$2,C$6,$B36,$A35,$A36,'Cement Volumes & Prices'!$D$6,$A$4,$A37) -> #VALUE! | D36: =_xll.DBRW($A$1,$A$2,D$6,$B36,$A35,$A36,'Cement Volumes & Prices'!$D$6,$A$4,$A37) -> #VALUE! | E36: =_xll.DBRW($A$1,$A$2,E$6,$B36,$A35,$A36,'Cement Volumes & Prices'!$D$6,$A$4,$A37) -> #VALUE! | F36: =_xll.DBRW($A$1,$A$2,F$6,$B36,$A35,$A36,'Cement Volumes & Prices'!$D$6,$A$4,$A37) -> #VALUE! | G36: =_xll.DBRW($A$1,$A$2,G$6,$B36,$A35,$A36,'Cement Volumes & Prices'!$D$6,$A$4,$A37) -> #VALUE! | H36: =_xll.DBRW($A$1,$A$2,H$6,$B36,$A35,$A36,'Cement Volumes & Prices'!$D$6,$A$4,$A37) -> #VALUE! | I36: =_xll.DBRW($A$1,$A$2,I$6,$B36,$A35,$A36,'Cement Volumes & Prices'!$D$6,$A$4,$A37) -> #VALUE! | J36: =_xll.DBRW($A$1,$A$2,J$6,$B36,$A35,$A36,'Cement Volumes & Prices'!$D$6,$A$4,$A37) -> #VALUE! | ... N36: =_xll.DBRW($A$1,$A$2,N$6,$B36,$A35,$A36,'Cement Volumes & Prices'!$D$6,$A$4,$A37) -> #VALUE!
A37: =_xll.SUBNM("CONS_VC:REV.M.100.Revenue_Consolidated","Default","Price Premium [$/ton]") -> Price Premium [$/ton] | B37: ='Cement Volumes & Prices'!$X$6 -> #N/A | C37: =_xll.DBRW($A$1,$A$2,C$6,$B37,$A35,$A36,'Cement Volumes & Prices'!$D$6,$A$4,$A37) -> #VALUE! | D37: =_xll.DBRW($A$1,$A$2,D$6,$B37,$A35,$A36,'Cement Volumes & Prices'!$D$6,$A$4,$A37) -> #VALUE! | E37: =_xll.DBRW($A$1,$A$2,E$6,$B37,$A35,$A36,'Cement Volumes & Prices'!$D$6,$A$4,$A37) -> #VALUE! | F37: =_xll.DBRW($A$1,$A$2,F$6,$B37,$A35,$A36,'Cement Volumes & Prices'!$D$6,$A$4,$A37) -> #VALUE! | G37: =_xll.DBRW($A$1,$A$2,G$6,$B37,$A35,$A36,'Cement Volumes & Prices'!$D$6,$A$4,$A37) -> #VALUE! | H37: =_xll.DBRW($A$1,$A$2,H$6,$B37,$A35,$A36,'Cement Volumes & Prices'!$D$6,$A$4,$A37) -> #VALUE! | I37: =_xll.DBRW($A$1,$A$2,I$6,$B37,$A35,$A36,'Cement Volumes & Prices'!$D$6,$A$4,$A37) -> #VALUE! | J37: =_xll.DBRW($A$1,$A$2,J$6,$B37,$A35,$A36,'Cement Volumes & Prices'!$D$6,$A$4,$A37) -> #VALUE! | ... N37: =_xll.DBRW($A$1,$A$2,N$6,$B37,$A35,$A36,'Cement Volumes & Prices'!$D$6,$A$4,$A37) -> #VALUE!

Sheet Cement Volumes & Prices
B1: Volume & Prices - Overview
C6: Product: | D6: =_xll.SUBNM("CONS_VC_PRD:ALL.D.Products","Products","Cement Group","Código e Descrição") -> #N/A | S6: Year: | T6: =_xll.SUBNM("CONS_VC_PRD:ALL.D.Year","Sys_Picklist","2026","MEMBER_NAME") -> #N/A | V6: =_xll.SUBNM("CONS_VC_PRD:ALL.D.Version","Sys.Report","L300","Descrição") -> #N/A | X6: =_xll.SUBNM("CONS_VC_PRD:ALL.D.Version","Sys.Report","RF","Descrição") -> #N/A
C8: Volumes | O8: Price

Sheet EBITDA - Fx
A1: CONS_VC:ALL.010.Economic_Assumptions
A2: CONS_VC:DFS.100.Profit_and_Loss
A3: Year
A4: =EBITDA!M6 -> #N/A
A5: =_xll.SUBNM("CONS_VC:DFS.M.100.Profit_and_Loss",,"Total Value") -> Total Value
A6: =_xll.SUBNM("CONS_VC:ALL.D.Version","Sys.Report","Actual","Descrição") -> Actual | C6: =EBITDA!C6 -> #N/A
A7: =EBITDA!X6 -> #N/A
A8: =EBITDA!R6 -> #N/A
A9: =_xll.SUBNM("CONS_VC:ALL.D.Products",,"Total Products") -> Total Products
A12: Quarter View | C12: Q1 | D12: Q2 | E12: Q3 | F12: Q4 | H12: Full Year View | J12: Versão | K12: =EBITDA!$AI$6 -> #N/A | L12: L300 | M12: =EBITDA!$AM$6 -> #N/A | N12: =EBITDA!$AM$6 -> #N/A | O12: =EBITDA!$AM$6 -> #N/A | P12: =EBITDA!$AM$6 -> #N/A | Q12: =EBITDA!$AM$6 -> #N/A | R12: =EBITDA!$AI$6 -> #N/A | S12: =EBITDA!$AM$6 -> #N/A
A13: =EBITDA!$AI$6 -> #N/A | B13: =$A$4-1 -> #N/A | C13: =_xll.DBRW($A$2,$B$13,C$12,$A13,$A$7,$A$8,$A$9,$C$6,$A$5) -> #VALUE! | D13: =_xll.DBRW($A$2,$B$13,D$12,$A13,$A$7,$A$8,$A$9,$C$6,$A$5) -> #VALUE! | E13: =_xll.DBRW($A$2,$B$13,E$12,$A13,$A$7,$A$8,$A$9,$C$6,$A$5) -> #VALUE! | F13: =_xll.DBRW($A$2,$B$13,F$12,$A13,$A$7,$A$8,$A$9,$C$6,$A$5) -> #VALUE! | J13: Empresa | K13: Global | L13: Global | M13: VCBR | N13: VCNA | O13: VCEAA | P13: VCLATAM | Q13: VCOTHERS | R13: Fx | S13: Global
A14: =EBITDA!$AK$6 -> #N/A | B14: =$A$4 -> #N/A | C14: =_xll.DBRW($A$2,$A$4,C$12,$A14,$A$7,$A$8,$A$9,$C$6,$A$5) -> #VALUE! | D14: =_xll.DBRW($A$2,$A$4,D$12,$A14,$A$7,$A$8,$A$9,$C$6,$A$5) -> #VALUE! | E14: =_xll.DBRW($A$2,$A$4,E$12,$A14,$A$7,$A$8,$A$9,$C$6,$A$5) -> #VALUE! | F14: =_xll.DBRW($A$2,$A$4,F$12,$A14,$A$7,$A$8,$A$9,$C$6,$A$5) -> #VALUE! | K14: =A4-1 -> #N/A | L14: L300 | M14: VCBR | N14: VCNA | O14: VCEA | P14: VCLATAM | Q14: Others | R14: FX | S14: =A4 -> #N/A
A15: =EBITDA!$AM$6 -> #N/A | B15: =$A$4 -> #N/A | C15: =_xll.DBRW($A$2,$A$4,C$12,$A15,$A$7,$A$8,$A$9,$C$6,$A$5) -> #VALUE! | D15: =_xll.DBRW($A$2,$A$4,D$12,$A15,$A$7,$A$8,$A$9,$C$6,$A$5) -> #VALUE! | E15: =_xll.DBRW($A$2,$A$4,E$12,$A15,$A$7,$A$8,$A$9,$C$6,$A$5) -> #VALUE! | F15: =_xll.DBRW($A$2,$A$4,F$12,$A15,$A$7,$A$8,$A$9,$C$6,$A$5) -> #VALUE! | K15: =_xll.DBRW($A$2,$K$14,$A$3,K$12,EBITDA!$X$6,K$13,$A$9,$C$6,$A$5) -> #VALUE! | L15: =_xll.DBRW($A$2,$A$4,$A$3,L$12,EBITDA!$X$6,L$13,$A$9,$C$6,$A$5) -> #VALUE! | M15: =_xll.DBRW($A$2,$A$4,$A$3,M$12,EBITDA!$X$6,M$13,$A$9,$C$6,$A$5) -> #VALUE! | N15: =_xll.DBRW($A$2,$A$4,$A$3,N$12,EBITDA!$X$6,N$13,$A$9,$C$6,$A$5) -> #VALUE! | O15: =_xll.DBRW($A$2,$A$4,$A$3,O$12,EBITDA!$X$6,O$13,$A$9,$C$6,$A$5) -> #VALUE! | P15: =_xll.DBRW($A$2,$A$4,$A$3,P$12,EBITDA!$X$6,P$13,$A$9,$C$6,$A$5) -> #VALUE! | Q15: =_xll.DBRW($A$2,$A$4,$A$3,Q$12,EBITDA!$X$6,Q$13,$A$9,$C$6,$A$5) -> #VALUE! | R15: =_xll.DBRW($A$2,$A$4,$A$3,R$12,EBITDA!$X$6,R$13,$A$9,$C$6,$A$5) -> #VALUE! | S15: =_xll.DBRW($A$2,$A$4,$A$3,S$12,EBITDA!$X$6,S$13,$A$9,$C$6,$A$5) -> #VALUE!
J16: =EBITDA!AK6 -> #N/A | M16: =_xll.DBRW($A$2,$A$4,$A$3,$J$16,EBITDA!$X$6,M$13,$A$9,$C$6,$A$5) -> #VALUE! | N16: =_xll.DBRW($A$2,$A$4,$A$3,$J$16,EBITDA!$X$6,N$13,$A$9,$C$6,$A$5) -> #VALUE! | O16: =_xll.DBRW($A$2,$A$4,$A$3,$J$16,EBITDA!$X$6,O$13,$A$9,$C$6,$A$5) -> #VALUE! | P16: =_xll.DBRW($A$2,$A$4,$A$3,$J$16,EBITDA!$X$6,P$13,$A$9,$C$6,$A$5) -> #VALUE! | Q16: =_xll.DBRW($A$2,$A$4,$A$3,$J$16,EBITDA!$X$6,Q$13,$A$9,$C$6,$A$5) -> #VALUE!
A20: EBITDA/Net Revenue (%) | C20: Q1 | D20: Q2 | E20: Q3 | F20: Q4
A21: =EBITDA!$AI$6 -> #N/A | B21: =$A$4-1 -> #N/A | C21: =_xll.DBRW($A$2,$B21,C$20,$A21,$A$7,$A$8,$A$9,$A$20,$A$5) -> #VALUE! | D21: =_xll.DBRW($A$2,$B21,D$20,$A21,$A$7,$A$8,$A$9,$A$20,$A$5) -> #VALUE! | E21: =_xll.DBRW($A$2,$B21,E$20,$A21,$A$7,$A$8,$A$9,$A$20,$A$5) -> #VALUE! | F21: =_xll.DBRW($A$2,$B21,F$20,$A21,$A$7,$A$8,$A$9,$A$20,$A$5) -> #VALUE! | K21: =_xll.DBRW($A$2,$B21,A$3,$A21,$A$7,$A$8,$A$9,$A$20,$A$5) -> #VALUE! | L21: =_xll.DBRW($A$2,$B22,A$3,$A22,$A$7,$A$8,$A$9,$A$20,$A$5) -> #VALUE! | S21: =_xll.DBRW($A$2,$B23,A$3,$A23,$A$7,$A$8,$A$9,$A$20,$A$5) -> #VALUE!
A22: =EBITDA!$AK$6 -> #N/A | B22: =$A$4 -> #N/A | C22: =_xll.DBRW($A$2,$B22,C$20,$A22,$A$7,$A$8,$A$9,$A$20,$A$5) -> #VALUE! | D22: =_xll.DBRW($A$2,$B22,D$20,$A22,$A$7,$A$8,$A$9,$A$20,$A$5) -> #VALUE! | E22: =_xll.DBRW($A$2,$B22,E$20,$A22,$A$7,$A$8,$A$9,$A$20,$A$5) -> #VALUE! | F22: =_xll.DBRW($A$2,$B22,F$20,$A22,$A$7,$A$8,$A$9,$A$20,$A$5) -> #VALUE!
A23: =EBITDA!$AM$6 -> #N/A | B23: =$A$4 -> #N/A | C23: =_xll.DBRW($A$2,$B23,C$20,$A23,$A$7,$A$8,$A$9,$A$20,$A$5) -> #VALUE! | D23: =_xll.DBRW($A$2,$B23,D$20,$A23,$A$7,$A$8,$A$9,$A$20,$A$5) -> #VALUE! | E23: =_xll.DBRW($A$2,$B23,E$20,$A23,$A$7,$A$8,$A$9,$A$20,$A$5) -> #VALUE! | F23: =_xll.DBRW($A$2,$B23,F$20,$A23,$A$7,$A$8,$A$9,$A$20,$A$5) -> #VALUE!
C26: Year | D26: Year | E26: Year
A27: Value | C27: =A21 -> #N/A | D27: =A22 -> #N/A | E27: =A23 -> #N/A
C28: =B21 -> #N/A | D28: =B22 -> #N/A | E28: =B23 -> #N/A
A29: Average FX Rate R$/US$ | C29: =_xll.DBRW($A$1,C$28,C$26,C$27,$A29,$A$27) -> #VALUE! | D29: =_xll.DBRW($A$1,D$28,D$26,D$27,$A29,$A$27) -> #VALUE! | E29: =_xll.DBRW($A$1,E$28,E$26,E$27,$A29,$A$27) -> #VALUE!
A30: Avg. FX BRL/EUR | C30: =_xll.DBRW($A$1,C$28,C$26,C$27,$A30,$A$27) -> #VALUE! | D30: =_xll.DBRW($A$1,D$28,D$26,D$27,$A30,$A$27) -> #VALUE! | E30: =_xll.DBRW($A$1,E$28,E$26,E$27,$A30,$A$27) -> #VALUE!
A31: Brazilian CPI | C31: =_xll.DBRW($A$1,C$28,C$26,C$27,$A31,$A$27) -> #VALUE! | D31: =_xll.DBRW($A$1,D$28,D$26,D$27,$A31,$A$27) -> #VALUE! | E31: =_xll.DBRW($A$1,E$28,E$26,E$27,$A31,$A$27) -> #VALUE!
A32: American CPI | C32: =_xll.DBRW($A$1,C$28,C$26,C$27,$A32,$A$27) -> #VALUE! | D32: =_xll.DBRW($A$1,D$28,D$26,D$27,$A32,$A$27) -> #VALUE! | E32: =_xll.DBRW($A$1,E$28,E$26,E$27,$A32,$A$27) -> #VALUE!
A33: CPI EUR | C33: =_xll.DBRW($A$1,C$28,C$26,C$27,$A33,$A$27) -> #VALUE! | D33: =_xll.DBRW($A$1,D$28,D$26,D$27,$A33,$A$27) -> #VALUE! | E33: =_xll.DBRW($A$1,E$28,E$26,E$27,$A33,$A$27) -> #VALUE!
A34: PACE (USD) | C34: =_xll.DBRW($A$1,C$28,C$26,C$27,$A34,$A$27) -> #VALUE! | D34: =_xll.DBRW($A$1,D$28,D$26,D$27,$A34,$A$27) -> #VALUE! | E34: =_xll.DBRW($A$1,E$28,E$26,E$27,$A34,$A$27) -> #VALUE!

Sheet EBITDA
B1: Quarterly Account Analysis by Region
C6: =_xll.SUBNM("CONS_VC_PRD:DFS.D.Accounts_PnL","Default","EBITDA") -> #N/A | M6: =_xll.SUBNM("CONS_VC_PRD:ALL.D.Year","","2025") -> #N/A | R6: =_xll.SUBNM("CONS_VC_PRD:ALL.D.Region","Default","Global") -> #N/A | X6: =_xll.SUBNM("CONS_VC_PRD:ALL.D.Currency","Default","BRL Conv.") -> #N/A | AI6: =_xll.SUBNM("CONS_VC_PRD:ALL.D.Version","Sys.Report","Actual","Descrição") -> #N/A | AK6: =_xll.SUBNM("CONS_VC_PRD:ALL.D.Version","Sys.Report","L300","Descrição") -> #N/A | AM6: =_xll.SUBNM("CONS_VC_PRD:ALL.D.Version","Sys.Report","RF","Descrição") -> #N/A
C8: QoQ Overview | AC8: Full Year
A28: ="Margin "&$C$6 &'EBITDA - Fx'!A10 -> #N/A | D28: ='EBITDA - Fx'!C21 -> #VALUE! | E28: ='EBITDA - Fx'!C22 -> #VALUE! | F28: ='EBITDA - Fx'!C23 -> #VALUE! | I28: ='EBITDA - Fx'!D21 -> #VALUE! | J28: ='EBITDA - Fx'!D22 -> #VALUE! | K28: ='EBITDA - Fx'!D23 -> #VALUE! | M28: ='EBITDA - Fx'!E21 -> #VALUE! | N28: ='EBITDA - Fx'!E22 -> #VALUE! | O28: ='EBITDA - Fx'!E23 -> #VALUE! | R28: ='EBITDA - Fx'!F21 -> #VALUE! | S28: ='EBITDA - Fx'!F22 -> #VALUE! | T28: ='EBITDA - Fx'!F23 -> #VALUE! | AC28: ='EBITDA - Fx'!K21 -> #VALUE! | AD28: ='EBITDA - Fx'!L21 -> #VALUE! | AK28: ='EBITDA - Fx'!S21 -> #VALUE!
N31: ='EBITDA - Fx'!C28 -> #N/A | P31: ='EBITDA - Fx'!D27 -> #N/A | R31: ='EBITDA - Fx'!E28 -> #N/A
I32: Avg.FX Rate R$/US$ | N32: ='EBITDA - Fx'!C29 -> #VALUE! | P32: ='EBITDA - Fx'!D29 -> #VALUE! | R32: ='EBITDA - Fx'!E29 -> #VALUE!
I33: Avg. FX BRL/EUR | N33: ='EBITDA - Fx'!C30 -> #VALUE! | P33: ='EBITDA - Fx'!D30 -> #VALUE! | R33: ='EBITDA - Fx'!E30 -> #VALUE!
I34: IPCA | N34: ='EBITDA - Fx'!C31 -> #VALUE! | P34: ='EBITDA - Fx'!D31 -> #VALUE! | R34: ='EBITDA - Fx'!E31 -> #VALUE!
I35: American CPI | N35: ='EBITDA - Fx'!C32 -> #VALUE! | P35: ='EBITDA - Fx'!D32 -> #VALUE! | R35: ='EBITDA - Fx'!E32 -> #VALUE!
I36: CPI EUR | N36: ='EBITDA - Fx'!C33 -> #VALUE! | P36: ='EBITDA - Fx'!D33 -> #VALUE! | R36: ='EBITDA - Fx'!E33 -> #VALUE!
I37: PACE (USD) | N37: ='EBITDA - Fx'!C34 -> #VALUE! | P37: ='EBITDA - Fx'!D34 -> #VALUE! | R37: ='EBITDA - Fx'!E34 -> #VALUE!

Sheet Net Income - Fx
A1: CONS_VC:ALL.010.Economic_Assumptions
A2: CONS_VC:DFS.100.Profit_and_loss
A3: ALL.D.Year | B3: ='Net Income'!M6 -> #N/A
A4: DFS.M.140.Indirect_Cash_Flow | B4: =_xll.SUBNM("CONS_VC:DFS.M.140.Indirect_Cash_Flow","","Total Value") -> Total Value
A5: DFS.D.Accounts_ICF | B5: ='Net Income'!$C$6 -> #N/A
A6: ALL.D.Currency | B6: ='Net Income'!X6 -> #N/A | G6: =$B$3-1 -> #N/A | H6: =$B$3 -> #N/A | I6: =$B$3 -> #N/A | J6: =$B$3 -> #N/A | K6: =$B$3 -> #N/A | L6: =$B$3 -> #N/A | M6: =$B$3 -> #N/A | N6: =$B$3 -> #N/A | O6: =$B$3 -> #N/A
A7: ALL.D.Region | B7: ='Net Income'!R6 -> #N/A | G7: =$B$5 -> #N/A | H7: =$B$5 -> #N/A | I7: EBITDA | J7: Depreciation | K7: Financial Results | L7: Equity Pickup | M7: Income Tax | N7: FX/Others | O7: =$B$5 -> #N/A
A8: All.d.Products | B8: =_xll.SUBNM("CONS_VC:All.d.Products","Default","Total Products") -> Total Products | G8: Year | H8: Year | I8: Year | J8: Year | K8: Year | L8: Year | M8: Year | N8: Year | O8: Year
B9: Q1 | C9: Q2 | D9: Q3 | E9: Q4 | G9: =$A$10 -> #N/A | H9: =$A$11 -> #N/A | I9: =$A$12 -> #N/A | J9: =$A$12 -> #N/A | K9: =$A$12 -> #N/A | L9: =$A$12 -> #N/A | M9: =$A$12 -> #N/A | N9: =$A$12 -> #N/A | O9: =$A$12 -> #N/A
A10: ='Net Income'!$AI$6 -> #N/A | B10: =_xll.DBRW($A$2,$B$3,B$9,$A10,$B$6,$B$7,$B$8,$B$5,$B$4) -> #VALUE! | C10: =_xll.DBRW($A$2,$B$3,C$9,$A10,$B$6,$B$7,$B$8,$B$5,$B$4) -> #VALUE! | D10: =_xll.DBRW($A$2,$B$3,D$9,$A10,$B$6,$B$7,$B$8,$B$5,$B$4) -> #VALUE! | E10: =_xll.DBRW($A$2,$B$3,E$9,$A10,$B$6,$B$7,$B$8,$B$5,$B$4) -> #VALUE! | G10: =$B$7 -> #N/A | H10: =$B$7 -> #N/A | I10: =$B$7 -> #N/A | J10: =$B$7 -> #N/A | K10: =$B$7 -> #N/A | L10: =$B$7 -> #N/A | M10: =$B$7 -> #N/A | N10: =$B$7 -> #N/A | O10: =$B$7 -> #N/A
A11: ='Net Income'!$AK$6 -> #N/A | B11: =_xll.DBRW($A$2,$B$3,B$9,$A11,$B$6,$B$7,$B$8,$B$5,$B$4) -> #VALUE! | C11: =_xll.DBRW($A$2,$B$3,C$9,$A11,$B$6,$B$7,$B$8,$B$5,$B$4) -> #VALUE! | D11: =_xll.DBRW($A$2,$B$3,D$9,$A11,$B$6,$B$7,$B$8,$B$5,$B$4) -> #VALUE! | E11: =_xll.DBRW($A$2,$B$3,E$9,$A11,$B$6,$B$7,$B$8,$B$5,$B$4) -> #VALUE! | G11: =B3-1 -> #N/A | H11: L300 | I11: EBITDA | J11: Deprec. | K11: Fin. Results | L11: Equity Pickup | M11: Tax | N11: FX/Others | O11: 2025
A12: ='Net Income'!$AM$6 -> #N/A | B12: =_xll.DBRW($A$2,$B$3,B$9,$A12,$B$6,$B$7,$B$8,$B$5,$B$4) -> #VALUE! | C12: =_xll.DBRW($A$2,$B$3,C$9,$A12,$B$6,$B$7,$B$8,$B$5,$B$4) -> #VALUE! | D12: =_xll.DBRW($A$2,$B$3,D$9,$A12,$B$6,$B$7,$B$8,$B$5,$B$4) -> #VALUE! | E12: =_xll.DBRW($A$2,$B$3,E$9,$A12,$B$6,$B$7,$B$8,$B$5,$B$4) -> #VALUE! | G12: =_xll.DBRW($A$2,G$6,G$8,G9,$B$6,G$10,$B$8,G$7,$B$4) -> #VALUE! | H12: =_xll.DBRW($A$2,H$6,H$8,H9,$B$6,H$10,$B$8,H$7,$B$4) -> #VALUE! | I12: =_xll.DBRW($A$2,I$6,I$8,I9,$B$6,I$10,$B$8,I$7,$B$4) -> #VALUE! | J12: =_xll.DBRW($A$2,J$6,J$8,J9,$B$6,J$10,$B$8,J$7,$B$4) -> #VALUE! | K12: =_xll.DBRW($A$2,K$6,K$8,K9,$B$6,K$10,$B$8,K$7,$B$4) -> #VALUE! | L12: =_xll.DBRW($A$2,L$6,L$8,L9,$B$6,L$10,$B$8,L$7,$B$4) -> #VALUE! | M12: =_xll.DBRW($A$2,M$6,M$8,M9,$B$6,M$10,$B$8,M$7,$B$4) -> #VALUE! | N12: =_xll.DBRW($A$2,N$6,N$8,N9,$B$6,N$10,$B$8,N$7,$B$4) -> #VALUE! | O12: =_xll.DBRW($A$2,O$6,O$8,O9,$B$6,O$10,$B$8,B$5,$B$4) -> #VALUE!
A20: Net Revenue | C20: Q1 | D20: Q2 | E20: Q3 | F20: Q4
A21: =EBITDA!$AI$6 -> #N/A | B21: =G6 -> #N/A | C21: =_xll.DBRW($A$2,$B21,C$20,$A21,$B$6,$B$7,$B$8,$B$5,$B$4)/_xll.DBRW($A$2,$B21,C$20,$A21,$B$6,$B$7,$B$8,$A$20,$B$4) -> #VALUE! | D21: =_xll.DBRW($A$2,$B21,D$20,$A21,$B$6,$B$7,$B$8,$B$5,$B$4)/_xll.DBRW($A$2,$B21,D$20,$A21,$B$6,$B$7,$B$8,$A$20,$B$4) -> #VALUE! | E21: =_xll.DBRW($A$2,$B21,E$20,$A21,$B$6,$B$7,$B$8,$B$5,$B$4)/_xll.DBRW($A$2,$B21,E$20,$A21,$B$6,$B$7,$B$8,$A$20,$B$4) -> #VALUE! | F21: =_xll.DBRW($A$2,$B21,F$20,$A21,$B$6,$B$7,$B$8,$B$5,$B$4)/_xll.DBRW($A$2,$B21,F$20,$A21,$B$6,$B$7,$B$8,$A$20,$B$4) -> #VALUE! | G21: =_xll.DBRW($A$2,$B21,G$8,$A21,$B$6,$B$7,$B$8,$B$5,$B$4)/_xll.DBRW($A$2,$B21,G$8,$A21,$B$6,$B$7,$B$8,$A$20,$B$4) -> #VALUE! | H21: =_xll.DBRW($A$2,$B22,H$8,$A22,$B$6,$B$7,$B$8,$B$5,$B$4)/_xll.DBRW($A$2,$B22,H$8,$A22,$B$6,$B$7,$B$8,$A$20,$B$4) -> #VALUE! | O21: =_xll.DBRW($A$2,$B23,O$8,$A23,$B$6,$B$7,$B$8,$B$5,$B$4)/_xll.DBRW($A$2,$B23,O$8,$A23,$B$6,$B$7,$B$8,$A$20,$B$4) -> #VALUE!
A22: =EBITDA!$AK$6 -> #N/A | B22: =I6 -> #N/A | C22: =_xll.DBRW($A$2,$B22,C$20,$A22,$B$6,$B$7,$B$8,$B$5,$B$4)/_xll.DBRW($A$2,$B22,C$20,$A22,$B$6,$B$7,$B$8,$A$20,$B$4) -> #VALUE! | D22: =_xll.DBRW($A$2,$B22,D$20,$A22,$B$6,$B$7,$B$8,$B$5,$B$4)/_xll.DBRW($A$2,$B22,D$20,$A22,$B$6,$B$7,$B$8,$A$20,$B$4) -> #VALUE! | E22: =_xll.DBRW($A$2,$B22,E$20,$A22,$B$6,$B$7,$B$8,$B$5,$B$4)/_xll.DBRW($A$2,$B22,E$20,$A22,$B$6,$B$7,$B$8,$A$20,$B$4) -> #VALUE! | F22: =_xll.DBRW($A$2,$B22,F$20,$A22,$B$6,$B$7,$B$8,$B$5,$B$4)/_xll.DBRW($A$2,$B22,F$20,$A22,$B$6,$B$7,$B$8,$A$20,$B$4) -> #VALUE!
A23: =EBITDA!$AM$6 -> #N/A | B23: =I6 -> #N/A | C23: =_xll.DBRW($A$2,$B23,C$20,$A23,$B$6,$B$7,$B$8,$B$5,$B$4)/_xll.DBRW($A$2,$B23,C$20,$A23,$B$6,$B$7,$B$8,$A$20,$B$4) -> #VALUE! | D23: =_xll.DBRW($A$2,$B23,D$20,$A23,$B$6,$B$7,$B$8,$B$5,$B$4)/_xll.DBRW($A$2,$B23,D$20,$A23,$B$6,$B$7,$B$8,$A$20,$B$4) -> #VALUE! | E23: =_xll.DBRW($A$2,$B23,E$20,$A23,$B$6,$B$7,$B$8,$B$5,$B$4)/_xll.DBRW($A$2,$B23,E$20,$A23,$B$6,$B$7,$B$8,$A$20,$B$4) -> #VALUE! | F23: =_xll.DBRW($A$2,$B23,F$20,$A23,$B$6,$B$7,$B$8,$B$5,$B$4)/_xll.DBRW($A$2,$B23,F$20,$A23,$B$6,$B$7,$B$8,$A$20,$B$4) -> #VALUE!
C27: Year | D27: Year | E27: Year
A28: Value | C28: =A10 -> #N/A | D28: =A11 -> #N/A | E28: =A12 -> #N/A
C29: =G6 -> #N/A | D29: =H6 -> #N/A | E29: =H6 -> #N/A
A30: VCBR | C30: =_xll.DBRW($A$2,C$29,C$27,C$28,$B$6,$A30,$B$8,$B$5,$B$4) -> #VALUE! | D30: =_xll.DBRW($A$2,D$29,D$27,D$28,$B$6,$A30,$B$8,$B$5,$B$4) -> #VALUE! | E30: =_xll.DBRW($A$2,E$29,E$27,E$28,$B$6,$A30,$B$8,$B$5,$B$4) -> #VALUE!
A31: VCNA | C31: =_xll.DBRW($A$2,C$29,C$27,C$28,$B$6,$A31,$B$8,$B$5,$B$4) -> #VALUE! | D31: =_xll.DBRW($A$2,D$29,D$27,D$28,$B$6,$A31,$B$8,$B$5,$B$4) -> #VALUE! | E31: =_xll.DBRW($A$2,E$29,E$27,E$28,$B$6,$A31,$B$8,$B$5,$B$4) -> #VALUE!
A32: VCEAA | C32: =_xll.DBRW($A$2,C$29,C$27,C$28,$B$6,$A32,$B$8,$B$5,$B$4) -> #VALUE! | D32: =_xll.DBRW($A$2,D$29,D$27,D$28,$B$6,$A32,$B$8,$B$5,$B$4) -> #VALUE! | E32: =_xll.DBRW($A$2,E$29,E$27,E$28,$B$6,$A32,$B$8,$B$5,$B$4) -> #VALUE!
A33: VCLatam | C33: =_xll.DBRW($A$2,C$29,C$27,C$28,$B$6,$A33,$B$8,$B$5,$B$4) -> #VALUE! | D33: =_xll.DBRW($A$2,D$29,D$27,D$28,$B$6,$A33,$B$8,$B$5,$B$4) -> #VALUE! | E33: =_xll.DBRW($A$2,E$29,E$27,E$28,$B$6,$A33,$B$8,$B$5,$B$4) -> #VALUE!
A34: VCothers | C34: =_xll.DBRW($A$2,C$29,C$27,C$28,$B$6,$A34,$B$8,$B$5,$B$4) -> #VALUE! | D34: =_xll.DBRW($A$2,D$29,D$27,D$28,$B$6,$A34,$B$8,$B$5,$B$4) -> #VALUE! | E34: =_xll.DBRW($A$2,E$29,E$27,E$28,$B$6,$A34,$B$8,$B$5,$B$4) -> #VALUE!

Sheet Net Income
B1: Quarterly Account Analysis by Region
C6: =_xll.SUBNM("CONS_VC_PRD:DFS.D.Accounts_Pnl","Default","Net Profit") -> #N/A | M6: =_xll.SUBNM("CONS_VC_PRD:ALL.D.Year","","2025") -> #N/A | R6: =_xll.SUBNM("CONS_VC_PRD:ALL.D.Region","Default","Global") -> #N/A | X6: =_xll.SUBNM("CONS_VC_PRD:ALL.D.Currency","","BRL Conv.") -> #N/A | AI6: =_xll.SUBNM("CONS_VC_PRD:ALL.D.Version","Sys.Report","Actual","Descrição") -> #N/A | AK6: =_xll.SUBNM("CONS_VC_PRD:ALL.D.Version","Sys.Report","L300","Descrição") -> #N/A | AM6: =_xll.SUBNM("CONS_VC_PRD:ALL.D.Version","Sys.Report","RF","Descrição") -> #N/A
C8: QoQ Overview | AC8: Full Year
A28: ="Margin "&$C$6 &'Net Income - Fx'!A10 -> #N/A | E28: ='Net Income - Fx'!C21 -> #VALUE! | F28: ='Net Income - Fx'!C22 -> #VALUE! | G28: ='Net Income - Fx'!C23 -> #VALUE! | J28: ='Net Income - Fx'!D21 -> #VALUE! | K28: ='Net Income - Fx'!D22 -> #VALUE! | L28: ='Net Income - Fx'!D23 -> #VALUE! | N28: ='Net Income - Fx'!E21 -> #VALUE! | O28: ='Net Income - Fx'!E22 -> #VALUE! | P28: ='Net Income - Fx'!E23 -> #VALUE! | S28: ='Net Income - Fx'!F21 -> #VALUE! | T28: ='Net Income - Fx'!F22 -> #VALUE! | U28: ='Net Income - Fx'!F23 -> #VALUE! | AC28: ='Net Income - Fx'!G21 -> #VALUE! | AD28: ='Net Income - Fx'!H21 -> #VALUE! | AK28: ='Net Income - Fx'!O21 -> #VALUE!
N31: ='Net Income - Fx'!C29 -> #N/A | P31: ='Net Income - Fx'!D28 -> #N/A | R31: ='Net Income - Fx'!E29 -> #N/A
I32: VCBR | N32: ='Net Income - Fx'!C30 -> #VALUE! | P32: ='Net Income - Fx'!D30 -> #VALUE! | R32: ='Net Income - Fx'!E30 -> #VALUE!
I33: VCNA | N33: ='Net Income - Fx'!C31 -> #VALUE! | P33: ='Net Income - Fx'!D31 -> #VALUE! | R33: ='Net Income - Fx'!E31 -> #VALUE!
I34: VCEA | N34: ='Net Income - Fx'!C32 -> #VALUE! | P34: ='Net Income - Fx'!D32 -> #VALUE! | R34: ='Net Income - Fx'!E32 -> #VALUE!
I35: VCLatam | N35: ='Net Income - Fx'!C33 -> #VALUE! | P35: ='Net Income - Fx'!D33 -> #VALUE! | R35: ='Net Income - Fx'!E33 -> #VALUE!
I36: VCI+Others | N36: ='Net Income - Fx'!C34 -> #VALUE! | P36: ='Net Income - Fx'!D34 -> #VALUE! | R36: ='Net Income - Fx'!E34 -> #VALUE!

Sheet Cash Generation - Fx
A1: CONS_VC:DFS.140.Indirect_Cash_Flow
A2: ALL.D.Year | B2: ='Cash Generation'!O6 -> #N/A
A3: DFS.M.140.Indirect_Cash_Flow | B3: =_xll.SUBNM("CONS_VC:DFS.M.140.Indirect_Cash_Flow","","Total Value") -> Total Value
A4: DFS.D.Accounts_ICF | B4: ='Cash Generation'!C$6 -> #N/A
A5: ALL.D.Currency | B5: ='Cash Generation'!X6 -> #N/A | G5: =$B$2-1 -> #N/A | H5: =$B$2 -> #N/A | I5: =$B$2 -> #N/A | J5: =$B$2 -> #N/A | K5: =$B$2 -> #N/A | L5: =$B$2 -> #N/A | M5: =$B$2 -> #N/A | N5: =$B$2-1 -> #N/A | O5: =$B$2 -> #N/A | P5: =$B$2 -> #N/A | Q5: =$B$2 -> #N/A
A6: ALL.D.Region | B6: ='Cash Generation'!S6 -> #N/A | G6: =$B$4 -> #N/A | H6: =$B$4 -> #N/A | I6: EBITDA | J6: Income tax on transactions | K6: Working capital | L6: Expansion capex | M6: Dividends received | N6: Financial Results | O6: Invested Cash | P6: FX/Others | Q6: =$B$4 -> #N/A
G7: Year | H7: Year | I7: Year | J7: Year | K7: Year | L7: Year | M7: Year | N7: Year | O7: Year | P7: Year | Q7: Year
B8: Q1 | C8: Q2 | D8: Q3 | E8: Q4 | G8: =$A$9 -> #N/A | H8: =$A$10 -> #N/A | I8: =$A$11 -> #N/A | J8: =$A$11 -> #N/A | K8: =$A$11 -> #N/A | L8: =$A$11 -> #N/A | M8: =$A$11 -> #N/A | N8: =$A$9 -> #N/A | O8: =$A$11 -> #N/A | P8: =$A$11 -> #N/A | Q8: =$A$11 -> #N/A
A9: ='Cash Generation'!$AI$6 -> #N/A | B9: =_xll.DBRW($A$1,$B$2,B$8,$A9,$B$5,$B$6,$B$4,$B$3) -> #VALUE! | C9: =_xll.DBRW($A$1,$B$2,C$8,$A9,$B$5,$B$6,$B$4,$B$3) -> #VALUE! | D9: =_xll.DBRW($A$1,$B$2,D$8,$A9,$B$5,$B$6,$B$4,$B$3) -> #VALUE! | E9: =_xll.DBRW($A$1,$B$2,E$8,$A9,$B$5,$B$6,$B$4,$B$3) -> #VALUE! | G9: =$B$6 -> #N/A | H9: =$B$6 -> #N/A | I9: =$B$6 -> #N/A | J9: =$B$6 -> #N/A | K9: =$B$6 -> #N/A | L9: =$B$6 -> #N/A | M9: =$B$6 -> #N/A | N9: =$B$6 -> #N/A | ... Q9: =$B$6 -> #N/A
A10: ='Cash Generation'!$AK$6 -> #N/A | B10: =_xll.DBRW($A$1,$B$2,B$8,$A10,$B$5,$B$6,$B$4,$B$3) -> #VALUE! | C10: =_xll.DBRW($A$1,$B$2,C$8,$A10,$B$5,$B$6,$B$4,$B$3) -> #VALUE! | D10: =_xll.DBRW($A$1,$B$2,D$8,$A10,$B$5,$B$6,$B$4,$B$3) -> #VALUE! | E10: =_xll.DBRW($A$1,$B$2,E$8,$A10,$B$5,$B$6,$B$4,$B$3) -> #VALUE! | G10: =B2-1 -> #N/A | H10: L300 | I10: EBITDA | J10: Tax | K10: WK | L10: CAPEX | M10: Div. | N10: Fin. Results | O10: Invest. | P10: FX/Others | Q10: 2025
A11: ='Cash Generation'!$AM$6 -> #N/A | B11: =_xll.DBRW($A$1,$B$2,B$8,$A11,$B$5,$B$6,$B$4,$B$3) -> #VALUE! | C11: =_xll.DBRW($A$1,$B$2,C$8,$A11,$B$5,$B$6,$B$4,$B$3) -> #VALUE! | D11: =_xll.DBRW($A$1,$B$2,D$8,$A11,$B$5,$B$6,$B$4,$B$3) -> #VALUE! | E11: =_xll.DBRW($A$1,$B$2,E$8,$A11,$B$5,$B$6,$B$4,$B$3) -> #VALUE! | G11: =_xll.DBRW($A$1,G$5,G$7,G8,$B$5,G$9,G$6,$B$3) -> #VALUE! | H11: =_xll.DBRW($A$1,H$5,H$7,H8,$B$5,H$9,H$6,$B$3) -> #VALUE! | I11: =_xll.DBRW($A$1,I$5,I$7,I8,$B$5,I$9,I$6,$B$3) -> #VALUE! | J11: =_xll.DBRW($A$1,J$5,J$7,J8,$B$5,J$9,J$6,$B$3) -> #VALUE! | K11: =_xll.DBRW($A$1,K$5,K$7,K8,$B$5,K$9,K$6,$B$3) -> #VALUE! | L11: =_xll.DBRW($A$1,L$5,L$7,L8,$B$5,L$9,L$6,$B$3) -> #VALUE! | M11: =_xll.DBRW($A$1,M$5,M$7,M8,$B$5,M$9,M$6,$B$3) -> #VALUE! | N11: =_xll.DBRW($A$1,N$5,N$7,N8,$B$5,N$9,N$6,$B$3) -> #VALUE! | ... Q11: =_xll.DBRW($A$1,Q$5,Q$7,Q8,$B$5,Q$9,Q$6,$B$3) -> #VALUE!
C13: Year | D13: Year | E13: Year
C14: =A9 -> #N/A | D14: =A10 -> #N/A | E14: =A11 -> #N/A
C15: =G5 -> #N/A | D15: =H5 -> #N/A | E15: =H5 -> #N/A
A16: Cash generation before financing | B16: EBITDA | C16: =_xll.DBRW($A$1,C$15,C$13,C$14,$B$5,$B$6,$A16,$B$3)/_xll.DBRW($A$1,C$15,C$13,C$14,$B$5,$B$6,$B16,$B$3) -> #VALUE! | D16: =_xll.DBRW($A$1,D$15,D$13,D$14,$B$5,$B$6,$A16,$B$3)/_xll.DBRW($A$1,D$15,D$13,D$14,$B$5,$B$6,$B16,$B$3) -> #VALUE! | E16: =_xll.DBRW($A$1,E$15,E$13,E$14,$B$5,$B$6,$A16,$B$3)/_xll.DBRW($A$1,E$15,E$13,E$14,$B$5,$B$6,$B16,$B$3) -> #VALUE!
A17: Sustainable Cash Flow | B17: EBITDA | C17: =_xll.DBRW($A$1,C$15,C$13,C$14,$B$5,$B$6,$A17,$B$3)/_xll.DBRW($A$1,C$15,C$13,C$14,$B$5,$B$6,$B17,$B$3) -> #VALUE! | D17: =_xll.DBRW($A$1,D$15,D$13,D$14,$B$5,$B$6,$A17,$B$3)/_xll.DBRW($A$1,D$15,D$13,D$14,$B$5,$B$6,$B17,$B$3) -> #VALUE! | E17: =_xll.DBRW($A$1,E$15,E$13,E$14,$B$5,$B$6,$A17,$B$3)/_xll.DBRW($A$1,E$15,E$13,E$14,$B$5,$B$6,$B17,$B$3) -> #VALUE!
A18: Final Net Debt | B18: BRL | C18: =_xll.DBRW($A$1,C$15,C$13,C$14,$B$18,$B$6,$A18,$B$3)/1000 -> #VALUE! | D18: =_xll.DBRW($A$1,D$15,D$13,D$14,$B$18,$B$6,$A18,$B$3)/1000 -> #VALUE! | E18: =_xll.DBRW($A$1,E$15,E$13,E$14,$B$18,$B$6,$A18,$B$3)/1000 -> #VALUE!
A19: Final Net Debt | B19: Adj EBITDA LTM | C19: =_xll.DBRW($A$1,C$15,C$13,C$14,$B$5,$B$6,$A19,$B$3)/_xll.DBRW($A$1,C$15,C$13,C$14,$B$5,$B$6,$B19,$B$3) -> #VALUE! | D19: =_xll.DBRW($A$1,D$15,D$13,D$14,$B$5,$B$6,$A19,$B$3)/_xll.DBRW($A$1,D$15,D$13,D$14,$B$5,$B$6,$B19,$B$3) -> #VALUE! | E19: =_xll.DBRW($A$1,E$15,E$13,E$14,$B$5,$B$6,$A19,$B$3)/_xll.DBRW($A$1,E$15,E$13,E$14,$B$5,$B$6,$B19,$B$3) -> #VALUE!

Sheet Cash Generation
B1: Quarterly Account Analysis by Region
C6: =_xll.SUBNM("CONS_VC_PRD:DFS.D.Accounts_ICF","Default","Cash generation before financing") -> #N/A | O6: =_xll.SUBNM("CONS_VC_PRD:ALL.D.Year","","2025") -> #N/A | S6: =_xll.SUBNM("CONS_VC_PRD:ALL.D.Region","Default","Global") -> #N/A | X6: =_xll.SUBNM("CONS_VC_PRD:ALL.D.Currency","","BRL Conv.") -> #N/A | AI6: =_xll.SUBNM("CONS_VC_PRD:ALL.D.Version","Sys.Report","Actual","Descrição") -> #N/A | AK6: =_xll.SUBNM("CONS_VC_PRD:ALL.D.Version","Sys.Report","L300","Descrição") -> #N/A | AM6: =_xll.SUBNM("CONS_VC_PRD:ALL.D.Version","Sys.Report","RF","Descrição") -> #N/A
C8: QoQ Overview | AC8: Full Year
N30: ='Cash Generation - Fx'!C15 -> #N/A | P30: ='Cash Generation - Fx'!D14 -> #N/A | R30: ='Cash Generation - Fx'!E15 -> #N/A
F31: =C6&" / EBITDA" -> #N/A | N31: ='Cash Generation - Fx'!C16 -> #VALUE! | P31: ='Cash Generation - Fx'!D16 -> #VALUE! | R31: ='Cash Generation - Fx'!E16 -> #VALUE!
F32: Sustainable Cash Flow / EBITDA | N32: ='Cash Generation - Fx'!C17 -> #VALUE! | P32: ='Cash Generation - Fx'!D17 -> #VALUE! | R32: ='Cash Generation - Fx'!E17 -> #VALUE!
F33: Net Debt in BRL Bi | N33: ='Cash Generation - Fx'!C178 -> 0 | P33: ='Cash Generation - Fx'!D18 -> #VALUE! | R33: ='Cash Generation - Fx'!E18 -> #VALUE!
F34: Net Debt/Adj. EBITDA | N34: ='Cash Generation - Fx'!C19 -> #VALUE! | P34: ='Cash Generation - Fx'!D19 -> #VALUE! | R34: ='Cash Generation - Fx'!E19 -> #VALUE!

Sheet Vol | Price (product ) - Fx
A1: CONS_VC:REV.100.Revenue_Consolidated
A2: ='Vol | Price (product)'!M6 -> #N/A | C2: Sales Volume [kt] | D2: Q1 | E2: Q2 | F2: Q3 | G2: Q4 | I2: Price Premium [$/ton] | J2: Q1 | K2: Q2 | L2: Q3 | M2: Q4 | O2: Year
A3: Month | C3: ='Vol | Price (product)'!$AI6 -> #N/A | D3: =_xll.DBRW($A$1,$A$2,D$2,$C3,$A$6,$A$5,$B$4,$A$7,$C$2) -> #VALUE! | E3: =_xll.DBRW($A$1,$A$2,E$2,$C3,$A$6,$A$5,$B$4,$A$7,$C$2) -> #VALUE! | F3: =_xll.DBRW($A$1,$A$2,F$2,$C3,$A$6,$A$5,$B$4,$A$7,$C$2) -> #VALUE! | G3: =_xll.DBRW($A$1,$A$2,G$2,$C3,$A$6,$A$5,$B$4,$A$7,$C$2) -> #VALUE! | I3: ='Vol | Price (product)'!$AI6 -> #N/A | J3: =_xll.DBRW($A$1,$A$2,J$2,$I3,$A$6,$A$5,$B$4,$A$7,$I$2) -> #VALUE! | K3: =_xll.DBRW($A$1,$A$2,K$2,$I3,$A$6,$A$5,$B$4,$A$7,$I$2) -> #VALUE! | L3: =_xll.DBRW($A$1,$A$2,L$2,$I3,$A$6,$A$5,$B$4,$A$7,$I$2) -> #VALUE! | M3: =_xll.DBRW($A$1,$A$2,M$2,$I3,$A$6,$A$5,$B$4,$A$7,$I$2) -> #VALUE! | O3: =_xll.DBRW($A$1,$A$2,O$2,$I3,$A$6,$A$5,$B$4,$A$7,$I$2) -> #VALUE!
A4: Version | B4: ='Vol | Price (product)'!B9 -> #N/A | C4: ='Vol | Price (product)'!$AK6 -> #N/A | D4: =_xll.DBRW($A$1,$A$2,D$2,$C4,$A$6,$A$5,$B$4,$A$7,$C$2) -> #VALUE! | E4: =_xll.DBRW($A$1,$A$2,E$2,$C4,$A$6,$A$5,$B$4,$A$7,$C$2) -> #VALUE! | F4: =_xll.DBRW($A$1,$A$2,F$2,$C4,$A$6,$A$5,$B$4,$A$7,$C$2) -> #VALUE! | G4: =_xll.DBRW($A$1,$A$2,G$2,$C4,$A$6,$A$5,$B$4,$A$7,$C$2) -> #VALUE! | I4: ='Vol | Price (product)'!$AK6 -> #N/A | J4: =_xll.DBRW($A$1,$A$2,J$2,$I4,$A$6,$A$5,$B$4,$A$7,$I$2) -> #VALUE! | K4: =_xll.DBRW($A$1,$A$2,K$2,$I4,$A$6,$A$5,$B$4,$A$7,$I$2) -> #VALUE! | L4: =_xll.DBRW($A$1,$A$2,L$2,$I4,$A$6,$A$5,$B$4,$A$7,$I$2) -> #VALUE! | M4: =_xll.DBRW($A$1,$A$2,M$2,$I4,$A$6,$A$5,$B$4,$A$7,$I$2) -> #VALUE! | O4: =_xll.DBRW($A$1,$A$2,O$2,$I4,$A$6,$A$5,$B$4,$A$7,$I$2) -> #VALUE!
A5: ='Vol | Price (product)'!R6 -> #N/A | C5: ='Vol | Price (product)'!$AM6 -> #N/A | D5: =_xll.DBRW($A$1,$A$2,D$2,$C5,$A$6,$A$5,$B$4,$A$7,$C$2) -> #VALUE! | E5: =_xll.DBRW($A$1,$A$2,E$2,$C5,$A$6,$A$5,$B$4,$A$7,$C$2) -> #VALUE! | F5: =_xll.DBRW($A$1,$A$2,F$2,$C5,$A$6,$A$5,$B$4,$A$7,$C$2) -> #VALUE! | G5: =_xll.DBRW($A$1,$A$2,G$2,$C5,$A$6,$A$5,$B$4,$A$7,$C$2) -> #VALUE! | I5: ='Vol | Price (product)'!$AM6 -> #N/A | J5: =_xll.DBRW($A$1,$A$2,J$2,$I5,$A$6,$A$5,$B$4,$A$7,$I$2) -> #VALUE! | K5: =_xll.DBRW($A$1,$A$2,K$2,$I5,$A$6,$A$5,$B$4,$A$7,$I$2) -> #VALUE! | L5: =_xll.DBRW($A$1,$A$2,L$2,$I5,$A$6,$A$5,$B$4,$A$7,$I$2) -> #VALUE! | M5: =_xll.DBRW($A$1,$A$2,M$2,$I5,$A$6,$A$5,$B$4,$A$7,$I$2) -> #VALUE! | O5: =_xll.DBRW($A$1,$A$2,O$2,$I5,$A$6,$A$5,$B$4,$A$7,$I$2) -> #VALUE!
A6: ='Vol | Price (product)'!X6 -> #N/A
A7: Total Market
C8: Sales Volume [kt] | D8: Q1 | E8: Q2 | F8: Q3 | G8: Q4 | I8: Price Premium [$/ton] | J8: Q1 | K8: Q2 | L8: Q3 | M8: Q4 | O8: Year
C9: ='Vol | Price (product)'!$AI6 -> #N/A | D9: =_xll.DBRW($A$1,$A$2,D$2,$C9,$A$6,$A$5,$B$10,$A$7,$C$8) -> #VALUE! | E9: =_xll.DBRW($A$1,$A$2,E$2,$C9,$A$6,$A$5,$B$10,$A$7,$C$8) -> #VALUE! | F9: =_xll.DBRW($A$1,$A$2,F$2,$C9,$A$6,$A$5,$B$10,$A$7,$C$8) -> #VALUE! | G9: =_xll.DBRW($A$1,$A$2,G$2,$C9,$A$6,$A$5,$B$10,$A$7,$C$8) -> #VALUE! | I9: ='Vol | Price (product)'!$AI6 -> #N/A | J9: =_xll.DBRW($A$1,$A$2,J$8,$I9,$A$6,$A$5,$B$10,$A$7,$I$8) -> #VALUE! | K9: =_xll.DBRW($A$1,$A$2,K$8,$I9,$A$6,$A$5,$B$10,$A$7,$I$8) -> #VALUE! | L9: =_xll.DBRW($A$1,$A$2,L$8,$I9,$A$6,$A$5,$B$10,$A$7,$I$8) -> #VALUE! | M9: =_xll.DBRW($A$1,$A$2,M$8,$I9,$A$6,$A$5,$B$10,$A$7,$I$8) -> #VALUE! | O9: =_xll.DBRW($A$1,$A$2,O$8,$I9,$A$6,$A$5,$B$10,$A$7,$I$8) -> #VALUE!
B10: ='Vol | Price (product)'!B19 -> #N/A | C10: ='Vol | Price (product)'!$AK6 -> #N/A | D10: =_xll.DBRW($A$1,$A$2,D$2,$C10,$A$6,$A$5,$B$10,$A$7,$C$8) -> #VALUE! | E10: =_xll.DBRW($A$1,$A$2,E$2,$C10,$A$6,$A$5,$B$10,$A$7,$C$8) -> #VALUE! | F10: =_xll.DBRW($A$1,$A$2,F$2,$C10,$A$6,$A$5,$B$10,$A$7,$C$8) -> #VALUE! | G10: =_xll.DBRW($A$1,$A$2,G$2,$C10,$A$6,$A$5,$B$10,$A$7,$C$8) -> #VALUE! | I10: ='Vol | Price (product)'!$AK6 -> #N/A | J10: =_xll.DBRW($A$1,$A$2,J$8,$I10,$A$6,$A$5,$B$10,$A$7,$I$8) -> #VALUE! | K10: =_xll.DBRW($A$1,$A$2,K$8,$I10,$A$6,$A$5,$B$10,$A$7,$I$8) -> #VALUE! | L10: =_xll.DBRW($A$1,$A$2,L$8,$I10,$A$6,$A$5,$B$10,$A$7,$I$8) -> #VALUE! | M10: =_xll.DBRW($A$1,$A$2,M$8,$I10,$A$6,$A$5,$B$10,$A$7,$I$8) -> #VALUE! | O10: =_xll.DBRW($A$1,$A$2,O$8,$I10,$A$6,$A$5,$B$10,$A$7,$I$8) -> #VALUE!
C11: ='Vol | Price (product)'!$AM6 -> #N/A | D11: =_xll.DBRW($A$1,$A$2,D$2,$C11,$A$6,$A$5,$B$10,$A$7,$C$8) -> #VALUE! | E11: =_xll.DBRW($A$1,$A$2,E$2,$C11,$A$6,$A$5,$B$10,$A$7,$C$8) -> #VALUE! | F11: =_xll.DBRW($A$1,$A$2,F$2,$C11,$A$6,$A$5,$B$10,$A$7,$C$8) -> #VALUE! | G11: =_xll.DBRW($A$1,$A$2,G$2,$C11,$A$6,$A$5,$B$10,$A$7,$C$8) -> #VALUE! | I11: ='Vol | Price (product)'!$AM6 -> #N/A | J11: =_xll.DBRW($A$1,$A$2,J$8,$I11,$A$6,$A$5,$B$10,$A$7,$I$8) -> #VALUE! | K11: =_xll.DBRW($A$1,$A$2,K$8,$I11,$A$6,$A$5,$B$10,$A$7,$I$8) -> #VALUE! | L11: =_xll.DBRW($A$1,$A$2,L$8,$I11,$A$6,$A$5,$B$10,$A$7,$I$8) -> #VALUE! | M11: =_xll.DBRW($A$1,$A$2,M$8,$I11,$A$6,$A$5,$B$10,$A$7,$I$8) -> #VALUE! | O11: =_xll.DBRW($A$1,$A$2,O$8,$I11,$A$6,$A$5,$B$10,$A$7,$I$8) -> #VALUE!
C14: Sales Volume [kt] | D14: Q1 | E14: Q2 | F14: Q3 | G14: Q4 | I14: Price Premium [$/ton] | J14: Q1 | K14: Q2 | L14: Q3 | M14: Q4 | O14: Year
C15: =$C9 -> #N/A | D15: =_xll.DBRW($A$1,$A$2,D$2,$C15,$A$6,$A$5,$B$16,$A$7,$C$14) -> #VALUE! | E15: =_xll.DBRW($A$1,$A$2,E$2,$C15,$A$6,$A$5,$B$16,$A$7,$C$14) -> #VALUE! | F15: =_xll.DBRW($A$1,$A$2,F$2,$C15,$A$6,$A$5,$B$16,$A$7,$C$14) -> #VALUE! | G15: =_xll.DBRW($A$1,$A$2,G$2,$C15,$A$6,$A$5,$B$16,$A$7,$C$14) -> #VALUE! | I15: ='Vol | Price (product)'!$AI6 -> #N/A | J15: =_xll.DBRW($A$1,$A$2,J$14,$I15,$A$6,$A$5,$B$16,$A$7,$I$14) -> #VALUE! | K15: =_xll.DBRW($A$1,$A$2,K$14,$I15,$A$6,$A$5,$B$16,$A$7,$I$14) -> #VALUE! | L15: =_xll.DBRW($A$1,$A$2,L$14,$I15,$A$6,$A$5,$B$16,$A$7,$I$14) -> #VALUE! | M15: =_xll.DBRW($A$1,$A$2,M$14,$I15,$A$6,$A$5,$B$16,$A$7,$I$14) -> #VALUE! | O15: =_xll.DBRW($A$1,$A$2,O$14,$I15,$A$6,$A$5,$B$16,$A$7,$I$14) -> #VALUE!
B16: ='Vol | Price (product)'!B28 -> #N/A | C16: =$C10 -> #N/A | D16: =_xll.DBRW($A$1,$A$2,D$2,$C16,$A$6,$A$5,$B$16,$A$7,$C$14) -> #VALUE! | E16: =_xll.DBRW($A$1,$A$2,E$2,$C16,$A$6,$A$5,$B$16,$A$7,$C$14) -> #VALUE! | F16: =_xll.DBRW($A$1,$A$2,F$2,$C16,$A$6,$A$5,$B$16,$A$7,$C$14) -> #VALUE! | G16: =_xll.DBRW($A$1,$A$2,G$2,$C16,$A$6,$A$5,$B$16,$A$7,$C$14) -> #VALUE! | I16: ='Vol | Price (product)'!$AK6 -> #N/A | J16: =_xll.DBRW($A$1,$A$2,J$14,$I16,$A$6,$A$5,$B$16,$A$7,$I$14) -> #VALUE! | K16: =_xll.DBRW($A$1,$A$2,K$14,$I16,$A$6,$A$5,$B$16,$A$7,$I$14) -> #VALUE! | L16: =_xll.DBRW($A$1,$A$2,L$14,$I16,$A$6,$A$5,$B$16,$A$7,$I$14) -> #VALUE! | M16: =_xll.DBRW($A$1,$A$2,M$14,$I16,$A$6,$A$5,$B$16,$A$7,$I$14) -> #VALUE! | O16: =_xll.DBRW($A$1,$A$2,O$14,$I16,$A$6,$A$5,$B$16,$A$7,$I$14) -> #VALUE!
C17: =$C11 -> #N/A | D17: =_xll.DBRW($A$1,$A$2,D$2,$C17,$A$6,$A$5,$B$16,$A$7,$C$14) -> #VALUE! | E17: =_xll.DBRW($A$1,$A$2,E$2,$C17,$A$6,$A$5,$B$16,$A$7,$C$14) -> #VALUE! | F17: =_xll.DBRW($A$1,$A$2,F$2,$C17,$A$6,$A$5,$B$16,$A$7,$C$14) -> #VALUE! | G17: =_xll.DBRW($A$1,$A$2,G$2,$C17,$A$6,$A$5,$B$16,$A$7,$C$14) -> #VALUE! | I17: ='Vol | Price (product)'!$AM6 -> #N/A | J17: =_xll.DBRW($A$1,$A$2,J$14,$I17,$A$6,$A$5,$B$16,$A$7,$I$14) -> #VALUE! | K17: =_xll.DBRW($A$1,$A$2,K$14,$I17,$A$6,$A$5,$B$16,$A$7,$I$14) -> #VALUE! | L17: =_xll.DBRW($A$1,$A$2,L$14,$I17,$A$6,$A$5,$B$16,$A$7,$I$14) -> #VALUE! | M17: =_xll.DBRW($A$1,$A$2,M$14,$I17,$A$6,$A$5,$B$16,$A$7,$I$14) -> #VALUE! | O17: =_xll.DBRW($A$1,$A$2,O$14,$I17,$A$6,$A$5,$B$16,$A$7,$I$14) -> #VALUE!

Sheet Vol | Price  (product)
B1: Volume | Price
M6: =_xll.SUBNM("CONS_VC_PRD:ALL.D.Year","","2025") -> #N/A | R6: =_xll.SUBNM("CONS_VC_PRD:ALL.D.Region","DEFAuLT","VCBR - VCBR","Código e Descrição" ) -> #N/A | X6: =_xll.SUBNM("CONS_VC_PRD:ALL.D.Currency","Default","BRL","Código e Descrição") -> #N/A | AI6: =_xll.SUBNM("CONS_VC_PRD:ALL.D.Version","Sys.Report","Actual","Descrição") -> #N/A | AK6: =_xll.SUBNM("CONS_VC_PRD:ALL.D.Version","Sys.Report","L300","Descrição") -> #N/A | AM6: =_xll.SUBNM("CONS_VC_PRD:ALL.D.Version","Sys.Report","RF","Descrição") -> #N/A
G8: Sales Volumes | AB8: ="FOB Price " &( X6 ) -> #N/A
B9: =_xll.SUBNM("CONS_VC_PRD:ALL.D.Products","Products","PRODCE010 - Cement","Código e Descrição") -> #N/A
B19: =_xll.SUBNM("CONS_VC_PRD:ALL.D.Products","Products","PRODRM010 - Ready Mix","Código e Descrição") -> #N/A
B28: =_xll.SUBNM("CONS_VC_PRD:ALL.D.Products","Products","PRODAG010 - Aggregates","Código e Descrição") -> #N/A

Sheet Reg | Product - Fx 
A1: CONS_VC:REV.100.Revenue_Consolidated
A2: =_xll.SUBNM("CONS_VC:ALL.D.Year","","2025") -> 2025
A3: Month
A4: Version
A7: Total Market
B8: ='Reg | Product'!$D$6 -> #N/A | I8: ='Reg | Product'!$D$6 -> #N/A
B9: Sales Volume [kt] | C9: Q1 | D9: Q2 | E9: Q3 | F9: Q4 | I9: Price Premium [$/ton] | J9: Q1 | K9: Q2 | L9: Q3 | M9: Q4 | O9: Year
B10: ='Reg | Product'!$AI$6 -> #N/A | C10: =_xll.DBRW($A$1,$A$2,C$9,$B10,$A$12,$A$11,$B$8,$A$7,$B$9) -> #VALUE! | D10: =_xll.DBRW($A$1,$A$2,D$9,$B10,$A$12,$A$11,$B$8,$A$7,$B$9) -> #VALUE! | E10: =_xll.DBRW($A$1,$A$2,E$9,$B10,$A$12,$A$11,$B$8,$A$7,$B$9) -> #VALUE! | F10: =_xll.DBRW($A$1,$A$2,F$9,$B10,$A$12,$A$11,$B$8,$A$7,$B$9) -> #VALUE! | I10: ='Reg | Product'!$AI$6 -> #N/A | J10: =_xll.DBRW($A$1,$A$2,J$9,$I10,$A$12,$A$11,$I$8,$A$7,$I$9) -> #VALUE! | K10: =_xll.DBRW($A$1,$A$2,K$9,$I10,$A$12,$A$11,$I$8,$A$7,$I$9) -> #VALUE! | L10: =_xll.DBRW($A$1,$A$2,L$9,$I10,$A$12,$A$11,$I$8,$A$7,$I$9) -> #VALUE! | M10: =_xll.DBRW($A$1,$A$2,M$9,$I10,$A$12,$A$11,$I$8,$A$7,$I$9) -> #VALUE! | O10: =_xll.DBRW($A$1,$A$2,O$9,$I10,$A$12,$A$11,$I$8,$A$7,$I$9) -> #VALUE!
A11: ='Reg | Product'!B9 -> #N/A | B11: ='Reg | Product'!$AK$6 -> #N/A | C11: =_xll.DBRW($A$1,$A$2,C$9,$B11,$A$12,$A$11,$B$8,$A$7,$B$9) -> #VALUE! | D11: =_xll.DBRW($A$1,$A$2,D$9,$B11,$A$12,$A$11,$B$8,$A$7,$B$9) -> #VALUE! | E11: =_xll.DBRW($A$1,$A$2,E$9,$B11,$A$12,$A$11,$B$8,$A$7,$B$9) -> #VALUE! | F11: =_xll.DBRW($A$1,$A$2,F$9,$B11,$A$12,$A$11,$B$8,$A$7,$B$9) -> #VALUE! | I11: ='Reg | Product'!$AK$6 -> #N/A | J11: =_xll.DBRW($A$1,$A$2,J$9,$I11,$A$12,$A$11,$I$8,$A$7,$I$9) -> #VALUE! | K11: =_xll.DBRW($A$1,$A$2,K$9,$I11,$A$12,$A$11,$I$8,$A$7,$I$9) -> #VALUE! | L11: =_xll.DBRW($A$1,$A$2,L$9,$I11,$A$12,$A$11,$I$8,$A$7,$I$9) -> #VALUE! | M11: =_xll.DBRW($A$1,$A$2,M$9,$I11,$A$12,$A$11,$I$8,$A$7,$I$9) -> #VALUE! | O11: =_xll.DBRW($A$1,$A$2,O$9,$I11,$A$12,$A$11,$I$8,$A$7,$I$9) -> #VALUE!
A12: ='Reg | Product'!B12 -> #N/A | B12: ='Reg | Product'!$AM$6 -> #N/A | C12: =_xll.DBRW($A$1,$A$2,C$9,$B12,$A$12,$A$11,$B$8,$A$7,$B$9) -> #VALUE! | D12: =_xll.DBRW($A$1,$A$2,D$9,$B12,$A$12,$A$11,$B$8,$A$7,$B$9) -> #VALUE! | E12: =_xll.DBRW($A$1,$A$2,E$9,$B12,$A$12,$A$11,$B$8,$A$7,$B$9) -> #VALUE! | F12: =_xll.DBRW($A$1,$A$2,F$9,$B12,$A$12,$A$11,$B$8,$A$7,$B$9) -> #VALUE! | I12: ='Reg | Product'!$AM$6 -> #N/A | J12: =_xll.DBRW($A$1,$A$2,J$9,$I12,$A$12,$A$11,$I$8,$A$7,$I$9) -> #VALUE! | K12: =_xll.DBRW($A$1,$A$2,K$9,$I12,$A$12,$A$11,$I$8,$A$7,$I$9) -> #VALUE! | L12: =_xll.DBRW($A$1,$A$2,L$9,$I12,$A$12,$A$11,$I$8,$A$7,$I$9) -> #VALUE! | M12: =_xll.DBRW($A$1,$A$2,M$9,$I12,$A$12,$A$11,$I$8,$A$7,$I$9) -> #VALUE! | O12: =_xll.DBRW($A$1,$A$2,O$9,$I12,$A$12,$A$11,$I$8,$A$7,$I$9) -> #VALUE!
I13: ='Reg | Product'!$X$6 -> 0
B15: Sales Volume [kt] | C15: Q1 | D15: Q2 | E15: Q3 | F15: Q4 | I15: Price Premium [$/ton] | J15: Q1 | K15: Q2 | L15: Q3 | M15: Q4 | O15: Year
B16: ='Reg | Product'!$AI$6 -> #N/A | C16: =_xll.DBRW($A$1,$A$2,C$15,$B16,$A$18,$A$17,$B$8,$A$7,$B$15) -> #VALUE! | D16: =_xll.DBRW($A$1,$A$2,D$15,$B16,$A$18,$A$17,$B$8,$A$7,$B$15) -> #VALUE! | E16: =_xll.DBRW($A$1,$A$2,E$15,$B16,$A$18,$A$17,$B$8,$A$7,$B$15) -> #VALUE! | F16: =_xll.DBRW($A$1,$A$2,F$15,$B16,$A$18,$A$17,$B$8,$A$7,$B$15) -> #VALUE! | I16: ='Reg | Product'!$AI$6 -> #N/A | J16: =_xll.DBRW($A$1,$A$2,J$15,$I16,$A$18,$A$17,$I$8,$A$7,$I$15) -> #VALUE! | K16: =_xll.DBRW($A$1,$A$2,K$15,$I16,$A$18,$A$17,$I$8,$A$7,$I$15) -> #VALUE! | L16: =_xll.DBRW($A$1,$A$2,L$15,$I16,$A$18,$A$17,$I$8,$A$7,$I$15) -> #VALUE! | M16: =_xll.DBRW($A$1,$A$2,M$15,$I16,$A$18,$A$17,$I$8,$A$7,$I$15) -> #VALUE! | O16: =_xll.DBRW($A$1,$A$2,O$15,$I16,$A$18,$A$17,$I$8,$A$7,$I$15) -> #VALUE!
A17: ='Reg | Product'!B19 -> #N/A | B17: ='Reg | Product'!$AK$6 -> #N/A | C17: =_xll.DBRW($A$1,$A$2,C$15,$B17,$A$18,$A$17,$B$8,$A$7,$B$15) -> #VALUE! | D17: =_xll.DBRW($A$1,$A$2,D$15,$B17,$A$18,$A$17,$B$8,$A$7,$B$15) -> #VALUE! | E17: =_xll.DBRW($A$1,$A$2,E$15,$B17,$A$18,$A$17,$B$8,$A$7,$B$15) -> #VALUE! | F17: =_xll.DBRW($A$1,$A$2,F$15,$B17,$A$18,$A$17,$B$8,$A$7,$B$15) -> #VALUE! | I17: ='Reg | Product'!$AK$6 -> #N/A | J17: =_xll.DBRW($A$1,$A$2,J$15,$I17,$A$18,$A$17,$I$8,$A$7,$I$15) -> #VALUE! | K17: =_xll.DBRW($A$1,$A$2,K$15,$I17,$A$18,$A$17,$I$8,$A$7,$I$15) -> #VALUE! | L17: =_xll.DBRW($A$1,$A$2,L$15,$I17,$A$18,$A$17,$I$8,$A$7,$I$15) -> #VALUE! | M17: =_xll.DBRW($A$1,$A$2,M$15,$I17,$A$18,$A$17,$I$8,$A$7,$I$15) -> #VALUE! | O17: =_xll.DBRW($A$1,$A$2,O$15,$I17,$A$18,$A$17,$I$8,$A$7,$I$15) -> #VALUE!
