Workbook
Name ID: "3f7751d6-d8ba-4019-b93b-f908a13f3e0f"
Name ID: "1b435c45-51a4-4dee-9013-d77740d1f498"

Sheet Cognos_Office_Connection_Cache
B1: [Value Tree.xlsx]Value Tree'!J6
B2: 2024
B3: 2025
B4: 2026
B5: 2027
B6: 2028
B7: 2029
B8: 2030
B9: 2031
B10: 2032
B11: 2033
B12: 2034
... B18: 2040

Sheet Value Tree - Fx
A2: Cubo
A3: CONS_VC:DFS.200.KPIs
A4: CONS_VC:DFS.100.Profit_and_loss | C4: =3% -> 0.03 | AR4: ='Value Tree'!$D$6 -> #N/A | AS4: =$A$17 -> Year
A5: CONS_VC:DFS.140.Indirect_Cash_Flow | AC5: EBITDA LTM | AR5: global | AS5: global | BB5: ='Value Tree'!$D$4 -> #N/A | BF5: ='Value Tree'!$D$4 -> #N/A
A6: CONS_VC:DFS.180.Gross_Debt | P6: + | R6: ='Value Tree'!$D$6 -> #N/A | V6: =$A$17 -> Year | AA6: + | AC6: ='Value Tree'!$D$6 -> #N/A | AF6: ='Value Tree'!$D$6 -> #N/A | AJ6: =$A$17 -> Year | AM6: =$A$17 -> Year | BB6: ='Value Tree'!$D$6 -> #N/A | BF6: =$A$17 -> Year | BW6: + | BY6: ='Value Tree'!$D$6 -> #N/A | BZ6: ='Value Tree'!$D$6 -> #N/A | CC6: =$A$17 -> Year | CD6: =$A$17 -> Year | CG6: ='Value Tree'!$D$6 -> #N/A | CH6: ='Value Tree'!$D$6 -> #N/A | CK6: =$A$17 -> Year | CL6: =$A$17 -> Year
A7: CONS_VC:REV.100.Revenue_Consolidated | Q7: Net Debt (M) | AB7: EBITDA (BRL M) Mg. EBITDA - VCBR | AU7: EBITDA VCBR Breakdown (BRL M) | BX7: Month | BY7: ='Value Tree'!$J$4 -> #N/A | BZ7: =$A$20 -> l500 | CB7: FY | CC7: ='Value Tree'!$J$4 -> #N/A | CD7: =$A$20 -> l500 | CG7: ='Value Tree'!$J$4 -> #N/A | CH7: =$A$20 -> l500 | CJ7: FY | CK7: ='Value Tree'!$J$4 -> #N/A | CL7: =$A$20 -> l500
B8: - | E8: + | G8: ='Value Tree'!$D$6 -> #N/A | K8: =$A$17 -> Year | P8: ='Value Tree'!$D$4 -> #N/A | R8: {=_xll.DBRW(A6,'Value Tree'!J6,R6,P8,A24,A28,"Closing Balance Debt",A48)} -> #VALUE! | V8: {=_xll.DBRW(A6,'Value Tree'!J6,V6,P8,A24,A28,"Closing Balance Debt",A48)} -> #VALUE! | AA8: ='Value Tree'!$D$4 -> #N/A | AC8: =_xll.DBRW($A$3,'Value Tree'!$J$6,AC$6,$AA8,$AQ8,$AP8,"Total Products","EBITDA LTM","Value") -> #VALUE! | AF8: =AC8/_xll.DBRW($A$3,'Value Tree'!$J$6,AF6,$AA8,$AQ8,$AR8,"Total Products","EBITDA LTM","Value") -> #VALUE! | AJ8: =_xll.DBRW($A$3,'Value Tree'!$J$6,AJ$6,$AA8,$AQ8,$AP8,"Total Products","EBITDA LTM","Value") -> #VALUE! | AM8: =AJ8/_xll.DBRW($A$3,'Value Tree'!$J$6,AM6,$AA8,$AQ8,$AR8,"Total Products","EBITDA LTM","Value") -> #VALUE! | AP8: =_xll.SUBNM("CONS_VC:ALL.D.Region","","VCBR") -> VCBR | AQ8: BRL Conv. | AR8: Global | AU8: Cement | BB8: =_xll.DBRW($A$3,'Value Tree'!$J$6,BB$6,$CV8,$CR8,$CT8,$CX8,"EBITDA LTM","Value") -> #VALUE! | BF8: =_xll.DBRW($A$3,'Value Tree'!$J$6,BF$6,$CV8,$CR8,$CT8,$CX8,"EBITDA LTM","Value") -> #VALUE! | BX8: =IF($BW$6="+",IF(BB8>BZ8*(1+IF(BZ8>0,$C$4,-$C$4)),1,IF(BB8>=BY8*(1+IF(BY8>0,-$C$4,$C$4)),0,-1)),IF($BW$6="-",IF(BB8<BZ8*(1+IF(BZ8>0,-$C$4,$C$4)),1,IF(BB8<=BY8*(1+IF(BY8>0,$C$4,-$C$4)),0,-1)))) -> #VALUE! | BY8: =_xll.DBRW($A$3,'Value Tree'!$J$6,BY$6,BY$7,$CR8,$CT8,$CX8,"EBITDA LTM","Value") -> #VALUE! | BZ8: =_xll.DBRW($A$3,'Value Tree'!$J$6,BZ$6,BZ$7,$CR8,$CT8,$CX8,"EBITDA LTM","Value") -> #VALUE! | CB8: =IF($BW$6="+",IF(BF8>CD8*(1+IF(CD8>0,$C$4,-$C$4)),1,IF(BF8>=CC8*(1+IF(CC8>0,-$C$4,$C$4)),0,-1)),IF($BW$6="-",IF(BF8<CD8*(1+IF(CD8>0,-$C$4,$C$4)),1,IF(BF8<=CC8*(1+IF(CC8>0,$C$4,-$C$4)),0,-1)))) -> #VALUE! | CC8: =_xll.DBRW($A$3,'Value Tree'!$J$6,CC$6,CC$7,$CR8,$CT8,$CX8,"EBITDA LTM","Value") -> #VALUE! | CD8: =_xll.DBRW($A$3,'Value Tree'!$J$6,CD$6,CD$7,$CR8,$CT8,$CX8,"EBITDA LTM","Value") -> #VALUE! | CR8: BRL Conv. | CT8: VCBR | CV8: RF | CX8: PRODCE010 - Cement
A9: Ano | F9: Net Debt / Adj EBITDA (x) | P9: ='Value Tree'!$J$4 -> #N/A | R9: {=_xll.DBRW(A6,'Value Tree'!J6,R6,P9,A24,A28,"Closing Balance Debt",A48)} -> #VALUE! | V9: {=_xll.DBRW(A6,'Value Tree'!J6,V6,P9,A24,A28,"Closing Balance Debt",A48)} -> #VALUE! | AA9: ='Value Tree'!$J$4 -> #N/A | AC9: =_xll.DBRW($A$3,'Value Tree'!$J$6,AC$6,$AA9,$AQ9,$AP9,"Total Products","EBITDA LTM","Value") -> #VALUE! | AF9: =AC9/_xll.DBRW($A$3,'Value Tree'!$J$6,AF6,$AA9,$AQ9,$AR9,"Total Products","EBITDA LTM","Value") -> #VALUE! | AJ9: =_xll.DBRW($A$3,'Value Tree'!$J$6,AJ$6,$AA9,$AQ9,$AP9,"Total Products","EBITDA LTM","Value") -> #VALUE! | AM9: =AJ9/_xll.DBRW($A$3,'Value Tree'!$J$6,AM6,$AA9,$AQ9,$AR9,"Total Products","EBITDA LTM","Value") -> #VALUE! | AP9: =_xll.SUBNM("CONS_VC:ALL.D.Region","","VCBR") -> VCBR | AQ9: BRL Conv. | AR9: Global | AU9: Ready Mix | BB9: =_xll.DBRW($A$3,'Value Tree'!$J$6,BB$6,$CV9,$CR9,$CT9,$CX9,"EBITDA LTM","Value") -> #VALUE! | BF9: =_xll.DBRW($A$3,'Value Tree'!$J$6,BF$6,$CV9,$CR9,$CT9,$CX9,"EBITDA LTM","Value") -> #VALUE! | BX9: =IF($BW$6="+",IF(BB9>BZ9*(1+IF(BZ9>0,$C$4,-$C$4)),1,IF(BB9>=BY9*(1+IF(BY9>0,-$C$4,$C$4)),0,-1)),IF($BW$6="-",IF(BB9<BZ9*(1+IF(BZ9>0,-$C$4,$C$4)),1,IF(BB9<=BY9*(1+IF(BY9>0,$C$4,-$C$4)),0,-1)))) -> #VALUE! | BY9: =_xll.DBRW($A$3,'Value Tree'!$J$6,BY$6,BY$7,$CR9,$CT9,$CX9,"EBITDA LTM","Value") -> #VALUE! | BZ9: =_xll.DBRW($A$3,'Value Tree'!$J$6,BZ$6,BZ$7,$CR9,$CT9,$CX9,"EBITDA LTM","Value") -> #VALUE! | CB9: =IF($BW$6="+",IF(BF9>CD9*(1+IF(CD9>0,$C$4,-$C$4)),1,IF(BF9>=CC9*(1+IF(CC9>0,-$C$4,$C$4)),0,-1)),IF($BW$6="-",IF(BF9<CD9*(1+IF(CD9>0,-$C$4,$C$4)),1,IF(BF9<=CC9*(1+IF(CC9>0,$C$4,-$C$4)),0,-1)))) -> #VALUE! | CC9: =_xll.DBRW($A$3,'Value Tree'!$J$6,CC$6,CC$7,$CR9,$CT9,$CX9,"EBITDA LTM","Value") -> #VALUE! | CD9: =_xll.DBRW($A$3,'Value Tree'!$J$6,CD$6,CD$7,$CR9,$CT9,$CX9,"EBITDA LTM","Value") -> #VALUE! | CR9: BRL Conv. | CT9: VCBR | CV9: RF | CX9: PRODRM010 - Ready Mix
P10: =$A$20 -> l500 | Q10: =IF(P6="+",IF(R8>R10*(1+IF(R10>0,$C$4,-$C$4)),1,IF(R8>=R9*(1+IF(R9>0,-$C$4,$C$4)),0,-1)),IF(P6="-",IF(R8<R10*(1+IF(R10>0,-$C$4,$C$4)),1,IF(R8<=R9*(1+IF(R9>0,$C$4,-$C$4)),0,-1)))) -> #VALUE! | R10: {=_xll.DBRW($A$6,'Value Tree'!$J$6,R6,P10,$A$24,$A$28,"Closing Balance Debt",$A$48)} -> #VALUE! | U10: =IF(P6="+",IF(V8>V10*(1+IF(V10>0,$C$4,-$C$4)),1,IF(V8>=V9*(1+IF(V9>0,-$C$4,$C$4)),0,-1)),IF(P6="-",IF(V8<V10*(1+IF(V10>0,-$C$4,$C$4)),1,IF(V8<=V9*(1+IF(V9>0,$C$4,-$C$4)),0,-1)))) -> #VALUE! | V10: {=_xll.DBRW($A$6,'Value Tree'!$J$6,V6,P10,$A$24,$A$28,"Closing Balance Debt",$A$48)} -> #VALUE! | AA10: =$A$20 -> l500 | AB10: =IF(AA6="+",IF(AC8>AC10*(1+IF(AC10>0,$C$4,-$C$4)),1,IF(AC8>=AC9*(1+IF(AC9>0,-$C$4,$C$4)),0,-1)),IF(AA6="-",IF(AC8<AC10*(1+IF(AC10>0,-$C$4,$C$4)),1,IF(AC8<=AC9*(1+IF(AC9>0,$C$4,-$C$4)),0,-1)))) -> #VALUE! | AC10: =_xll.DBRW($A$3,'Value Tree'!$J$6,AC$6,$AA10,$AQ9,$AP9,"Total Products","EBITDA LTM","Value") -> #VALUE! | AI10: =IF(AA6="+",IF(AJ8>AJ10*(1+IF(AJ10>0,$C$4,-$C$4)),1,IF(AJ8>=AJ9*(1+IF(AJ9>0,-$C$4,$C$4)),0,-1)),IF(AA6="-",IF(AJ8<AJ10*(1+IF(AJ10>0,-$C$4,$C$4)),1,IF(AJ8<=AJ9*(1+IF(AJ9>0,$C$4,-$C$4)),0,-1)))) -> #VALUE! | AJ10: =_xll.DBRW($A$3,'Value Tree'!$J$6,AJ$6,$AA10,$AQ9,$AP9,"Total Products","EBITDA LTM","Value") -> #VALUE!
E11: ='Value Tree'!$D$4 -> #N/A | G11: =_xll.DBRW(A6,'Value Tree'!J6,G8,E11,A24,A28,"Closing Balance Debt",A48)/_xll.DBRW(A3,'Value Tree'!J6,G8,E11,A24,A28,"Total Products","EBITDA Adjacências","Value") -> #VALUE! | K11: =_xll.DBRW(A6,'Value Tree'!J6,K8,E11,A24,A28,"Closing Balance Debt",A48)/_xll.DBRW(A3,'Value Tree'!J6,K8,E11,A24,A28,"Total Products","EBITDA Adjacências","Value") -> #VALUE! | P11: + | R11: ='Value Tree'!$D$6 -> #N/A | V11: =$A$17 -> Year | AB11: EBIT (BRL M) Mg. EBIT - VCBR | AU11: Aggregates | BB11: =_xll.DBRW($A$3,'Value Tree'!$J$6,BB$6,$CV11,$CR11,$CT11,$CX11,"EBITDA LTM","Value") -> #VALUE! | BF11: =_xll.DBRW($A$3,'Value Tree'!$J$6,BF$6,$CV11,$CR11,$CT11,$CX11,"EBITDA LTM","Value") -> #VALUE! | BX11: =IF($BW$6="+",IF(BB11>BZ11*(1+IF(BZ11>0,$C$4,-$C$4)),1,IF(BB11>=BY11*(1+IF(BY11>0,-$C$4,$C$4)),0,-1)),IF($BW$6="-",IF(BB11<BZ11*(1+IF(BZ11>0,-$C$4,$C$4)),1,IF(BB11<=BY11*(1+IF(BY11>0,$C$4,-$C$4)),0,-1)))) -> #VALUE! | BY11: =_xll.DBRW($A$3,'Value Tree'!$J$6,BY$6,BY$7,$CR11,$CT11,$CX11,"EBITDA LTM","Value") -> #VALUE! | BZ11: =_xll.DBRW($A$3,'Value Tree'!$J$6,BZ$6,BZ$7,$CR11,$CT11,$CX11,"EBITDA LTM","Value") -> #VALUE! | CB11: =IF($BW$6="+",IF(BF11>CD11*(1+IF(CD11>0,$C$4,-$C$4)),1,IF(BF11>=CC11*(1+IF(CC11>0,-$C$4,$C$4)),0,-1)),IF($BW$6="-",IF(BF11<CD11*(1+IF(CD11>0,-$C$4,$C$4)),1,IF(BF11<=CC11*(1+IF(CC11>0,$C$4,-$C$4)),0,-1)))) -> #VALUE! | CC11: =_xll.DBRW($A$3,'Value Tree'!$J$6,CC$6,CC$7,$CR11,$CT11,$CX11,"EBITDA LTM","Value") -> #VALUE! | CD11: =_xll.DBRW($A$3,'Value Tree'!$J$6,CD$6,CD$7,$CR11,$CT11,$CX11,"EBITDA LTM","Value") -> #VALUE! | CR11: BRL Conv. | CT11: VCBR | CV11: RF | CX11: PRODAG010 - Aggregates
E12: ='Value Tree'!$J$4 -> #N/A | G12: =_xll.DBRW(A6,'Value Tree'!J6,G8,E12,A24,A28,"Closing Balance Debt",A48)/_xll.DBRW(A3,'Value Tree'!J6,G8,E12,A24,A28,"Total Products","EBITDA Adjacências","Value") -> #VALUE! | K12: =_xll.DBRW(A6,'Value Tree'!J6,K8,E12,A24,A28,"Closing Balance Debt",A48)/_xll.DBRW(A3,'Value Tree'!J6,K8,E12,A24,A28,"Total Products","EBITDA Adjacências","Value") -> #VALUE! | Q12: EBITDA (M) | AA12: ='Value Tree'!$D$4 -> #N/A | AC12: =_xll.DBRW($A$3,'Value Tree'!$J$6,AC$6,$AA12,$AQ12,$AP12,"Total Products","EBIT","Value") -> #VALUE! | AF12: =AC12/_xll.DBRW($A$3,'Value Tree'!$J$6,AF6,$AA12,$AQ12,$AR12,"Total Products","EBITDA LTM","Value") -> #VALUE! | AJ12: =_xll.DBRW($A$3,'Value Tree'!$J$6,AJ$6,$AA12,$AQ12,$AP12,"Total Products","EBIT","Value") -> #VALUE! | AM12: =AJ12/_xll.DBRW($A$3,'Value Tree'!$J$6,AM6,$AA12,$AQ12,$AR12,"Total Products","EBITDA LTM","Value") -> #VALUE! | AP12: =_xll.SUBNM("CONS_VC:ALL.D.Region","","VCBR") -> VCBR | AQ12: BRL Conv. | AR12: Global | AU12: Mortars | BB12: =_xll.DBRW($A$3,'Value Tree'!$J$6,BB$6,$CV12,$CR12,$CT12,$CX12,"EBITDA LTM","Value") -> #VALUE! | BF12: =_xll.DBRW($A$3,'Value Tree'!$J$6,BF$6,$CV12,$CR12,$CT12,$CX12,"EBITDA LTM","Value") -> #VALUE! | BX12: =IF($BW$6="+",IF(BB12>BZ12*(1+IF(BZ12>0,$C$4,-$C$4)),1,IF(BB12>=BY12*(1+IF(BY12>0,-$C$4,$C$4)),0,-1)),IF($BW$6="-",IF(BB12<BZ12*(1+IF(BZ12>0,-$C$4,$C$4)),1,IF(BB12<=BY12*(1+IF(BY12>0,$C$4,-$C$4)),0,-1)))) -> #VALUE! | BY12: =_xll.DBRW($A$3,'Value Tree'!$J$6,BY$6,BY$7,$CR12,$CT12,$CX12,"EBITDA LTM","Value") -> #VALUE! | BZ12: =_xll.DBRW($A$3,'Value Tree'!$J$6,BZ$6,BZ$7,$CR12,$CT12,$CX12,"EBITDA LTM","Value") -> #VALUE! | CB12: =IF($BW$6="+",IF(BF12>CD12*(1+IF(CD12>0,$C$4,-$C$4)),1,IF(BF12>=CC12*(1+IF(CC12>0,-$C$4,$C$4)),0,-1)),IF($BW$6="-",IF(BF12<CD12*(1+IF(CD12>0,-$C$4,$C$4)),1,IF(BF12<=CC12*(1+IF(CC12>0,$C$4,-$C$4)),0,-1)))) -> #VALUE! | CC12: =_xll.DBRW($A$3,'Value Tree'!$J$6,CC$6,CC$7,$CR12,$CT12,$CX12,"EBITDA LTM","Value") -> #VALUE! | CD12: =_xll.DBRW($A$3,'Value Tree'!$J$6,CD$6,CD$7,$CR12,$CT12,$CX12,"EBITDA LTM","Value") -> #VALUE! | CR12: BRL Conv. | CT12: VCBR | CV12: RF | CX12: PRODMT010 - Mortars
E13: =$A$20 -> l500 | F13: =IF(E8="+",IF(G11>G13*(1+IF(G13>0,$C$4,-$C$4)),1,IF(G11>=G12*(1+IF(G12>0,-$C$4,$C$4)),0,-1)),IF(E8="-",IF(G11<G13*(1+IF(G13>0,-$C$4,$C$4)),1,IF(G11<=G12*(1+IF(G12>0,$C$4,-$C$4)),0,-1)))) -> #VALUE! | G13: =_xll.DBRW(A6,'Value Tree'!J6,G8,E13,A24,A28,"Closing Balance Debt",A48)/_xll.DBRW(A3,'Value Tree'!J6,G8,E13,A24,A28,"Total Products","EBITDA Adjacências","Value") -> #VALUE! | J13: =IF(E8="+",IF(K11>K13*(1+IF(K13>0,$C$4,-$C$4)),1,IF(K11>=K12*(1+IF(K12>0,-$C$4,$C$4)),0,-1)),IF(E8="-",IF(K11<K13*(1+IF(K13>0,-$C$4,$C$4)),1,IF(K11<=K12*(1+IF(K12>0,$C$4,-$C$4)),0,-1)))) -> #VALUE! | K13: =_xll.DBRW(A6,'Value Tree'!J6,K8,E13,A24,A28,"Closing Balance Debt",A48)/_xll.DBRW(A3,'Value Tree'!J6,K8,E13,A24,A28,"Total Products","EBITDA Adjacências","Value") -> #VALUE!
A14: Mês | E14: + | G14: ='Value Tree'!$D$6 -> #N/A | K14: =$A$17 -> Year | P14: ='Value Tree'!$D$4 -> #N/A | R14: =_xll.DBRW(A3,'Value Tree'!J6,R11,P14,A24,A28,"Total Products","EBITDA LTM","Value") -> #VALUE! | V14: =_xll.DBRW(A3,'Value Tree'!J6,V11,P14,A24,A28,"Total Products","EBITDA LTM","Value") -> #VALUE! | AA14: ='Value Tree'!$J$4 -> #N/A | AC14: =_xll.DBRW($A$3,'Value Tree'!$J$6,AC$6,$AA14,$AQ14,$AP14,"Total Products","EBIT","Value") -> #VALUE! | AF14: =AC14/_xll.DBRW($A$3,'Value Tree'!$J$6,AF6,$AA14,$AQ14,$AR14,"Total Products","EBITDA LTM","Value") -> #VALUE! | AJ14: =_xll.DBRW($A$3,'Value Tree'!$J$6,AJ$6,$AA14,$AQ14,$AP14,"Total Products","EBIT","Value") -> #VALUE! | AM14: =AJ14/_xll.DBRW($A$3,'Value Tree'!$J$6,AM6,$AA14,$AQ14,$AR14,"Total Products","EBITDA LTM","Value") -> #VALUE! | AP14: =_xll.SUBNM("CONS_VC:ALL.D.Region","","VCBR") -> VCBR | AQ14: BRL Conv. | AR14: Global | AU14: Agric Lime | BB14: =_xll.DBRW($A$3,'Value Tree'!$J$6,BB$6,$CV14,$CR14,$CT14,$CX14,"EBITDA LTM","Value") -> #VALUE! | BF14: =_xll.DBRW($A$3,'Value Tree'!$J$6,BF$6,$CV14,$CR14,$CT14,$CX14,"EBITDA LTM","Value") -> #VALUE! | BX14: =IF($BW$6="+",IF(BB14>BZ14*(1+IF(BZ14>0,$C$4,-$C$4)),1,IF(BB14>=BY14*(1+IF(BY14>0,-$C$4,$C$4)),0,-1)),IF($BW$6="-",IF(BB14<BZ14*(1+IF(BZ14>0,-$C$4,$C$4)),1,IF(BB14<=BY14*(1+IF(BY14>0,$C$4,-$C$4)),0,-1)))) -> #VALUE! | BY14: =_xll.DBRW($A$3,'Value Tree'!$J$6,BY$6,BY$7,$CR14,$CT14,$CX14,"EBITDA LTM","Value") -> #VALUE! | BZ14: =_xll.DBRW($A$3,'Value Tree'!$J$6,BZ$6,BZ$7,$CR14,$CT14,$CX14,"EBITDA LTM","Value") -> #VALUE! | CB14: =IF($BW$6="+",IF(BF14>CD14*(1+IF(CD14>0,$C$4,-$C$4)),1,IF(BF14>=CC14*(1+IF(CC14>0,-$C$4,$C$4)),0,-1)),IF($BW$6="-",IF(BF14<CD14*(1+IF(CD14>0,-$C$4,$C$4)),1,IF(BF14<=CC14*(1+IF(CC14>0,$C$4,-$C$4)),0,-1)))) -> #VALUE! | CC14: =_xll.DBRW($A$3,'Value Tree'!$J$6,CC$6,CC$7,$CR14,$CT14,$CX14,"EBITDA LTM","Value") -> #VALUE! | CD14: =_xll.DBRW($A$3,'Value Tree'!$J$6,CD$6,CD$7,$CR14,$CT14,$CX14,"EBITDA LTM","Value") -> #VALUE! | CR14: BRL Conv. | CT14: VCBR | CV14: RF | CX14: PRODAL010 - Ag. Lime
F15: Net Profit (M) | P15: ='Value Tree'!$J$4 -> #N/A | R15: =_xll.DBRW(A3,'Value Tree'!J6,R11,P15,A24,A28,"Total Products","EBITDA LTM","Value") -> #VALUE! | V15: =_xll.DBRW(A3,'Value Tree'!J6,V11,P15,A24,A28,"Total Products","EBITDA LTM","Value") -> #VALUE! | AA15: =$A$20 -> l500 | AB15: =IF(AA6="+",IF(AC12>AC15*(1+IF(AC15>0,$C$4,-$C$4)),1,IF(AC12>=AC14*(1+IF(AC14>0,-$C$4,$C$4)),0,-1)),IF(AA6="-",IF(AC12<AC15*(1+IF(AC15>0,-$C$4,$C$4)),1,IF(AC12<=AC14*(1+IF(AC14>0,$C$4,-$C$4)),0,-1)))) -> #VALUE! | AC15: =_xll.DBRW($A$3,'Value Tree'!$J$6,AC$6,$AA15,$AQ14,$AP14,"Total Products","EBIT","Value") -> #VALUE! | AI15: =IF(AA6="+",IF(AJ12>AJ15*(1+IF(AJ15>0,$C$4,-$C$4)),1,IF(AJ12>=AJ14*(1+IF(AJ14>0,-$C$4,$C$4)),0,-1)),IF(AA6="-",IF(AJ12<AJ15*(1+IF(AJ15>0,-$C$4,$C$4)),1,IF(AJ12<=AJ14*(1+IF(AJ14>0,$C$4,-$C$4)),0,-1)))) -> #VALUE! | AJ15: =_xll.DBRW($A$3,'Value Tree'!$J$6,AJ$6,$AA15,$AQ14,$AP14,"Total Products","EBIT","Value") -> #VALUE! | AU15: Lime | BB15: =_xll.DBRW($A$3,'Value Tree'!$J$6,BB$6,$CV15,$CR15,$CT15,$CX15,"EBITDA LTM","Value") -> #VALUE! | BF15: =_xll.DBRW($A$3,'Value Tree'!$J$6,BF$6,$CV15,$CR15,$CT15,$CX15,"EBITDA LTM","Value") -> #VALUE! | BX15: =IF($BW$6="+",IF(BB15>BZ15*(1+IF(BZ15>0,$C$4,-$C$4)),1,IF(BB15>=BY15*(1+IF(BY15>0,-$C$4,$C$4)),0,-1)),IF($BW$6="-",IF(BB15<BZ15*(1+IF(BZ15>0,-$C$4,$C$4)),1,IF(BB15<=BY15*(1+IF(BY15>0,$C$4,-$C$4)),0,-1)))) -> #VALUE! | BY15: =_xll.DBRW($A$3,'Value Tree'!$J$6,BY$6,BY$7,$CR15,$CT15,$CX15,"EBITDA LTM","Value") -> #VALUE! | BZ15: =_xll.DBRW($A$3,'Value Tree'!$J$6,BZ$6,BZ$7,$CR15,$CT15,$CX15,"EBITDA LTM","Value") -> #VALUE! | CB15: =IF($BW$6="+",IF(BF15>CD15*(1+IF(CD15>0,$C$4,-$C$4)),1,IF(BF15>=CC15*(1+IF(CC15>0,-$C$4,$C$4)),0,-1)),IF($BW$6="-",IF(BF15<CD15*(1+IF(CD15>0,-$C$4,$C$4)),1,IF(BF15<=CC15*(1+IF(CC15>0,$C$4,-$C$4)),0,-1)))) -> #VALUE! | CC15: =_xll.DBRW($A$3,'Value Tree'!$J$6,CC$6,CC$7,$CR15,$CT15,$CX15,"EBITDA LTM","Value") -> #VALUE! | CD15: =_xll.DBRW($A$3,'Value Tree'!$J$6,CD$6,CD$7,$CR15,$CT15,$CX15,"EBITDA LTM","Value") -> #VALUE! | CR15: BRL Conv. | CT15: VCBR | CV15: RF | CX15: PRODLM010 - Lime
P16: =$A$20 -> l500 | Q16: =IF(P11="+",IF(R14>R16*(1+IF(R16>0,$C$4,-$C$4)),1,IF(R14>=R15*(1+IF(R15>0,-$C$4,$C$4)),0,-1)),IF(P11="-",IF(R14<R16*(1+IF(R16>0,-$C$4,$C$4)),1,IF(R14<=R15*(1+IF(R15>0,$C$4,-$C$4)),0,-1)))) -> #VALUE! | R16: =_xll.DBRW(A3,'Value Tree'!J6,R11,P16,A24,A28,"Total Products","EBITDA LTM","Value") -> #VALUE! | U16: =IF(P11="+",IF(V14>V16*(1+IF(V16>0,$C$4,-$C$4)),1,IF(V14>=V15*(1+IF(V15>0,-$C$4,$C$4)),0,-1)),IF(P11="-",IF(V14<V16*(1+IF(V16>0,-$C$4,$C$4)),1,IF(V14<=V15*(1+IF(V15>0,$C$4,-$C$4)),0,-1)))) -> #VALUE! | V16: =_xll.DBRW(A3,'Value Tree'!J6,V11,P16,A24,A28,"Total Products","EBITDA LTM","Value") -> #VALUE!
A17: =_xll.SUBNM("CONS_VC:ALL.D.Month",,"Year","MEMBER_NAME") -> Year | E17: ='Value Tree'!$D$4 -> #N/A | G17: =_xll.DBRW(A4,'Value Tree'!J6,G14,E17,A24,A28,A31,A36,A45) -> #VALUE! | K17: =_xll.DBRW(A4,'Value Tree'!J6,K14,E17,A24,A28,A31,A36,A45) -> #VALUE! | P17: + | R17: ='Value Tree'!$D$6 -> #N/A | V17: =$A$17 -> Year | AU17: Motz | BB17: =_xll.DBRW($A$3,'Value Tree'!$J$6,BB$6,$CV17,$CR17,$CT17,$CX17,"EBITDA LTM","Value") -> #VALUE! | BF17: =_xll.DBRW($A$3,'Value Tree'!$J$6,BF$6,$CV17,$CR17,$CT17,$CX17,"EBITDA LTM","Value") -> #VALUE! | BX17: =IF($BW$6="+",IF(BB17>BZ17*(1+IF(BZ17>0,$C$4,-$C$4)),1,IF(BB17>=BY17*(1+IF(BY17>0,-$C$4,$C$4)),0,-1)),IF($BW$6="-",IF(BB17<BZ17*(1+IF(BZ17>0,-$C$4,$C$4)),1,IF(BB17<=BY17*(1+IF(BY17>0,$C$4,-$C$4)),0,-1)))) -> #VALUE! | BY17: =_xll.DBRW($A$3,'Value Tree'!$J$6,BY$6,BY$7,$CR17,$CT17,$CX17,"EBITDA LTM","Value") -> #VALUE! | BZ17: =_xll.DBRW($A$3,'Value Tree'!$J$6,BZ$6,BZ$7,$CR17,$CT17,$CX17,"EBITDA LTM","Value") -> #VALUE! | CB17: =IF($BW$6="+",IF(BF17>CD17*(1+IF(CD17>0,$C$4,-$C$4)),1,IF(BF17>=CC17*(1+IF(CC17>0,-$C$4,$C$4)),0,-1)),IF($BW$6="-",IF(BF17<CD17*(1+IF(CD17>0,-$C$4,$C$4)),1,IF(BF17<=CC17*(1+IF(CC17>0,$C$4,-$C$4)),0,-1)))) -> #VALUE! | CC17: =_xll.DBRW($A$3,'Value Tree'!$J$6,CC$6,CC$7,$CR17,$CT17,$CX17,"EBITDA LTM","Value") -> #VALUE! | CD17: =_xll.DBRW($A$3,'Value Tree'!$J$6,CD$6,CD$7,$CR17,$CT17,$CX17,"EBITDA LTM","Value") -> #VALUE! | CR17: BRL Conv. | CT17: VCBR | CV17: RF | CX17: PRODMZ010 - Motz
E18: ='Value Tree'!$J$4 -> #N/A | G18: =_xll.DBRW(A4,'Value Tree'!J6,G14,E18,A24,A28,A31,A36,A45) -> #VALUE! | K18: =_xll.DBRW(A4,'Value Tree'!J6,K14,E18,A24,A28,A31,A36,A45) -> #VALUE! | Q18: EBIT (M)
A19: Versão | E19: =$A$20 -> l500 | F19: =IF(E14="+",IF(G17>G19*(1+IF(G19>0,$C$4,-$C$4)),1,IF(G17>=G18*(1+IF(G18>0,-$C$4,$C$4)),0,-1)),IF(E14="-",IF(G17<G19*(1+IF(G19>0,-$C$4,$C$4)),1,IF(G17<=G18*(1+IF(G18>0,$C$4,-$C$4)),0,-1)))) -> #VALUE! | G19: =_xll.DBRW(A4,'Value Tree'!J6,G14,E19,A24,A28,A31,A36,A45) -> #VALUE! | J19: =IF(E14="+",IF(K17>K19*(1+IF(K19>0,$C$4,-$C$4)),1,IF(K17>=K18*(1+IF(K18>0,-$C$4,$C$4)),0,-1)),IF(E14="-",IF(K17<K19*(1+IF(K19>0,-$C$4,$C$4)),1,IF(K17<=K18*(1+IF(K18>0,$C$4,-$C$4)),0,-1)))) -> #VALUE! | K19: =_xll.DBRW(A4,'Value Tree'!J6,K14,E19,A24,A28,A31,A36,A45) -> #VALUE! | P19: ='Value Tree'!$D$4 -> #N/A | R19: =_xll.DBRW(A3,'Value Tree'!J6,R17,P19,A24,A28,"Total Products","EBIT","Value") -> #VALUE! | V19: =_xll.DBRW(A3,'Value Tree'!J6,V17,P19,A24,A28,"Total Products","EBIT","Value") -> #VALUE! | AA19: + | AC19: ='Value Tree'!$D$6 -> #N/A | AF19: ='Value Tree'!$D$6 -> #N/A | AJ19: Year | AM19: Year | BB19: ='Value Tree'!$D$6 -> #N/A | BF19: =$A$17 -> Year
A20: l500 | P20: ='Value Tree'!$J$4 -> #N/A | R20: =_xll.DBRW(A3,'Value Tree'!J6,R17,P20,A24,A28,"Total Products","EBIT","Value") -> #VALUE! | V20: =_xll.DBRW(A3,'Value Tree'!J6,V17,P20,A24,A28,"Total Products","EBIT","Value") -> #VALUE! | AB20: EBITDA (USD M) Mg. EBITDA - VCNA | AU20: EBITDA VCNA Breakdown (USD M) | BW20: +
P21: =$A$20 -> l500 | Q21: =IF(P17="+",IF(R19>R21*(1+IF(R21>0,$C$4,-$C$4)),1,IF(R19>=R20*(1+IF(R20>0,-$C$4,$C$4)),0,-1)),IF(P17="-",IF(R19<R21*(1+IF(R21>0,-$C$4,$C$4)),1,IF(R19<=R20*(1+IF(R20>0,$C$4,-$C$4)),0,-1)))) -> #VALUE! | R21: =_xll.DBRW(A3,'Value Tree'!J6,R17,P21,A24,A28,"Total Products","EBIT","Value") -> #VALUE! | U21: =IF(P17="+",IF(V19>V21*(1+IF(V21>0,$C$4,-$C$4)),1,IF(V19>=V20*(1+IF(V20>0,-$C$4,$C$4)),0,-1)),IF(P17="-",IF(V19<V21*(1+IF(V21>0,-$C$4,$C$4)),1,IF(V19<=V20*(1+IF(V20>0,$C$4,-$C$4)),0,-1)))) -> #VALUE! | V21: =_xll.DBRW(A3,'Value Tree'!J6,V17,P21,A24,A28,"Total Products","EBIT","Value") -> #VALUE! | AA21: ='Value Tree'!$D$4 -> #N/A | AC21: =_xll.DBRW($A$3,'Value Tree'!$J$6,AC$19,$AA21,$AQ21,$AP21,"Total Products","EBITDA LTM","Value") -> #VALUE! | AF21: =AC21/_xll.DBRW($A$3,'Value Tree'!$J$6,AF19,$AA21,$AQ21,$AR21,"Total Products","EBITDA LTM","Value") -> #VALUE! | AJ21: =_xll.DBRW($A$3,'Value Tree'!$J$6,AJ$19,$AA21,$AQ21,$AP21,"Total Products","EBITDA LTM","Value") -> #VALUE! | AM21: =AJ21/_xll.DBRW($A$3,'Value Tree'!$J$6,AM19,$AA21,$AQ21,$AR21,"Total Products","EBITDA LTM","Value") -> #VALUE! | AP21: VCNA | AQ21: USD Conv. | AR21: Global | AU21: Cement | BB21: =_xll.DBRW($A$3,'Value Tree'!$J$6,BB$19,$CV21,$CR21,$CT21,$CX21,"EBITDA LTM","Value") -> #VALUE! | BF21: =_xll.DBRW($A$3,'Value Tree'!$J$6,BF$19,$CV21,$CR21,$CT21,$CX21,"EBITDA LTM","Value") -> #VALUE! | BX21: =IF($BW$20="+",IF(BB21>BZ21*(1+IF(BZ21>0,$C$4,-$C$4)),1,IF(BB21>=BY21*(1+IF(BY21>0,-$C$4,$C$4)),0,-1)),IF($BW$20="-",IF(BB21<BZ21*(1+IF(BZ21>0,-$C$4,$C$4)),1,IF(BB21<=BY21*(1+IF(BY21>0,$C$4,-$C$4)),0,-1)))) -> #VALUE! | BY21: =_xll.DBRW($A$3,'Value Tree'!$J$6,BY$6,BY$7,$CR21,$CT21,$CX21,"EBITDA LTM","Value") -> #VALUE! | BZ21: =_xll.DBRW($A$3,'Value Tree'!$J$6,BZ$6,BZ$7,$CR21,$CT21,$CX21,"EBITDA LTM","Value") -> #VALUE! | CB21: =IF($BW$20="+",IF(BF21>CD21*(1+IF(CD21>0,$C$4,-$C$4)),1,IF(BF21>=CC21*(1+IF(CC21>0,-$C$4,$C$4)),0,-1)),IF($BW$20="-",IF(BF21<CD21*(1+IF(CD21>0,-$C$4,$C$4)),1,IF(BF21<=CC21*(1+IF(CC21>0,$C$4,-$C$4)),0,-1)))) -> #VALUE! | CC21: =_xll.DBRW($A$3,'Value Tree'!$J$6,CC$6,CC$7,$CR21,$CT21,$CX21,"EBITDA LTM","Value") -> #VALUE! | CD21: =_xll.DBRW($A$3,'Value Tree'!$J$6,CD$6,CD$7,$CR21,$CT21,$CX21,"EBITDA LTM","Value") -> #VALUE! | CR21: USD Conv. | CT21: VCNA | CV21: RF | CX21: PRODCE010 - Cement
A22: Currency | P22: + | R22: ='Value Tree'!$D$6 -> #N/A | V22: =$A$17 -> Year | AA22: ='Value Tree'!$J$4 -> #N/A | AC22: =_xll.DBRW($A$3,'Value Tree'!$J$6,AC$19,$AA22,$AQ22,$AP22,"Total Products","EBITDA LTM","Value") -> #VALUE! | AF22: =AC22/_xll.DBRW($A$3,'Value Tree'!$J$6,AF19,$AA22,$AQ22,$AR22,"Total Products","EBITDA LTM","Value") -> #VALUE! | AJ22: =_xll.DBRW($A$3,'Value Tree'!$J$6,AJ$19,$AA22,$AQ22,$AP22,"Total Products","EBITDA LTM","Value") -> #VALUE! | AM22: =AJ22/_xll.DBRW($A$3,'Value Tree'!$J$6,AM19,$AA22,$AQ22,$AR22,"Total Products","EBITDA LTM","Value") -> #VALUE! | AP22: VCNA | AQ22: USD Conv. | AR22: Global | AU22: Ready Mix | BB22: =_xll.DBRW($A$3,'Value Tree'!$J$6,BB$19,$CV22,$CR22,$CT22,$CX22,"EBITDA LTM","Value") -> #VALUE! | BF22: =_xll.DBRW($A$3,'Value Tree'!$J$6,BF$19,$CV22,$CR22,$CT22,$CX22,"EBITDA LTM","Value") -> #VALUE! | BX22: =IF($BW$20="+",IF(BB22>BZ22*(1+IF(BZ22>0,$C$4,-$C$4)),1,IF(BB22>=BY22*(1+IF(BY22>0,-$C$4,$C$4)),0,-1)),IF($BW$20="-",IF(BB22<BZ22*(1+IF(BZ22>0,-$C$4,$C$4)),1,IF(BB22<=BY22*(1+IF(BY22>0,$C$4,-$C$4)),0,-1)))) -> #VALUE! | BY22: =_xll.DBRW($A$3,'Value Tree'!$J$6,BY$6,BY$7,$CR22,$CT22,$CX22,"EBITDA LTM","Value") -> #VALUE! | BZ22: =_xll.DBRW($A$3,'Value Tree'!$J$6,BZ$6,BZ$7,$CR22,$CT22,$CX22,"EBITDA LTM","Value") -> #VALUE! | CB22: =IF($BW$20="+",IF(BF22>CD22*(1+IF(CD22>0,$C$4,-$C$4)),1,IF(BF22>=CC22*(1+IF(CC22>0,-$C$4,$C$4)),0,-1)),IF($BW$20="-",IF(BF22<CD22*(1+IF(CD22>0,-$C$4,$C$4)),1,IF(BF22<=CC22*(1+IF(CC22>0,$C$4,-$C$4)),0,-1)))) -> #VALUE! | CC22: =_xll.DBRW($A$3,'Value Tree'!$J$6,CC$6,CC$7,$CR22,$CT22,$CX22,"EBITDA LTM","Value") -> #VALUE! | CD22: =_xll.DBRW($A$3,'Value Tree'!$J$6,CD$6,CD$7,$CR22,$CT22,$CX22,"EBITDA LTM","Value") -> #VALUE! | CR22: USD Conv. | CT22: VCNA | CV22: RF | CX22: PRODRM010 - Ready Mix
AA23: =$A$20 -> l500 | AB23: =IF(AA19="+",IF(AC21>AC23*(1+IF(AC23>0,$C$4,-$C$4)),1,IF(AC21>=AC22*(1+IF(AC22>0,-$C$4,$C$4)),0,-1)),IF(AA19="-",IF(AC21<AC23*(1+IF(AC23>0,-$C$4,$C$4)),1,IF(AC21<=AC22*(1+IF(AC22>0,$C$4,-$C$4)),0,-1)))) -> #VALUE! | AC23: =_xll.DBRW($A$3,'Value Tree'!$J$6,AC$19,$AA23,$AQ22,$AP22,"Total Products","EBITDA LTM","Value") -> #VALUE! | AI23: =IF(AA19="+",IF(AJ21>AJ23*(1+IF(AJ23>0,$C$4,-$C$4)),1,IF(AJ21>=AJ22*(1+IF(AJ22>0,-$C$4,$C$4)),0,-1)),IF(AA19="-",IF(AJ21<AJ23*(1+IF(AJ23>0,-$C$4,$C$4)),1,IF(AJ21<=AJ22*(1+IF(AJ22>0,$C$4,-$C$4)),0,-1)))) -> #VALUE! | AJ23: =_xll.DBRW($A$3,'Value Tree'!$J$6,AJ$19,$AA23,$AQ22,$AP22,"Total Products","EBITDA LTM","Value") -> #VALUE!
A24: =_xll.SUBNM("CONS_VC:ALL.D.Currency","","BRL") -> BRL | Q24: Capex (M) | AB24: EBIT (USD M) Mg. EBITDA - VCNA | AU24: Aggregates | BB24: =_xll.DBRW($A$3,'Value Tree'!$J$6,BB$19,$CV24,$CR24,$CT24,$CX24,"EBITDA LTM","Value") -> #VALUE! | BF24: =_xll.DBRW($A$3,'Value Tree'!$J$6,BF$19,$CV24,$CR24,$CT24,$CX24,"EBITDA LTM","Value") -> #VALUE! | BX24: =IF($BW$20="+",IF(BB24>BZ24*(1+IF(BZ24>0,$C$4,-$C$4)),1,IF(BB24>=BY24*(1+IF(BY24>0,-$C$4,$C$4)),0,-1)),IF($BW$20="-",IF(BB24<BZ24*(1+IF(BZ24>0,-$C$4,$C$4)),1,IF(BB24<=BY24*(1+IF(BY24>0,$C$4,-$C$4)),0,-1)))) -> #VALUE! | BY24: =_xll.DBRW($A$3,'Value Tree'!$J$6,BY$6,BY$7,$CR24,$CT24,$CX24,"EBITDA LTM","Value") -> #VALUE! | BZ24: =_xll.DBRW($A$3,'Value Tree'!$J$6,BZ$6,BZ$7,$CR24,$CT24,$CX24,"EBITDA LTM","Value") -> #VALUE! | CB24: =IF($BW$20="+",IF(BF24>CD24*(1+IF(CD24>0,$C$4,-$C$4)),1,IF(BF24>=CC24*(1+IF(CC24>0,-$C$4,$C$4)),0,-1)),IF($BW$20="-",IF(BF24<CD24*(1+IF(CD24>0,-$C$4,$C$4)),1,IF(BF24<=CC24*(1+IF(CC24>0,$C$4,-$C$4)),0,-1)))) -> #VALUE! | CC24: =_xll.DBRW($A$3,'Value Tree'!$J$6,CC$6,CC$7,$CR24,$CT24,$CX24,"EBITDA LTM","Value") -> #VALUE! | CD24: =_xll.DBRW($A$3,'Value Tree'!$J$6,CD$6,CD$7,$CR24,$CT24,$CX24,"EBITDA LTM","Value") -> #VALUE! | CR24: USD Conv. | CT24: VCNA | CV24: RF | CX24: PRODAG010 - Aggregates
P25: ='Value Tree'!$D$4 -> #N/A | R25: =_xll.DBRW(A5,'Value Tree'!J6,R22,P25,A24,A28,"Expansion Capex",A48) -> #VALUE! | V25: =_xll.DBRW(A5,'Value Tree'!J6,V22,P25,A24,A28,"Expansion Capex",A48) -> #VALUE! | AA25: ='Value Tree'!$D$4 -> #N/A | AC25: =_xll.DBRW($A$3,'Value Tree'!$J$6,AC$19,$AA25,$AQ25,$AP25,"Total Products","EBIT","Value") -> #VALUE! | AF25: =AC25/_xll.DBRW($A$3,'Value Tree'!$J$6,AF19,$AA25,$AQ25,$AR25,"Total Products","EBITDA LTM","Value") -> #VALUE! | AJ25: =_xll.DBRW($A$3,'Value Tree'!$J$6,AJ$19,$AA25,$AQ25,$AP25,"Total Products","EBITDA LTM","Value") -> #VALUE! | AM25: =AJ25/_xll.DBRW($A$3,'Value Tree'!$J$6,AM19,$AA25,$AQ25,$AR25,"Total Products","EBITDA LTM","Value") -> #VALUE! | AP25: VCNA | AQ25: USD Conv. | AR25: Global | AU25: Corporate | BB25: =_xll.DBRW($A$3,'Value Tree'!$J$6,BB$19,$CV25,$CR25,$CT25,$CX25,"EBITDA LTM","Value") -> #VALUE! | BF25: =_xll.DBRW($A$3,'Value Tree'!$J$6,BF$19,$CV25,$CR25,$CT25,$CX25,"EBITDA LTM","Value") -> #VALUE! | BX25: =IF($BW$20="+",IF(BB25>BZ25*(1+IF(BZ25>0,$C$4,-$C$4)),1,IF(BB25>=BY25*(1+IF(BY25>0,-$C$4,$C$4)),0,-1)),IF($BW$20="-",IF(BB25<BZ25*(1+IF(BZ25>0,-$C$4,$C$4)),1,IF(BB25<=BY25*(1+IF(BY25>0,$C$4,-$C$4)),0,-1)))) -> #VALUE! | BY25: =_xll.DBRW($A$3,'Value Tree'!$J$6,BY$6,BY$7,$CR25,$CT25,$CX25,"EBITDA LTM","Value") -> #VALUE! | BZ25: =_xll.DBRW($A$3,'Value Tree'!$J$6,BZ$6,BZ$7,$CR25,$CT25,$CX25,"EBITDA LTM","Value") -> #VALUE! | CB25: =IF($BW$20="+",IF(BF25>CD25*(1+IF(CD25>0,$C$4,-$C$4)),1,IF(BF25>=CC25*(1+IF(CC25>0,-$C$4,$C$4)),0,-1)),IF($BW$20="-",IF(BF25<CD25*(1+IF(CD25>0,-$C$4,$C$4)),1,IF(BF25<=CC25*(1+IF(CC25>0,$C$4,-$C$4)),0,-1)))) -> #VALUE! | CC25: =_xll.DBRW($A$3,'Value Tree'!$J$6,CC$6,CC$7,$CR25,$CT25,$CX25,"EBITDA LTM","Value") -> #VALUE! | CD25: =_xll.DBRW($A$3,'Value Tree'!$J$6,CD$6,CD$7,$CR25,$CT25,$CX25,"EBITDA LTM","Value") -> #VALUE! | CR25: USD Conv. | CT25: VCNA | CV25: RF | CX25: PRODCORP - Corporate
A26: Region | P26: ='Value Tree'!$J$4 -> #N/A | R26: =_xll.DBRW(A5,'Value Tree'!J6,R22,P26,A24,A28,"Expansion Capex",A48) -> #VALUE! | V26: =_xll.DBRW(A5,'Value Tree'!J6,V22,P26,A24,A28,"Expansion Capex",A48) -> #VALUE! | AA26: ='Value Tree'!$J$4 -> #N/A | AC26: =_xll.DBRW($A$3,'Value Tree'!$J$6,AC$19,$AA26,$AQ26,$AP26,"Total Products","EBIT","Value") -> #VALUE! | AF26: =AC26/_xll.DBRW($A$3,'Value Tree'!$J$6,AF19,$AA26,$AQ26,$AR26,"Total Products","EBITDA LTM","Value") -> #VALUE! | AJ26: =_xll.DBRW($A$3,'Value Tree'!$J$6,AJ$19,$AA26,$AQ26,$AP26,"Total Products","EBITDA LTM","Value") -> #VALUE! | AM26: =AJ26/_xll.DBRW($A$3,'Value Tree'!$J$6,AM19,$AA26,$AQ26,$AR26,"Total Products","EBITDA LTM","Value") -> #VALUE! | AP26: VCNA | AQ26: USD Conv. | AR26: Global
P27: =$A$20 -> l500 | Q27: =IF(P22="+",IF(R25>R27*(1+IF(R27>0,$C$4,-$C$4)),1,IF(R25>=R26*(1+IF(R26>0,-$C$4,$C$4)),0,-1)),IF(P22="-",IF(R25<R27*(1+IF(R27>0,-$C$4,$C$4)),1,IF(R25<=R26*(1+IF(R26>0,$C$4,-$C$4)),0,-1)))) -> #VALUE! | R27: =_xll.DBRW(A5,'Value Tree'!J6,R22,P27,A24,A28,"Expansion Capex",A48) -> #VALUE! | U27: =IF(P22="+",IF(V25>V27*(1+IF(V27>0,$C$4,-$C$4)),1,IF(V25>=V26*(1+IF(V26>0,-$C$4,$C$4)),0,-1)),IF(P22="-",IF(V25<V27*(1+IF(V27>0,-$C$4,$C$4)),1,IF(V25<=V26*(1+IF(V26>0,$C$4,-$C$4)),0,-1)))) -> #VALUE! | V27: =_xll.DBRW(A5,'Value Tree'!J6,V22,P27,A24,A28,"Expansion Capex",A48) -> #VALUE! | AA27: =$A$20 -> l500 | AB27: =IF(AA19="+",IF(AC25>AC27*(1+IF(AC27>0,$C$4,-$C$4)),1,IF(AC25>=AC26*(1+IF(AC26>0,-$C$4,$C$4)),0,-1)),IF(AA19="-",IF(AC25<AC27*(1+IF(AC27>0,-$C$4,$C$4)),1,IF(AC25<=AC26*(1+IF(AC26>0,$C$4,-$C$4)),0,-1)))) -> #VALUE! | AC27: =_xll.DBRW($A$3,'Value Tree'!$J$6,AC$19,$AA27,$AQ26,$AP26,"Total Products","EBIT","Value") -> #VALUE! | AI27: =IF(AA19="+",IF(AJ25>AJ27*(1+IF(AJ27>0,$C$4,-$C$4)),1,IF(AJ25>=AJ26*(1+IF(AJ26>0,-$C$4,$C$4)),0,-1)),IF(AA19="-",IF(AJ25<AJ27*(1+IF(AJ27>0,-$C$4,$C$4)),1,IF(AJ25<=AJ26*(1+IF(AJ26>0,$C$4,-$C$4)),0,-1)))) -> #VALUE! | AJ27: =_xll.DBRW($A$3,'Value Tree'!$J$6,AJ$19,$AA27,$AQ26,$AP26,"Total Products","EBITDA LTM","Value") -> #VALUE!
A28: =_xll.SUBNM("CONS_VC:ALL.D.Region","DEFAuLT","Global") -> Global | E28: + | G28: ='Value Tree'!$D$6 -> #N/A | K28: =$A$17 -> Year | P28: + | R28: ='Value Tree'!$D$6 -> #N/A | V28: =$A$17 -> Year
F29: FCF (M) | Q29: WK Capital (M) | AA29: + | AC29: ='Value Tree'!$D$6 -> #N/A | AF29: ='Value Tree'!$D$6 -> #N/A | AJ29: Year | AM29: Year | BB29: ='Value Tree'!$D$6 -> #N/A | BF29: =$A$17 -> Year | BK29: ='Value Tree'!$D$6 -> #N/A | BO29: =$A$17 -> Year
A30: Produto | E30: ='Value Tree'!$D$4 -> #N/A | G30: =_xll.DBRW($A$5,'Value Tree'!J6,G28,E30,A24,A28,A40,$A$48) -> #VALUE! | K30: =_xll.DBRW($A$5,'Value Tree'!J6,K28,E30,A24,A28,A40,$A$48) -> #VALUE! | P30: ='Value Tree'!$D$4 -> #N/A | R30: =_xll.DBRW(A3,'Value Tree'!J6,R28,P30,A24,A28,"Total Products","Working Capital Balance","Value") -> #VALUE! | V30: =_xll.DBRW(A3,'Value Tree'!J6,V28,P30,A24,A28,"Total Products","Working Capital Balance","Value") -> #VALUE! | AB30: EBITDA (EUR M) Mg. EBITDA - VCEA | AU30: EBITDA VCEA Breakdown (EUR M) | BJ30: EBITDA VCEA (LMU M) | BW30: +
A31: =_xll.SUBNM("CONS_VC:ALL.D.Products","","Total Products") -> Total Products | E31: ='Value Tree'!$J$4 -> #N/A | G31: =_xll.DBRW($A$5,'Value Tree'!J6,G28,E31,A24,A28,A40,$A$48) -> #VALUE! | K31: =_xll.DBRW($A$5,'Value Tree'!J6,K28,E31,A24,A28,A40,$A$48) -> #VALUE! | P31: ='Value Tree'!$J$4 -> #N/A | R31: =_xll.DBRW(A3,'Value Tree'!J6,R28,P31,A24,A28,"Total Products","Working Capital Balance","Value") -> #VALUE! | V31: =_xll.DBRW(A3,'Value Tree'!J6,V28,P31,A24,A28,"Total Products","Working Capital Balance","Value") -> #VALUE! | AA31: ='Value Tree'!$D$4 -> #N/A | AC31: =_xll.DBRW($A$3,'Value Tree'!$J$6,AC$29,$AA31,$AQ31,$AP31,"Total Products","EBITDA LTM","Value") -> #VALUE! | AF31: =AC31/_xll.DBRW($A$3,'Value Tree'!$J$6,AF29,$AA31,$AQ31,$AR31,"Total Products","EBITDA LTM","Value") -> #VALUE! | AJ31: =_xll.DBRW($A$3,'Value Tree'!$J$6,AJ$29,$AA31,$AQ31,$AP31,"Total Products","EBITDA LTM","Value") -> #VALUE! | AM31: =AJ31/_xll.DBRW($A$3,'Value Tree'!$J$6,AM29,$AA31,$AQ31,$AR31,"Total Products","EBITDA LTM","Value") -> #VALUE! | AP31: VCEAA | AQ31: EUR Conv. | AR31: Global | AU31: Spain | BB31: =_xll.DBRW($A$3,'Value Tree'!$J$6,BB$29,$CV31,$CR31,$CT31,$CX31,"EBITDA LTM","Value") -> #VALUE! | BF31: =_xll.DBRW($A$3,'Value Tree'!$J$6,BF$29,$CV31,$CR31,$CT31,$CX31,"EBITDA LTM","Value") -> #VALUE! | BK31: =_xll.DBRW($A$3,'Value Tree'!$J$6,BK$29,$DF31,$DB31,$DD31,$DH31,"EBITDA LTM","Value") -> #VALUE! | BO31: =_xll.DBRW($A$3,'Value Tree'!$J$6,BO$29,$DF31,$DB31,$DD31,$DH31,"EBITDA LTM","Value") -> #VALUE! | BX31: =IF($BW$30="+",IF(BB31>BZ31*(1+IF(BZ31>0,$C$4,-$C$4)),1,IF(BB31>=BY31*(1+IF(BY31>0,-$C$4,$C$4)),0,-1)),IF($BW$30="-",IF(BB31<BZ31*(1+IF(BZ31>0,-$C$4,$C$4)),1,IF(BB31<=BY31*(1+IF(BY31>0,$C$4,-$C$4)),0,-1)))) -> #VALUE! | BY31: =_xll.DBRW($A$3,'Value Tree'!$J$6,BY$6,BY$7,$CR31,$CT31,$CX31,"EBITDA LTM","Value") -> #VALUE! | BZ31: =_xll.DBRW($A$3,'Value Tree'!$J$6,BZ$6,BZ$7,$CR31,$CT31,$CX31,"EBITDA LTM","Value") -> #VALUE! | CB31: =IF($BW$30="+",IF(BF31>CD31*(1+IF(CD31>0,$C$4,-$C$4)),1,IF(BF31>=CC31*(1+IF(CC31>0,-$C$4,$C$4)),0,-1)),IF($BW$30="-",IF(BF31<CD31*(1+IF(CD31>0,-$C$4,$C$4)),1,IF(BF31<=CC31*(1+IF(CC31>0,$C$4,-$C$4)),0,-1)))) -> #VALUE! | CC31: =_xll.DBRW($A$3,'Value Tree'!$J$6,CC$6,CC$7,$CR31,$CT31,$CX31,"EBITDA LTM","Value") -> #VALUE! | CD31: =_xll.DBRW($A$3,'Value Tree'!$J$6,CD$6,CD$7,$CR31,$CT31,$CX31,"EBITDA LTM","Value") -> #VALUE! | CF31: =IF($BW$30="+",IF(BK31>CH31*(1+IF(CH31>0,$C$4,-$C$4)),1,IF(BK31>=CG31*(1+IF(CG31>0,-$C$4,$C$4)),0,-1)),IF($BW$30="-",IF(BK31<CH31*(1+IF(CH31>0,-$C$4,$C$4)),1,IF(BK31<=CG31*(1+IF(CG31>0,$C$4,-$C$4)),0,-1)))) -> #VALUE! | CG31: =_xll.DBRW($A$3,'Value Tree'!$J$6,CG$6,CG$7,$DB31,$CT31,$CX31,"EBITDA LTM","Value") -> #VALUE! | CH31: =_xll.DBRW($A$3,'Value Tree'!$J$6,CH$6,CH$7,$DB31,$CT31,$CX31,"EBITDA LTM","Value") -> #VALUE! | CJ31: =IF($BW$30="+",IF(BO31>CL31*(1+IF(CL31>0,$C$4,-$C$4)),1,IF(BO31>=CK31*(1+IF(CK31>0,-$C$4,$C$4)),0,-1)),IF($BW$30="-",IF(BO31<CL31*(1+IF(CL31>0,-$C$4,$C$4)),1,IF(BO31<=CK31*(1+IF(CK31>0,$C$4,-$C$4)),0,-1)))) -> #VALUE! | CK31: =_xll.DBRW($A$3,'Value Tree'!$J$6,CK$6,CK$7,$DB31,$CT31,$CX31,"EBITDA LTM","Value") -> #VALUE! | CL31: =_xll.DBRW($A$3,'Value Tree'!$J$6,CL$6,CL$7,$DB31,$CT31,$CX31,"EBITDA LTM","Value") -> #VALUE! | CR31: EUR Conv. | CT31: VCEAA | CV31: RF | CX31: Total Products | DB31: EUR | DD31: VCEAA | DF31: RF | DH31: Total Products
E32: =$A$20 -> l500 | F32: =IF(E28="+",IF(G30>G32*(1+IF(G32>0,$C$4,-$C$4)),1,IF(G30>=G31*(1+IF(G31>0,-$C$4,$C$4)),0,-1)),IF(E28="-",IF(G30<G32*(1+IF(G32>0,-$C$4,$C$4)),1,IF(G30<=G31*(1+IF(G31>0,$C$4,-$C$4)),0,-1)))) -> #VALUE! | G32: =_xll.DBRW($A$5,'Value Tree'!J6,G28,E32,A24,A28,A40,$A$48) -> #VALUE! | J32: =IF(E28="+",IF(K30>K32*(1+IF(K32>0,$C$4,-$C$4)),1,IF(K30>=K31*(1+IF(K31>0,-$C$4,$C$4)),0,-1)),IF(E28="-",IF(K30<K32*(1+IF(K32>0,-$C$4,$C$4)),1,IF(K30<=K31*(1+IF(K31>0,$C$4,-$C$4)),0,-1)))) -> #VALUE! | K32: =_xll.DBRW($A$5,'Value Tree'!J6,K28,E32,A24,A28,A40,$A$48) -> #VALUE! | P32: =$A$20 -> l500 | Q32: =IF(P28="+",IF(R30>R32*(1+IF(R32>0,$C$4,-$C$4)),1,IF(R30>=R31*(1+IF(R31>0,-$C$4,$C$4)),0,-1)),IF(P28="-",IF(R30<R32*(1+IF(R32>0,-$C$4,$C$4)),1,IF(R30<=R31*(1+IF(R31>0,$C$4,-$C$4)),0,-1)))) -> #VALUE! | R32: =_xll.DBRW(A3,'Value Tree'!J6,R28,P32,A24,A28,"Total Products","Working Capital Balance","Value") -> #VALUE! | U32: =IF(P28="+",IF(V30>V32*(1+IF(V32>0,$C$4,-$C$4)),1,IF(V30>=V31*(1+IF(V31>0,-$C$4,$C$4)),0,-1)),IF(P28="-",IF(V30<V32*(1+IF(V32>0,-$C$4,$C$4)),1,IF(V30<=V31*(1+IF(V31>0,$C$4,-$C$4)),0,-1)))) -> #VALUE! | V32: =_xll.DBRW(A3,'Value Tree'!J6,V28,P32,A24,A28,"Total Products","Working Capital Balance","Value") -> #VALUE!
E33: + | G33: ='Value Tree'!$D$6 -> #N/A | K33: =$A$17 -> Year | P33: + | R33: ='Value Tree'!$D$6 -> #N/A | V33: =$A$17 -> Year | AA33: ='Value Tree'!$J$4 -> #N/A | AC33: =_xll.DBRW($A$3,'Value Tree'!$J$6,AC$29,$AA33,$AQ33,$AP33,"Total Products","EBITDA LTM","Value") -> #VALUE! | AF33: =AC33/_xll.DBRW($A$3,'Value Tree'!$J$6,AF29,$AA33,$AQ33,$AR33,"Total Products","EBITDA LTM","Value") -> #VALUE! | AJ33: =_xll.DBRW($A$3,'Value Tree'!$J$6,AJ$29,$AA33,$AQ33,$AP33,"Total Products","EBITDA LTM","Value") -> #VALUE! | AM33: =AJ33/_xll.DBRW($A$3,'Value Tree'!$J$6,AM29,$AA33,$AQ33,$AR33,"Total Products","EBITDA LTM","Value") -> #VALUE! | AP33: VCEAA | AQ33: EUR Conv. | AR33: Global | AU33: Turkey | BB33: =_xll.DBRW($A$3,'Value Tree'!$J$6,BB$29,$CV33,$CR33,$CT33,$CX33,"EBITDA LTM","Value") -> #VALUE! | BF33: =_xll.DBRW($A$3,'Value Tree'!$J$6,BF$29,$CV33,$CR33,$CT33,$CX33,"EBITDA LTM","Value") -> #VALUE! | BK33: =_xll.DBRW($A$3,'Value Tree'!$J$6,BK$29,$DF33,$DB33,$DD33,$DH33,"EBITDA LTM","Value") -> #VALUE! | BO33: =_xll.DBRW($A$3,'Value Tree'!$J$6,BO$29,$DF33,$DB33,$DD33,$DH33,"EBITDA LTM","Value") -> #VALUE! | BX33: =IF($BW$30="+",IF(BB33>BZ33*(1+IF(BZ33>0,$C$4,-$C$4)),1,IF(BB33>=BY33*(1+IF(BY33>0,-$C$4,$C$4)),0,-1)),IF($BW$30="-",IF(BB33<BZ33*(1+IF(BZ33>0,-$C$4,$C$4)),1,IF(BB33<=BY33*(1+IF(BY33>0,$C$4,-$C$4)),0,-1)))) -> #VALUE! | BY33: =_xll.DBRW($A$3,'Value Tree'!$J$6,BY$6,BY$7,$CR33,$CT33,$CX33,"EBITDA LTM","Value") -> #VALUE! | BZ33: =_xll.DBRW($A$3,'Value Tree'!$J$6,BZ$6,BZ$7,$CR33,$CT33,$CX33,"EBITDA LTM","Value") -> #VALUE! | CB33: =IF($BW$30="+",IF(BF33>CD33*(1+IF(CD33>0,$C$4,-$C$4)),1,IF(BF33>=CC33*(1+IF(CC33>0,-$C$4,$C$4)),0,-1)),IF($BW$30="-",IF(BF33<CD33*(1+IF(CD33>0,-$C$4,$C$4)),1,IF(BF33<=CC33*(1+IF(CC33>0,$C$4,-$C$4)),0,-1)))) -> #VALUE! | CC33: =_xll.DBRW($A$3,'Value Tree'!$J$6,CC$6,CC$7,$CR33,$CT33,$CX33,"EBITDA LTM","Value") -> #VALUE! | CD33: =_xll.DBRW($A$3,'Value Tree'!$J$6,CD$6,CD$7,$CR33,$CT33,$CX33,"EBITDA LTM","Value") -> #VALUE! | CF33: =IF($BW$30="+",IF(BK33>CH33*(1+IF(CH33>0,$C$4,-$C$4)),1,IF(BK33>=CG33*(1+IF(CG33>0,-$C$4,$C$4)),0,-1)),IF($BW$30="-",IF(BK33<CH33*(1+IF(CH33>0,-$C$4,$C$4)),1,IF(BK33<=CG33*(1+IF(CG33>0,$C$4,-$C$4)),0,-1)))) -> #VALUE! | CG33: =_xll.DBRW($A$3,'Value Tree'!$J$6,CG$6,CG$7,$DB33,$CT33,$CX33,"EBITDA LTM","Value") -> #VALUE! | CH33: =_xll.DBRW($A$3,'Value Tree'!$J$6,CH$6,CH$7,$DB33,$CT33,$CX33,"EBITDA LTM","Value") -> #VALUE! | CJ33: =IF($BW$30="+",IF(BO33>CL33*(1+IF(CL33>0,$C$4,-$C$4)),1,IF(BO33>=CK33*(1+IF(CK33>0,-$C$4,$C$4)),0,-1)),IF($BW$30="-",IF(BO33<CL33*(1+IF(CL33>0,-$C$4,$C$4)),1,IF(BO33<=CK33*(1+IF(CK33>0,$C$4,-$C$4)),0,-1)))) -> #VALUE! | CK33: =_xll.DBRW($A$3,'Value Tree'!$J$6,CK$6,CK$7,$DB33,$CT33,$CX33,"EBITDA LTM","Value") -> #VALUE! | CL33: =_xll.DBRW($A$3,'Value Tree'!$J$6,CL$6,CL$7,$DB33,$CT33,$CX33,"EBITDA LTM","Value") -> #VALUE! | CR33: EUR Conv. | CT33: VCEAA | CV33: RF | CX33: Total Products | DB33: TRY | DD33: VCEAA | DF33: RF | DH33: Total Products
AA34: =$A$20 -> l500 | AB34: =IF(AA29="+",IF(AC31>AC34*(1+IF(AC34>0,$C$4,-$C$4)),1,IF(AC31>=AC33*(1+IF(AC33>0,-$C$4,$C$4)),0,-1)),IF(AA29="-",IF(AC31<AC34*(1+IF(AC34>0,-$C$4,$C$4)),1,IF(AC31<=AC33*(1+IF(AC33>0,$C$4,-$C$4)),0,-1)))) -> #VALUE! | AC34: =_xll.DBRW($A$3,'Value Tree'!$J$6,AC$29,$AA34,$AQ33,$AP33,"Total Products","EBITDA LTM","Value") -> #VALUE! | AI34: =IF(AA29="+",IF(AJ31>AJ34*(1+IF(AJ34>0,$C$4,-$C$4)),1,IF(AJ31>=AJ33*(1+IF(AJ33>0,-$C$4,$C$4)),0,-1)),IF(AA29="-",IF(AJ31<AJ34*(1+IF(AJ34>0,-$C$4,$C$4)),1,IF(AJ31<=AJ33*(1+IF(AJ33>0,$C$4,-$C$4)),0,-1)))) -> #VALUE! | AJ34: =_xll.DBRW($A$3,'Value Tree'!$J$6,AJ$29,$AA34,$AQ33,$AP33,"Total Products","EBITDA LTM","Value") -> #VALUE!
A35: Accounts_PNL | F35: ROIC (%) | Q35: Income Tax (M) | AB35: EBIT (EUR M) Mg. EBITDA - VCEA | AU35: Corporate | BB35: =_xll.DBRW($A$3,'Value Tree'!$J$6,BB$29,$CV35,$CR35,$CT35,$CX35,"EBITDA LTM","Value") -> #VALUE! | BF35: =_xll.DBRW($A$3,'Value Tree'!$J$6,BF$29,$CV35,$CR35,$CT35,$CX35,"EBITDA LTM","Value") -> #VALUE! | BK35: =_xll.DBRW($A$3,'Value Tree'!$J$6,BK$29,$DF35,$DB35,$DD35,$DH35,"EBITDA LTM","Value") -> #VALUE! | BO35: =_xll.DBRW($A$3,'Value Tree'!$J$6,BO$29,$DF35,$DB35,$DD35,$DH35,"EBITDA LTM","Value") -> #VALUE! | BX35: =IF($BW$30="+",IF(BB35>BZ35*(1+IF(BZ35>0,$C$4,-$C$4)),1,IF(BB35>=BY35*(1+IF(BY35>0,-$C$4,$C$4)),0,-1)),IF($BW$30="-",IF(BB35<BZ35*(1+IF(BZ35>0,-$C$4,$C$4)),1,IF(BB35<=BY35*(1+IF(BY35>0,$C$4,-$C$4)),0,-1)))) -> #VALUE! | BY35: =_xll.DBRW($A$3,'Value Tree'!$J$6,BY$6,BY$7,$CR35,$CT35,$CX35,"EBITDA LTM","Value") -> #VALUE! | BZ35: =_xll.DBRW($A$3,'Value Tree'!$J$6,BZ$6,BZ$7,$CR35,$CT35,$CX35,"EBITDA LTM","Value") -> #VALUE! | CB35: =IF($BW$30="+",IF(BF35>CD35*(1+IF(CD35>0,$C$4,-$C$4)),1,IF(BF35>=CC35*(1+IF(CC35>0,-$C$4,$C$4)),0,-1)),IF($BW$30="-",IF(BF35<CD35*(1+IF(CD35>0,-$C$4,$C$4)),1,IF(BF35<=CC35*(1+IF(CC35>0,$C$4,-$C$4)),0,-1)))) -> #VALUE! | CC35: =_xll.DBRW($A$3,'Value Tree'!$J$6,CC$6,CC$7,$CR35,$CT35,$CX35,"EBITDA LTM","Value") -> #VALUE! | CD35: =_xll.DBRW($A$3,'Value Tree'!$J$6,CD$6,CD$7,$CR35,$CT35,$CX35,"EBITDA LTM","Value") -> #VALUE! | CF35: =IF($BW$30="+",IF(BK35>CH35*(1+IF(CH35>0,$C$4,-$C$4)),1,IF(BK35>=CG35*(1+IF(CG35>0,-$C$4,$C$4)),0,-1)),IF($BW$30="-",IF(BK35<CH35*(1+IF(CH35>0,-$C$4,$C$4)),1,IF(BK35<=CG35*(1+IF(CG35>0,$C$4,-$C$4)),0,-1)))) -> #VALUE! | CG35: =_xll.DBRW($A$3,'Value Tree'!$J$6,CG$6,CG$7,$DB35,$CT35,$CX35,"EBITDA LTM","Value") -> #VALUE! | CH35: =_xll.DBRW($A$3,'Value Tree'!$J$6,CH$6,CH$7,$DB35,$CT35,$CX35,"EBITDA LTM","Value") -> #VALUE! | CJ35: =IF($BW$30="+",IF(BO35>CL35*(1+IF(CL35>0,$C$4,-$C$4)),1,IF(BO35>=CK35*(1+IF(CK35>0,-$C$4,$C$4)),0,-1)),IF($BW$30="-",IF(BO35<CL35*(1+IF(CL35>0,-$C$4,$C$4)),1,IF(BO35<=CK35*(1+IF(CK35>0,$C$4,-$C$4)),0,-1)))) -> #VALUE! | CK35: =_xll.DBRW($A$3,'Value Tree'!$J$6,CK$6,CK$7,$DB35,$CT35,$CX35,"EBITDA LTM","Value") -> #VALUE! | CL35: =_xll.DBRW($A$3,'Value Tree'!$J$6,CL$6,CL$7,$DB35,$CT35,$CX35,"EBITDA LTM","Value") -> #VALUE! | CR35: EUR Conv. | CT35: VCEAA | CV35: RF | CX35: Total Products | DB35: EUR | DD35: VCEAA | DF35: RF | DH35: Total Products
A36: Net Profit | E36: ='Value Tree'!$D$4 -> #N/A | G36: =_xll.DBRW(A3,'Value Tree'!J6,G33,E36,A24,A28,A31,"% ROIC","Value") -> #VALUE! | K36: =_xll.DBRW(A3,'Value Tree'!J6,K33,E36,A24,A28,A31,"% ROIC","Value") -> #VALUE! | P36: ='Value Tree'!$D$4 -> #N/A | R36: =_xll.DBRW(A3,'Value Tree'!J6,R33,P36,A24,A28,"Total Products","Income Tax LTM","Value") -> #VALUE! | V36: =_xll.DBRW(A3,'Value Tree'!J6,V33,P36,A24,A28,"Total Products","Income Tax LTM","Value") -> #VALUE! | AA36: ='Value Tree'!$D$4 -> #N/A | AC36: =_xll.DBRW($A$3,'Value Tree'!$J$6,AC$29,$AA36,$AQ36,$AP36,"Total Products","EBIT","Value") -> #VALUE! | AF36: =AC36/_xll.DBRW($A$3,'Value Tree'!$J$6,AF29,$AA36,$AQ36,$AR36,"Total Products","EBITDA LTM","Value") -> #VALUE! | AJ36: =_xll.DBRW($A$3,'Value Tree'!$J$6,AJ$29,$AA36,$AQ36,$AP36,"Total Products","EBITDA LTM","Value") -> #VALUE! | AM36: =AJ36/_xll.DBRW($A$3,'Value Tree'!$J$6,AM29,$AA36,$AQ36,$AR36,"Total Products","EBITDA LTM","Value") -> #VALUE! | AP36: VCEAA | AQ36: EUR Conv. | AR36: Global
E37: ='Value Tree'!$J$4 -> #N/A | G37: =_xll.DBRW(A3,'Value Tree'!J6,G33,E37,A24,A28,A31,"% ROIC","Value") -> #VALUE! | K37: =_xll.DBRW(A3,'Value Tree'!J6,K33,E37,A24,A28,A31,"% ROIC","Value") -> #VALUE! | P37: ='Value Tree'!$J$4 -> #N/A | R37: =_xll.DBRW(A3,'Value Tree'!J6,R33,P37,A24,A28,"Total Products","Income Tax LTM","Value") -> #VALUE! | V37: =_xll.DBRW(A3,'Value Tree'!J6,V33,P37,A24,A28,"Total Products","Income Tax LTM","Value") -> #VALUE! | AA37: ='Value Tree'!$J$4 -> #N/A | AC37: =_xll.DBRW($A$3,'Value Tree'!$J$6,AC$29,$AA37,$AQ37,$AP37,"Total Products","EBIT","Value") -> #VALUE! | AF37: =AC37/_xll.DBRW($A$3,'Value Tree'!$J$6,AF29,$AA37,$AQ37,$AR37,"Total Products","EBITDA LTM","Value") -> #VALUE! | AJ37: =_xll.DBRW($A$3,'Value Tree'!$J$6,AJ$29,$AA37,$AQ37,$AP37,"Total Products","EBITDA LTM","Value") -> #VALUE! | AM37: =AJ37/_xll.DBRW($A$3,'Value Tree'!$J$6,AM29,$AA37,$AQ37,$AR37,"Total Products","EBITDA LTM","Value") -> #VALUE! | AP37: VCEAA | AQ37: EUR Conv. | AR37: Global
A38: Accounts_ICF | E38: =$A$20 -> l500 | F38: =IF(E33="+",IF(G36>G38*(1+IF(G38>0,$C$4,-$C$4)),1,IF(G36>=G37*(1+IF(G37>0,-$C$4,$C$4)),0,-1)),IF(E33="-",IF(G36<G38*(1+IF(G38>0,-$C$4,$C$4)),1,IF(G36<=G37*(1+IF(G37>0,$C$4,-$C$4)),0,-1)))) -> #VALUE! | G38: =_xll.DBRW(A3,'Value Tree'!J6,G33,E38,A24,A28,A31,"% ROIC","Value") -> #VALUE! | J38: =IF(E33="+",IF(K36>K38*(1+IF(K38>0,$C$4,-$C$4)),1,IF(K36>=K37*(1+IF(K37>0,-$C$4,$C$4)),0,-1)),IF(E33="-",IF(K36<K38*(1+IF(K38>0,-$C$4,$C$4)),1,IF(K36<=K37*(1+IF(K37>0,$C$4,-$C$4)),0,-1)))) -> #VALUE! | K38: =_xll.DBRW(A3,'Value Tree'!J6,K33,E38,A24,A28,A31,"% ROIC","Value") -> #VALUE! | P38: =$A$20 -> l500 | Q38: =IF(P33="+",IF(R36>R38*(1+IF(R38>0,$C$4,-$C$4)),1,IF(R36>=R37*(1+IF(R37>0,-$C$4,$C$4)),0,-1)),IF(P33="-",IF(R36<R38*(1+IF(R38>0,-$C$4,$C$4)),1,IF(R36<=R37*(1+IF(R37>0,$C$4,-$C$4)),0,-1)))) -> #VALUE! | R38: =_xll.DBRW(A3,'Value Tree'!J6,R33,P38,A24,A28,"Total Products","Income Tax LTM","Value") -> #VALUE! | U38: =IF(P33="+",IF(V36>V38*(1+IF(V38>0,$C$4,-$C$4)),1,IF(V36>=V37*(1+IF(V37>0,-$C$4,$C$4)),0,-1)),IF(P33="-",IF(V36<V38*(1+IF(V38>0,-$C$4,$C$4)),1,IF(V36<=V37*(1+IF(V37>0,$C$4,-$C$4)),0,-1)))) -> #VALUE! | V38: =_xll.DBRW(A3,'Value Tree'!J6,V33,P38,A24,A28,"Total Products","Income Tax LTM","Value") -> #VALUE! | AA38: =$A$20 -> l500 | AB38: =IF(AA29="+",IF(AC36>AC38*(1+IF(AC38>0,$C$4,-$C$4)),1,IF(AC36>=AC37*(1+IF(AC37>0,-$C$4,$C$4)),0,-1)),IF(AA29="-",IF(AC36<AC38*(1+IF(AC38>0,-$C$4,$C$4)),1,IF(AC36<=AC37*(1+IF(AC37>0,$C$4,-$C$4)),0,-1)))) -> #VALUE! | AC38: =_xll.DBRW($A$3,'Value Tree'!$J$6,AC$29,$AA38,$AQ37,$AP37,"Total Products","EBIT","Value") -> #VALUE! | AI38: =IF(AA29="+",IF(AJ36>AJ38*(1+IF(AJ38>0,$C$4,-$C$4)),1,IF(AJ36>=AJ37*(1+IF(AJ37>0,-$C$4,$C$4)),0,-1)),IF(AA29="-",IF(AJ36<AJ38*(1+IF(AJ38>0,-$C$4,$C$4)),1,IF(AJ36<=AJ37*(1+IF(AJ37>0,$C$4,-$C$4)),0,-1)))) -> #VALUE! | AJ38: =_xll.DBRW($A$3,'Value Tree'!$J$6,AJ$29,$AA38,$AQ37,$AP37,"Total Products","EBITDA LTM","Value") -> #VALUE!
P39: + | R39: ='Value Tree'!$D$6 -> #N/A | V39: =$A$17 -> Year
A40: Cash Generation Before Financing | Q40: Fin. Results (M) | AA40: + | AC40: ='Value Tree'!$D$6 -> #N/A | AF40: ='Value Tree'!$D$6 -> #N/A | AJ40: Year | AM40: Year | AT40: - | BB40: ='Value Tree'!$D$6 -> #N/A | BF40: =$A$17 -> Year | BK40: ='Value Tree'!$D$6 -> #N/A | BO40: =$A$17 -> Year
P41: ='Value Tree'!$D$4 -> #N/A | R41: =_xll.DBRW(A5,'Value Tree'!J6,R39,P41,A24,A28,"Financial Results",A48) -> #VALUE! | V41: =_xll.DBRW(A5,'Value Tree'!J6,V39,P41,A24,A28,"Financial Results",A48) -> #VALUE! | AB41: EBITDA (USD M) Mg. EBITDA - VCLatam | AU41: EBITDA VCLatam Breakdown (USD M) | BJ41: EBITDA VCLatam (LMU M) | BW41: +
...

Sheet Value Tree
B1: Summary: Comparison between Actual/RF and L300/PY (YTD & FY)
D4: =_xll.SUBNM("CONS_VC_PRD:ALL.D.Version","sys.Report","RF","Descrição") -> #N/A | J4: =_xll.SUBNM("CONS_VC_PRD:ALL.D.Version","sys.Report","L300","Descrição") -> #N/A
D6: =_xll.SUBNM("CONS_VC_PRD:ALL.D.Month","SYS.YTD","YTD 12","Desc") -> #N/A | J6: =_xll.SUBNM("CONS_VC_PRD:ALL.D.Year","SYS_PICKLIST","2025","id do membro") -> #N/A
Q8: Net Debt (M) | AB8: EBITDA (BRL M) Mg. EBITDA - VCBR | AS8: EBITDA VCBR Breakdown (BRL M)
R9: ='Value Tree - Fx'!R8 -> #VALUE! | V9: ='Value Tree - Fx'!V8 -> #VALUE! | AC9: ='Value Tree - Fx'!AC8 -> #VALUE! | AF9: ='Value Tree - Fx'!AF8 -> #VALUE! | AJ9: ='Value Tree - Fx'!AJ8 -> #VALUE! | AM9: ='Value Tree - Fx'!AM8 -> #VALUE! | AS9: Cement | AZ9: ='Value Tree - Fx'!BB8 -> #VALUE! | BD9: ='Value Tree - Fx'!BF8 -> #VALUE!
F10: Net Debt / Adj EBITDA (x) | R10: ='Value Tree - Fx'!R9 -> #VALUE! | V10: ='Value Tree - Fx'!V9 -> #VALUE! | AC10: ='Value Tree - Fx'!AC9 -> #VALUE! | AF10: ='Value Tree - Fx'!AF9 -> #VALUE! | AJ10: ='Value Tree - Fx'!AJ9 -> #VALUE! | AM10: ='Value Tree - Fx'!AM9 -> #VALUE! | AS10: Ready Mix | AZ10: ='Value Tree - Fx'!BB9 -> #VALUE! | BD10: ='Value Tree - Fx'!BF9 -> #VALUE!
G11: ='Value Tree - Fx'!G11 -> #VALUE! | K11: ='Value Tree - Fx'!K11 -> #VALUE! | AB11: EBIT (BRL M) Mg. EBIT - VCBR | AS11: Aggregates | AZ11: ='Value Tree - Fx'!BB11 -> #VALUE! | BD11: ='Value Tree - Fx'!BF11 -> #VALUE!
G12: ='Value Tree - Fx'!G12 -> #VALUE! | K12: ='Value Tree - Fx'!K12 -> #VALUE! | Q12: EBITDA (M) | AC12: ='Value Tree - Fx'!AC12 -> #VALUE! | AF12: ='Value Tree - Fx'!AF12 -> #VALUE! | AJ12: ='Value Tree - Fx'!AJ12 -> #VALUE! | AM12: ='Value Tree - Fx'!AM12 -> #VALUE! | AS12: Mortars | AZ12: ='Value Tree - Fx'!BB12 -> #VALUE! | BD12: ='Value Tree - Fx'!BF12 -> #VALUE!
R13: ='Value Tree - Fx'!R14 -> #VALUE! | V13: ='Value Tree - Fx'!V14 -> #VALUE! | AC13: ='Value Tree - Fx'!AC14 -> #VALUE! | AF13: ='Value Tree - Fx'!AF14 -> #VALUE! | AJ13: ='Value Tree - Fx'!AJ14 -> #VALUE! | AM13: ='Value Tree - Fx'!AM14 -> #VALUE! | AS13: Agric Lime | AZ13: ='Value Tree - Fx'!BB14 -> #VALUE! | BD13: ='Value Tree - Fx'!BF14 -> #VALUE!
F14: Net Profit (M) | R14: ='Value Tree - Fx'!R15 -> #VALUE! | V14: ='Value Tree - Fx'!V15 -> #VALUE! | AS14: Lime | AZ14: ='Value Tree - Fx'!BB15 -> #VALUE! | BD14: ='Value Tree - Fx'!BF15 -> #VALUE!
G15: ='Value Tree - Fx'!G17 -> #VALUE! | K15: ='Value Tree - Fx'!K17 -> #VALUE! | AS15: Motz | AZ15: ='Value Tree - Fx'!BB17 -> #VALUE! | BD15: ='Value Tree - Fx'!BF17 -> #VALUE!
G16: ='Value Tree - Fx'!G18 -> #VALUE! | K16: ='Value Tree - Fx'!K18 -> #VALUE! | Q16: EBIT (M)
R17: ='Value Tree - Fx'!R19 -> #VALUE! | V17: ='Value Tree - Fx'!V19 -> #VALUE!
R18: ='Value Tree - Fx'!R20 -> #VALUE! | V18: ='Value Tree - Fx'!V20 -> #VALUE! | AB18: EBITDA (USD M) Mg. EBITDA - VCNA | AS18: EBITDA VCNA Breakdown (USD M)
AC19: ='Value Tree - Fx'!AC21 -> #VALUE! | AF19: ='Value Tree - Fx'!AF21 -> #VALUE! | AJ19: ='Value Tree - Fx'!AJ21 -> #VALUE! | AM19: ='Value Tree - Fx'!AM21 -> #VALUE! | AS19: Cement | AZ19: ='Value Tree - Fx'!BB21 -> #VALUE! | BD19: ='Value Tree - Fx'!BF21 -> #VALUE!
AC20: ='Value Tree - Fx'!AC22 -> #VALUE! | AF20: ='Value Tree - Fx'!AF22 -> #VALUE! | AJ20: ='Value Tree - Fx'!AJ22 -> #VALUE! | AM20: ='Value Tree - Fx'!AM22 -> #VALUE! | AS20: Ready Mix | AZ20: ='Value Tree - Fx'!BB22 -> #VALUE! | BD20: ='Value Tree - Fx'!BF22 -> #VALUE!
Q21: Capex (M) | AB21: EBIT (USD M) Mg. EBITDA - VCNA | AS21: Aggregates | AZ21: ='Value Tree - Fx'!BB24 -> #VALUE! | BD21: ='Value Tree - Fx'!BF24 -> #VALUE!
R22: ='Value Tree - Fx'!R25 -> #VALUE! | V22: ='Value Tree - Fx'!V25 -> #VALUE! | AC22: ='Value Tree - Fx'!AC25 -> #VALUE! | AF22: ='Value Tree - Fx'!AF25 -> #VALUE! | AJ22: ='Value Tree - Fx'!AJ25 -> #VALUE! | AM22: ='Value Tree - Fx'!AM25 -> #VALUE! | AS22: Corporate | AZ22: ='Value Tree - Fx'!BB25 -> #VALUE! | BD22: ='Value Tree - Fx'!BF25 -> #VALUE!
R23: ='Value Tree - Fx'!R26 -> #VALUE! | V23: ='Value Tree - Fx'!V26 -> #VALUE! | AC23: ='Value Tree - Fx'!AC26 -> #VALUE! | AF23: ='Value Tree - Fx'!AF26 -> #VALUE! | AJ23: ='Value Tree - Fx'!AJ26 -> #VALUE! | AM23: ='Value Tree - Fx'!AM26 -> #VALUE!
F25: FCF (M) | Q25: WK Capital (M)
G26: ='Value Tree - Fx'!G30 -> #VALUE! | K26: ='Value Tree - Fx'!K30 -> #VALUE! | R26: ='Value Tree - Fx'!R30 -> #VALUE! | V26: ='Value Tree - Fx'!V30 -> #VALUE! | AB26: EBITDA (EUR M) Mg. EBITDA - VCEA | AS26: EBITDA VCEA Breakdown (EUR M) | BH26: EBITDA VCEA (LMU M)
G27: ='Value Tree - Fx'!G31 -> #VALUE! | K27: ='Value Tree - Fx'!K31 -> #VALUE! | R27: ='Value Tree - Fx'!R31 -> #VALUE! | V27: ='Value Tree - Fx'!V31 -> #VALUE! | AC27: ='Value Tree - Fx'!AC31 -> #VALUE! | AF27: ='Value Tree - Fx'!AF31 -> #VALUE! | AJ27: ='Value Tree - Fx'!AJ31 -> #VALUE! | AM27: ='Value Tree - Fx'!AM31 -> #VALUE! | AS27: Spain | AZ27: ='Value Tree - Fx'!BB31 -> #VALUE! | BD27: ='Value Tree - Fx'!BF31 -> #VALUE! | BI27: ='Value Tree - Fx'!BK31 -> #VALUE! | BM27: ='Value Tree - Fx'!BO31 -> #VALUE!
AC28: ='Value Tree - Fx'!AC33 -> #VALUE! | AF28: ='Value Tree - Fx'!AF33 -> #VALUE! | AJ28: ='Value Tree - Fx'!AJ33 -> #VALUE! | AM28: ='Value Tree - Fx'!AM33 -> #VALUE! | AS28: Turkey | AZ28: ='Value Tree - Fx'!BB33 -> #VALUE! | BD28: ='Value Tree - Fx'!BF33 -> #VALUE! | BI28: ='Value Tree - Fx'!BK33 -> #VALUE! | BM28: ='Value Tree - Fx'!BO33 -> #VALUE!
F29: ROIC (%) | Q29: Income Tax (M) | AB29: EBIT (EUR M) Mg. EBITDA - VCEA | AS29: Corporate | AZ29: ='Value Tree - Fx'!BB35 -> #VALUE! | BD29: ='Value Tree - Fx'!BF35 -> #VALUE! | BI29: ='Value Tree - Fx'!BK35 -> #VALUE! | BM29: ='Value Tree - Fx'!BO35 -> #VALUE!
G30: ='Value Tree - Fx'!G36 -> #VALUE! | K30: ='Value Tree - Fx'!K36 -> #VALUE! | R30: ='Value Tree - Fx'!R36 -> #VALUE! | V30: ='Value Tree - Fx'!V36 -> #VALUE! | AC30: ='Value Tree - Fx'!AC36 -> #VALUE! | AF30: ='Value Tree - Fx'!AF36 -> #VALUE! | AJ30: ='Value Tree - Fx'!AJ36 -> #VALUE! | AM30: ='Value Tree - Fx'!AM36 -> #VALUE!
G31: ='Value Tree - Fx'!G37 -> #VALUE! | K31: ='Value Tree - Fx'!K37 -> #VALUE! | R31: ='Value Tree - Fx'!R37 -> #VALUE! | V31: ='Value Tree - Fx'!V37 -> #VALUE! | AC31: ='Value Tree - Fx'!AC37 -> #VALUE! | AF31: ='Value Tree - Fx'!AF37 -> #VALUE! | AJ31: ='Value Tree - Fx'!AJ37 -> #VALUE! | AM31: ='Value Tree - Fx'!AM37 -> #VALUE!
Q33: Fin. Results (M)
R34: ='Value Tree - Fx'!R41 -> #VALUE! | V34: ='Value Tree - Fx'!V41 -> #VALUE! | AB34: EBITDA (USD M) Mg. EBITDA - VCLatam | AS34: EBITDA VCLatam Breakdown (USD M) | BH34: EBITDA VCLatam (LMU M)
R35: ='Value Tree - Fx'!R42 -> #VALUE! | V35: ='Value Tree - Fx'!V42 -> #VALUE! | AC35: ='Value Tree - Fx'!AC42 -> #VALUE! | AF35: ='Value Tree - Fx'!AF42 -> #VALUE! | AJ35: ='Value Tree - Fx'!AJ42 -> #VALUE! | AM35: ='Value Tree - Fx'!AM42 -> #VALUE! | AS35: Itacamba | AZ35: ='Value Tree - Fx'!BB42 -> #VALUE! | BD35: ='Value Tree - Fx'!BF42 -> #VALUE! | BI35: ='Value Tree - Fx'!BK42 -> #VALUE! | BM35: ='Value Tree - Fx'!BO42 -> #VALUE!
AC36: ='Value Tree - Fx'!AC43 -> #VALUE! | AF36: ='Value Tree - Fx'!AF43 -> #VALUE! | AJ36: ='Value Tree - Fx'!AJ43 -> #VALUE! | AM36: ='Value Tree - Fx'!AM43 -> #VALUE! | AS36: Artigas | AZ36: ='Value Tree - Fx'!BB43 -> #VALUE! | BD36: ='Value Tree - Fx'!BF43 -> #VALUE! | BI36: ='Value Tree - Fx'!BK43 -> #VALUE! | BM36: ='Value Tree - Fx'!BO43 -> #VALUE!
AB37: EBIT (USD M) Mg. EBITDA - VCLatam
AC38: ='Value Tree - Fx'!AC46 -> #VALUE! | AF38: ='Value Tree - Fx'!AF46 -> #VALUE! | AJ38: ='Value Tree - Fx'!AJ46 -> #VALUE! | AM38: ='Value Tree - Fx'!AM46 -> #VALUE!
AC39: ='Value Tree - Fx'!AC47 -> #VALUE! | AF39: ='Value Tree - Fx'!AF47 -> #VALUE! | AJ39: ='Value Tree - Fx'!AJ47 -> #VALUE! | AM39: ='Value Tree - Fx'!AM47 -> #VALUE!
