Workbook
Name ID: "5b421e04-befd-4cfb-94b4-6b4bb8b045d3"

Sheet Cognos_Office_Connection_Cache

Sheet Value Tree - Fx
A2: Cubo
A3: CONS_VC:DFS.200.KPIs
A4: CONS_VC:DFS.100.Profit_and_loss | C4: =3% -> 0.03
A5: CONS_VC:DFS.140.Indirect_Cash_Flow
A6: CONS_VC:DFS.180.Gross_Debt
A7: CONS_VC:REV.100.Revenue_Consolidated
B8: - | P8: + | R8: =$A$13 -> #N/A | V8: =$A$12 -> Year | AA8: + | AC8: =$A$13 -> #N/A | AG8: =$A$12 -> Year | AM8: + | AO8: =$A$13 -> #N/A | AS8: =$A$12 -> Year | AY8: + | BA8: =$A$13 -> #N/A | BE8: =$A$12 -> Year | BK8: + | BM8: =$A$13 -> #N/A | BQ8: =$A$12 -> Year
A9: Ano | Q9: Net Debt (M) | AB9: Net Rev. (M) | AN9: Cement Volume | AZ9: Fuel (LMU/t) | BL9: Thermal Sub. (%)
A10: ='Value Tree 2'!$J$6 -> #N/A | P10: =$A$16 -> #N/A | R10: {=_xll.DBRW($A$6,$A$10,R8,P10,$A$19,$A$21,"Closing Balance Debt",$A$30)} -> #VALUE! | V10: {=_xll.DBRW($A$6,$A$10,V8,P10,$A$19,$A$21,"Closing Balance Debt",$A$30)} -> #VALUE! | AA10: =$A$16 -> #N/A | AC10: {=_xll.DBRW($A$4,$A$10,AC8,AA10,$A$19,$A$21,$A$23,"Net Revenue",$A$30)} -> #VALUE! | AG10: {=_xll.DBRW($A$4,$A$10,AG8,AA10,$A$19,$A$21,$A$23,"Net Revenue",$A$30)} -> #VALUE! | AM10: =$A$16 -> #N/A | AO10: {=_xll.DBRW($A$3,$A$10,AO8,AM10,$A$19,$A$21,$A$31,"Volume",$A$29)} -> #VALUE! | AS10: {=_xll.DBRW($A$3,$A$10,AS8,AM10,$A$19,$A$21,$A$31,"Volume",$A$29)} -> #VALUE! | AY10: =$A$16 -> #N/A | BA10: =_xll.DBRW($A$3,$A$10,$BA8,$AY10,$A$19,$A$21,$A$23,$AZ9,$A$29) -> #VALUE! | BE10: =_xll.DBRW($A$3,$A$10,$BE8,$AY10,$A$19,$A$21,$A$23,$AZ9,$A$29) -> #VALUE! | BK10: =$A$16 -> #N/A | BM10: =_xll.DBRW($A$3,$A$10,$BM8,$BK10,$A$19,$A$21,$A$23,$BL9,$A$29) -> #VALUE! | BQ10: =_xll.DBRW($A$3,$A$10,$BQ8,$BK10,$A$19,$A$21,$A$23,$BL9,$A$29) -> #VALUE!
A11: Mês | P11: =$A$17 -> #N/A | R11: {=_xll.DBRW($A$6,$A$10,R8,P11,$A$19,$A$21,"Closing Balance Debt",$A$30)} -> #VALUE! | V11: {=_xll.DBRW($A$6,$A$10,V8,P11,$A$19,$A$21,"Closing Balance Debt",$A$30)} -> #VALUE! | AA11: =$A$17 -> #N/A | AC11: {=_xll.DBRW($A$4,$A$10,AC8,AA11,$A$19,$A$21,$A$23,"Net Revenue",$A$30)} -> #VALUE! | AG11: {=_xll.DBRW($A$4,$A$10,AG8,AA11,$A$19,$A$21,$A$23,"Net Revenue",$A$30)} -> #VALUE! | AM11: =$A$17 -> #N/A | AO11: {=_xll.DBRW($A$3,$A$10,AO8,AM11,$A$19,$A$21,$A$31,"Volume",$A$29)} -> #VALUE! | AS11: {=_xll.DBRW($A$3,$A$10,AS8,AM11,$A$19,$A$21,$A$31,"Volume",$A$29)} -> #VALUE! | AY11: =$A$17 -> #N/A | BA11: =_xll.DBRW($A$3,$A$10,$BA8,$AY11,$A$19,$A$21,$A$23,$AZ9,$A$29) -> #VALUE! | BE11: =_xll.DBRW($A$3,$A$10,$BE8,$AY11,$A$19,$A$21,$A$23,$AZ9,$A$29) -> #VALUE! | BK11: =$A$17 -> #N/A | BM11: =_xll.DBRW($A$3,$A$10,$BM8,$BK11,$A$19,$A$21,$A$23,$BL9,$A$29) -> #VALUE! | BQ11: =_xll.DBRW($A$3,$A$10,$BQ8,$BK11,$A$19,$A$21,$A$23,$BL9,$A$29) -> #VALUE!
A12: =_xll.SUBNM("CONS_VC:ALL.D.Month",,"Year","MEMBER_NAME") -> Year | P12: =$A$15 -> l500 | Q12: =IF(P8="+",IF(R10>R12*(1+IF(R12>0,$C$4,-$C$4)),1,IF(R10>=R11*(1+IF(R11>0,-$C$4,$C$4)),0,-1)),IF(P8="-",IF(R10<R12*(1+IF(R12>0,-$C$4,$C$4)),1,IF(R10<=R11*(1+IF(R11>0,$C$4,-$C$4)),0,-1)))) -> #VALUE! | R12: {=_xll.DBRW($A$6,'Value Tree 2'!$J$6,R8,P12,$A$19,$A$21,"Closing Balance Debt",$A$30)} -> #VALUE! | U12: =IF(P8="+",IF(V10>V12*(1+IF(V12>0,$C$4,-$C$4)),1,IF(V10>=V11*(1+IF(V11>0,-$C$4,$C$4)),0,-1)),IF(P8="-",IF(V10<V12*(1+IF(V12>0,-$C$4,$C$4)),1,IF(V10<=V11*(1+IF(V11>0,$C$4,-$C$4)),0,-1)))) -> #VALUE! | V12: {=_xll.DBRW($A$6,'Value Tree 2'!$J$6,V8,P12,$A$19,$A$21,"Closing Balance Debt",$A$30)} -> #VALUE! | AA12: =$A$15 -> l500 | AB12: =IF(AA8="+",IF(AC10>AC12*(1+IF(AC12>0,$C$4,-$C$4)),1,IF(AC10>=AC11*(1+IF(AC11>0,-$C$4,$C$4)),0,-1)),IF(AA8="-",IF(AC10<AC12*(1+IF(AC12>0,-$C$4,$C$4)),1,IF(AC10<=AC11*(1+IF(AC11>0,$C$4,-$C$4)),0,-1)))) -> #VALUE! | AC12: {=_xll.DBRW($A$4,$A$10,AC8,AA12,$A$19,$A$21,$A$23,"Net Revenue",$A$30)} -> #VALUE! | AF12: =IF(AA8="+",IF(AG10>AG12*(1+IF(AG12>0,$C$4,-$C$4)),1,IF(AG10>=AG11*(1+IF(AG11>0,-$C$4,$C$4)),0,-1)),IF(AA8="-",IF(AG10<AG12*(1+IF(AG12>0,-$C$4,$C$4)),1,IF(AG10<=AG11*(1+IF(AG11>0,$C$4,-$C$4)),0,-1)))) -> #VALUE! | AG12: {=_xll.DBRW($A$4,$A$10,AG8,AA12,$A$19,$A$21,$A$23,"Net Revenue",$A$30)} -> #VALUE! | AM12: =$A$15 -> l500 | AN12: =IF(AM8="+",IF(AO10>AO12*(1+IF(AO12>0,$C$4,-$C$4)),1,IF(AO10>=AO11*(1+IF(AO11>0,-$C$4,$C$4)),0,-1)),IF(AM8="-",IF(AO10<AO12*(1+IF(AO12>0,-$C$4,$C$4)),1,IF(AO10<=AO11*(1+IF(AO11>0,$C$4,-$C$4)),0,-1)))) -> #VALUE! | AO12: {=_xll.DBRW($A$3,$A$10,AO8,AM12,$A$19,$A$21,$A$31,"Volume",$A$29)} -> #VALUE! | AR12: =IF(AM8="+",IF(AS10>AS12*(1+IF(AS12>0,$C$4,-$C$4)),1,IF(AS10>=AS11*(1+IF(AS11>0,-$C$4,$C$4)),0,-1)),IF(AM8="-",IF(AS10<AS12*(1+IF(AS12>0,-$C$4,$C$4)),1,IF(AS10<=AS11*(1+IF(AS11>0,$C$4,-$C$4)),0,-1)))) -> #VALUE! | AS12: {=_xll.DBRW($A$7,$A$10,AS8,AM12,$A$19,$A$21,$A$31,$A$32,"Sales Volume [kt]")} -> #VALUE! | AY12: =$A$15 -> l500 | AZ12: =IF(AY8="+",IF(BA10>BA12*(1+IF(BA12>0,$C$4,-$C$4)),1,IF(BA10>=BA11*(1+IF(BA11>0,-$C$4,$C$4)),0,-1)),IF(AY8="-",IF(BA10<BA12*(1+IF(BA12>0,-$C$4,$C$4)),1,IF(BA10<=BA11*(1+IF(BA11>0,$C$4,-$C$4)),0,-1)))) -> #VALUE! | BA12: =_xll.DBRW($A$3,$A$10,$BA8,$AY12,$A$19,$A$21,$A$23,$AZ9,$A$29) -> #VALUE! | BD12: =IF(AY8="+",IF(BE10>BE12*(1+IF(BE12>0,$C$4,-$C$4)),1,IF(BE10>=BE11*(1+IF(BE11>0,-$C$4,$C$4)),0,-1)),IF(AY8="-",IF(BE10<BE12*(1+IF(BE12>0,-$C$4,$C$4)),1,IF(BE10<=BE11*(1+IF(BE11>0,$C$4,-$C$4)),0,-1)))) -> #VALUE! | BE12: =_xll.DBRW($A$3,$A$10,$BE8,$AY12,$A$19,$A$21,$A$23,$AZ9,$A$29) -> #VALUE! | BK12: =$A$15 -> l500 | BL12: =IF(BK8="+",IF(BM10>BM12*(1+IF(BM12>0,$C$4,-$C$4)),1,IF(BM10>=BM11*(1+IF(BM11>0,-$C$4,$C$4)),0,-1)),IF(BK8="-",IF(BM10<BM12*(1+IF(BM12>0,-$C$4,$C$4)),1,IF(BM10<=BM11*(1+IF(BM11>0,$C$4,-$C$4)),0,-1)))) -> #VALUE! | BM12: =_xll.DBRW($A$3,$A$10,$BM8,$BK12,$A$19,$A$21,$A$23,$BL9,$A$29) -> #VALUE! | BP12: =IF(BK8="+",IF(BQ10>BQ12*(1+IF(BQ12>0,$C$4,-$C$4)),1,IF(BQ10>=BQ11*(1+IF(BQ11>0,-$C$4,$C$4)),0,-1)),IF(BK8="-",IF(BQ10<BQ12*(1+IF(BQ12>0,-$C$4,$C$4)),1,IF(BQ10<=BQ11*(1+IF(BQ11>0,$C$4,-$C$4)),0,-1)))) -> #VALUE! | BQ12: =_xll.DBRW($A$3,$A$10,$BQ8,$BK12,$A$19,$A$21,$A$23,$BL9,$A$29) -> #VALUE!
A13: ='Value Tree 2'!$D$6 -> #N/A
A14: Versão
A15: l500 | E15: + | G15: =$A$13 -> #N/A | K15: =$A$12 -> Year | P15: + | R15: =$A$13 -> #N/A | V15: =$A$12 -> Year | AA15: + | AC15: =$A$13 -> #N/A | AG15: =$A$12 -> Year | AM15: + | AO15: =$A$13 -> #N/A | AS15: =$A$12 -> Year | AY15: + | BA15: =$A$13 -> #N/A | BE15: =$A$12 -> Year | BK15: + | BM15: YTD 12 | BQ15: Year
A16: ='Value Tree 2'!$D$4 -> #N/A | F16: Net Profit (M) | Q16: EBITDA (M) | AB16: EBITDA Oth. BUs. (M) | AN16: Cement Net | AZ16: CO2 Gross (kg/ton) | BL16: Thermal C. (kcal/t kk)
A17: ='Value Tree 2'!$J$4 -> #N/A | E17: =$A$16 -> #N/A | G17: =_xll.DBRW(A4,$A$10,G15,E17,A19,A21,A23,A25,A29) -> #VALUE! | K17: =_xll.DBRW(A4,$A$10,K15,E17,A19,A21,A23,A25,A29) -> #VALUE! | P17: =$A$16 -> #N/A | R17: =_xll.DBRW(A3,$A$10,R15,P17,A19,A21,"Total Products","EBITDA LTM","Value") -> #VALUE! | V17: =_xll.DBRW(A3,$A$10,V15,P17,A19,A21,"Total Products","EBITDA LTM","Value") -> #VALUE! | AA17: =$A$16 -> #N/A | AC17: =_xll.DBRW($A$3,$A$10,AC15,AA17,$A$19,$A$21,$A$23,"EBITDA LTM",$A$29)-_xll.DBRW($A$3,$A$10,AC15,AA17,$A$19,$A$21,$A$31,"EBITDA LTM",$A$29) -> #VALUE! | AG17: =_xll.DBRW($A$3,$A$10,AG15,AA17,$A$19,$A$21,$A$23,"EBITDA LTM",$A$29)-_xll.DBRW($A$3,$A$10,AG15,AA17,$A$19,$A$21,$A$31,"EBITDA LTM",$A$29) -> #VALUE! | AM17: =$A$16 -> #N/A | AO17: {=_xll.DBRW($A$7,$A$10,AO15,AM17,$A$19,$A$21,$A$31,$A$32,"Net Revenue [$MM]")} -> #VALUE! | AS17: {=_xll.DBRW($A$7,$A$10,AS15,AM17,$A$19,$A$21,$A$31,$A$32,"Net Revenue [$MM]")} -> #VALUE! | AY17: =$A$16 -> #N/A | BA17: =_xll.DBRW($A$3,$A$10,$BA15,$AY17,$A$19,$A$21,$A$23,$AZ16,$A$29) -> #VALUE! | BE17: =_xll.DBRW($A$3,$A$10,$BE15,$AY17,$A$19,$A$21,$A$23,$AZ16,$A$29) -> #VALUE! | BK17: RF | BM17: =_xll.DBRW($A$3,$A$10,$BM15,$BK17,$A$19,$A$21,$A$23,$BL16,$A$29) -> #VALUE! | BQ17: =_xll.DBRW($A$3,$A$10,$BQ15,$BK17,$A$19,$A$21,$A$23,$BL16,$A$29) -> #VALUE!
A18: Currency | E18: =$A$17 -> #N/A | G18: =_xll.DBRW(A4,$A$10,G15,E18,A19,A21,A23,A25,A29) -> #VALUE! | K18: =_xll.DBRW(A4,$A$10,K15,E18,A19,A21,A23,A25,A29) -> #VALUE! | P18: =$A$17 -> #N/A | R18: =_xll.DBRW(A3,$A$10,R15,P18,A19,A21,"Total Products","EBITDA LTM","Value") -> #VALUE! | V18: =_xll.DBRW(A3,$A$10,V15,P18,A19,A21,"Total Products","EBITDA LTM","Value") -> #VALUE! | AA18: =$A$17 -> #N/A | AC18: =_xll.DBRW($A$3,$A$10,AC15,AA18,$A$19,$A$21,$A$23,"EBITDA LTM",$A$29)-_xll.DBRW($A$3,$A$10,AC15,AA18,$A$19,$A$21,$A$31,"EBITDA LTM",$A$29) -> #VALUE! | AG18: =_xll.DBRW($A$3,$A$10,AG15,AA18,$A$19,$A$21,$A$23,"EBITDA LTM",$A$29)-_xll.DBRW($A$3,$A$10,AG15,AA18,$A$19,$A$21,$A$31,"EBITDA LTM",$A$29) -> #VALUE! | AM18: =$A$17 -> #N/A | AO18: {=_xll.DBRW($A$7,$A$10,AO15,AM18,$A$19,$A$21,$A$31,$A$32,"Net Revenue [$MM]")} -> #VALUE! | AS18: {=_xll.DBRW($A$7,$A$10,AS15,AM18,$A$19,$A$21,$A$31,$A$32,"Net Revenue [$MM]")} -> #VALUE! | AY18: =$A$17 -> #N/A | BA18: =_xll.DBRW($A$3,$A$10,$BA15,$AY18,$A$19,$A$21,$A$23,$AZ16,$A$29) -> #VALUE! | BE18: =_xll.DBRW($A$3,$A$10,$BE15,$AY18,$A$19,$A$21,$A$23,$AZ16,$A$29) -> #VALUE! | BK18: L300 | BM18: =_xll.DBRW($A$3,$A$10,$BM15,$BK18,$A$19,$A$21,$A$23,$BL16,$A$29) -> #VALUE! | BQ18: =_xll.DBRW($A$3,$A$10,$BQ15,$BK18,$A$19,$A$21,$A$23,$BL16,$A$29) -> #VALUE!
A19: =_xll.SUBNM("CONS_VC:ALL.D.Currency","","EUR") -> EUR | E19: =$A$15 -> l500 | F19: =IF(E15="+",IF(G17>G19*(1+IF(G19>0,$C$4,-$C$4)),1,IF(G17>=G18*(1+IF(G18>0,-$C$4,$C$4)),0,-1)),IF(E15="-",IF(G17<G19*(1+IF(G19>0,-$C$4,$C$4)),1,IF(G17<=G18*(1+IF(G18>0,$C$4,-$C$4)),0,-1)))) -> #VALUE! | G19: =_xll.DBRW(A4,$A$10,G15,E19,A19,A21,A23,A25,A29) -> #VALUE! | J19: =IF(E15="+",IF(K17>K19*(1+IF(K19>0,$C$4,-$C$4)),1,IF(K17>=K18*(1+IF(K18>0,-$C$4,$C$4)),0,-1)),IF(E15="-",IF(K17<K19*(1+IF(K19>0,-$C$4,$C$4)),1,IF(K17<=K18*(1+IF(K18>0,$C$4,-$C$4)),0,-1)))) -> #VALUE! | K19: =_xll.DBRW(A4,$A$10,K15,E19,A19,A21,A23,A25,A29) -> #VALUE! | P19: =$A$15 -> l500 | Q19: =IF(P15="+",IF(R17>R19*(1+IF(R19>0,$C$4,-$C$4)),1,IF(R17>=R18*(1+IF(R18>0,-$C$4,$C$4)),0,-1)),IF(P15="-",IF(R17<R19*(1+IF(R19>0,-$C$4,$C$4)),1,IF(R17<=R18*(1+IF(R18>0,$C$4,-$C$4)),0,-1)))) -> #VALUE! | R19: =_xll.DBRW(A3,$A$10,R15,P19,A19,A21,"Total Products","EBITDA LTM","Value") -> #VALUE! | U19: =IF(P15="+",IF(V17>V19*(1+IF(V19>0,$C$4,-$C$4)),1,IF(V17>=V18*(1+IF(V18>0,-$C$4,$C$4)),0,-1)),IF(P15="-",IF(V17<V19*(1+IF(V19>0,-$C$4,$C$4)),1,IF(V17<=V18*(1+IF(V18>0,$C$4,-$C$4)),0,-1)))) -> #VALUE! | V19: =_xll.DBRW(A3,$A$10,V15,P19,A19,A21,"Total Products","EBITDA LTM","Value") -> #VALUE! | AA19: =$A$15 -> l500 | AB19: =IF(AA15="+",IF(AC17>AC19*(1+IF(AC19>0,$C$4,-$C$4)),1,IF(AC17>=AC18*(1+IF(AC18>0,-$C$4,$C$4)),0,-1)),IF(AA15="-",IF(AC17<AC19*(1+IF(AC19>0,-$C$4,$C$4)),1,IF(AC17<=AC18*(1+IF(AC18>0,$C$4,-$C$4)),0,-1)))) -> #VALUE! | AC19: =_xll.DBRW($A$3,$A$10,AC15,AA19,$A$19,$A$21,$A$23,"EBITDA LTM",$A$29)-_xll.DBRW($A$3,$A$10,AC15,AA19,$A$19,$A$21,$A$31,"EBITDA LTM",$A$29) -> #VALUE! | AF19: =IF(AA15="+",IF(AG17>AG19*(1+IF(AG19>0,$C$4,-$C$4)),1,IF(AG17>=AG18*(1+IF(AG18>0,-$C$4,$C$4)),0,-1)),IF(AA15="-",IF(AG17<AG19*(1+IF(AG19>0,-$C$4,$C$4)),1,IF(AG17<=AG18*(1+IF(AG18>0,$C$4,-$C$4)),0,-1)))) -> #VALUE! | AG19: =_xll.DBRW($A$3,$A$10,AG15,AA19,$A$19,$A$21,$A$23,"EBITDA LTM",$A$29)-_xll.DBRW($A$3,$A$10,AG15,AA19,$A$19,$A$21,$A$31,"EBITDA LTM",$A$29) -> #VALUE! | AM19: =$A$15 -> l500 | AN19: =IF(AM15="+",IF(AO17>AO19*(1+IF(AO19>0,$C$4,-$C$4)),1,IF(AO17>=AO18*(1+IF(AO18>0,-$C$4,$C$4)),0,-1)),IF(AM15="-",IF(AO17<AO19*(1+IF(AO19>0,-$C$4,$C$4)),1,IF(AO17<=AO18*(1+IF(AO18>0,$C$4,-$C$4)),0,-1)))) -> #VALUE! | AO19: {=_xll.DBRW($A$7,$A$10,AO15,AM19,$A$19,$A$21,$A$31,$A$32,"Net Revenue [$MM]")} -> #VALUE! | AR19: =IF(AM15="+",IF(AS17>AS19*(1+IF(AS19>0,$C$4,-$C$4)),1,IF(AS17>=AS18*(1+IF(AS18>0,-$C$4,$C$4)),0,-1)),IF(AM15="-",IF(AS17<AS19*(1+IF(AS19>0,-$C$4,$C$4)),1,IF(AS17<=AS18*(1+IF(AS18>0,$C$4,-$C$4)),0,-1)))) -> #VALUE! | AS19: {=_xll.DBRW($A$7,$A$10,AS15,AM19,$A$19,$A$21,$A$31,$A$32,"Net Revenue [$MM]")} -> #VALUE! | AY19: =$A$15 -> l500 | AZ19: =IF(AY15="+",IF(BA17>BA19*(1+IF(BA19>0,$C$4,-$C$4)),1,IF(BA17>=BA18*(1+IF(BA18>0,-$C$4,$C$4)),0,-1)),IF(AY15="-",IF(BA17<BA19*(1+IF(BA19>0,-$C$4,$C$4)),1,IF(BA17<=BA18*(1+IF(BA18>0,$C$4,-$C$4)),0,-1)))) -> #VALUE! | BA19: =_xll.DBRW($A$3,$A$10,$BA15,$AY19,$A$19,$A$21,$A$23,$AZ16,$A$29) -> #VALUE! | BD19: =IF(AY15="+",IF(BE17>BE19*(1+IF(BE19>0,$C$4,-$C$4)),1,IF(BE17>=BE18*(1+IF(BE18>0,-$C$4,$C$4)),0,-1)),IF(AY15="-",IF(BE17<BE19*(1+IF(BE19>0,-$C$4,$C$4)),1,IF(BE17<=BE18*(1+IF(BE18>0,$C$4,-$C$4)),0,-1)))) -> #VALUE! | BE19: =_xll.DBRW($A$3,$A$10,$BE15,$AY19,$A$19,$A$21,$A$23,$AZ16,$A$29) -> #VALUE! | BK19: l500 | BL19: 1 | BM19: =_xll.DBRW($A$3,$A$10,$BM15,$BK19,$A$19,$A$21,$A$23,$BL16,$A$29) -> #VALUE! | BP19: 1 | BQ19: =_xll.DBRW($A$3,$A$10,$BQ15,$BK19,$A$19,$A$21,$A$23,$BL16,$A$29) -> #VALUE!
A20: Region
A21: =_xll.SUBNM("CONS_VC:ALL.D.Region","DEFAuLT","Global") -> Global
A22: Produto | E22: + | G22: =$A$13 -> #N/A | K22: =$A$12 -> Year | P22: + | R22: =$A$13 -> #N/A | V22: =$A$12 -> Year | AY22: + | BA22: YTD 12 | BE22: Year | BK22: + | BM22: YTD 12 | BQ22: Year
A23: =_xll.SUBNM("CONS_VC:ALL.D.Products","","Total Products") -> Total Products | F23: FCF (M) | Q23: Capex (M) | AZ23: CO2 Net (kg/ton) | BL23: Petcoke Price (LMU/t)
A24: Accounts_PNL | E24: =$A$16 -> #N/A | G24: =_xll.DBRW($A$5,$A$10,G22,E24,A19,A21,A27,$A$30) -> #VALUE! | K24: =_xll.DBRW($A$5,$A$10,K22,E24,A19,A21,A27,$A$30) -> #VALUE! | P24: =$A$16 -> #N/A | R24: =_xll.DBRW(A5,$A$10,R22,P24,A19,A21,"Expansion Capex",A30) -> #VALUE! | V24: =_xll.DBRW(A5,$A$10,V22,P24,A19,A21,"Expansion Capex",A30) -> #VALUE! | AY24: RF | BA24: =_xll.DBRW($A$3,$A$10,$BA22,$AY24,$A$19,$A$21,$A$23,$AZ23,$A$29) -> #VALUE! | BE24: =_xll.DBRW($A$3,$A$10,$BE22,$AY24,$A$19,$A$21,$A$23,$AZ23,$A$29) -> #VALUE! | BK24: RF | BM24: =_xll.DBRW($A$3,$A$10,$BM22,$BK24,$A$19,$A$21,$A$23,$BL23,$A$29) -> #VALUE! | BQ24: =_xll.DBRW($A$3,$A$10,$BQ22,$BK24,$A$19,$A$21,$A$23,$BL23,$A$29) -> #VALUE!
A25: Net Profit | E25: =$A$17 -> #N/A | G25: =_xll.DBRW($A$5,$A$10,G22,E25,A19,A21,A27,$A$30) -> #VALUE! | K25: =_xll.DBRW($A$5,$A$10,K22,E25,A19,A21,A27,$A$30) -> #VALUE! | P25: =$A$17 -> #N/A | R25: =_xll.DBRW(A5,$A$10,R22,P25,A19,A21,"Expansion Capex",A30) -> #VALUE! | V25: =_xll.DBRW(A5,$A$10,V22,P25,A19,A21,"Expansion Capex",A30) -> #VALUE! | AY25: L300 | BA25: =_xll.DBRW($A$3,$A$10,$BA22,$AY25,$A$19,$A$21,$A$23,$AZ23,$A$29) -> #VALUE! | BE25: =_xll.DBRW($A$3,$A$10,$BE22,$AY25,$A$19,$A$21,$A$23,$AZ23,$A$29) -> #VALUE! | BK25: L300 | BM25: =_xll.DBRW($A$3,$A$10,$BM22,$BK25,$A$19,$A$21,$A$23,$BL23,$A$29) -> #VALUE! | BQ25: =_xll.DBRW($A$3,$A$10,$BQ22,$BK25,$A$19,$A$21,$A$23,$BL23,$A$29) -> #VALUE!
A26: Accounts_ICF | E26: =$A$15 -> l500 | F26: =IF(E22="+",IF(G24>G26*(1+IF(G26>0,$C$4,-$C$4)),1,IF(G24>=G25*(1+IF(G25>0,-$C$4,$C$4)),0,-1)),IF(E22="-",IF(G24<G26*(1+IF(G26>0,-$C$4,$C$4)),1,IF(G24<=G25*(1+IF(G25>0,$C$4,-$C$4)),0,-1)))) -> #VALUE! | G26: =_xll.DBRW($A$5,$A$10,G22,E26,A19,A21,A27,$A$30) -> #VALUE! | J26: =IF(E22="+",IF(K24>K26*(1+IF(K26>0,$C$4,-$C$4)),1,IF(K24>=K25*(1+IF(K25>0,-$C$4,$C$4)),0,-1)),IF(E22="-",IF(K24<K26*(1+IF(K26>0,-$C$4,$C$4)),1,IF(K24<=K25*(1+IF(K25>0,$C$4,-$C$4)),0,-1)))) -> #VALUE! | K26: =_xll.DBRW($A$5,$A$10,K22,E26,A19,A21,A27,$A$30) -> #VALUE! | P26: =$A$15 -> l500 | Q26: =IF(P22="+",IF(R24>R26*(1+IF(R26>0,$C$4,-$C$4)),1,IF(R24>=R25*(1+IF(R25>0,-$C$4,$C$4)),0,-1)),IF(P22="-",IF(R24<R26*(1+IF(R26>0,-$C$4,$C$4)),1,IF(R24<=R25*(1+IF(R25>0,$C$4,-$C$4)),0,-1)))) -> #VALUE! | R26: =_xll.DBRW(A5,$A$10,R22,P26,A19,A21,"Expansion Capex",A30) -> #VALUE! | U26: =IF(P22="+",IF(V24>V26*(1+IF(V26>0,$C$4,-$C$4)),1,IF(V24>=V25*(1+IF(V25>0,-$C$4,$C$4)),0,-1)),IF(P22="-",IF(V24<V26*(1+IF(V26>0,-$C$4,$C$4)),1,IF(V24<=V25*(1+IF(V25>0,$C$4,-$C$4)),0,-1)))) -> #VALUE! | V26: =_xll.DBRW(A5,$A$10,V22,P26,A19,A21,"Expansion Capex",A30) -> #VALUE! | AY26: l500 | AZ26: 1 | BA26: =_xll.DBRW($A$3,$A$10,$BA22,$AY26,$A$19,$A$21,$A$23,$AZ23,$A$29) -> #VALUE! | BD26: 1 | BE26: =_xll.DBRW($A$3,$A$10,$BE22,$AY26,$A$19,$A$21,$A$23,$AZ23,$A$29) -> #VALUE! | BK26: l500 | BL26: 1 | BM26: =_xll.DBRW($A$3,$A$10,$BM22,$BK26,$A$19,$A$21,$A$23,$BL23,$A$29) -> #VALUE! | BP26: 1 | BQ26: =_xll.DBRW($A$3,$A$10,$BQ22,$BK26,$A$19,$A$21,$A$23,$BL23,$A$29) -> #VALUE!
A27: Cash Generation Before Financing
A28: Métrica
A29: Value | E29: + | G29: =$A$13 -> #N/A | K29: =$A$12 -> Year | P29: + | R29: =$A$13 -> #N/A | V29: =$A$12 -> Year | AA29: + | AC29: =$A$13 -> #N/A | AG29: =$A$12 -> Year | AM29: + | AO29: =$A$13 -> #N/A | AS29: =$A$12 -> Year | AY29: + | BA29: YTD 12 | BE29: Year | BK29: + | BM29: YTD 12 | BQ29: Year
A30: Total Value | F30: % ROIC | Q30: WK Capital (M) | AB30: Cem. Cash Cost | AN30: Cement Var. Costs (LMU/t) | AZ30: Power (LMU/t) | BL30: Power Price (LMU/MWh)
A31: PRODCE010 - Cement | E31: =$A$16 -> #N/A | G31: =_xll.DBRW(A3,$A$10,G29,E31,A19,A21,A23,"% ROIC","Value") -> #VALUE! | K31: =_xll.DBRW(A3,$A$10,K29,E31,A19,A21,A23,"% ROIC","Value") -> #VALUE! | P31: =$A$16 -> #N/A | R31: =_xll.DBRW(A3,$A$10,R29,P31,A19,A21,"Total Products","Working Capital Balance","Value") -> #VALUE! | V31: =_xll.DBRW(A3,$A$10,V29,P31,A19,A21,"Total Products","Working Capital Balance","Value") -> #VALUE! | AA31: =$A$16 -> #N/A | AC31: =AO31+AO38 -> #VALUE! | AG31: =AS31+AS38 -> #VALUE! | AM31: =$A$16 -> #N/A | AO31: =SUM(BA10,BA31,BA38,BA45) -> #VALUE! | AS31: =SUM(BE10,BE31,BE38,BE45) -> #VALUE! | AY31: RF | BA31: =_xll.DBRW($A$3,$A$10,$BA29,$AY31,$A$19,$A$21,$A$23,$AZ30,$A$29) -> #VALUE! | BE31: =_xll.DBRW($A$3,$A$10,$BE29,$AY31,$A$19,$A$21,$A$23,$AZ30,$A$29) -> #VALUE! | BK31: RF | BM31: =_xll.DBRW($A$3,$A$10,$BM29,$BK31,$A$19,$A$21,$A$23,$BL30,$A$29) -> #VALUE! | BQ31: =_xll.DBRW($A$3,$A$10,$BQ29,$BK31,$A$19,$A$21,$A$23,$BL30,$A$29) -> #VALUE!
A32: Total Market | E32: =$A$17 -> #N/A | G32: =_xll.DBRW(A3,$A$10,G29,E32,A19,A21,A23,"% ROIC","Value") -> #VALUE! | K32: =_xll.DBRW(A3,$A$10,K29,E32,A19,A21,A23,"% ROIC","Value") -> #VALUE! | P32: =$A$17 -> #N/A | R32: =_xll.DBRW(A3,$A$10,R29,P32,A19,A21,"Total Products","Working Capital Balance","Value") -> #VALUE! | V32: =_xll.DBRW(A3,$A$10,V29,P32,A19,A21,"Total Products","Working Capital Balance","Value") -> #VALUE! | AA32: =$A$17 -> #N/A | AC32: =AO32+AO39 -> #VALUE! | AG32: =AS32+AS39 -> #VALUE! | AM32: =$A$17 -> #N/A | AO32: =SUM(BA11,BA32,BA39,BA46) -> #VALUE! | AS32: =SUM(BE11,BE32,BE39,BE46) -> #VALUE! | AY32: L300 | BA32: =_xll.DBRW($A$3,$A$10,$BA29,$AY32,$A$19,$A$21,$A$23,$AZ30,$A$29) -> #VALUE! | BE32: =_xll.DBRW($A$3,$A$10,$BE29,$AY32,$A$19,$A$21,$A$23,$AZ30,$A$29) -> #VALUE! | BK32: L300 | BM32: =_xll.DBRW($A$3,$A$10,$BM29,$BK32,$A$19,$A$21,$A$23,$BL30,$A$29) -> #VALUE! | BQ32: =_xll.DBRW($A$3,$A$10,$BQ29,$BK32,$A$19,$A$21,$A$23,$BL30,$A$29) -> #VALUE!
E33: =$A$15 -> l500 | F33: =IF(E29="+",IF(G31>G33*(1+IF(G33>0,$C$4,-$C$4)),1,IF(G31>=G32*(1+IF(G32>0,-$C$4,$C$4)),0,-1)),IF(E29="-",IF(G31<G33*(1+IF(G33>0,-$C$4,$C$4)),1,IF(G31<=G32*(1+IF(G32>0,$C$4,-$C$4)),0,-1)))) -> #VALUE! | G33: =_xll.DBRW(A3,$A$10,G29,E33,A19,A21,A23,"% ROIC","Value") -> #VALUE! | J33: =IF(E29="+",IF(K31>K33*(1+IF(K33>0,$C$4,-$C$4)),1,IF(K31>=K32*(1+IF(K32>0,-$C$4,$C$4)),0,-1)),IF(E29="-",IF(K31<K33*(1+IF(K33>0,-$C$4,$C$4)),1,IF(K31<=K32*(1+IF(K32>0,$C$4,-$C$4)),0,-1)))) -> #VALUE! | K33: =_xll.DBRW(A3,$A$10,K29,E33,A19,A21,A23,"% ROIC","Value") -> #VALUE! | P33: =$A$15 -> l500 | Q33: =IF(P29="+",IF(R31>R33*(1+IF(R33>0,$C$4,-$C$4)),1,IF(R31>=R32*(1+IF(R32>0,-$C$4,$C$4)),0,-1)),IF(P29="-",IF(R31<R33*(1+IF(R33>0,-$C$4,$C$4)),1,IF(R31<=R32*(1+IF(R32>0,$C$4,-$C$4)),0,-1)))) -> #VALUE! | R33: =_xll.DBRW(A3,$A$10,R29,P33,A19,A21,"Total Products","Working Capital Balance","Value") -> #VALUE! | U33: =IF(P29="+",IF(V31>V33*(1+IF(V33>0,$C$4,-$C$4)),1,IF(V31>=V32*(1+IF(V32>0,-$C$4,$C$4)),0,-1)),IF(P29="-",IF(V31<V33*(1+IF(V33>0,-$C$4,$C$4)),1,IF(V31<=V32*(1+IF(V32>0,$C$4,-$C$4)),0,-1)))) -> #VALUE! | V33: =_xll.DBRW(A3,$A$10,V29,P33,A19,A21,"Total Products","Working Capital Balance","Value") -> #VALUE! | AA33: =$A$15 -> l500 | AB33: =IF(AA29="+",IF(AC31>AC33*(1+IF(AC33>0,$C$4,-$C$4)),1,IF(AC31>=AC32*(1+IF(AC32>0,-$C$4,$C$4)),0,-1)),IF(AA29="-",IF(AC31<AC33*(1+IF(AC33>0,-$C$4,$C$4)),1,IF(AC31<=AC32*(1+IF(AC32>0,$C$4,-$C$4)),0,-1)))) -> #VALUE! | AC33: =AO33+AO40 -> #VALUE! | AF33: =IF(AA29="+",IF(AG31>AG33*(1+IF(AG33>0,$C$4,-$C$4)),1,IF(AG31>=AG32*(1+IF(AG32>0,-$C$4,$C$4)),0,-1)),IF(AA29="-",IF(AG31<AG33*(1+IF(AG33>0,-$C$4,$C$4)),1,IF(AG31<=AG32*(1+IF(AG32>0,$C$4,-$C$4)),0,-1)))) -> #VALUE! | AG33: =AS33+AS40 -> #VALUE! | AM33: =$A$15 -> l500 | AN33: =IF(AM29="+",IF(AO31>AO33*(1+IF(AO33>0,$C$4,-$C$4)),1,IF(AO31>=AO32*(1+IF(AO32>0,-$C$4,$C$4)),0,-1)),IF(AM29="-",IF(AO31<AO33*(1+IF(AO33>0,-$C$4,$C$4)),1,IF(AO31<=AO32*(1+IF(AO32>0,$C$4,-$C$4)),0,-1)))) -> #VALUE! | AO33: =SUM(BA12,BA33,BA40,BA47) -> #VALUE! | AR33: =IF(AM29="+",IF(AS31>AS33*(1+IF(AS33>0,$C$4,-$C$4)),1,IF(AS31>=AS32*(1+IF(AS32>0,-$C$4,$C$4)),0,-1)),IF(AM29="-",IF(AS31<AS33*(1+IF(AS33>0,-$C$4,$C$4)),1,IF(AS31<=AS32*(1+IF(AS32>0,$C$4,-$C$4)),0,-1)))) -> #VALUE! | AS33: =SUM(BE12,BE33,BE40,BE47) -> #VALUE! | AY33: l500 | AZ33: 1 | BA33: =_xll.DBRW($A$3,$A$10,$BA29,$AY33,$A$19,$A$21,$A$23,$AZ30,$A$29) -> #VALUE! | BD33: 1 | BE33: =_xll.DBRW($A$3,$A$10,$BE29,$AY33,$A$19,$A$21,$A$23,$AZ30,$A$29) -> #VALUE! | BK33: l500 | BL33: 1 | BM33: =_xll.DBRW($A$3,$A$10,$BM29,$BK33,$A$19,$A$21,$A$23,$BL30,$A$29) -> #VALUE! | BP33: 1 | BQ33: =_xll.DBRW($A$3,$A$10,$BQ29,$BK33,$A$19,$A$21,$A$23,$BL30,$A$29) -> #VALUE!
P36: + | R36: =$A$13 -> #N/A | V36: =$A$12 -> Year | AA36: + | AC36: =$A$13 -> #N/A | AG36: =$A$12 -> Year | AM36: + | AO36: YTD 12 | AS36: Year | AY36: + | BA36: YTD 12 | BE36: Year | BK36: + | BM36: YTD 12 | BQ36: Year
Q37: Income Tax (M) | AB37: Fixed Cost (M) | AN37: Cement Fix. Costs (LMU/t) | AZ37: Raw Material (LMU/t) | BL37: Power Cons. (kWh/t)
P38: =$A$16 -> #N/A | R38: =_xll.DBRW(A3,$A$10,R36,P38,A19,A21,"Total Products","Income Tax LTM","Value") -> #VALUE! | V38: =_xll.DBRW(A3,$A$10,V36,P38,A19,A21,"Total Products","Income Tax LTM","Value") -> #VALUE! | AA38: =$A$16 -> #N/A | AC38: =_xll.DBRW($A$4,$A$10,AC36,AA38,$A$19,$A$21,$A$23,"Fixed Costs",$A$29) -> #VALUE! | AG38: =_xll.DBRW($A$4,$A$10,AG36,AA38,$A$19,$A$21,$A$23,"Fixed Costs",$A$29) -> #VALUE! | AM38: RF | AO38: =_xll.DBRW($A$3,$A$10,AO36,AM38,$A$19,$A$21,$A$31,"Cement Fix. Costs (LMU/t)",$A$29) -> #VALUE! | AS38: =_xll.DBRW($A$3,$A$10,AS36,AM38,$A$19,$A$21,$A$31,"Cement Fix. Costs (LMU/t)",$A$29) -> #VALUE! | AY38: RF | BA38: =_xll.DBRW($A$3,$A$10,$BA36,$AY38,$A$19,$A$21,$A$23,$AZ37,$A$29) -> #VALUE! | BE38: =_xll.DBRW($A$3,$A$10,$BE36,$AY38,$A$19,$A$21,$A$23,$AZ37,$A$29) -> #VALUE! | BK38: RF | BM38: =_xll.DBRW($A$3,$A$10,$BM36,$BK38,$A$19,$A$21,$A$23,$BL37,$A$29) -> #VALUE! | BQ38: =_xll.DBRW($A$3,$A$10,$BQ36,$BK38,$A$19,$A$21,$A$23,$BL37,$A$29) -> #VALUE!
P39: =$A$17 -> #N/A | R39: =_xll.DBRW(A3,$A$10,R36,P39,A19,A21,"Total Products","Income Tax LTM","Value") -> #VALUE! | V39: =_xll.DBRW(A3,$A$10,V36,P39,A19,A21,"Total Products","Income Tax LTM","Value") -> #VALUE! | AA39: =$A$17 -> #N/A | AC39: =_xll.DBRW($A$4,$A$10,AC36,AA39,$A$19,$A$21,$A$23,"Fixed Costs",$A$29) -> #VALUE! | AG39: =_xll.DBRW($A$4,$A$10,AG36,AA39,$A$19,$A$21,$A$23,"Fixed Costs",$A$29) -> #VALUE! | AM39: L300 | AO39: =_xll.DBRW($A$3,$A$10,AO36,AM39,$A$19,$A$21,$A$31,"Cement Fix. Costs (LMU/t)",$A$29) -> #VALUE! | AS39: =_xll.DBRW($A$3,$A$10,AS36,AM39,$A$19,$A$21,$A$31,"Cement Fix. Costs (LMU/t)",$A$29) -> #VALUE! | AY39: L300 | BA39: =_xll.DBRW($A$3,$A$10,$BA36,$AY39,$A$19,$A$21,$A$23,$AZ37,$A$29) -> #VALUE! | BE39: =_xll.DBRW($A$3,$A$10,$BE36,$AY39,$A$19,$A$21,$A$23,$AZ37,$A$29) -> #VALUE! | BK39: L300 | BM39: =_xll.DBRW($A$3,$A$10,$BM36,$BK39,$A$19,$A$21,$A$23,$BL37,$A$29) -> #VALUE! | BQ39: =_xll.DBRW($A$3,$A$10,$BQ36,$BK39,$A$19,$A$21,$A$23,$BL37,$A$29) -> #VALUE!
P40: =$A$15 -> l500 | Q40: =IF(P36="+",IF(R38>R40*(1+IF(R40>0,$C$4,-$C$4)),1,IF(R38>=R39*(1+IF(R39>0,-$C$4,$C$4)),0,-1)),IF(P36="-",IF(R38<R40*(1+IF(R40>0,-$C$4,$C$4)),1,IF(R38<=R39*(1+IF(R39>0,$C$4,-$C$4)),0,-1)))) -> #VALUE! | R40: =_xll.DBRW(A3,$A$10,R36,P40,A19,A21,"Total Products","Income Tax LTM","Value") -> #VALUE! | U40: =IF(P36="+",IF(V38>V40*(1+IF(V40>0,$C$4,-$C$4)),1,IF(V38>=V39*(1+IF(V39>0,-$C$4,$C$4)),0,-1)),IF(P36="-",IF(V38<V40*(1+IF(V40>0,-$C$4,$C$4)),1,IF(V38<=V39*(1+IF(V39>0,$C$4,-$C$4)),0,-1)))) -> #VALUE! | V40: =_xll.DBRW(A3,$A$10,V36,P40,A19,A21,"Total Products","Income Tax LTM","Value") -> #VALUE! | AA40: =$A$15 -> l500 | AB40: =IF(AA36="+",IF(AC38>AC40*(1+IF(AC40>0,$C$4,-$C$4)),1,IF(AC38>=AC39*(1+IF(AC39>0,-$C$4,$C$4)),0,-1)),IF(AA36="-",IF(AC38<AC40*(1+IF(AC40>0,-$C$4,$C$4)),1,IF(AC38<=AC39*(1+IF(AC39>0,$C$4,-$C$4)),0,-1)))) -> #VALUE! | AC40: =_xll.DBRW($A$4,$A$10,AC36,AA40,$A$19,$A$21,$A$23,"Fixed Costs",$A$29) -> #VALUE! | AF40: =IF(AA36="+",IF(AG38>AG40*(1+IF(AG40>0,$C$4,-$C$4)),1,IF(AG38>=AG39*(1+IF(AG39>0,-$C$4,$C$4)),0,-1)),IF(AA36="-",IF(AG38<AG40*(1+IF(AG40>0,-$C$4,$C$4)),1,IF(AG38<=AG39*(1+IF(AG39>0,$C$4,-$C$4)),0,-1)))) -> #VALUE! | AG40: =_xll.DBRW($A$4,$A$10,AG36,AA40,$A$19,$A$21,$A$23,"Fixed Costs",$A$29) -> #VALUE! | AM40: l500 | AN40: 0 | AO40: =_xll.DBRW($A$3,$A$10,AO36,AM40,$A$19,$A$21,$A$31,"Cement Fix. Costs (LMU/t)",$A$29) -> #VALUE! | AR40: 0 | AS40: =_xll.DBRW($A$3,$A$10,AS36,AM40,$A$19,$A$21,$A$31,"Cement Fix. Costs (LMU/t)",$A$29) -> #VALUE! | AY40: l500 | AZ40: 1 | BA40: =_xll.DBRW($A$3,$A$10,$BA36,$AY40,$A$19,$A$21,$A$23,$AZ37,$A$29) -> #VALUE! | BD40: 1 | BE40: =_xll.DBRW($A$3,$A$10,$BE36,$AY40,$A$19,$A$21,$A$23,$AZ37,$A$29) -> #VALUE! | BK40: l500 | BL40: 1 | BM40: =_xll.DBRW($A$3,$A$10,$BM36,$BK40,$A$19,$A$21,$A$23,$BL37,$A$29) -> #VALUE! | BP40: 1 | BQ40: =_xll.DBRW($A$3,$A$10,$BQ36,$BK40,$A$19,$A$21,$A$23,$BL37,$A$29) -> #VALUE!
P43: + | R43: =$A$13 -> #N/A | V43: =$A$12 -> Year | AA43: + | AC43: =$A$13 -> #N/A | AG43: =$A$12 -> Year | AM43: + | AY43: + | BA43: YTD 12 | BE43: Year | BK43: + | BM43: YTD 12 | BQ43: Year
Q44: Fin. Results (M) | AB44: FC+SG&A/Net Sales (%) | AN44: FC+SG&A/Net Sales (%) | AZ44: Other Variable (LMU/t) | BL44: Clinker Factor (%)
P45: =$A$16 -> #N/A | R45: =_xll.DBRW($A$5,$A$10,R43,P45,$A$19,$A$21,"Financial Results",$A$30)+_xll.DBRW($A$5,$A$10,R43,P45,$A$19,$A$21,"FX/OTHERS",$A$30)+_xll.DBRW($A$5,$A$10,R43,P45,$A$19,$A$21,"OTHER",$A$30) -> #VALUE! | V45: =_xll.DBRW($A$5,$A$10,V43,P45,$A$19,$A$21,"Financial Results",$A$30)+_xll.DBRW($A$5,$A$10,V43,P45,$A$19,$A$21,"FX/OTHERS",$A$30)+_xll.DBRW($A$5,$A$10,V43,P45,$A$19,$A$21,"OTHER",$A$30) -> #VALUE! | AA45: =$A$16 -> #N/A | AC45: =_xll.DBRW($A$3,$A$10,AC43,AA45,$A$19,$A$21,$A$23,"ZBB Total",$A$29) -> #VALUE! | AG45: =_xll.DBRW($A$3,$A$10,AG43,AA45,$A$19,$A$21,$A$23,"ZBB Total",$A$29) -> #VALUE! | AO45: =(AC38+AC45)/AC10 -> #VALUE! | AS45: =(AG38+AG45)/AG10 -> #VALUE! | AY45: RF | BA45: =_xll.DBRW($A$3,$A$10,$BA43,$AY45,$A$19,$A$21,$A$23,$AZ44,$A$29) -> #VALUE! | BE45: =_xll.DBRW($A$3,$A$10,$BE43,$AY45,$A$19,$A$21,$A$23,$AZ44,$A$29) -> #VALUE! | BK45: RF | BM45: =_xll.DBRW($A$3,$A$10,$BM43,$BK45,$A$19,$A$21,$A$23,$BL44,$A$29) -> #VALUE! | BQ45: =_xll.DBRW($A$3,$A$10,$BQ43,$BK45,$A$19,$A$21,$A$23,$BL44,$A$29) -> #VALUE!
...

Sheet Value Tree 2
B1: Cement: Comparison between Actual/RF and L300/PY (YTD & FY)
D4: =_xll.SUBNM("CONS_VC_PRD:ALL.D.Version","sys.Report","RF","Descrição") -> #N/A | J4: =_xll.SUBNM("CONS_VC_PRD:ALL.D.Version","sys.Report","L300","Descrição") -> #N/A
D6: =_xll.SUBNM("CONS_VC_PRD:ALL.D.Month","SYS.YTD","YTD 12","Desc") -> #N/A | J6: =_xll.SUBNM("CONS_VC_PRD:ALL.D.Year","SYS_PICKLIST","2025","id do membro") -> #N/A
P8: ='Value Tree - Fx'!P8 -> + | R8: ='Value Tree 2'!$D$6 -> #N/A | V8: ='Value Tree - Fx'!$A$12 -> Year | AA8: ='Value Tree - Fx'!AA8 -> + | AC8: ='Value Tree 2'!$D$6 -> #N/A | AG8: ='Value Tree - Fx'!$A$12 -> Year | AM8: ='Value Tree - Fx'!AM8 -> + | AO8: ='Value Tree 2'!$D$6 -> #N/A | AS8: ='Value Tree - Fx'!$A$12 -> Year | AY8: ='Value Tree - Fx'!AY8 -> + | BA8: ='Value Tree 2'!$D$6 -> #N/A | BE8: ='Value Tree - Fx'!$A$12 -> Year | BK8: ='Value Tree - Fx'!BK8 -> + | BM8: ='Value Tree 2'!$D$6 -> #N/A | BQ8: ='Value Tree - Fx'!$A$12 -> Year
Q9: Net Debt (M) | AB9: Net Rev. (M) | AN9: Cement Volume | AZ9: Fuel (LMU/t) | BL9: Thermal Sub. (%)
P10: ='Value Tree - Fx'!P10 -> #N/A | R10: ='Value Tree - Fx'!R10 -> #VALUE! | V10: ='Value Tree - Fx'!V10 -> #VALUE! | AA10: ='Value Tree - Fx'!AA10 -> #N/A | AC10: ='Value Tree - Fx'!AC10 -> #VALUE! | AG10: ='Value Tree - Fx'!AG10 -> #VALUE! | AM10: ='Value Tree - Fx'!AM10 -> #N/A | AO10: ='Value Tree - Fx'!AO10 -> #VALUE! | AS10: ='Value Tree - Fx'!AS10 -> #VALUE! | AY10: ='Value Tree - Fx'!AY10 -> #N/A | BA10: ='Value Tree - Fx'!BA10 -> #VALUE! | BE10: ='Value Tree - Fx'!BE10 -> #VALUE! | BK10: ='Value Tree - Fx'!BK10 -> #N/A | BM10: ='Value Tree - Fx'!BM10 -> #VALUE! | BQ10: ='Value Tree - Fx'!BQ10 -> #VALUE!
P11: ='Value Tree - Fx'!P11 -> #N/A | R11: ='Value Tree - Fx'!R11 -> #VALUE! | V11: ='Value Tree - Fx'!V11 -> #VALUE! | AA11: ='Value Tree - Fx'!AA11 -> #N/A | AC11: ='Value Tree - Fx'!AC11 -> #VALUE! | AG11: ='Value Tree - Fx'!AG11 -> #VALUE! | AM11: ='Value Tree - Fx'!AM11 -> #N/A | AO11: ='Value Tree - Fx'!AO11 -> #VALUE! | AS11: ='Value Tree - Fx'!AS11 -> #VALUE! | AY11: ='Value Tree - Fx'!AY11 -> #N/A | BA11: ='Value Tree - Fx'!BA11 -> #VALUE! | BE11: ='Value Tree - Fx'!BE11 -> #VALUE! | BK11: ='Value Tree - Fx'!BK11 -> #N/A | BM11: ='Value Tree - Fx'!BM11 -> #VALUE! | BQ11: ='Value Tree - Fx'!BQ11 -> #VALUE!
P12: ='Value Tree - Fx'!P12 -> l500 | Q12: ='Value Tree - Fx'!Q12 -> #VALUE! | R12: ='Value Tree - Fx'!R12 -> #VALUE! | U12: ='Value Tree - Fx'!U12 -> #VALUE! | V12: ='Value Tree - Fx'!V12 -> #VALUE! | AA12: ='Value Tree - Fx'!AA12 -> l500 | AB12: ='Value Tree - Fx'!AB12 -> #VALUE! | AC12: ='Value Tree - Fx'!AC12 -> #VALUE! | AF12: ='Value Tree - Fx'!AF12 -> #VALUE! | AG12: ='Value Tree - Fx'!AG12 -> #VALUE! | AM12: ='Value Tree - Fx'!AM12 -> l500 | AN12: ='Value Tree - Fx'!AN12 -> #VALUE! | AO12: ='Value Tree - Fx'!AO12 -> #VALUE! | AR12: ='Value Tree - Fx'!AR12 -> #VALUE! | AS12: ='Value Tree - Fx'!AS12 -> #VALUE! | AY12: ='Value Tree - Fx'!AY12 -> l500 | AZ12: ='Value Tree - Fx'!AZ12 -> #VALUE! | BA12: ='Value Tree - Fx'!BA12 -> #VALUE! | BD12: ='Value Tree - Fx'!BD12 -> #VALUE! | BE12: ='Value Tree - Fx'!BE12 -> #VALUE! | BK12: ='Value Tree - Fx'!BK12 -> l500 | BL12: ='Value Tree - Fx'!BL12 -> #VALUE! | BM12: ='Value Tree - Fx'!BM12 -> #VALUE! | BP12: ='Value Tree - Fx'!BP12 -> #VALUE! | BQ12: ='Value Tree - Fx'!BQ12 -> #VALUE!
E15: ='Value Tree - Fx'!E15 -> + | G15: ='Value Tree 2'!$D$6 -> #N/A | K15: ='Value Tree - Fx'!$A$12 -> Year | P15: ='Value Tree - Fx'!P15 -> + | R15: ='Value Tree 2'!$D$6 -> #N/A | V15: ='Value Tree - Fx'!$A$12 -> Year | AA15: ='Value Tree - Fx'!AA15 -> + | AC15: ='Value Tree 2'!$D$6 -> #N/A | AG15: ='Value Tree - Fx'!$A$12 -> Year | AM15: ='Value Tree - Fx'!AM15 -> + | AO15: ='Value Tree 2'!$D$6 -> #N/A | AS15: ='Value Tree - Fx'!$A$12 -> Year | AY15: ='Value Tree - Fx'!AY15 -> + | BA15: ='Value Tree 2'!$D$6 -> #N/A | BE15: ='Value Tree - Fx'!$A$12 -> Year | BK15: ='Value Tree - Fx'!BK15 -> + | BM15: ='Value Tree 2'!$D$6 -> #N/A | BQ15: ='Value Tree - Fx'!$A$12 -> Year
F16: Net Profit (M) | Q16: EBITDA (M) | AB16: EBITDA Oth. BUs. (M) | AN16: Cement Net | AZ16: CO2 Gross (kg/ton) | BL16: Thermal C. (kcal/t kk)
E17: ='Value Tree - Fx'!E17 -> #N/A | G17: ='Value Tree - Fx'!G17 -> #VALUE! | K17: ='Value Tree - Fx'!K17 -> #VALUE! | P17: ='Value Tree - Fx'!P17 -> #N/A | R17: ='Value Tree - Fx'!R17 -> #VALUE! | V17: ='Value Tree - Fx'!V17 -> #VALUE! | AA17: ='Value Tree - Fx'!AA17 -> #N/A | AC17: ='Value Tree - Fx'!AC17 -> #VALUE! | AG17: ='Value Tree - Fx'!AG17 -> #VALUE! | AM17: ='Value Tree - Fx'!AM17 -> #N/A | AO17: ='Value Tree - Fx'!AO17 -> #VALUE! | AS17: ='Value Tree - Fx'!AS17 -> #VALUE! | AY17: ='Value Tree - Fx'!AY17 -> #N/A | BA17: ='Value Tree - Fx'!BA17 -> #VALUE! | BE17: ='Value Tree - Fx'!BE17 -> #VALUE! | BK17: ='Value Tree - Fx'!BK17 -> RF | BM17: ='Value Tree - Fx'!BM17 -> #VALUE! | BQ17: ='Value Tree - Fx'!BQ17 -> #VALUE!
E18: ='Value Tree - Fx'!E18 -> #N/A | G18: ='Value Tree - Fx'!G18 -> #VALUE! | K18: ='Value Tree - Fx'!K18 -> #VALUE! | P18: ='Value Tree - Fx'!P18 -> #N/A | R18: ='Value Tree - Fx'!R18 -> #VALUE! | V18: ='Value Tree - Fx'!V18 -> #VALUE! | AA18: ='Value Tree - Fx'!AA18 -> #N/A | AC18: ='Value Tree - Fx'!AC18 -> #VALUE! | AG18: ='Value Tree - Fx'!AG18 -> #VALUE! | AM18: ='Value Tree - Fx'!AM18 -> #N/A | AO18: ='Value Tree - Fx'!AO18 -> #VALUE! | AS18: ='Value Tree - Fx'!AS18 -> #VALUE! | AY18: ='Value Tree - Fx'!AY18 -> #N/A | BA18: ='Value Tree - Fx'!BA18 -> #VALUE! | BE18: ='Value Tree - Fx'!BE18 -> #VALUE! | BK18: ='Value Tree - Fx'!BK18 -> L300 | BM18: ='Value Tree - Fx'!BM18 -> #VALUE! | BQ18: ='Value Tree - Fx'!BQ18 -> #VALUE!
E19: ='Value Tree - Fx'!E19 -> l500 | F19: ='Value Tree - Fx'!F19 -> #VALUE! | G19: ='Value Tree - Fx'!G19 -> #VALUE! | J19: ='Value Tree - Fx'!J19 -> #VALUE! | K19: ='Value Tree - Fx'!K19 -> #VALUE! | P19: ='Value Tree - Fx'!P19 -> l500 | Q19: ='Value Tree - Fx'!Q19 -> #VALUE! | R19: ='Value Tree - Fx'!R19 -> #VALUE! | U19: ='Value Tree - Fx'!U19 -> #VALUE! | V19: ='Value Tree - Fx'!V19 -> #VALUE! | AA19: ='Value Tree - Fx'!AA19 -> l500 | AB19: ='Value Tree - Fx'!AB19 -> #VALUE! | AC19: ='Value Tree - Fx'!AC19 -> #VALUE! | AF19: ='Value Tree - Fx'!AF19 -> #VALUE! | AG19: ='Value Tree - Fx'!AG19 -> #VALUE! | AM19: ='Value Tree - Fx'!AM19 -> l500 | AN19: ='Value Tree - Fx'!AN19 -> #VALUE! | AO19: ='Value Tree - Fx'!AO19 -> #VALUE! | AR19: ='Value Tree - Fx'!AR19 -> #VALUE! | AS19: ='Value Tree - Fx'!AS19 -> #VALUE! | AY19: ='Value Tree - Fx'!AY19 -> l500 | AZ19: ='Value Tree - Fx'!AZ19 -> #VALUE! | BA19: ='Value Tree - Fx'!BA19 -> #VALUE! | BD19: ='Value Tree - Fx'!BD19 -> #VALUE! | BE19: ='Value Tree - Fx'!BE19 -> #VALUE! | BK19: ='Value Tree - Fx'!BK19 -> l500 | BL19: ='Value Tree - Fx'!BL19 -> 1 | BM19: ='Value Tree - Fx'!BM19 -> #VALUE! | BP19: ='Value Tree - Fx'!BP19 -> 1 | BQ19: ='Value Tree - Fx'!BQ19 -> #VALUE!
E22: ='Value Tree - Fx'!E22 -> + | G22: ='Value Tree 2'!$D$6 -> #N/A | K22: ='Value Tree - Fx'!$A$12 -> Year | P22: ='Value Tree - Fx'!P22 -> + | R22: ='Value Tree 2'!$D$6 -> #N/A | V22: ='Value Tree - Fx'!$A$12 -> Year | AY22: ='Value Tree - Fx'!AY22 -> + | BA22: ='Value Tree 2'!$D$6 -> #N/A | BE22: ='Value Tree - Fx'!$A$12 -> Year | BK22: ='Value Tree - Fx'!BK22 -> + | BM22: ='Value Tree 2'!$D$6 -> #N/A | BQ22: ='Value Tree - Fx'!$A$12 -> Year
F23: FCF (M) | Q23: Capex (M) | AZ23: CO2 Net (kg/ton) | BL23: Petcoke Price (LMU/t)
E24: ='Value Tree - Fx'!E24 -> #N/A | G24: ='Value Tree - Fx'!G24 -> #VALUE! | K24: ='Value Tree - Fx'!K24 -> #VALUE! | P24: ='Value Tree - Fx'!P24 -> #N/A | R24: ='Value Tree - Fx'!R24 -> #VALUE! | V24: ='Value Tree - Fx'!V24 -> #VALUE! | AY24: ='Value Tree - Fx'!AY24 -> RF | BA24: ='Value Tree - Fx'!BA24 -> #VALUE! | BE24: ='Value Tree - Fx'!BE24 -> #VALUE! | BK24: ='Value Tree - Fx'!BK24 -> RF | BM24: ='Value Tree - Fx'!BM24 -> #VALUE! | BQ24: ='Value Tree - Fx'!BQ24 -> #VALUE!
E25: ='Value Tree - Fx'!E25 -> #N/A | G25: ='Value Tree - Fx'!G25 -> #VALUE! | K25: ='Value Tree - Fx'!K25 -> #VALUE! | P25: ='Value Tree - Fx'!P25 -> #N/A | R25: ='Value Tree - Fx'!R25 -> #VALUE! | V25: ='Value Tree - Fx'!V25 -> #VALUE! | AY25: ='Value Tree - Fx'!AY25 -> L300 | BA25: ='Value Tree - Fx'!BA25 -> #VALUE! | BE25: ='Value Tree - Fx'!BE25 -> #VALUE! | BK25: ='Value Tree - Fx'!BK25 -> L300 | BM25: ='Value Tree - Fx'!BM25 -> #VALUE! | BQ25: ='Value Tree - Fx'!BQ25 -> #VALUE!
E26: ='Value Tree - Fx'!E26 -> l500 | F26: ='Value Tree - Fx'!F26 -> #VALUE! | G26: ='Value Tree - Fx'!G26 -> #VALUE! | J26: ='Value Tree - Fx'!J26 -> #VALUE! | K26: ='Value Tree - Fx'!K26 -> #VALUE! | P26: ='Value Tree - Fx'!P26 -> l500 | Q26: ='Value Tree - Fx'!Q26 -> #VALUE! | R26: ='Value Tree - Fx'!R26 -> #VALUE! | U26: ='Value Tree - Fx'!U26 -> #VALUE! | V26: ='Value Tree - Fx'!V26 -> #VALUE! | AY26: ='Value Tree - Fx'!AY26 -> l500 | AZ26: ='Value Tree - Fx'!AZ26 -> 1 | BA26: ='Value Tree - Fx'!BA26 -> #VALUE! | BD26: ='Value Tree - Fx'!BD26 -> 1 | BE26: ='Value Tree - Fx'!BE26 -> #VALUE! | BK26: ='Value Tree - Fx'!BK26 -> l500 | BL26: ='Value Tree - Fx'!BL26 -> 1 | BM26: ='Value Tree - Fx'!BM26 -> #VALUE! | BP26: ='Value Tree - Fx'!BP26 -> 1 | BQ26: ='Value Tree - Fx'!BQ26 -> #VALUE!
E29: ='Value Tree - Fx'!E29 -> + | G29: ='Value Tree 2'!$D$6 -> #N/A | K29: ='Value Tree - Fx'!$A$12 -> Year | P29: ='Value Tree - Fx'!P29 -> + | R29: ='Value Tree 2'!$D$6 -> #N/A | V29: ='Value Tree - Fx'!$A$12 -> Year | AA29: ='Value Tree - Fx'!AA29 -> + | AC29: ='Value Tree 2'!$D$6 -> #N/A | AG29: ='Value Tree - Fx'!$A$12 -> Year | AM29: ='Value Tree - Fx'!AM29 -> + | AO29: ='Value Tree 2'!$D$6 -> #N/A | AS29: ='Value Tree - Fx'!$A$12 -> Year | AY29: ='Value Tree - Fx'!AY29 -> + | BA29: ='Value Tree 2'!$D$6 -> #N/A | BE29: ='Value Tree - Fx'!$A$12 -> Year | BK29: ='Value Tree - Fx'!BK29 -> + | BM29: ='Value Tree 2'!$D$6 -> #N/A | BQ29: ='Value Tree - Fx'!$A$12 -> Year
F30: % ROIC | Q30: WK Capital (M) | AB30: Cem. Cash Cost | AN30: Cement Var. Costs (LMU/t) | AZ30: Power (LMU/t) | BL30: Power Price (LMU/MWh)
E31: ='Value Tree - Fx'!E31 -> #N/A | G31: ='Value Tree - Fx'!G31 -> #VALUE! | K31: ='Value Tree - Fx'!K31 -> #VALUE! | P31: ='Value Tree - Fx'!P31 -> #N/A | R31: ='Value Tree - Fx'!R31 -> #VALUE! | V31: ='Value Tree - Fx'!V31 -> #VALUE! | AA31: ='Value Tree - Fx'!AA31 -> #N/A | AC31: ='Value Tree - Fx'!AC31 -> #VALUE! | AG31: ='Value Tree - Fx'!AG31 -> #VALUE! | AM31: ='Value Tree - Fx'!AM31 -> #N/A | AO31: ='Value Tree - Fx'!AO31 -> #VALUE! | AS31: ='Value Tree - Fx'!AS31 -> #VALUE! | AY31: ='Value Tree - Fx'!AY31 -> RF | BA31: ='Value Tree - Fx'!BA31 -> #VALUE! | BE31: ='Value Tree - Fx'!BE31 -> #VALUE! | BK31: ='Value Tree - Fx'!BK31 -> RF | BM31: ='Value Tree - Fx'!BM31 -> #VALUE! | BQ31: ='Value Tree - Fx'!BQ31 -> #VALUE!
E32: ='Value Tree - Fx'!E32 -> #N/A | G32: ='Value Tree - Fx'!G32 -> #VALUE! | K32: ='Value Tree - Fx'!K32 -> #VALUE! | P32: ='Value Tree - Fx'!P32 -> #N/A | R32: ='Value Tree - Fx'!R32 -> #VALUE! | V32: ='Value Tree - Fx'!V32 -> #VALUE! | AA32: ='Value Tree - Fx'!AA32 -> #N/A | AC32: ='Value Tree - Fx'!AC32 -> #VALUE! | AG32: ='Value Tree - Fx'!AG32 -> #VALUE! | AM32: ='Value Tree - Fx'!AM32 -> #N/A | AO32: ='Value Tree - Fx'!AO32 -> #VALUE! | AS32: ='Value Tree - Fx'!AS32 -> #VALUE! | AY32: ='Value Tree - Fx'!AY32 -> L300 | BA32: ='Value Tree - Fx'!BA32 -> #VALUE! | BE32: ='Value Tree - Fx'!BE32 -> #VALUE! | BK32: ='Value Tree - Fx'!BK32 -> L300 | BM32: ='Value Tree - Fx'!BM32 -> #VALUE! | BQ32: ='Value Tree - Fx'!BQ32 -> #VALUE!
E33: ='Value Tree - Fx'!E33 -> l500 | F33: ='Value Tree - Fx'!F33 -> #VALUE! | G33: ='Value Tree - Fx'!G33 -> #VALUE! | J33: ='Value Tree - Fx'!J33 -> #VALUE! | K33: ='Value Tree - Fx'!K33 -> #VALUE! | P33: ='Value Tree - Fx'!P33 -> l500 | Q33: ='Value Tree - Fx'!Q33 -> #VALUE! | R33: ='Value Tree - Fx'!R33 -> #VALUE! | U33: ='Value Tree - Fx'!U33 -> #VALUE! | V33: ='Value Tree - Fx'!V33 -> #VALUE! | AA33: ='Value Tree - Fx'!AA33 -> l500 | AB33: ='Value Tree - Fx'!AB33 -> #VALUE! | AC33: ='Value Tree - Fx'!AC33 -> #VALUE! | AF33: ='Value Tree - Fx'!AF33 -> #VALUE! | AG33: ='Value Tree - Fx'!AG33 -> #VALUE! | AM33: ='Value Tree - Fx'!AM33 -> l500 | AN33: ='Value Tree - Fx'!AN33 -> #VALUE! | AO33: ='Value Tree - Fx'!AO33 -> #VALUE! | AR33: ='Value Tree - Fx'!AR33 -> #VALUE! | AS33: ='Value Tree - Fx'!AS33 -> #VALUE! | AY33: ='Value Tree - Fx'!AY33 -> l500 | AZ33: ='Value Tree - Fx'!AZ33 -> 1 | BA33: ='Value Tree - Fx'!BA33 -> #VALUE! | BD33: ='Value Tree - Fx'!BD33 -> 1 | BE33: ='Value Tree - Fx'!BE33 -> #VALUE! | BK33: ='Value Tree - Fx'!BK33 -> l500 | BL33: ='Value Tree - Fx'!BL33 -> 1 | BM33: ='Value Tree - Fx'!BM33 -> #VALUE! | BP33: ='Value Tree - Fx'!BP33 -> 1 | BQ33: ='Value Tree - Fx'!BQ33 -> #VALUE!
P36: ='Value Tree - Fx'!P36 -> + | R36: ='Value Tree 2'!$D$6 -> #N/A | V36: ='Value Tree - Fx'!$A$12 -> Year | AA36: ='Value Tree - Fx'!AA36 -> + | AC36: ='Value Tree 2'!$D$6 -> #N/A | AG36: ='Value Tree - Fx'!$A$12 -> Year | AM36: ='Value Tree - Fx'!AM36 -> + | AO36: ='Value Tree 2'!$D$6 -> #N/A | AS36: ='Value Tree - Fx'!$A$12 -> Year | AY36: ='Value Tree - Fx'!AY36 -> + | BA36: ='Value Tree 2'!$D$6 -> #N/A | BE36: ='Value Tree - Fx'!$A$12 -> Year | BK36: ='Value Tree - Fx'!BK36 -> + | BM36: ='Value Tree 2'!$D$6 -> #N/A | BQ36: ='Value Tree - Fx'!$A$12 -> Year
Q37: Income Tax (M) | AB37: Fixed Cost (M) | AN37: Cement Fix. Costs (LMU/t) | AZ37: Raw Material (LMU/t) | BL37: Power Cons. (kWh/t)
P38: ='Value Tree - Fx'!P38 -> #N/A | R38: ='Value Tree - Fx'!R38 -> #VALUE! | V38: ='Value Tree - Fx'!V38 -> #VALUE! | AA38: ='Value Tree - Fx'!AA38 -> #N/A | AC38: ='Value Tree - Fx'!AC38 -> #VALUE! | AG38: ='Value Tree - Fx'!AG38 -> #VALUE! | AM38: ='Value Tree - Fx'!AM38 -> RF | AO38: ='Value Tree - Fx'!AO38 -> #VALUE! | AS38: ='Value Tree - Fx'!AS38 -> #VALUE! | AY38: ='Value Tree - Fx'!AY38 -> RF | BA38: ='Value Tree - Fx'!BA38 -> #VALUE! | BE38: ='Value Tree - Fx'!BE38 -> #VALUE! | BK38: ='Value Tree - Fx'!BK38 -> RF | BM38: ='Value Tree - Fx'!BM38 -> #VALUE! | BQ38: ='Value Tree - Fx'!BQ38 -> #VALUE!
P39: ='Value Tree - Fx'!P39 -> #N/A | R39: ='Value Tree - Fx'!R39 -> #VALUE! | V39: ='Value Tree - Fx'!V39 -> #VALUE! | AA39: ='Value Tree - Fx'!AA39 -> #N/A | AC39: ='Value Tree - Fx'!AC39 -> #VALUE! | AG39: ='Value Tree - Fx'!AG39 -> #VALUE! | AM39: ='Value Tree - Fx'!AM39 -> L300 | AO39: ='Value Tree - Fx'!AO39 -> #VALUE! | AS39: ='Value Tree - Fx'!AS39 -> #VALUE! | AY39: ='Value Tree - Fx'!AY39 -> L300 | BA39: ='Value Tree - Fx'!BA39 -> #VALUE! | BE39: ='Value Tree - Fx'!BE39 -> #VALUE! | BK39: ='Value Tree - Fx'!BK39 -> L300 | BM39: ='Value Tree - Fx'!BM39 -> #VALUE! | BQ39: ='Value Tree - Fx'!BQ39 -> #VALUE!
P40: ='Value Tree - Fx'!P40 -> l500 | Q40: ='Value Tree - Fx'!Q40 -> #VALUE! | R40: ='Value Tree - Fx'!R40 -> #VALUE! | U40: ='Value Tree - Fx'!U40 -> #VALUE! | V40: ='Value Tree - Fx'!V40 -> #VALUE! | AA40: ='Value Tree - Fx'!AA40 -> l500 | AB40: ='Value Tree - Fx'!AB40 -> #VALUE! | AC40: ='Value Tree - Fx'!AC40 -> #VALUE! | AF40: ='Value Tree - Fx'!AF40 -> #VALUE! | AG40: ='Value Tree - Fx'!AG40 -> #VALUE! | AM40: ='Value Tree - Fx'!AM40 -> l500 | AN40: ='Value Tree - Fx'!AN40 -> 0 | AO40: ='Value Tree - Fx'!AO40 -> #VALUE! | AR40: ='Value Tree - Fx'!AR40 -> 0 | AS40: ='Value Tree - Fx'!AS40 -> #VALUE! | AY40: ='Value Tree - Fx'!AY40 -> l500 | AZ40: ='Value Tree - Fx'!AZ40 -> 1 | BA40: ='Value Tree - Fx'!BA40 -> #VALUE! | BD40: ='Value Tree - Fx'!BD40 -> 1 | BE40: ='Value Tree - Fx'!BE40 -> #VALUE! | BK40: ='Value Tree - Fx'!BK40 -> l500 | BL40: ='Value Tree - Fx'!BL40 -> 1 | BM40: ='Value Tree - Fx'!BM40 -> #VALUE! | BP40: ='Value Tree - Fx'!BP40 -> 1 | BQ40: ='Value Tree - Fx'!BQ40 -> #VALUE!
P43: ='Value Tree - Fx'!P43 -> + | R43: ='Value Tree 2'!$D$6 -> #N/A | V43: ='Value Tree - Fx'!$A$12 -> Year | AA43: ='Value Tree - Fx'!AA43 -> + | AC43: ='Value Tree 2'!$D$6 -> #N/A | AG43: ='Value Tree - Fx'!$A$12 -> Year | AM43: ='Value Tree - Fx'!AM43 -> + | AY43: ='Value Tree - Fx'!AY43 -> + | BA43: ='Value Tree 2'!$D$6 -> #N/A | BE43: ='Value Tree - Fx'!$A$12 -> Year | BK43: ='Value Tree - Fx'!BK43 -> + | BM43: ='Value Tree 2'!$D$6 -> #N/A | BQ43: ='Value Tree - Fx'!$A$12 -> Year
Q44: Fin. Results (M) | AB44: FC+SG&A/Net Sales (%) | AN44: FC+SG&A/Net Sales (%) | AZ44: Other Variable (LMU/t) | BL44: Clinker Factor (%)
P45: ='Value Tree - Fx'!P45 -> #N/A | R45: ='Value Tree - Fx'!R45 -> #VALUE! | V45: ='Value Tree - Fx'!V45 -> #VALUE! | AA45: ='Value Tree - Fx'!AA45 -> #N/A | AC45: ='Value Tree - Fx'!AC45 -> #VALUE! | AG45: ='Value Tree - Fx'!AG45 -> #VALUE! | AM45: ='Value Tree - Fx'!AM45 -> 0 | AO45: ='Value Tree - Fx'!AO45 -> #VALUE! | AS45: ='Value Tree - Fx'!AS45 -> #VALUE! | AY45: ='Value Tree - Fx'!AY45 -> RF | BA45: ='Value Tree - Fx'!BA45 -> #VALUE! | BE45: ='Value Tree - Fx'!BE45 -> #VALUE! | BK45: ='Value Tree - Fx'!BK45 -> RF | BM45: ='Value Tree - Fx'!BM45 -> #VALUE! | BQ45: ='Value Tree - Fx'!BQ45 -> #VALUE!
P46: ='Value Tree - Fx'!P46 -> #N/A | R46: ='Value Tree - Fx'!R46 -> #VALUE! | V46: ='Value Tree - Fx'!V46 -> #VALUE! | AA46: ='Value Tree - Fx'!AA46 -> #N/A | AC46: ='Value Tree - Fx'!AC46 -> #VALUE! | AG46: ='Value Tree - Fx'!AG46 -> #VALUE! | AM46: ='Value Tree - Fx'!AM46 -> 0 | AO46: ='Value Tree - Fx'!AO46 -> #VALUE! | AS46: ='Value Tree - Fx'!AS46 -> #VALUE! | AY46: ='Value Tree - Fx'!AY46 -> L300 | BA46: ='Value Tree - Fx'!BA46 -> #VALUE! | BE46: ='Value Tree - Fx'!BE46 -> #VALUE! | BK46: ='Value Tree - Fx'!BK46 -> L300 | BM46: ='Value Tree - Fx'!BM46 -> #VALUE! | BQ46: ='Value Tree - Fx'!BQ46 -> #VALUE!
P47: ='Value Tree - Fx'!P47 -> l500 | Q47: ='Value Tree - Fx'!Q47 -> #VALUE! | R47: ='Value Tree - Fx'!R47 -> #VALUE! | U47: ='Value Tree - Fx'!U47 -> #VALUE! | V47: ='Value Tree - Fx'!V47 -> #VALUE! | AA47: ='Value Tree - Fx'!AA47 -> l500 | AB47: ='Value Tree - Fx'!AB47 -> #VALUE! | AC47: ='Value Tree - Fx'!AC47 -> #VALUE! | AF47: ='Value Tree - Fx'!AF47 -> #VALUE! | AG47: ='Value Tree - Fx'!AG47 -> #VALUE! | AM47: ='Value Tree - Fx'!AM47 -> 0 | AN47: ='Value Tree - Fx'!AN47 -> #VALUE! | AO47: ='Value Tree - Fx'!AO47 -> #VALUE! | AR47: ='Value Tree - Fx'!AR47 -> #VALUE! | AS47: ='Value Tree - Fx'!AS47 -> #VALUE! | AY47: ='Value Tree - Fx'!AY47 -> l500 | AZ47: ='Value Tree - Fx'!AZ47 -> 1 | BA47: ='Value Tree - Fx'!BA47 -> #VALUE! | BD47: ='Value Tree - Fx'!BD47 -> 1 | BE47: ='Value Tree - Fx'!BE47 -> #VALUE! | BK47: ='Value Tree - Fx'!BK47 -> l500 | BL47: ='Value Tree - Fx'!BL47 -> 1 | BM47: ='Value Tree - Fx'!BM47 -> #VALUE! | BP47: ='Value Tree - Fx'!BP47 -> 1 | BQ47: ='Value Tree - Fx'!BQ47 -> #VALUE!
