Workbook

Sheet Cons_Region
B1: =_xll.VIEW("CONS_VC:STG.100.DataBase_Uploads",D9) -> CONS_VC:STG.100.DataBase_Uploads:-7526985491597873023 | C1: =_xll.VIEW("CONS_VC:ALL.015.Region_Assumptions") -> CONS_VC:ALL.015.Region_Assumptions:-752698549-412528343 | D1: =_xll.VIEW("CONS_VC:DFS.120.Financial_Results") -> CONS_VC:DFS.120.Financial_Results:-752698549-1678799984 | K1: Value | L1: N/A | M1: =_xll.SUBNM("CONS_VC:ALL.D.Version","","T4") -> T4 | N1: PROD099
B2: =_xll.VIEW("CONS_VC:REV.100.Revenue_Consolidated") -> CONS_VC:REV.100.Revenue_Consolidated:-752698549-1045742215 | C2: =_xll.VIEW("CONS_VC:ALL.010.Economic_Assumptions") -> CONS_VC:ALL.010.Economic_Assumptions:-752698549-2110203674 | D2: =_xll.VIEW("CONS_VC:DFS.140.Indirect_Cash_Flow") -> CONS_VC:DFS.140.Indirect_Cash_Flow:-7526985491192101094 | K2: Total Market | N2: Total Products
B3: =_xll.VIEW("CONS_VC:DFS.100.Profit_and_Loss") -> CONS_VC:DFS.100.Profit_and_Loss:-7526985491293352199 | C3: =_xll.VIEW("CONS_VC:DFS.160.Working_Capital") -> CONS_VC:DFS.160.Working_Capital:-752698549-593608013 | D3: =_xll.VIEW("CONS_VC:ALL.004.Uploads_Status_Planning") -> CONS_VC:ALL.004.Uploads_Status_Planning:-7526985492074531375 | G3: Flag
B4: =_xll.VIEW("CONS_VC:ALL.001.Actual_Control") -> CONS_VC:ALL.001.Actual_Control:-7526985491690317456 | C4: =_xll.VIEW("CONS_VC:DFS.180.Gross_Debt") -> CONS_VC:DFS.180.Gross_Debt:-7526985491758842948
C5: =_xll.DBRW(Cons_Region!$B$4,Cons_Region!$D$9,Cons_Region!C11,$M$1,$G$3) -> PLAN | D5: =_xll.DBRW(Cons_Region!$B$4,Cons_Region!$D$9,Cons_Region!D11,$M$1,$G$3) -> PLAN | E5: =_xll.DBRW(Cons_Region!$B$4,Cons_Region!$D$9,Cons_Region!E11,$M$1,$G$3) -> PLAN | F5: =_xll.DBRW(Cons_Region!$B$4,Cons_Region!$D$9,Cons_Region!F11,$M$1,$G$3) -> PLAN | G5: =_xll.DBRW(Cons_Region!$B$4,Cons_Region!$D$9,Cons_Region!G11,$M$1,$G$3) -> PLAN | H5: =_xll.DBRW(Cons_Region!$B$4,Cons_Region!$D$9,Cons_Region!H11,$M$1,$G$3) -> PLAN | I5: =_xll.DBRW(Cons_Region!$B$4,Cons_Region!$D$9,Cons_Region!I11,$M$1,$G$3) -> PLAN | J5: =_xll.DBRW(Cons_Region!$B$4,Cons_Region!$D$9,Cons_Region!J11,$M$1,$G$3) -> PLAN | ... N5: =_xll.DBRW(Cons_Region!$B$4,Cons_Region!$D$9,Cons_Region!N11,$M$1,$G$3) -> PLAN
L7: System Input Status: | N7: =_xll.DBRW($D$3,$M$1,$J$9,"Status") -> Closed
B8: GLOBAL ASSUMPTIONS
C9: Year: | D9: =_xll.SUBNM("CONS_VC:ALL.D.Year","SYS_Picklist","2026","MEMBER_NAME") -> 2026 | F9: Currency: | G9: =_xll.SUBNM("CONS_VC:ALL.D.Currency","PAX","USD","Nome alternativo") -> USD | I9: Region: | J9: =_xll.SUBNM("CONS_VC:ALL.D.Region","Nível 0","VCNA","MEMBER_NAME") -> VCNA
C11: 01 | D11: 02 | E11: 03 | F11: 04 | G11: 05 | H11: 06 | I11: 07 | J11: 08 | K11: 09 | L11: 10 | M11: 11 | N11: 12
C12: =$D$9&"."&C11 -> 2026.01 | D12: =$D$9&"."&D11 -> 2026.02 | E12: =$D$9&"."&E11 -> 2026.03 | F12: =$D$9&"."&F11 -> 2026.04 | G12: =$D$9&"."&G11 -> 2026.05 | H12: =$D$9&"."&H11 -> 2026.06 | I12: =$D$9&"."&I11 -> 2026.07 | J12: =$D$9&"."&J11 -> 2026.08 | ... N12: =$D$9&"."&N11 -> 2026.12
B13: Begining FX Rate R$/US$ | C13: =_xll.DBRW($C$2,Cons_Region!$D$9,Cons_Region!$C$11,$M$1,$B13,$K$1) -> 0 | D13: =_xll.DBRW($C$2,Cons_Region!$D$9,Cons_Region!$C$11,$M$1,$B13,$K$1) -> 0 | E13: =_xll.DBRW($C$2,Cons_Region!$D$9,Cons_Region!$C$11,$M$1,$B13,$K$1) -> 0 | F13: =_xll.DBRW($C$2,Cons_Region!$D$9,Cons_Region!$C$11,$M$1,$B13,$K$1) -> 0 | G13: =_xll.DBRW($C$2,Cons_Region!$D$9,Cons_Region!$C$11,$M$1,$B13,$K$1) -> 0 | H13: =_xll.DBRW($C$2,Cons_Region!$D$9,Cons_Region!$C$11,$M$1,$B13,$K$1) -> 0 | I13: =_xll.DBRW($C$2,Cons_Region!$D$9,Cons_Region!$C$11,$M$1,$B13,$K$1) -> 0 | J13: =_xll.DBRW($C$2,Cons_Region!$D$9,Cons_Region!$C$11,$M$1,$B13,$K$1) -> 0 | ... N13: =_xll.DBRW($C$2,Cons_Region!$D$9,Cons_Region!$C$11,$M$1,$B13,$K$1) -> 0
B14: Average FX Rate R$/US$ | C14: =_xll.DBRW($C$2,Cons_Region!$D$9,Cons_Region!$C$11,$M$1,$B14,$K$1) -> 0 | D14: =_xll.DBRW($C$2,Cons_Region!$D$9,Cons_Region!$C$11,$M$1,$B14,$K$1) -> 0 | E14: =_xll.DBRW($C$2,Cons_Region!$D$9,Cons_Region!$C$11,$M$1,$B14,$K$1) -> 0 | F14: =_xll.DBRW($C$2,Cons_Region!$D$9,Cons_Region!$C$11,$M$1,$B14,$K$1) -> 0 | G14: =_xll.DBRW($C$2,Cons_Region!$D$9,Cons_Region!$C$11,$M$1,$B14,$K$1) -> 0 | H14: =_xll.DBRW($C$2,Cons_Region!$D$9,Cons_Region!$C$11,$M$1,$B14,$K$1) -> 0 | I14: =_xll.DBRW($C$2,Cons_Region!$D$9,Cons_Region!$C$11,$M$1,$B14,$K$1) -> 0 | J14: =_xll.DBRW($C$2,Cons_Region!$D$9,Cons_Region!$C$11,$M$1,$B14,$K$1) -> 0 | ... N14: =_xll.DBRW($C$2,Cons_Region!$D$9,Cons_Region!$C$11,$M$1,$B14,$K$1) -> 0
B15: Final FX Rate R$/US$ | C15: =_xll.DBRW($C$2,Cons_Region!$D$9,Cons_Region!$C$11,$M$1,$B15,$K$1) -> 0 | D15: =_xll.DBRW($C$2,Cons_Region!$D$9,Cons_Region!$C$11,$M$1,$B15,$K$1) -> 0 | E15: =_xll.DBRW($C$2,Cons_Region!$D$9,Cons_Region!$C$11,$M$1,$B15,$K$1) -> 0 | F15: =_xll.DBRW($C$2,Cons_Region!$D$9,Cons_Region!$C$11,$M$1,$B15,$K$1) -> 0 | G15: =_xll.DBRW($C$2,Cons_Region!$D$9,Cons_Region!$C$11,$M$1,$B15,$K$1) -> 0 | H15: =_xll.DBRW($C$2,Cons_Region!$D$9,Cons_Region!$C$11,$M$1,$B15,$K$1) -> 0 | I15: =_xll.DBRW($C$2,Cons_Region!$D$9,Cons_Region!$C$11,$M$1,$B15,$K$1) -> 0 | J15: =_xll.DBRW($C$2,Cons_Region!$D$9,Cons_Region!$C$11,$M$1,$B15,$K$1) -> 0 | ... N15: =_xll.DBRW($C$2,Cons_Region!$D$9,Cons_Region!$C$11,$M$1,$B15,$K$1) -> 0
B16: Begining FX Rate US$/EUR | C16: =_xll.DBRW($C$2,Cons_Region!$D$9,Cons_Region!$C$11,$M$1,$B16,$K$1) -> 0 | D16: =_xll.DBRW($C$2,Cons_Region!$D$9,Cons_Region!$C$11,$M$1,$B16,$K$1) -> 0 | E16: =_xll.DBRW($C$2,Cons_Region!$D$9,Cons_Region!$C$11,$M$1,$B16,$K$1) -> 0 | F16: =_xll.DBRW($C$2,Cons_Region!$D$9,Cons_Region!$C$11,$M$1,$B16,$K$1) -> 0 | G16: =_xll.DBRW($C$2,Cons_Region!$D$9,Cons_Region!$C$11,$M$1,$B16,$K$1) -> 0 | H16: =_xll.DBRW($C$2,Cons_Region!$D$9,Cons_Region!$C$11,$M$1,$B16,$K$1) -> 0 | I16: =_xll.DBRW($C$2,Cons_Region!$D$9,Cons_Region!$C$11,$M$1,$B16,$K$1) -> 0 | J16: =_xll.DBRW($C$2,Cons_Region!$D$9,Cons_Region!$C$11,$M$1,$B16,$K$1) -> 0 | ... N16: =_xll.DBRW($C$2,Cons_Region!$D$9,Cons_Region!$C$11,$M$1,$B16,$K$1) -> 0
B17: Average FX Rate US$/EUR | C17: =_xll.DBRW($C$2,Cons_Region!$D$9,Cons_Region!$C$11,$M$1,$B17,$K$1) -> 5 | D17: =_xll.DBRW($C$2,Cons_Region!$D$9,Cons_Region!$C$11,$M$1,$B17,$K$1) -> 5 | E17: =_xll.DBRW($C$2,Cons_Region!$D$9,Cons_Region!$C$11,$M$1,$B17,$K$1) -> 5 | F17: =_xll.DBRW($C$2,Cons_Region!$D$9,Cons_Region!$C$11,$M$1,$B17,$K$1) -> 5 | G17: =_xll.DBRW($C$2,Cons_Region!$D$9,Cons_Region!$C$11,$M$1,$B17,$K$1) -> 5 | H17: =_xll.DBRW($C$2,Cons_Region!$D$9,Cons_Region!$C$11,$M$1,$B17,$K$1) -> 5 | I17: =_xll.DBRW($C$2,Cons_Region!$D$9,Cons_Region!$C$11,$M$1,$B17,$K$1) -> 5 | J17: =_xll.DBRW($C$2,Cons_Region!$D$9,Cons_Region!$C$11,$M$1,$B17,$K$1) -> 5 | ... N17: =_xll.DBRW($C$2,Cons_Region!$D$9,Cons_Region!$C$11,$M$1,$B17,$K$1) -> 5
B18: Final FX Rate US$/EUR | C18: =_xll.DBRW($C$2,Cons_Region!$D$9,Cons_Region!$C$11,$M$1,$B18,$K$1) -> 0 | D18: =_xll.DBRW($C$2,Cons_Region!$D$9,Cons_Region!$C$11,$M$1,$B18,$K$1) -> 0 | E18: =_xll.DBRW($C$2,Cons_Region!$D$9,Cons_Region!$C$11,$M$1,$B18,$K$1) -> 0 | F18: =_xll.DBRW($C$2,Cons_Region!$D$9,Cons_Region!$C$11,$M$1,$B18,$K$1) -> 0 | G18: =_xll.DBRW($C$2,Cons_Region!$D$9,Cons_Region!$C$11,$M$1,$B18,$K$1) -> 0 | H18: =_xll.DBRW($C$2,Cons_Region!$D$9,Cons_Region!$C$11,$M$1,$B18,$K$1) -> 0 | I18: =_xll.DBRW($C$2,Cons_Region!$D$9,Cons_Region!$C$11,$M$1,$B18,$K$1) -> 0 | J18: =_xll.DBRW($C$2,Cons_Region!$D$9,Cons_Region!$C$11,$M$1,$B18,$K$1) -> 0 | ... N18: =_xll.DBRW($C$2,Cons_Region!$D$9,Cons_Region!$C$11,$M$1,$B18,$K$1) -> 0
B19: Câmbio Inicial UYU$/US$ | C19: =_xll.DBRW($C$2,Cons_Region!$D$9,Cons_Region!$C$11,$M$1,$B19,$K$1) -> 0 | D19: =_xll.DBRW($C$2,Cons_Region!$D$9,Cons_Region!$C$11,$M$1,$B19,$K$1) -> 0 | E19: =_xll.DBRW($C$2,Cons_Region!$D$9,Cons_Region!$C$11,$M$1,$B19,$K$1) -> 0 | F19: =_xll.DBRW($C$2,Cons_Region!$D$9,Cons_Region!$C$11,$M$1,$B19,$K$1) -> 0 | G19: =_xll.DBRW($C$2,Cons_Region!$D$9,Cons_Region!$C$11,$M$1,$B19,$K$1) -> 0 | H19: =_xll.DBRW($C$2,Cons_Region!$D$9,Cons_Region!$C$11,$M$1,$B19,$K$1) -> 0 | I19: =_xll.DBRW($C$2,Cons_Region!$D$9,Cons_Region!$C$11,$M$1,$B19,$K$1) -> 0 | J19: =_xll.DBRW($C$2,Cons_Region!$D$9,Cons_Region!$C$11,$M$1,$B19,$K$1) -> 0 | ... N19: =_xll.DBRW($C$2,Cons_Region!$D$9,Cons_Region!$C$11,$M$1,$B19,$K$1) -> 0
B20: Câmbio Médio UYU$/US$ | C20: =_xll.DBRW($C$2,Cons_Region!$D$9,Cons_Region!$C$11,$M$1,$B20,$K$1) -> 0 | D20: =_xll.DBRW($C$2,Cons_Region!$D$9,Cons_Region!$C$11,$M$1,$B20,$K$1) -> 0 | E20: =_xll.DBRW($C$2,Cons_Region!$D$9,Cons_Region!$C$11,$M$1,$B20,$K$1) -> 0 | F20: =_xll.DBRW($C$2,Cons_Region!$D$9,Cons_Region!$C$11,$M$1,$B20,$K$1) -> 0 | G20: =_xll.DBRW($C$2,Cons_Region!$D$9,Cons_Region!$C$11,$M$1,$B20,$K$1) -> 0 | H20: =_xll.DBRW($C$2,Cons_Region!$D$9,Cons_Region!$C$11,$M$1,$B20,$K$1) -> 0 | I20: =_xll.DBRW($C$2,Cons_Region!$D$9,Cons_Region!$C$11,$M$1,$B20,$K$1) -> 0 | J20: =_xll.DBRW($C$2,Cons_Region!$D$9,Cons_Region!$C$11,$M$1,$B20,$K$1) -> 0 | ... N20: =_xll.DBRW($C$2,Cons_Region!$D$9,Cons_Region!$C$11,$M$1,$B20,$K$1) -> 0
B21: Câmbio Final UYU$/US$ | C21: =_xll.DBRW($C$2,Cons_Region!$D$9,Cons_Region!$C$11,$M$1,$B21,$K$1) -> 0 | D21: =_xll.DBRW($C$2,Cons_Region!$D$9,Cons_Region!$C$11,$M$1,$B21,$K$1) -> 0 | E21: =_xll.DBRW($C$2,Cons_Region!$D$9,Cons_Region!$C$11,$M$1,$B21,$K$1) -> 0 | F21: =_xll.DBRW($C$2,Cons_Region!$D$9,Cons_Region!$C$11,$M$1,$B21,$K$1) -> 0 | G21: =_xll.DBRW($C$2,Cons_Region!$D$9,Cons_Region!$C$11,$M$1,$B21,$K$1) -> 0 | H21: =_xll.DBRW($C$2,Cons_Region!$D$9,Cons_Region!$C$11,$M$1,$B21,$K$1) -> 0 | I21: =_xll.DBRW($C$2,Cons_Region!$D$9,Cons_Region!$C$11,$M$1,$B21,$K$1) -> 0 | J21: =_xll.DBRW($C$2,Cons_Region!$D$9,Cons_Region!$C$11,$M$1,$B21,$K$1) -> 0 | ... N21: =_xll.DBRW($C$2,Cons_Region!$D$9,Cons_Region!$C$11,$M$1,$B21,$K$1) -> 0
B22: Câmbio Inicial ARS$/US$ | C22: =_xll.DBRW($C$2,Cons_Region!$D$9,Cons_Region!$C$11,$M$1,$B22,$K$1) -> 0 | D22: =_xll.DBRW($C$2,Cons_Region!$D$9,Cons_Region!$C$11,$M$1,$B22,$K$1) -> 0 | E22: =_xll.DBRW($C$2,Cons_Region!$D$9,Cons_Region!$C$11,$M$1,$B22,$K$1) -> 0 | F22: =_xll.DBRW($C$2,Cons_Region!$D$9,Cons_Region!$C$11,$M$1,$B22,$K$1) -> 0 | G22: =_xll.DBRW($C$2,Cons_Region!$D$9,Cons_Region!$C$11,$M$1,$B22,$K$1) -> 0 | H22: =_xll.DBRW($C$2,Cons_Region!$D$9,Cons_Region!$C$11,$M$1,$B22,$K$1) -> 0 | I22: =_xll.DBRW($C$2,Cons_Region!$D$9,Cons_Region!$C$11,$M$1,$B22,$K$1) -> 0 | J22: =_xll.DBRW($C$2,Cons_Region!$D$9,Cons_Region!$C$11,$M$1,$B22,$K$1) -> 0 | ... N22: =_xll.DBRW($C$2,Cons_Region!$D$9,Cons_Region!$C$11,$M$1,$B22,$K$1) -> 0
B23: Câmbio Médio ARS$/US$ | C23: =_xll.DBRW($C$2,Cons_Region!$D$9,Cons_Region!$C$11,$M$1,$B23,$K$1) -> 0 | D23: =_xll.DBRW($C$2,Cons_Region!$D$9,Cons_Region!$C$11,$M$1,$B23,$K$1) -> 0 | E23: =_xll.DBRW($C$2,Cons_Region!$D$9,Cons_Region!$C$11,$M$1,$B23,$K$1) -> 0 | F23: =_xll.DBRW($C$2,Cons_Region!$D$9,Cons_Region!$C$11,$M$1,$B23,$K$1) -> 0 | G23: =_xll.DBRW($C$2,Cons_Region!$D$9,Cons_Region!$C$11,$M$1,$B23,$K$1) -> 0 | H23: =_xll.DBRW($C$2,Cons_Region!$D$9,Cons_Region!$C$11,$M$1,$B23,$K$1) -> 0 | I23: =_xll.DBRW($C$2,Cons_Region!$D$9,Cons_Region!$C$11,$M$1,$B23,$K$1) -> 0 | J23: =_xll.DBRW($C$2,Cons_Region!$D$9,Cons_Region!$C$11,$M$1,$B23,$K$1) -> 0 | ... N23: =_xll.DBRW($C$2,Cons_Region!$D$9,Cons_Region!$C$11,$M$1,$B23,$K$1) -> 0
B24: Câmbio Final ARS$/US$ | C24: =_xll.DBRW($C$2,Cons_Region!$D$9,Cons_Region!$C$11,$M$1,$B24,$K$1) -> 0 | D24: =_xll.DBRW($C$2,Cons_Region!$D$9,Cons_Region!$C$11,$M$1,$B24,$K$1) -> 0 | E24: =_xll.DBRW($C$2,Cons_Region!$D$9,Cons_Region!$C$11,$M$1,$B24,$K$1) -> 0 | F24: =_xll.DBRW($C$2,Cons_Region!$D$9,Cons_Region!$C$11,$M$1,$B24,$K$1) -> 0 | G24: =_xll.DBRW($C$2,Cons_Region!$D$9,Cons_Region!$C$11,$M$1,$B24,$K$1) -> 0 | H24: =_xll.DBRW($C$2,Cons_Region!$D$9,Cons_Region!$C$11,$M$1,$B24,$K$1) -> 0 | I24: =_xll.DBRW($C$2,Cons_Region!$D$9,Cons_Region!$C$11,$M$1,$B24,$K$1) -> 0 | J24: =_xll.DBRW($C$2,Cons_Region!$D$9,Cons_Region!$C$11,$M$1,$B24,$K$1) -> 0 | ... N24: =_xll.DBRW($C$2,Cons_Region!$D$9,Cons_Region!$C$11,$M$1,$B24,$K$1) -> 0
... B26: American CPI | C26: =_xll.DBRW($C$2,Cons_Region!$D$9,Cons_Region!$C$11,$M$1,$B26,$K$1) -> 0 | D26: =_xll.DBRW($C$2,Cons_Region!$D$9,Cons_Region!$C$11,$M$1,$B26,$K$1) -> 0 | E26: =_xll.DBRW($C$2,Cons_Region!$D$9,Cons_Region!$C$11,$M$1,$B26,$K$1) -> 0 | F26: =_xll.DBRW($C$2,Cons_Region!$D$9,Cons_Region!$C$11,$M$1,$B26,$K$1) -> 0 | G26: =_xll.DBRW($C$2,Cons_Region!$D$9,Cons_Region!$C$11,$M$1,$B26,$K$1) -> 0 | H26: =_xll.DBRW($C$2,Cons_Region!$D$9,Cons_Region!$C$11,$M$1,$B26,$K$1) -> 0 | I26: =_xll.DBRW($C$2,Cons_Region!$D$9,Cons_Region!$C$11,$M$1,$B26,$K$1) -> 0 | J26: =_xll.DBRW($C$2,Cons_Region!$D$9,Cons_Region!$C$11,$M$1,$B26,$K$1) -> 0 | ... N26: =_xll.DBRW($C$2,Cons_Region!$D$9,Cons_Region!$C$11,$M$1,$B26,$K$1) -> 0
B27: Number of Days | C27: =_xll.DBRW($C$2,Cons_Region!$D$9,C$11,$M$1,$B27,$K$1) -> 31 | D27: =_xll.DBRW($C$2,Cons_Region!$D$9,D$11,$M$1,$B27,$K$1) -> 30 | E27: =_xll.DBRW($C$2,Cons_Region!$D$9,E$11,$M$1,$B27,$K$1) -> 31 | F27: =_xll.DBRW($C$2,Cons_Region!$D$9,F$11,$M$1,$B27,$K$1) -> 30 | G27: =_xll.DBRW($C$2,Cons_Region!$D$9,G$11,$M$1,$B27,$K$1) -> 31 | H27: =_xll.DBRW($C$2,Cons_Region!$D$9,H$11,$M$1,$B27,$K$1) -> 31 | I27: =_xll.DBRW($C$2,Cons_Region!$D$9,I$11,$M$1,$B27,$K$1) -> 30 | J27: =_xll.DBRW($C$2,Cons_Region!$D$9,J$11,$M$1,$B27,$K$1) -> 31 | ... N27: =_xll.DBRW($C$2,Cons_Region!$D$9,N$11,$M$1,$B27,$K$1) -> 0
B30: NET REVENUES
C33: =$D$9&"."&C11 -> 2026.01 | D33: =$D$9&"."&D11 -> 2026.02 | E33: =$D$9&"."&E11 -> 2026.03 | F33: =$D$9&"."&F11 -> 2026.04 | G33: =$D$9&"."&G11 -> 2026.05 | H33: =$D$9&"."&H11 -> 2026.06 | I33: =$D$9&"."&I11 -> 2026.07 | J33: =$D$9&"."&J11 -> 2026.08 | ... N33: =$D$9&"."&N11 -> 2026.12
B34: % Operational Tax | C34: =_xll.DBRW($B$2,Cons_Region!$D$9,Cons_Region!C$11,$M$1,Cons_Region!$G$9,Cons_Region!$J$9,$N$2,$K$2,$B$34) -> 0 | D34: =_xll.DBRW($B$2,Cons_Region!$D$9,Cons_Region!D$11,$M$1,Cons_Region!$G$9,Cons_Region!$J$9,$N$2,$K$2,$B$34) -> 0 | E34: =_xll.DBRW($B$2,Cons_Region!$D$9,Cons_Region!E$11,$M$1,Cons_Region!$G$9,Cons_Region!$J$9,$N$2,$K$2,$B$34) -> 0 | F34: =_xll.DBRW($B$2,Cons_Region!$D$9,Cons_Region!F$11,$M$1,Cons_Region!$G$9,Cons_Region!$J$9,$N$2,$K$2,$B$34) -> 0 | G34: =_xll.DBRW($B$2,Cons_Region!$D$9,Cons_Region!G$11,$M$1,Cons_Region!$G$9,Cons_Region!$J$9,$N$2,$K$2,$B$34) -> 0 | H34: =_xll.DBRW($B$2,Cons_Region!$D$9,Cons_Region!H$11,$M$1,Cons_Region!$G$9,Cons_Region!$J$9,$N$2,$K$2,$B$34) -> 0 | I34: =_xll.DBRW($B$2,Cons_Region!$D$9,Cons_Region!I$11,$M$1,Cons_Region!$G$9,Cons_Region!$J$9,$N$2,$K$2,$B$34) -> 0 | J34: =_xll.DBRW($B$2,Cons_Region!$D$9,Cons_Region!J$11,$M$1,Cons_Region!$G$9,Cons_Region!$J$9,$N$2,$K$2,$B$34) -> 0 | ... N34: =_xll.DBRW($B$2,Cons_Region!$D$9,Cons_Region!N$11,$M$1,Cons_Region!$G$9,Cons_Region!$J$9,$N$2,$K$2,$B$34) -> 0
B35: Gross Revenue [$MM] | C35: =_xll.DBRW($B$2,Cons_Region!$D$9,Cons_Region!C$11,$M$1,Cons_Region!$G$9,Cons_Region!$J$9,$N$2,$K$2,$B$35) -> 53.485063 | D35: =_xll.DBRW($B$2,Cons_Region!$D$9,Cons_Region!D$11,$M$1,Cons_Region!$G$9,Cons_Region!$J$9,$N$2,$K$2,$B$35) -> 65.839564 | E35: =_xll.DBRW($B$2,Cons_Region!$D$9,Cons_Region!E$11,$M$1,Cons_Region!$G$9,Cons_Region!$J$9,$N$2,$K$2,$B$35) -> 90.971339 | F35: =_xll.DBRW($B$2,Cons_Region!$D$9,Cons_Region!F$11,$M$1,Cons_Region!$G$9,Cons_Region!$J$9,$N$2,$K$2,$B$35) -> 130.42887 | G35: =_xll.DBRW($B$2,Cons_Region!$D$9,Cons_Region!G$11,$M$1,Cons_Region!$G$9,Cons_Region!$J$9,$N$2,$K$2,$B$35) -> 157.2599 | H35: =_xll.DBRW($B$2,Cons_Region!$D$9,Cons_Region!H$11,$M$1,Cons_Region!$G$9,Cons_Region!$J$9,$N$2,$K$2,$B$35) -> 174.71501 | I35: =_xll.DBRW($B$2,Cons_Region!$D$9,Cons_Region!I$11,$M$1,Cons_Region!$G$9,Cons_Region!$J$9,$N$2,$K$2,$B$35) -> 176.77009 | J35: =_xll.DBRW($B$2,Cons_Region!$D$9,Cons_Region!J$11,$M$1,Cons_Region!$G$9,Cons_Region!$J$9,$N$2,$K$2,$B$35) -> 177.59375 | ... N35: =_xll.DBRW($B$2,Cons_Region!$D$9,Cons_Region!N$11,$M$1,Cons_Region!$G$9,Cons_Region!$J$9,$N$2,$K$2,$B$35) -> 83.919777
B36: Net Revenue [$MM] | C36: =_xll.DBRW($B$2,Cons_Region!$D$9,Cons_Region!C$11,$M$1,Cons_Region!$G$9,Cons_Region!$J$9,$N$2,$K$2,$B$36) -> 53.485063 | D36: =_xll.DBRW($B$2,Cons_Region!$D$9,Cons_Region!D$11,$M$1,Cons_Region!$G$9,Cons_Region!$J$9,$N$2,$K$2,$B$36) -> 65.839564 | E36: =_xll.DBRW($B$2,Cons_Region!$D$9,Cons_Region!E$11,$M$1,Cons_Region!$G$9,Cons_Region!$J$9,$N$2,$K$2,$B$36) -> 90.971339 | F36: =_xll.DBRW($B$2,Cons_Region!$D$9,Cons_Region!F$11,$M$1,Cons_Region!$G$9,Cons_Region!$J$9,$N$2,$K$2,$B$36) -> 130.42887 | G36: =_xll.DBRW($B$2,Cons_Region!$D$9,Cons_Region!G$11,$M$1,Cons_Region!$G$9,Cons_Region!$J$9,$N$2,$K$2,$B$36) -> 157.2599 | H36: =_xll.DBRW($B$2,Cons_Region!$D$9,Cons_Region!H$11,$M$1,Cons_Region!$G$9,Cons_Region!$J$9,$N$2,$K$2,$B$36) -> 174.71501 | I36: =_xll.DBRW($B$2,Cons_Region!$D$9,Cons_Region!I$11,$M$1,Cons_Region!$G$9,Cons_Region!$J$9,$N$2,$K$2,$B$36) -> 176.77009 | J36: =_xll.DBRW($B$2,Cons_Region!$D$9,Cons_Region!J$11,$M$1,Cons_Region!$G$9,Cons_Region!$J$9,$N$2,$K$2,$B$36) -> 177.59375 | ... N36: =_xll.DBRW($B$2,Cons_Region!$D$9,Cons_Region!N$11,$M$1,Cons_Region!$G$9,Cons_Region!$J$9,$N$2,$K$2,$B$36) -> 83.919777
B40: CONTRIBUTION MARGIN
C43: =$D$9&"."&C$11 -> 2026.01 | D43: =$D$9&"."&D$11 -> 2026.02 | E43: =$D$9&"."&E$11 -> 2026.03 | F43: =$D$9&"."&F$11 -> 2026.04 | G43: =$D$9&"."&G$11 -> 2026.05 | H43: =$D$9&"."&H$11 -> 2026.06 | I43: =$D$9&"."&I$11 -> 2026.07 | J43: =$D$9&"."&J$11 -> 2026.08 | ... N43: =$D$9&"."&N$11 -> 2026.12
B44: Final Variable Sales Expenses | C44: =_xll.DBRW($B$1,Cons_Region!$D$9,Cons_Region!C$11,$M$1,Cons_Region!$G$9,Cons_Region!$J$9,$N$2,Cons_Region!$B44,$L$1,$K$1) -> 10.755415 | D44: =_xll.DBRW($B$1,Cons_Region!$D$9,Cons_Region!D$11,$M$1,Cons_Region!$G$9,Cons_Region!$J$9,$N$1,Cons_Region!$B44,$L$1,$K$1) -> 11.194354 | E44: =_xll.DBRW($B$1,Cons_Region!$D$9,Cons_Region!E$11,$M$1,Cons_Region!$G$9,Cons_Region!$J$9,$N$1,Cons_Region!$B44,$L$1,$K$1) -> 17.865267 | F44: =_xll.DBRW($B$1,Cons_Region!$D$9,Cons_Region!F$11,$M$1,Cons_Region!$G$9,Cons_Region!$J$9,$N$1,Cons_Region!$B44,$L$1,$K$1) -> 25.541581 | G44: =_xll.DBRW($B$1,Cons_Region!$D$9,Cons_Region!G$11,$M$1,Cons_Region!$G$9,Cons_Region!$J$9,$N$1,Cons_Region!$B44,$L$1,$K$1) -> 32.065037 | H44: =_xll.DBRW($B$1,Cons_Region!$D$9,Cons_Region!H$11,$M$1,Cons_Region!$G$9,Cons_Region!$J$9,$N$1,Cons_Region!$B44,$L$1,$K$1) -> 32.16427 | I44: =_xll.DBRW($B$1,Cons_Region!$D$9,Cons_Region!I$11,$M$1,Cons_Region!$G$9,Cons_Region!$J$9,$N$1,Cons_Region!$B44,$L$1,$K$1) -> 33.559233 | J44: =_xll.DBRW($B$1,Cons_Region!$D$9,Cons_Region!J$11,$M$1,Cons_Region!$G$9,Cons_Region!$J$9,$N$1,Cons_Region!$B44,$L$1,$K$1) -> 33.758894 | K44: =_xll.DBRW($B$1,Cons_Region!$D$9,Cons_Region!K$11,$M$1,Cons_Region!$G$9,Cons_Region!$J$9,$N$1,Cons_Region!$B44,$L$1,$K$1) -> 34.329246 | ... N44: =_xll.DBRW($B$1,Cons_Region!$D$9,Cons_Region!N$11,$M$1,Cons_Region!$G$9,Cons_Region!$J$9,$N$1,Cons_Region!$B44,$L$1,$K$1) -> 17.751297
B45: Other Variable Costs | C45: =_xll.DBRW($B$1,Cons_Region!$D$9,Cons_Region!C$11,$M$1,Cons_Region!$G$9,Cons_Region!$J$9,$N$2,Cons_Region!$B45,$L$1,$K$1) -> 20.773323 | D45: =_xll.DBRW($B$1,Cons_Region!$D$9,Cons_Region!D$11,$M$1,Cons_Region!$G$9,Cons_Region!$J$9,$N$2,Cons_Region!$B45,$L$1,$K$1) -> 29.510057 | E45: =_xll.DBRW($B$1,Cons_Region!$D$9,Cons_Region!E$11,$M$1,Cons_Region!$G$9,Cons_Region!$J$9,$N$2,Cons_Region!$B45,$L$1,$K$1) -> 29.698686 | F45: =_xll.DBRW($B$1,Cons_Region!$D$9,Cons_Region!F$11,$M$1,Cons_Region!$G$9,Cons_Region!$J$9,$N$2,Cons_Region!$B45,$L$1,$K$1) -> 38.31103 | G45: =_xll.DBRW($B$1,Cons_Region!$D$9,Cons_Region!G$11,$M$1,Cons_Region!$G$9,Cons_Region!$J$9,$N$2,Cons_Region!$B45,$L$1,$K$1) -> 41.167295 | H45: =_xll.DBRW($B$1,Cons_Region!$D$9,Cons_Region!H$11,$M$1,Cons_Region!$G$9,Cons_Region!$J$9,$N$2,Cons_Region!$B45,$L$1,$K$1) -> 44.456398 | I45: =_xll.DBRW($B$1,Cons_Region!$D$9,Cons_Region!I$11,$M$1,Cons_Region!$G$9,Cons_Region!$J$9,$N$2,Cons_Region!$B45,$L$1,$K$1) -> 46.820857 | J45: =_xll.DBRW($B$1,Cons_Region!$D$9,Cons_Region!J$11,$M$1,Cons_Region!$G$9,Cons_Region!$J$9,$N$2,Cons_Region!$B45,$L$1,$K$1) -> 50.225845 | ... N45: =_xll.DBRW($B$1,Cons_Region!$D$9,Cons_Region!N$11,$M$1,Cons_Region!$G$9,Cons_Region!$J$9,$N$2,Cons_Region!$B45,$L$1,$K$1) -> 20.96795
B46: Fixed Costs | C46: =_xll.DBRW($B$1,Cons_Region!$D$9,Cons_Region!C$11,$M$1,Cons_Region!$G$9,Cons_Region!$J$9,$N$1,Cons_Region!$B46,$L$1,$K$1) -> 34.8395 | D46: =_xll.DBRW($B$1,Cons_Region!$D$9,Cons_Region!D$11,$M$1,Cons_Region!$G$9,Cons_Region!$J$9,$N$1,Cons_Region!$B46,$L$1,$K$1) -> 37.194558 | E46: =_xll.DBRW($B$1,Cons_Region!$D$9,Cons_Region!E$11,$M$1,Cons_Region!$G$9,Cons_Region!$J$9,$N$1,Cons_Region!$B46,$L$1,$K$1) -> 31.431682 | F46: =_xll.DBRW($B$1,Cons_Region!$D$9,Cons_Region!F$11,$M$1,Cons_Region!$G$9,Cons_Region!$J$9,$N$1,Cons_Region!$B46,$L$1,$K$1) -> 30.091597 | G46: =_xll.DBRW($B$1,Cons_Region!$D$9,Cons_Region!G$11,$M$1,Cons_Region!$G$9,Cons_Region!$J$9,$N$1,Cons_Region!$B46,$L$1,$K$1) -> 20.521551 | H46: =_xll.DBRW($B$1,Cons_Region!$D$9,Cons_Region!H$11,$M$1,Cons_Region!$G$9,Cons_Region!$J$9,$N$1,Cons_Region!$B46,$L$1,$K$1) -> 23.325895 | I46: =_xll.DBRW($B$1,Cons_Region!$D$9,Cons_Region!I$11,$M$1,Cons_Region!$G$9,Cons_Region!$J$9,$N$1,Cons_Region!$B46,$L$1,$K$1) -> 21.784902 | J46: =_xll.DBRW($B$1,Cons_Region!$D$9,Cons_Region!J$11,$M$1,Cons_Region!$G$9,Cons_Region!$J$9,$N$1,Cons_Region!$B46,$L$1,$K$1) -> 20.351641 | ... N46: =_xll.DBRW($B$1,Cons_Region!$D$9,Cons_Region!N$11,$M$1,Cons_Region!$G$9,Cons_Region!$J$9,$N$1,Cons_Region!$B46,$L$1,$K$1) -> 16.299832
B47: Operating Expenses | C47: =_xll.DBRW($B$1,Cons_Region!$D$9,Cons_Region!C$11,$M$1,Cons_Region!$G$9,Cons_Region!$J$9,$N$1,Cons_Region!$B47,$L$1,$K$1) -> 7.6474137 | D47: =_xll.DBRW($B$1,Cons_Region!$D$9,Cons_Region!D$11,$M$1,Cons_Region!$G$9,Cons_Region!$J$9,$N$1,Cons_Region!$B47,$L$1,$K$1) -> 8.1854403 | E47: =_xll.DBRW($B$1,Cons_Region!$D$9,Cons_Region!E$11,$M$1,Cons_Region!$G$9,Cons_Region!$J$9,$N$1,Cons_Region!$B47,$L$1,$K$1) -> 9.5925389 | F47: =_xll.DBRW($B$1,Cons_Region!$D$9,Cons_Region!F$11,$M$1,Cons_Region!$G$9,Cons_Region!$J$9,$N$1,Cons_Region!$B47,$L$1,$K$1) -> 8.5181996 | G47: =_xll.DBRW($B$1,Cons_Region!$D$9,Cons_Region!G$11,$M$1,Cons_Region!$G$9,Cons_Region!$J$9,$N$1,Cons_Region!$B47,$L$1,$K$1) -> 8.4528475 | H47: =_xll.DBRW($B$1,Cons_Region!$D$9,Cons_Region!H$11,$M$1,Cons_Region!$G$9,Cons_Region!$J$9,$N$1,Cons_Region!$B47,$L$1,$K$1) -> 9.6997918 | I47: =_xll.DBRW($B$1,Cons_Region!$D$9,Cons_Region!I$11,$M$1,Cons_Region!$G$9,Cons_Region!$J$9,$N$1,Cons_Region!$B47,$L$1,$K$1) -> 9.0077324 | J47: =_xll.DBRW($B$1,Cons_Region!$D$9,Cons_Region!J$11,$M$1,Cons_Region!$G$9,Cons_Region!$J$9,$N$1,Cons_Region!$B47,$L$1,$K$1) -> 8.7638409 | ... N47: =_xll.DBRW($B$1,Cons_Region!$D$9,Cons_Region!N$11,$M$1,Cons_Region!$G$9,Cons_Region!$J$9,$N$1,Cons_Region!$B47,$L$1,$K$1) -> 9.7192234
B48: Other | C48: =_xll.DBRW($B$1,Cons_Region!$D$9,Cons_Region!C$11,$M$1,Cons_Region!$G$9,Cons_Region!$J$9,$N$2,Cons_Region!$B48,"Total Accounts Line",$K$1) -> 0.013321036 | D48: =_xll.DBRW($B$1,Cons_Region!$D$9,Cons_Region!D$11,$M$1,Cons_Region!$G$9,Cons_Region!$J$9,$N$2,Cons_Region!$B48,"Total Accounts Line",$K$1) -> 0.67014606 | E48: =_xll.DBRW($B$1,Cons_Region!$D$9,Cons_Region!E$11,$M$1,Cons_Region!$G$9,Cons_Region!$J$9,$N$2,Cons_Region!$B48,"Total Accounts Line",$K$1) -> -0.0042525423 | F48: =_xll.DBRW($B$1,Cons_Region!$D$9,Cons_Region!F$11,$M$1,Cons_Region!$G$9,Cons_Region!$J$9,$N$2,Cons_Region!$B48,"Total Accounts Line",$K$1) -> -0.26754939 | G48: =_xll.DBRW($B$1,Cons_Region!$D$9,Cons_Region!G$11,$M$1,Cons_Region!$G$9,Cons_Region!$J$9,$N$2,Cons_Region!$B48,"Total Accounts Line",$K$1) -> -0.38664297 | H48: =_xll.DBRW($B$1,Cons_Region!$D$9,Cons_Region!H$11,$M$1,Cons_Region!$G$9,Cons_Region!$J$9,$N$2,Cons_Region!$B48,"Total Accounts Line",$K$1) -> -0.78180852 | I48: =_xll.DBRW($B$1,Cons_Region!$D$9,Cons_Region!I$11,$M$1,Cons_Region!$G$9,Cons_Region!$J$9,$N$2,Cons_Region!$B48,"Total Accounts Line",$K$1) -> -0.23141709 | J48: =_xll.DBRW($B$1,Cons_Region!$D$9,Cons_Region!J$11,$M$1,Cons_Region!$G$9,Cons_Region!$J$9,$N$2,Cons_Region!$B48,"Total Accounts Line",$K$1) -> -0.3926189 | ... N48: =_xll.DBRW($B$1,Cons_Region!$D$9,Cons_Region!N$11,$M$1,Cons_Region!$G$9,Cons_Region!$J$9,$N$2,Cons_Region!$B48,"Total Accounts Line",$K$1) -> 1.0399677
B49: EBITDA | C49: =_xll.DBRW($B$3,Cons_Region!$D$9,Cons_Region!C$11,$M$1,Cons_Region!$G$9,Cons_Region!$J$9,$N$2,Cons_Region!$B49,$K$1) -> -20.517267 | D49: =_xll.DBRW($B$3,Cons_Region!$D$9,Cons_Region!D$11,$M$1,Cons_Region!$G$9,Cons_Region!$J$9,$N$2,Cons_Region!$B49,$K$1) -> -19.574699 | E49: =_xll.DBRW($B$3,Cons_Region!$D$9,Cons_Region!E$11,$M$1,Cons_Region!$G$9,Cons_Region!$J$9,$N$2,Cons_Region!$B49,$K$1) -> 2.3789114 | F49: =_xll.DBRW($B$3,Cons_Region!$D$9,Cons_Region!F$11,$M$1,Cons_Region!$G$9,Cons_Region!$J$9,$N$2,Cons_Region!$B49,$K$1) -> 27.698911 | G49: =_xll.DBRW($B$3,Cons_Region!$D$9,Cons_Region!G$11,$M$1,Cons_Region!$G$9,Cons_Region!$J$9,$N$2,Cons_Region!$B49,$K$1) -> 54.666531 | H49: =_xll.DBRW($B$3,Cons_Region!$D$9,Cons_Region!H$11,$M$1,Cons_Region!$G$9,Cons_Region!$J$9,$N$2,Cons_Region!$B49,$K$1) -> 64.286844 | I49: =_xll.DBRW($B$3,Cons_Region!$D$9,Cons_Region!I$11,$M$1,Cons_Region!$G$9,Cons_Region!$J$9,$N$2,Cons_Region!$B49,$K$1) -> 65.365946 | J49: =_xll.DBRW($B$3,Cons_Region!$D$9,Cons_Region!J$11,$M$1,Cons_Region!$G$9,Cons_Region!$J$9,$N$2,Cons_Region!$B49,$K$1) -> 64.100911 | ... N49: =_xll.DBRW($B$3,Cons_Region!$D$9,Cons_Region!N$11,$M$1,Cons_Region!$G$9,Cons_Region!$J$9,$N$2,Cons_Region!$B49,$K$1) -> 20.221443
B52: Operating Profit
C54: =$D$9&"."&C$11 -> 2026.01 | D54: =$D$9&"."&D$11 -> 2026.02 | E54: =$D$9&"."&E$11 -> 2026.03 | F54: =$D$9&"."&F$11 -> 2026.04 | G54: =$D$9&"."&G$11 -> 2026.05 | H54: =$D$9&"."&H$11 -> 2026.06 | I54: =$D$9&"."&I$11 -> 2026.07 | J54: =$D$9&"."&J$11 -> 2026.08 | ... N54: =$D$9&"."&N$11 -> 2026.12
B55: Depreciation / amortization / depletion - Corporate | C55: =_xll.DBRW($B$1,Cons_Region!$D$9,Cons_Region!C$11,$M$1,Cons_Region!$G$9,Cons_Region!$J$9,$N$1,Cons_Region!$B55,$L$1,$K$1) -> 15.352669 | D55: =_xll.DBRW($B$1,Cons_Region!$D$9,Cons_Region!D$11,$M$1,Cons_Region!$G$9,Cons_Region!$J$9,$N$1,Cons_Region!$B55,$L$1,$K$1) -> 15.536694 | E55: =_xll.DBRW($B$1,Cons_Region!$D$9,Cons_Region!E$11,$M$1,Cons_Region!$G$9,Cons_Region!$J$9,$N$1,Cons_Region!$B55,$L$1,$K$1) -> 16.603118 | F55: =_xll.DBRW($B$1,Cons_Region!$D$9,Cons_Region!F$11,$M$1,Cons_Region!$G$9,Cons_Region!$J$9,$N$1,Cons_Region!$B55,$L$1,$K$1) -> 16.662678 | G55: =_xll.DBRW($B$1,Cons_Region!$D$9,Cons_Region!G$11,$M$1,Cons_Region!$G$9,Cons_Region!$J$9,$N$1,Cons_Region!$B55,$L$1,$K$1) -> 16.728464 | H55: =_xll.DBRW($B$1,Cons_Region!$D$9,Cons_Region!H$11,$M$1,Cons_Region!$G$9,Cons_Region!$J$9,$N$1,Cons_Region!$B55,$L$1,$K$1) -> 17.065599 | I55: =_xll.DBRW($B$1,Cons_Region!$D$9,Cons_Region!I$11,$M$1,Cons_Region!$G$9,Cons_Region!$J$9,$N$1,Cons_Region!$B55,$L$1,$K$1) -> 16.709348 | J55: =_xll.DBRW($B$1,Cons_Region!$D$9,Cons_Region!J$11,$M$1,Cons_Region!$G$9,Cons_Region!$J$9,$N$1,Cons_Region!$B55,$L$1,$K$1) -> 16.725034 | ... N55: =_xll.DBRW($B$1,Cons_Region!$D$9,Cons_Region!N$11,$M$1,Cons_Region!$G$9,Cons_Region!$J$9,$N$1,Cons_Region!$B55,$L$1,$K$1) -> 16.325931
...

Sheet Input_Prod_01
B1: =_xll.VIEW("CONS_VC:STG.100.DataBase_Uploads",D9) -> CONS_VC:STG.100.DataBase_Uploads:-7526985492024324052 | C1: =_xll.VIEW("CONS_VC:ALL.015.Region_Assumptions") -> CONS_VC:ALL.015.Region_Assumptions:-752698549-1942758411 | D1: =_xll.VIEW("CONS_VC:DFS.120.Financial_Results") -> CONS_VC:DFS.120.Financial_Results:-752698549-1075501928 | K1: Value | L1: N/A | M1: =_xll.SUBNM("CONS_VC:ALL.D.Version","","T4") -> T4 | N1: PROD099
B2: =_xll.VIEW("CONS_VC:REV.100.Revenue_Consolidated") -> CONS_VC:REV.100.Revenue_Consolidated:-752698549333326983 | C2: =_xll.VIEW("CONS_VC:ALL.010.Economic_Assumptions") -> CONS_VC:ALL.010.Economic_Assumptions:-752698549-1273320382 | D2: =_xll.VIEW("CONS_VC:DFS.140.Indirect_Cash_Flow") -> CONS_VC:DFS.140.Indirect_Cash_Flow:-752698549946636930 | K2: Total Market | N2: Total Products
B3: =_xll.VIEW("CONS_VC:DFS.100.Profit_and_Loss") -> CONS_VC:DFS.100.Profit_and_Loss:-752698549611332035 | C3: =_xll.VIEW("CONS_VC:DFS.160.Working_Capital") -> CONS_VC:DFS.160.Working_Capital:-752698549-1218331026 | D3: =_xll.VIEW("CONS_VC:ALL.004.Uploads_Status_Planning") -> CONS_VC:ALL.004.Uploads_Status_Planning:-7526985491996989984 | G3: Flag
B4: =_xll.VIEW("CONS_VC:ALL.001.Actual_Control") -> CONS_VC:ALL.001.Actual_Control:-7526985491439511960 | C4: =_xll.VIEW("CONS_VC:DFS.180.Gross_Debt") -> CONS_VC:DFS.180.Gross_Debt:-752698549-1828767557
C5: =_xll.DBRW(Input_Prod_01!$B$4,Input_Prod_01!$D$9,Input_Prod_01!C11,$M$1,$G$3) -> PLAN | D5: =_xll.DBRW(Input_Prod_01!$B$4,Input_Prod_01!$D$9,Input_Prod_01!D11,$M$1,$G$3) -> PLAN | E5: =_xll.DBRW(Input_Prod_01!$B$4,Input_Prod_01!$D$9,Input_Prod_01!E11,$M$1,$G$3) -> PLAN | F5: =_xll.DBRW(Input_Prod_01!$B$4,Input_Prod_01!$D$9,Input_Prod_01!F11,$M$1,$G$3) -> PLAN | G5: =_xll.DBRW(Input_Prod_01!$B$4,Input_Prod_01!$D$9,Input_Prod_01!G11,$M$1,$G$3) -> PLAN | H5: =_xll.DBRW(Input_Prod_01!$B$4,Input_Prod_01!$D$9,Input_Prod_01!H11,$M$1,$G$3) -> PLAN | I5: =_xll.DBRW(Input_Prod_01!$B$4,Input_Prod_01!$D$9,Input_Prod_01!I11,$M$1,$G$3) -> PLAN | J5: =_xll.DBRW(Input_Prod_01!$B$4,Input_Prod_01!$D$9,Input_Prod_01!J11,$M$1,$G$3) -> PLAN | ... N5: =_xll.DBRW(Input_Prod_01!$B$4,Input_Prod_01!$D$9,Input_Prod_01!N11,$M$1,$G$3) -> PLAN
L7: System Input Status: | N7: =_xll.DBRW($D$3,$M$1,$J$9,"Status") -> Closed
B8: GLOBAL ASSUMPTIONS
C9: Year: | D9: =_xll.SUBNM("CONS_VC:ALL.D.Year","SYS_Picklist","2026","MEMBER_NAME") -> 2026 | F9: Currency: | G9: =_xll.SUBNM("CONS_VC:ALL.D.Currency","PAX","USD","Nome alternativo") -> USD | I9: Region: | J9: =_xll.SUBNM("CONS_VC:ALL.D.Region","Nível 0","VCNA","MEMBER_NAME") -> VCNA
C11: 01 | D11: 02 | E11: 03 | F11: 04 | G11: 05 | H11: 06 | I11: 07 | J11: 08 | K11: 09 | L11: 10 | M11: 11 | N11: 12
C12: =$D$9&"."&C11 -> 2026.01 | D12: =$D$9&"."&D11 -> 2026.02 | E12: =$D$9&"."&E11 -> 2026.03 | F12: =$D$9&"."&F11 -> 2026.04 | G12: =$D$9&"."&G11 -> 2026.05 | H12: =$D$9&"."&H11 -> 2026.06 | I12: =$D$9&"."&I11 -> 2026.07 | J12: =$D$9&"."&J11 -> 2026.08 | ... N12: =$D$9&"."&N11 -> 2026.12
B13: Begining FX Rate R$/US$ | C13: =_xll.DBRW($C$2,Input_Prod_01!$D$9,Input_Prod_01!$C$11,$M$1,$B13,$K$1) -> 0 | D13: =_xll.DBRW($C$2,Input_Prod_01!$D$9,Input_Prod_01!$C$11,$M$1,$B13,$K$1) -> 0 | E13: =_xll.DBRW($C$2,Input_Prod_01!$D$9,Input_Prod_01!$C$11,$M$1,$B13,$K$1) -> 0 | F13: =_xll.DBRW($C$2,Input_Prod_01!$D$9,Input_Prod_01!$C$11,$M$1,$B13,$K$1) -> 0 | G13: =_xll.DBRW($C$2,Input_Prod_01!$D$9,Input_Prod_01!$C$11,$M$1,$B13,$K$1) -> 0 | H13: =_xll.DBRW($C$2,Input_Prod_01!$D$9,Input_Prod_01!$C$11,$M$1,$B13,$K$1) -> 0 | I13: =_xll.DBRW($C$2,Input_Prod_01!$D$9,Input_Prod_01!$C$11,$M$1,$B13,$K$1) -> 0 | J13: =_xll.DBRW($C$2,Input_Prod_01!$D$9,Input_Prod_01!$C$11,$M$1,$B13,$K$1) -> 0 | ... N13: =_xll.DBRW($C$2,Input_Prod_01!$D$9,Input_Prod_01!$C$11,$M$1,$B13,$K$1) -> 0
B14: Average FX Rate R$/US$ | C14: =_xll.DBRW($C$2,Input_Prod_01!$D$9,Input_Prod_01!$C$11,$M$1,$B14,$K$1) -> 0 | D14: =_xll.DBRW($C$2,Input_Prod_01!$D$9,Input_Prod_01!$C$11,$M$1,$B14,$K$1) -> 0 | E14: =_xll.DBRW($C$2,Input_Prod_01!$D$9,Input_Prod_01!$C$11,$M$1,$B14,$K$1) -> 0 | F14: =_xll.DBRW($C$2,Input_Prod_01!$D$9,Input_Prod_01!$C$11,$M$1,$B14,$K$1) -> 0 | G14: =_xll.DBRW($C$2,Input_Prod_01!$D$9,Input_Prod_01!$C$11,$M$1,$B14,$K$1) -> 0 | H14: =_xll.DBRW($C$2,Input_Prod_01!$D$9,Input_Prod_01!$C$11,$M$1,$B14,$K$1) -> 0 | I14: =_xll.DBRW($C$2,Input_Prod_01!$D$9,Input_Prod_01!$C$11,$M$1,$B14,$K$1) -> 0 | J14: =_xll.DBRW($C$2,Input_Prod_01!$D$9,Input_Prod_01!$C$11,$M$1,$B14,$K$1) -> 0 | ... N14: =_xll.DBRW($C$2,Input_Prod_01!$D$9,Input_Prod_01!$C$11,$M$1,$B14,$K$1) -> 0
B15: Final FX Rate R$/US$ | C15: =_xll.DBRW($C$2,Input_Prod_01!$D$9,Input_Prod_01!$C$11,$M$1,$B15,$K$1) -> 0 | D15: =_xll.DBRW($C$2,Input_Prod_01!$D$9,Input_Prod_01!$C$11,$M$1,$B15,$K$1) -> 0 | E15: =_xll.DBRW($C$2,Input_Prod_01!$D$9,Input_Prod_01!$C$11,$M$1,$B15,$K$1) -> 0 | F15: =_xll.DBRW($C$2,Input_Prod_01!$D$9,Input_Prod_01!$C$11,$M$1,$B15,$K$1) -> 0 | G15: =_xll.DBRW($C$2,Input_Prod_01!$D$9,Input_Prod_01!$C$11,$M$1,$B15,$K$1) -> 0 | H15: =_xll.DBRW($C$2,Input_Prod_01!$D$9,Input_Prod_01!$C$11,$M$1,$B15,$K$1) -> 0 | I15: =_xll.DBRW($C$2,Input_Prod_01!$D$9,Input_Prod_01!$C$11,$M$1,$B15,$K$1) -> 0 | J15: =_xll.DBRW($C$2,Input_Prod_01!$D$9,Input_Prod_01!$C$11,$M$1,$B15,$K$1) -> 0 | ... N15: =_xll.DBRW($C$2,Input_Prod_01!$D$9,Input_Prod_01!$C$11,$M$1,$B15,$K$1) -> 0
B16: Begining FX Rate US$/EUR | C16: =_xll.DBRW($C$2,Input_Prod_01!$D$9,Input_Prod_01!$C$11,$M$1,$B16,$K$1) -> 0 | D16: =_xll.DBRW($C$2,Input_Prod_01!$D$9,Input_Prod_01!$C$11,$M$1,$B16,$K$1) -> 0 | E16: =_xll.DBRW($C$2,Input_Prod_01!$D$9,Input_Prod_01!$C$11,$M$1,$B16,$K$1) -> 0 | F16: =_xll.DBRW($C$2,Input_Prod_01!$D$9,Input_Prod_01!$C$11,$M$1,$B16,$K$1) -> 0 | G16: =_xll.DBRW($C$2,Input_Prod_01!$D$9,Input_Prod_01!$C$11,$M$1,$B16,$K$1) -> 0 | H16: =_xll.DBRW($C$2,Input_Prod_01!$D$9,Input_Prod_01!$C$11,$M$1,$B16,$K$1) -> 0 | I16: =_xll.DBRW($C$2,Input_Prod_01!$D$9,Input_Prod_01!$C$11,$M$1,$B16,$K$1) -> 0 | J16: =_xll.DBRW($C$2,Input_Prod_01!$D$9,Input_Prod_01!$C$11,$M$1,$B16,$K$1) -> 0 | ... N16: =_xll.DBRW($C$2,Input_Prod_01!$D$9,Input_Prod_01!$C$11,$M$1,$B16,$K$1) -> 0
B17: Average FX Rate US$/EUR | C17: =_xll.DBRW($C$2,Input_Prod_01!$D$9,Input_Prod_01!$C$11,$M$1,$B17,$K$1) -> 5 | D17: =_xll.DBRW($C$2,Input_Prod_01!$D$9,Input_Prod_01!$C$11,$M$1,$B17,$K$1) -> 5 | E17: =_xll.DBRW($C$2,Input_Prod_01!$D$9,Input_Prod_01!$C$11,$M$1,$B17,$K$1) -> 5 | F17: =_xll.DBRW($C$2,Input_Prod_01!$D$9,Input_Prod_01!$C$11,$M$1,$B17,$K$1) -> 5 | G17: =_xll.DBRW($C$2,Input_Prod_01!$D$9,Input_Prod_01!$C$11,$M$1,$B17,$K$1) -> 5 | H17: =_xll.DBRW($C$2,Input_Prod_01!$D$9,Input_Prod_01!$C$11,$M$1,$B17,$K$1) -> 5 | I17: =_xll.DBRW($C$2,Input_Prod_01!$D$9,Input_Prod_01!$C$11,$M$1,$B17,$K$1) -> 5 | J17: =_xll.DBRW($C$2,Input_Prod_01!$D$9,Input_Prod_01!$C$11,$M$1,$B17,$K$1) -> 5 | ... N17: =_xll.DBRW($C$2,Input_Prod_01!$D$9,Input_Prod_01!$C$11,$M$1,$B17,$K$1) -> 5
B18: Final FX Rate US$/EUR | C18: =_xll.DBRW($C$2,Input_Prod_01!$D$9,Input_Prod_01!$C$11,$M$1,$B18,$K$1) -> 0 | D18: =_xll.DBRW($C$2,Input_Prod_01!$D$9,Input_Prod_01!$C$11,$M$1,$B18,$K$1) -> 0 | E18: =_xll.DBRW($C$2,Input_Prod_01!$D$9,Input_Prod_01!$C$11,$M$1,$B18,$K$1) -> 0 | F18: =_xll.DBRW($C$2,Input_Prod_01!$D$9,Input_Prod_01!$C$11,$M$1,$B18,$K$1) -> 0 | G18: =_xll.DBRW($C$2,Input_Prod_01!$D$9,Input_Prod_01!$C$11,$M$1,$B18,$K$1) -> 0 | H18: =_xll.DBRW($C$2,Input_Prod_01!$D$9,Input_Prod_01!$C$11,$M$1,$B18,$K$1) -> 0 | I18: =_xll.DBRW($C$2,Input_Prod_01!$D$9,Input_Prod_01!$C$11,$M$1,$B18,$K$1) -> 0 | J18: =_xll.DBRW($C$2,Input_Prod_01!$D$9,Input_Prod_01!$C$11,$M$1,$B18,$K$1) -> 0 | ... N18: =_xll.DBRW($C$2,Input_Prod_01!$D$9,Input_Prod_01!$C$11,$M$1,$B18,$K$1) -> 0
B19: Câmbio Inicial UYU$/US$ | C19: =_xll.DBRW($C$2,Input_Prod_01!$D$9,Input_Prod_01!$C$11,$M$1,$B19,$K$1) -> 0 | D19: =_xll.DBRW($C$2,Input_Prod_01!$D$9,Input_Prod_01!$C$11,$M$1,$B19,$K$1) -> 0 | E19: =_xll.DBRW($C$2,Input_Prod_01!$D$9,Input_Prod_01!$C$11,$M$1,$B19,$K$1) -> 0 | F19: =_xll.DBRW($C$2,Input_Prod_01!$D$9,Input_Prod_01!$C$11,$M$1,$B19,$K$1) -> 0 | G19: =_xll.DBRW($C$2,Input_Prod_01!$D$9,Input_Prod_01!$C$11,$M$1,$B19,$K$1) -> 0 | H19: =_xll.DBRW($C$2,Input_Prod_01!$D$9,Input_Prod_01!$C$11,$M$1,$B19,$K$1) -> 0 | I19: =_xll.DBRW($C$2,Input_Prod_01!$D$9,Input_Prod_01!$C$11,$M$1,$B19,$K$1) -> 0 | J19: =_xll.DBRW($C$2,Input_Prod_01!$D$9,Input_Prod_01!$C$11,$M$1,$B19,$K$1) -> 0 | ... N19: =_xll.DBRW($C$2,Input_Prod_01!$D$9,Input_Prod_01!$C$11,$M$1,$B19,$K$1) -> 0
B20: Câmbio Médio UYU$/US$ | C20: =_xll.DBRW($C$2,Input_Prod_01!$D$9,Input_Prod_01!$C$11,$M$1,$B20,$K$1) -> 0 | D20: =_xll.DBRW($C$2,Input_Prod_01!$D$9,Input_Prod_01!$C$11,$M$1,$B20,$K$1) -> 0 | E20: =_xll.DBRW($C$2,Input_Prod_01!$D$9,Input_Prod_01!$C$11,$M$1,$B20,$K$1) -> 0 | F20: =_xll.DBRW($C$2,Input_Prod_01!$D$9,Input_Prod_01!$C$11,$M$1,$B20,$K$1) -> 0 | G20: =_xll.DBRW($C$2,Input_Prod_01!$D$9,Input_Prod_01!$C$11,$M$1,$B20,$K$1) -> 0 | H20: =_xll.DBRW($C$2,Input_Prod_01!$D$9,Input_Prod_01!$C$11,$M$1,$B20,$K$1) -> 0 | I20: =_xll.DBRW($C$2,Input_Prod_01!$D$9,Input_Prod_01!$C$11,$M$1,$B20,$K$1) -> 0 | J20: =_xll.DBRW($C$2,Input_Prod_01!$D$9,Input_Prod_01!$C$11,$M$1,$B20,$K$1) -> 0 | ... N20: =_xll.DBRW($C$2,Input_Prod_01!$D$9,Input_Prod_01!$C$11,$M$1,$B20,$K$1) -> 0
B21: Câmbio Final UYU$/US$ | C21: =_xll.DBRW($C$2,Input_Prod_01!$D$9,Input_Prod_01!$C$11,$M$1,$B21,$K$1) -> 0 | D21: =_xll.DBRW($C$2,Input_Prod_01!$D$9,Input_Prod_01!$C$11,$M$1,$B21,$K$1) -> 0 | E21: =_xll.DBRW($C$2,Input_Prod_01!$D$9,Input_Prod_01!$C$11,$M$1,$B21,$K$1) -> 0 | F21: =_xll.DBRW($C$2,Input_Prod_01!$D$9,Input_Prod_01!$C$11,$M$1,$B21,$K$1) -> 0 | G21: =_xll.DBRW($C$2,Input_Prod_01!$D$9,Input_Prod_01!$C$11,$M$1,$B21,$K$1) -> 0 | H21: =_xll.DBRW($C$2,Input_Prod_01!$D$9,Input_Prod_01!$C$11,$M$1,$B21,$K$1) -> 0 | I21: =_xll.DBRW($C$2,Input_Prod_01!$D$9,Input_Prod_01!$C$11,$M$1,$B21,$K$1) -> 0 | J21: =_xll.DBRW($C$2,Input_Prod_01!$D$9,Input_Prod_01!$C$11,$M$1,$B21,$K$1) -> 0 | ... N21: =_xll.DBRW($C$2,Input_Prod_01!$D$9,Input_Prod_01!$C$11,$M$1,$B21,$K$1) -> 0
B22: Câmbio Inicial ARS$/US$ | C22: =_xll.DBRW($C$2,Input_Prod_01!$D$9,Input_Prod_01!$C$11,$M$1,$B22,$K$1) -> 0 | D22: =_xll.DBRW($C$2,Input_Prod_01!$D$9,Input_Prod_01!$C$11,$M$1,$B22,$K$1) -> 0 | E22: =_xll.DBRW($C$2,Input_Prod_01!$D$9,Input_Prod_01!$C$11,$M$1,$B22,$K$1) -> 0 | F22: =_xll.DBRW($C$2,Input_Prod_01!$D$9,Input_Prod_01!$C$11,$M$1,$B22,$K$1) -> 0 | G22: =_xll.DBRW($C$2,Input_Prod_01!$D$9,Input_Prod_01!$C$11,$M$1,$B22,$K$1) -> 0 | H22: =_xll.DBRW($C$2,Input_Prod_01!$D$9,Input_Prod_01!$C$11,$M$1,$B22,$K$1) -> 0 | I22: =_xll.DBRW($C$2,Input_Prod_01!$D$9,Input_Prod_01!$C$11,$M$1,$B22,$K$1) -> 0 | J22: =_xll.DBRW($C$2,Input_Prod_01!$D$9,Input_Prod_01!$C$11,$M$1,$B22,$K$1) -> 0 | ... N22: =_xll.DBRW($C$2,Input_Prod_01!$D$9,Input_Prod_01!$C$11,$M$1,$B22,$K$1) -> 0
B23: Câmbio Médio ARS$/US$ | C23: =_xll.DBRW($C$2,Input_Prod_01!$D$9,Input_Prod_01!$C$11,$M$1,$B23,$K$1) -> 0 | D23: =_xll.DBRW($C$2,Input_Prod_01!$D$9,Input_Prod_01!$C$11,$M$1,$B23,$K$1) -> 0 | E23: =_xll.DBRW($C$2,Input_Prod_01!$D$9,Input_Prod_01!$C$11,$M$1,$B23,$K$1) -> 0 | F23: =_xll.DBRW($C$2,Input_Prod_01!$D$9,Input_Prod_01!$C$11,$M$1,$B23,$K$1) -> 0 | G23: =_xll.DBRW($C$2,Input_Prod_01!$D$9,Input_Prod_01!$C$11,$M$1,$B23,$K$1) -> 0 | H23: =_xll.DBRW($C$2,Input_Prod_01!$D$9,Input_Prod_01!$C$11,$M$1,$B23,$K$1) -> 0 | I23: =_xll.DBRW($C$2,Input_Prod_01!$D$9,Input_Prod_01!$C$11,$M$1,$B23,$K$1) -> 0 | J23: =_xll.DBRW($C$2,Input_Prod_01!$D$9,Input_Prod_01!$C$11,$M$1,$B23,$K$1) -> 0 | ... N23: =_xll.DBRW($C$2,Input_Prod_01!$D$9,Input_Prod_01!$C$11,$M$1,$B23,$K$1) -> 0
B24: Câmbio Final ARS$/US$ | C24: =_xll.DBRW($C$2,Input_Prod_01!$D$9,Input_Prod_01!$C$11,$M$1,$B24,$K$1) -> 0 | D24: =_xll.DBRW($C$2,Input_Prod_01!$D$9,Input_Prod_01!$C$11,$M$1,$B24,$K$1) -> 0 | E24: =_xll.DBRW($C$2,Input_Prod_01!$D$9,Input_Prod_01!$C$11,$M$1,$B24,$K$1) -> 0 | F24: =_xll.DBRW($C$2,Input_Prod_01!$D$9,Input_Prod_01!$C$11,$M$1,$B24,$K$1) -> 0 | G24: =_xll.DBRW($C$2,Input_Prod_01!$D$9,Input_Prod_01!$C$11,$M$1,$B24,$K$1) -> 0 | H24: =_xll.DBRW($C$2,Input_Prod_01!$D$9,Input_Prod_01!$C$11,$M$1,$B24,$K$1) -> 0 | I24: =_xll.DBRW($C$2,Input_Prod_01!$D$9,Input_Prod_01!$C$11,$M$1,$B24,$K$1) -> 0 | J24: =_xll.DBRW($C$2,Input_Prod_01!$D$9,Input_Prod_01!$C$11,$M$1,$B24,$K$1) -> 0 | ... N24: =_xll.DBRW($C$2,Input_Prod_01!$D$9,Input_Prod_01!$C$11,$M$1,$B24,$K$1) -> 0
... B27: Number of Days | C27: =_xll.DBRW($C$2,Input_Prod_01!$D$9,Input_Prod_01!$C$11,$M$1,$B27,$K$1) -> 31 | D27: =_xll.DBRW($C$2,Input_Prod_01!$D$9,Input_Prod_01!$C$11,$M$1,$B27,$K$1) -> 31 | E27: =_xll.DBRW($C$2,Input_Prod_01!$D$9,Input_Prod_01!$C$11,$M$1,$B27,$K$1) -> 31 | F27: =_xll.DBRW($C$2,Input_Prod_01!$D$9,Input_Prod_01!$C$11,$M$1,$B27,$K$1) -> 31 | G27: =_xll.DBRW($C$2,Input_Prod_01!$D$9,Input_Prod_01!$C$11,$M$1,$B27,$K$1) -> 31 | H27: =_xll.DBRW($C$2,Input_Prod_01!$D$9,Input_Prod_01!$C$11,$M$1,$B27,$K$1) -> 31 | I27: =_xll.DBRW($C$2,Input_Prod_01!$D$9,Input_Prod_01!$C$11,$M$1,$B27,$K$1) -> 31 | J27: =_xll.DBRW($C$2,Input_Prod_01!$D$9,Input_Prod_01!$C$11,$M$1,$B27,$K$1) -> 31 | ... N27: =_xll.DBRW($C$2,Input_Prod_01!$D$9,Input_Prod_01!$C$11,$M$1,$B27,$K$1) -> 31
B30: NET REVENUES | D30: Products: | E30: =_xll.SUBNM("CONS_VC:ALL.D.Products","Nivel_0","PRODCE010 - Cement","Código e Descrição") -> PRODCE010 - Cement
C33: =$D$9&"."&C11 -> 2026.01 | D33: =$D$9&"."&D11 -> 2026.02 | E33: =$D$9&"."&E11 -> 2026.03 | F33: =$D$9&"."&F11 -> 2026.04 | G33: =$D$9&"."&G11 -> 2026.05 | H33: =$D$9&"."&H11 -> 2026.06 | I33: =$D$9&"."&I11 -> 2026.07 | J33: =$D$9&"."&J11 -> 2026.08 | ... N33: =$D$9&"."&N11 -> 2026.12
B34: Reference Price [$/ton] | C34: =_xll.DBRW($B$1,Input_Prod_01!$D$9,Input_Prod_01!C$11,$M$1,Input_Prod_01!$G$9,$J$9,Input_Prod_01!$E$30,Input_Prod_01!$B34,$L$1,$K$1) -> 0 | D34: =_xll.DBRW($B$1,Input_Prod_01!$D$9,Input_Prod_01!D$11,$M$1,Input_Prod_01!$G$9,$J$9,Input_Prod_01!$E$30,Input_Prod_01!$B34,$L$1,$K$1) -> 0 | E34: =_xll.DBRW($B$1,Input_Prod_01!$D$9,Input_Prod_01!E$11,$M$1,Input_Prod_01!$G$9,$J$9,Input_Prod_01!$E$30,Input_Prod_01!$B34,$L$1,$K$1) -> 0 | F34: =_xll.DBRW($B$1,Input_Prod_01!$D$9,Input_Prod_01!F$11,$M$1,Input_Prod_01!$G$9,$J$9,Input_Prod_01!$E$30,Input_Prod_01!$B34,$L$1,$K$1) -> 0 | G34: =_xll.DBRW($B$1,Input_Prod_01!$D$9,Input_Prod_01!G$11,$M$1,Input_Prod_01!$G$9,$J$9,Input_Prod_01!$E$30,Input_Prod_01!$B34,$L$1,$K$1) -> 0 | H34: =_xll.DBRW($B$1,Input_Prod_01!$D$9,Input_Prod_01!H$11,$M$1,Input_Prod_01!$G$9,$J$9,Input_Prod_01!$E$30,Input_Prod_01!$B34,$L$1,$K$1) -> 0 | I34: =_xll.DBRW($B$1,Input_Prod_01!$D$9,Input_Prod_01!I$11,$M$1,Input_Prod_01!$G$9,$J$9,Input_Prod_01!$E$30,Input_Prod_01!$B34,$L$1,$K$1) -> 0 | J34: =_xll.DBRW($B$1,Input_Prod_01!$D$9,Input_Prod_01!J$11,$M$1,Input_Prod_01!$G$9,$J$9,Input_Prod_01!$E$30,Input_Prod_01!$B34,$L$1,$K$1) -> 0 | ... N34: =_xll.DBRW($B$1,Input_Prod_01!$D$9,Input_Prod_01!N$11,$M$1,Input_Prod_01!$G$9,$J$9,Input_Prod_01!$E$30,Input_Prod_01!$B34,$L$1,$K$1) -> 0
B35: Local Market Sales Volume [kt] | C35: =_xll.DBRW($B$1,Input_Prod_01!$D$9,Input_Prod_01!C$11,$M$1,Input_Prod_01!$G$9,$J$9,Input_Prod_01!$E$30,Input_Prod_01!$B35,$L$1,$K$1) -> 0 | D35: =_xll.DBRW($B$1,Input_Prod_01!$D$9,Input_Prod_01!D$11,$M$1,Input_Prod_01!$G$9,$J$9,Input_Prod_01!$E$30,Input_Prod_01!$B35,$L$1,$K$1) -> 0 | E35: =_xll.DBRW($B$1,Input_Prod_01!$D$9,Input_Prod_01!E$11,$M$1,Input_Prod_01!$G$9,$J$9,Input_Prod_01!$E$30,Input_Prod_01!$B35,$L$1,$K$1) -> 0 | F35: =_xll.DBRW($B$1,Input_Prod_01!$D$9,Input_Prod_01!F$11,$M$1,Input_Prod_01!$G$9,$J$9,Input_Prod_01!$E$30,Input_Prod_01!$B35,$L$1,$K$1) -> 0 | G35: =_xll.DBRW($B$1,Input_Prod_01!$D$9,Input_Prod_01!G$11,$M$1,Input_Prod_01!$G$9,$J$9,Input_Prod_01!$E$30,Input_Prod_01!$B35,$L$1,$K$1) -> 0 | H35: =_xll.DBRW($B$1,Input_Prod_01!$D$9,Input_Prod_01!H$11,$M$1,Input_Prod_01!$G$9,$J$9,Input_Prod_01!$E$30,Input_Prod_01!$B35,$L$1,$K$1) -> 0 | I35: =_xll.DBRW($B$1,Input_Prod_01!$D$9,Input_Prod_01!I$11,$M$1,Input_Prod_01!$G$9,$J$9,Input_Prod_01!$E$30,Input_Prod_01!$B35,$L$1,$K$1) -> 0 | J35: =_xll.DBRW($B$1,Input_Prod_01!$D$9,Input_Prod_01!J$11,$M$1,Input_Prod_01!$G$9,$J$9,Input_Prod_01!$E$30,Input_Prod_01!$B35,$L$1,$K$1) -> 0 | ... N35: =_xll.DBRW($B$1,Input_Prod_01!$D$9,Input_Prod_01!N$11,$M$1,Input_Prod_01!$G$9,$J$9,Input_Prod_01!$E$30,Input_Prod_01!$B35,$L$1,$K$1) -> 0
B36: Export Market Sales Volume [kt] | C36: =_xll.DBRW($B$1,Input_Prod_01!$D$9,Input_Prod_01!C$11,$M$1,Input_Prod_01!$G$9,$J$9,Input_Prod_01!$E$30,Input_Prod_01!$B36,$L$1,$K$1) -> 207.21655 | D36: =_xll.DBRW($B$1,Input_Prod_01!$D$9,Input_Prod_01!D$11,$M$1,Input_Prod_01!$G$9,$J$9,Input_Prod_01!$E$30,Input_Prod_01!$B36,$L$1,$K$1) -> 244.64194 | E36: =_xll.DBRW($B$1,Input_Prod_01!$D$9,Input_Prod_01!E$11,$M$1,Input_Prod_01!$G$9,$J$9,Input_Prod_01!$E$30,Input_Prod_01!$B36,$L$1,$K$1) -> 362.2005 | F36: =_xll.DBRW($B$1,Input_Prod_01!$D$9,Input_Prod_01!F$11,$M$1,Input_Prod_01!$G$9,$J$9,Input_Prod_01!$E$30,Input_Prod_01!$B36,$L$1,$K$1) -> 503.21174 | G36: =_xll.DBRW($B$1,Input_Prod_01!$D$9,Input_Prod_01!G$11,$M$1,Input_Prod_01!$G$9,$J$9,Input_Prod_01!$E$30,Input_Prod_01!$B36,$L$1,$K$1) -> 603.05328 | H36: =_xll.DBRW($B$1,Input_Prod_01!$D$9,Input_Prod_01!H$11,$M$1,Input_Prod_01!$G$9,$J$9,Input_Prod_01!$E$30,Input_Prod_01!$B36,$L$1,$K$1) -> 680.11963 | I36: =_xll.DBRW($B$1,Input_Prod_01!$D$9,Input_Prod_01!I$11,$M$1,Input_Prod_01!$G$9,$J$9,Input_Prod_01!$E$30,Input_Prod_01!$B36,$L$1,$K$1) -> 655.73708 | J36: =_xll.DBRW($B$1,Input_Prod_01!$D$9,Input_Prod_01!J$11,$M$1,Input_Prod_01!$G$9,$J$9,Input_Prod_01!$E$30,Input_Prod_01!$B36,$L$1,$K$1) -> 619.07454 | ... N36: =_xll.DBRW($B$1,Input_Prod_01!$D$9,Input_Prod_01!N$11,$M$1,Input_Prod_01!$G$9,$J$9,Input_Prod_01!$E$30,Input_Prod_01!$B36,$L$1,$K$1) -> 329.92947
B37: Third Part Sales Volume [kt] | C37: =_xll.DBRW($B$1,Input_Prod_01!$D$9,Input_Prod_01!C$11,$M$1,Input_Prod_01!$G$9,$J$9,Input_Prod_01!$E$30,Input_Prod_01!$B37,$L$1,$K$1) -> 0 | D37: =_xll.DBRW($B$1,Input_Prod_01!$D$9,Input_Prod_01!D$11,$M$1,Input_Prod_01!$G$9,$J$9,Input_Prod_01!$E$30,Input_Prod_01!$B37,$L$1,$K$1) -> 0 | E37: =_xll.DBRW($B$1,Input_Prod_01!$D$9,Input_Prod_01!E$11,$M$1,Input_Prod_01!$G$9,$J$9,Input_Prod_01!$E$30,Input_Prod_01!$B37,$L$1,$K$1) -> 0 | F37: =_xll.DBRW($B$1,Input_Prod_01!$D$9,Input_Prod_01!F$11,$M$1,Input_Prod_01!$G$9,$J$9,Input_Prod_01!$E$30,Input_Prod_01!$B37,$L$1,$K$1) -> 0 | G37: =_xll.DBRW($B$1,Input_Prod_01!$D$9,Input_Prod_01!G$11,$M$1,Input_Prod_01!$G$9,$J$9,Input_Prod_01!$E$30,Input_Prod_01!$B37,$L$1,$K$1) -> 0 | H37: =_xll.DBRW($B$1,Input_Prod_01!$D$9,Input_Prod_01!H$11,$M$1,Input_Prod_01!$G$9,$J$9,Input_Prod_01!$E$30,Input_Prod_01!$B37,$L$1,$K$1) -> 0 | I37: =_xll.DBRW($B$1,Input_Prod_01!$D$9,Input_Prod_01!I$11,$M$1,Input_Prod_01!$G$9,$J$9,Input_Prod_01!$E$30,Input_Prod_01!$B37,$L$1,$K$1) -> 0 | J37: =_xll.DBRW($B$1,Input_Prod_01!$D$9,Input_Prod_01!J$11,$M$1,Input_Prod_01!$G$9,$J$9,Input_Prod_01!$E$30,Input_Prod_01!$B37,$L$1,$K$1) -> 0 | ... N37: =_xll.DBRW($B$1,Input_Prod_01!$D$9,Input_Prod_01!N$11,$M$1,Input_Prod_01!$G$9,$J$9,Input_Prod_01!$E$30,Input_Prod_01!$B37,$L$1,$K$1) -> 0
B38: Local Market Price Premium [$/ton] | C38: =_xll.DBRW($B$1,Input_Prod_01!$D$9,Input_Prod_01!C$11,$M$1,Input_Prod_01!$G$9,$J$9,Input_Prod_01!$E$30,Input_Prod_01!$B38,$L$1,$K$1) -> 0 | D38: =_xll.DBRW($B$1,Input_Prod_01!$D$9,Input_Prod_01!D$11,$M$1,Input_Prod_01!$G$9,$J$9,Input_Prod_01!$E$30,Input_Prod_01!$B38,$L$1,$K$1) -> 0 | E38: =_xll.DBRW($B$1,Input_Prod_01!$D$9,Input_Prod_01!E$11,$M$1,Input_Prod_01!$G$9,$J$9,Input_Prod_01!$E$30,Input_Prod_01!$B38,$L$1,$K$1) -> 0 | F38: =_xll.DBRW($B$1,Input_Prod_01!$D$9,Input_Prod_01!F$11,$M$1,Input_Prod_01!$G$9,$J$9,Input_Prod_01!$E$30,Input_Prod_01!$B38,$L$1,$K$1) -> 0 | G38: =_xll.DBRW($B$1,Input_Prod_01!$D$9,Input_Prod_01!G$11,$M$1,Input_Prod_01!$G$9,$J$9,Input_Prod_01!$E$30,Input_Prod_01!$B38,$L$1,$K$1) -> 0 | H38: =_xll.DBRW($B$1,Input_Prod_01!$D$9,Input_Prod_01!H$11,$M$1,Input_Prod_01!$G$9,$J$9,Input_Prod_01!$E$30,Input_Prod_01!$B38,$L$1,$K$1) -> 0 | I38: =_xll.DBRW($B$1,Input_Prod_01!$D$9,Input_Prod_01!I$11,$M$1,Input_Prod_01!$G$9,$J$9,Input_Prod_01!$E$30,Input_Prod_01!$B38,$L$1,$K$1) -> 0 | J38: =_xll.DBRW($B$1,Input_Prod_01!$D$9,Input_Prod_01!J$11,$M$1,Input_Prod_01!$G$9,$J$9,Input_Prod_01!$E$30,Input_Prod_01!$B38,$L$1,$K$1) -> 0 | ... N38: =_xll.DBRW($B$1,Input_Prod_01!$D$9,Input_Prod_01!N$11,$M$1,Input_Prod_01!$G$9,$J$9,Input_Prod_01!$E$30,Input_Prod_01!$B38,$L$1,$K$1) -> 0
B39: Export Market Price Premium [$/ton] | C39: =_xll.DBRW($B$1,Input_Prod_01!$D$9,Input_Prod_01!C$11,$M$1,Input_Prod_01!$G$9,$J$9,Input_Prod_01!$E$30,Input_Prod_01!$B39,$L$1,$K$1) -> 155.32501 | D39: =_xll.DBRW($B$1,Input_Prod_01!$D$9,Input_Prod_01!D$11,$M$1,Input_Prod_01!$G$9,$J$9,Input_Prod_01!$E$30,Input_Prod_01!$B39,$L$1,$K$1) -> 155.54341 | E39: =_xll.DBRW($B$1,Input_Prod_01!$D$9,Input_Prod_01!E$11,$M$1,Input_Prod_01!$G$9,$J$9,Input_Prod_01!$E$30,Input_Prod_01!$B39,$L$1,$K$1) -> 154.10349 | F39: =_xll.DBRW($B$1,Input_Prod_01!$D$9,Input_Prod_01!F$11,$M$1,Input_Prod_01!$G$9,$J$9,Input_Prod_01!$E$30,Input_Prod_01!$B39,$L$1,$K$1) -> 156.28361 | G39: =_xll.DBRW($B$1,Input_Prod_01!$D$9,Input_Prod_01!G$11,$M$1,Input_Prod_01!$G$9,$J$9,Input_Prod_01!$E$30,Input_Prod_01!$B39,$L$1,$K$1) -> 155.93802 | H39: =_xll.DBRW($B$1,Input_Prod_01!$D$9,Input_Prod_01!H$11,$M$1,Input_Prod_01!$G$9,$J$9,Input_Prod_01!$E$30,Input_Prod_01!$B39,$L$1,$K$1) -> 157.38036 | I39: =_xll.DBRW($B$1,Input_Prod_01!$D$9,Input_Prod_01!I$11,$M$1,Input_Prod_01!$G$9,$J$9,Input_Prod_01!$E$30,Input_Prod_01!$B39,$L$1,$K$1) -> 156.82383 | J39: =_xll.DBRW($B$1,Input_Prod_01!$D$9,Input_Prod_01!J$11,$M$1,Input_Prod_01!$G$9,$J$9,Input_Prod_01!$E$30,Input_Prod_01!$B39,$L$1,$K$1) -> 158.55054 | ... N39: =_xll.DBRW($B$1,Input_Prod_01!$D$9,Input_Prod_01!N$11,$M$1,Input_Prod_01!$G$9,$J$9,Input_Prod_01!$E$30,Input_Prod_01!$B39,$L$1,$K$1) -> 153.02143
B40: % Operational Tax | C40: =_xll.DBRW($B$1,Input_Prod_01!$D$9,Input_Prod_01!C$11,$M$1,Input_Prod_01!$G$9,$J$9,Input_Prod_01!$E$30,Input_Prod_01!$B40,$L$1,$K$1) -> 0 | D40: =_xll.DBRW($B$1,Input_Prod_01!$D$9,Input_Prod_01!D$11,$M$1,Input_Prod_01!$G$9,$J$9,Input_Prod_01!$E$30,Input_Prod_01!$B40,$L$1,$K$1) -> 0 | E40: =_xll.DBRW($B$1,Input_Prod_01!$D$9,Input_Prod_01!E$11,$M$1,Input_Prod_01!$G$9,$J$9,Input_Prod_01!$E$30,Input_Prod_01!$B40,$L$1,$K$1) -> 0 | F40: =_xll.DBRW($B$1,Input_Prod_01!$D$9,Input_Prod_01!F$11,$M$1,Input_Prod_01!$G$9,$J$9,Input_Prod_01!$E$30,Input_Prod_01!$B40,$L$1,$K$1) -> 0 | G40: =_xll.DBRW($B$1,Input_Prod_01!$D$9,Input_Prod_01!G$11,$M$1,Input_Prod_01!$G$9,$J$9,Input_Prod_01!$E$30,Input_Prod_01!$B40,$L$1,$K$1) -> 0 | H40: =_xll.DBRW($B$1,Input_Prod_01!$D$9,Input_Prod_01!H$11,$M$1,Input_Prod_01!$G$9,$J$9,Input_Prod_01!$E$30,Input_Prod_01!$B40,$L$1,$K$1) -> 0 | I40: =_xll.DBRW($B$1,Input_Prod_01!$D$9,Input_Prod_01!I$11,$M$1,Input_Prod_01!$G$9,$J$9,Input_Prod_01!$E$30,Input_Prod_01!$B40,$L$1,$K$1) -> 0 | J40: =_xll.DBRW($B$1,Input_Prod_01!$D$9,Input_Prod_01!J$11,$M$1,Input_Prod_01!$G$9,$J$9,Input_Prod_01!$E$30,Input_Prod_01!$B40,$L$1,$K$1) -> 0 | ... N40: =_xll.DBRW($B$1,Input_Prod_01!$D$9,Input_Prod_01!N$11,$M$1,Input_Prod_01!$G$9,$J$9,Input_Prod_01!$E$30,Input_Prod_01!$B40,$L$1,$K$1) -> 0
B41: Gross Revenue [$MM] | C41: =_xll.DBRW($B$2,Input_Prod_01!$D$9,Input_Prod_01!C$11,$M$1,Input_Prod_01!$G$9,$J$9,$E$30,$K$2,$B$41) -> 32.185912 | D41: =_xll.DBRW($B$2,Input_Prod_01!$D$9,Input_Prod_01!D$11,$M$1,Input_Prod_01!$G$9,$J$9,$E$30,$K$2,$B$41) -> 38.052441 | E41: =_xll.DBRW($B$2,Input_Prod_01!$D$9,Input_Prod_01!E$11,$M$1,Input_Prod_01!$G$9,$J$9,$E$30,$K$2,$B$41) -> 55.816362 | F41: =_xll.DBRW($B$2,Input_Prod_01!$D$9,Input_Prod_01!F$11,$M$1,Input_Prod_01!$G$9,$J$9,$E$30,$K$2,$B$41) -> 78.643745 | G41: =_xll.DBRW($B$2,Input_Prod_01!$D$9,Input_Prod_01!G$11,$M$1,Input_Prod_01!$G$9,$J$9,$E$30,$K$2,$B$41) -> 94.038934 | H41: =_xll.DBRW($B$2,Input_Prod_01!$D$9,Input_Prod_01!H$11,$M$1,Input_Prod_01!$G$9,$J$9,$E$30,$K$2,$B$41) -> 107.03747 | I41: =_xll.DBRW($B$2,Input_Prod_01!$D$9,Input_Prod_01!I$11,$M$1,Input_Prod_01!$G$9,$J$9,$E$30,$K$2,$B$41) -> 102.8352 | J41: =_xll.DBRW($B$2,Input_Prod_01!$D$9,Input_Prod_01!J$11,$M$1,Input_Prod_01!$G$9,$J$9,$E$30,$K$2,$B$41) -> 98.154603 | ... N41: =_xll.DBRW($B$2,Input_Prod_01!$D$9,Input_Prod_01!N$11,$M$1,Input_Prod_01!$G$9,$J$9,$E$30,$K$2,$B$41) -> 50.48628
B42: Net Revenue [$MM] | C42: =_xll.DBRW($B$2,Input_Prod_01!$D$9,Input_Prod_01!C$11,$M$1,Input_Prod_01!$G$9,$J$9,$E$30,$K$2,$B$42) -> 32.185912 | D42: =_xll.DBRW($B$2,Input_Prod_01!$D$9,Input_Prod_01!D$11,$M$1,Input_Prod_01!$G$9,$J$9,$E$30,$K$2,$B$42) -> 38.052441 | E42: =_xll.DBRW($B$2,Input_Prod_01!$D$9,Input_Prod_01!E$11,$M$1,Input_Prod_01!$G$9,$J$9,$E$30,$K$2,$B$42) -> 55.816362 | F42: =_xll.DBRW($B$2,Input_Prod_01!$D$9,Input_Prod_01!F$11,$M$1,Input_Prod_01!$G$9,$J$9,$E$30,$K$2,$B$42) -> 78.643745 | G42: =_xll.DBRW($B$2,Input_Prod_01!$D$9,Input_Prod_01!G$11,$M$1,Input_Prod_01!$G$9,$J$9,$E$30,$K$2,$B$42) -> 94.038934 | H42: =_xll.DBRW($B$2,Input_Prod_01!$D$9,Input_Prod_01!H$11,$M$1,Input_Prod_01!$G$9,$J$9,$E$30,$K$2,$B$42) -> 107.03747 | I42: =_xll.DBRW($B$2,Input_Prod_01!$D$9,Input_Prod_01!I$11,$M$1,Input_Prod_01!$G$9,$J$9,$E$30,$K$2,$B$42) -> 102.8352 | J42: =_xll.DBRW($B$2,Input_Prod_01!$D$9,Input_Prod_01!J$11,$M$1,Input_Prod_01!$G$9,$J$9,$E$30,$K$2,$B$42) -> 98.154603 | ... N42: =_xll.DBRW($B$2,Input_Prod_01!$D$9,Input_Prod_01!N$11,$M$1,Input_Prod_01!$G$9,$J$9,$E$30,$K$2,$B$42) -> 50.48628
B46: CONTRIBUTION MARGIN
C49: =$D$9&"."&C$11 -> 2026.01 | D49: =$D$9&"."&D$11 -> 2026.02 | E49: =$D$9&"."&E$11 -> 2026.03 | F49: =$D$9&"."&F$11 -> 2026.04 | G49: =$D$9&"."&G$11 -> 2026.05 | H49: =$D$9&"."&H$11 -> 2026.06 | I49: =$D$9&"."&I$11 -> 2026.07 | J49: =$D$9&"."&J$11 -> 2026.08 | ... N49: =$D$9&"."&N$11 -> 2026.12
B50: Final Variable Sales Expenses | C50: =_xll.DBRW($B$1,Input_Prod_01!$D$9,Input_Prod_01!C$11,$M$1,Input_Prod_01!$G$9,$J$9,$E$30,Input_Prod_01!$B50,$L$1,$K$1) -> 0 | D50: =_xll.DBRW($B$1,Input_Prod_01!$D$9,Input_Prod_01!D$11,$M$1,Input_Prod_01!$G$9,$J$9,$E$30,Input_Prod_01!$B50,$L$1,$K$1) -> 0 | E50: =_xll.DBRW($B$1,Input_Prod_01!$D$9,Input_Prod_01!E$11,$M$1,Input_Prod_01!$G$9,$J$9,$E$30,Input_Prod_01!$B50,$L$1,$K$1) -> 0 | F50: =_xll.DBRW($B$1,Input_Prod_01!$D$9,Input_Prod_01!F$11,$M$1,Input_Prod_01!$G$9,$J$9,$E$30,Input_Prod_01!$B50,$L$1,$K$1) -> 0 | G50: =_xll.DBRW($B$1,Input_Prod_01!$D$9,Input_Prod_01!G$11,$M$1,Input_Prod_01!$G$9,$J$9,$E$30,Input_Prod_01!$B50,$L$1,$K$1) -> 0 | H50: =_xll.DBRW($B$1,Input_Prod_01!$D$9,Input_Prod_01!H$11,$M$1,Input_Prod_01!$G$9,$J$9,$E$30,Input_Prod_01!$B50,$L$1,$K$1) -> 0 | I50: =_xll.DBRW($B$1,Input_Prod_01!$D$9,Input_Prod_01!I$11,$M$1,Input_Prod_01!$G$9,$J$9,$E$30,Input_Prod_01!$B50,$L$1,$K$1) -> 0 | J50: =_xll.DBRW($B$1,Input_Prod_01!$D$9,Input_Prod_01!J$11,$M$1,Input_Prod_01!$G$9,$J$9,$E$30,Input_Prod_01!$B50,$L$1,$K$1) -> 0 | ... N50: =_xll.DBRW($B$1,Input_Prod_01!$D$9,Input_Prod_01!N$11,$M$1,Input_Prod_01!$G$9,$J$9,$E$30,Input_Prod_01!$B50,$L$1,$K$1) -> 0
B51: Other Variable Costs | C51: =_xll.DBRW($B$1,Input_Prod_01!$D$9,Input_Prod_01!C$11,$M$1,Input_Prod_01!$G$9,$J$9,$E$30,Input_Prod_01!$B51,$L$1,$K$1) -> 9.9428448 | D51: =_xll.DBRW($B$1,Input_Prod_01!$D$9,Input_Prod_01!D$11,$M$1,Input_Prod_01!$G$9,$J$9,$E$30,Input_Prod_01!$B51,$L$1,$K$1) -> 18.330327 | E51: =_xll.DBRW($B$1,Input_Prod_01!$D$9,Input_Prod_01!E$11,$M$1,Input_Prod_01!$G$9,$J$9,$E$30,Input_Prod_01!$B51,$L$1,$K$1) -> 16.901681 | F51: =_xll.DBRW($B$1,Input_Prod_01!$D$9,Input_Prod_01!F$11,$M$1,Input_Prod_01!$G$9,$J$9,$E$30,Input_Prod_01!$B51,$L$1,$K$1) -> 21.671895 | G51: =_xll.DBRW($B$1,Input_Prod_01!$D$9,Input_Prod_01!G$11,$M$1,Input_Prod_01!$G$9,$J$9,$E$30,Input_Prod_01!$B51,$L$1,$K$1) -> 21.517253 | H51: =_xll.DBRW($B$1,Input_Prod_01!$D$9,Input_Prod_01!H$11,$M$1,Input_Prod_01!$G$9,$J$9,$E$30,Input_Prod_01!$B51,$L$1,$K$1) -> 24.83239 | I51: =_xll.DBRW($B$1,Input_Prod_01!$D$9,Input_Prod_01!I$11,$M$1,Input_Prod_01!$G$9,$J$9,$E$30,Input_Prod_01!$B51,$L$1,$K$1) -> 23.311851 | J51: =_xll.DBRW($B$1,Input_Prod_01!$D$9,Input_Prod_01!J$11,$M$1,Input_Prod_01!$G$9,$J$9,$E$30,Input_Prod_01!$B51,$L$1,$K$1) -> 22.717522 | ... N51: =_xll.DBRW($B$1,Input_Prod_01!$D$9,Input_Prod_01!N$11,$M$1,Input_Prod_01!$G$9,$J$9,$E$30,Input_Prod_01!$B51,$L$1,$K$1) -> 9.8084707
B52: Fixed Costs | C52: =_xll.DBRW($B$1,Input_Prod_01!$D$9,Input_Prod_01!C$11,$M$1,Input_Prod_01!$G$9,$J$9,$E$30,Input_Prod_01!$B52,$L$1,$K$1) -> 0 | D52: =_xll.DBRW($B$1,Input_Prod_01!$D$9,Input_Prod_01!D$11,$M$1,Input_Prod_01!$G$9,$J$9,$E$30,Input_Prod_01!$B52,$L$1,$K$1) -> 0 | E52: =_xll.DBRW($B$1,Input_Prod_01!$D$9,Input_Prod_01!E$11,$M$1,Input_Prod_01!$G$9,$J$9,$E$30,Input_Prod_01!$B52,$L$1,$K$1) -> 0 | F52: =_xll.DBRW($B$1,Input_Prod_01!$D$9,Input_Prod_01!F$11,$M$1,Input_Prod_01!$G$9,$J$9,$E$30,Input_Prod_01!$B52,$L$1,$K$1) -> 0 | G52: =_xll.DBRW($B$1,Input_Prod_01!$D$9,Input_Prod_01!G$11,$M$1,Input_Prod_01!$G$9,$J$9,$E$30,Input_Prod_01!$B52,$L$1,$K$1) -> 0 | H52: =_xll.DBRW($B$1,Input_Prod_01!$D$9,Input_Prod_01!H$11,$M$1,Input_Prod_01!$G$9,$J$9,$E$30,Input_Prod_01!$B52,$L$1,$K$1) -> 0 | I52: =_xll.DBRW($B$1,Input_Prod_01!$D$9,Input_Prod_01!I$11,$M$1,Input_Prod_01!$G$9,$J$9,$E$30,Input_Prod_01!$B52,$L$1,$K$1) -> 0 | J52: =_xll.DBRW($B$1,Input_Prod_01!$D$9,Input_Prod_01!J$11,$M$1,Input_Prod_01!$G$9,$J$9,$E$30,Input_Prod_01!$B52,$L$1,$K$1) -> 0 | ... N52: =_xll.DBRW($B$1,Input_Prod_01!$D$9,Input_Prod_01!N$11,$M$1,Input_Prod_01!$G$9,$J$9,$E$30,Input_Prod_01!$B52,$L$1,$K$1) -> 0
B53: Operating Expenses | C53: =_xll.DBRW($B$1,Input_Prod_01!$D$9,Input_Prod_01!C$11,$M$1,Input_Prod_01!$G$9,$J$9,$E$30,Input_Prod_01!$B53,$L$1,$K$1) -> 0 | D53: =_xll.DBRW($B$1,Input_Prod_01!$D$9,Input_Prod_01!D$11,$M$1,Input_Prod_01!$G$9,$J$9,$E$30,Input_Prod_01!$B53,$L$1,$K$1) -> 0 | E53: =_xll.DBRW($B$1,Input_Prod_01!$D$9,Input_Prod_01!E$11,$M$1,Input_Prod_01!$G$9,$J$9,$E$30,Input_Prod_01!$B53,$L$1,$K$1) -> 0 | F53: =_xll.DBRW($B$1,Input_Prod_01!$D$9,Input_Prod_01!F$11,$M$1,Input_Prod_01!$G$9,$J$9,$E$30,Input_Prod_01!$B53,$L$1,$K$1) -> 0 | G53: =_xll.DBRW($B$1,Input_Prod_01!$D$9,Input_Prod_01!G$11,$M$1,Input_Prod_01!$G$9,$J$9,$E$30,Input_Prod_01!$B53,$L$1,$K$1) -> 0 | H53: =_xll.DBRW($B$1,Input_Prod_01!$D$9,Input_Prod_01!H$11,$M$1,Input_Prod_01!$G$9,$J$9,$E$30,Input_Prod_01!$B53,$L$1,$K$1) -> 0 | I53: =_xll.DBRW($B$1,Input_Prod_01!$D$9,Input_Prod_01!I$11,$M$1,Input_Prod_01!$G$9,$J$9,$E$30,Input_Prod_01!$B53,$L$1,$K$1) -> 0 | J53: =_xll.DBRW($B$1,Input_Prod_01!$D$9,Input_Prod_01!J$11,$M$1,Input_Prod_01!$G$9,$J$9,$E$30,Input_Prod_01!$B53,$L$1,$K$1) -> 0 | ... N53: =_xll.DBRW($B$1,Input_Prod_01!$D$9,Input_Prod_01!N$11,$M$1,Input_Prod_01!$G$9,$J$9,$E$30,Input_Prod_01!$B53,$L$1,$K$1) -> 0
...

Sheet Input_Prod_02
B1: =_xll.VIEW("CONS_VC:STG.100.DataBase_Uploads",D9) -> CONS_VC:STG.100.DataBase_Uploads:-752698549379028367 | C1: =_xll.VIEW("CONS_VC:ALL.015.Region_Assumptions") -> CONS_VC:ALL.015.Region_Assumptions:-752698549-4785970 | D1: =_xll.VIEW("CONS_VC:DFS.120.Financial_Results") -> CONS_VC:DFS.120.Financial_Results:-752698549890993963 | K1: Value | L1: N/A | M1: =_xll.SUBNM("CONS_VC:ALL.D.Version","","T4") -> T4 | N1: PROD099
B2: =_xll.VIEW("CONS_VC:REV.100.Revenue_Consolidated") -> CONS_VC:REV.100.Revenue_Consolidated:-752698549-1043644815 | C2: =_xll.VIEW("CONS_VC:ALL.010.Economic_Assumptions") -> CONS_VC:ALL.010.Economic_Assumptions:-752698549-1652293987 | D2: =_xll.VIEW("CONS_VC:DFS.140.Indirect_Cash_Flow") -> CONS_VC:DFS.140.Indirect_Cash_Flow:-752698549-767194537 | K2: Total Market | N2: Total Products
B3: =_xll.VIEW("CONS_VC:DFS.100.Profit_and_Loss") -> CONS_VC:DFS.100.Profit_and_Loss:-7526985491143614695 | C3: =_xll.VIEW("CONS_VC:DFS.160.Working_Capital") -> CONS_VC:DFS.160.Working_Capital:-752698549-1628048918 | D3: =_xll.VIEW("CONS_VC:ALL.004.Uploads_Status_Planning") -> CONS_VC:ALL.004.Uploads_Status_Planning:-752698549-1635088025 | G3: Flag
B4: =_xll.VIEW("CONS_VC:ALL.001.Actual_Control") -> CONS_VC:ALL.001.Actual_Control:-752698549-938340181 | C4: =_xll.VIEW("CONS_VC:DFS.180.Gross_Debt") -> CONS_VC:DFS.180.Gross_Debt:-7526985491862422329
C5: =_xll.DBRW(Input_Prod_02!$B$4,Input_Prod_02!$D$9,Input_Prod_02!C11,$M$1,$G$3) -> PLAN | D5: =_xll.DBRW(Input_Prod_02!$B$4,Input_Prod_02!$D$9,Input_Prod_02!D11,$M$1,$G$3) -> PLAN | E5: =_xll.DBRW(Input_Prod_02!$B$4,Input_Prod_02!$D$9,Input_Prod_02!E11,$M$1,$G$3) -> PLAN | F5: =_xll.DBRW(Input_Prod_02!$B$4,Input_Prod_02!$D$9,Input_Prod_02!F11,$M$1,$G$3) -> PLAN | G5: =_xll.DBRW(Input_Prod_02!$B$4,Input_Prod_02!$D$9,Input_Prod_02!G11,$M$1,$G$3) -> PLAN | H5: =_xll.DBRW(Input_Prod_02!$B$4,Input_Prod_02!$D$9,Input_Prod_02!H11,$M$1,$G$3) -> PLAN | I5: =_xll.DBRW(Input_Prod_02!$B$4,Input_Prod_02!$D$9,Input_Prod_02!I11,$M$1,$G$3) -> PLAN | J5: =_xll.DBRW(Input_Prod_02!$B$4,Input_Prod_02!$D$9,Input_Prod_02!J11,$M$1,$G$3) -> PLAN | ... N5: =_xll.DBRW(Input_Prod_02!$B$4,Input_Prod_02!$D$9,Input_Prod_02!N11,$M$1,$G$3) -> PLAN
L7: System Input Status: | N7: =_xll.DBRW($D$3,$M$1,$J$9,"Status") -> Closed
B8: GLOBAL ASSUMPTIONS
