Workbook
Name Current_year: #REF!
Name CurrentForecast: #REF!
Name CurrentForecast: #REF!
Name CurrentMonth: #REF!
Name CurrentMonth: #REF!
Name Currentyear: #REF!
Name CurrentYear: #REF!
Name mes: #REF!
Name Month: #REF!
Name MonthName: #REF!
Name PriorYear: #REF!
Name PriorYear: #REF!
Name TM1RPTDATARNG4065595: 'EBITDA - Fx'!$23:$23
Name TM1RPTFMTIDCOL4065595: 'EBITDA - Fx'!$A$1:$A$10
Name TM1RPTFMTRNG4065595: 'EBITDA - Fx'!$B$1:$F$10
Name TM1RPTQRYRNG4065595: 'EBITDA - Fx'!$B$11
Name TM1RPTVIEWRNG4065595: 'EBITDA - Fx'!$B$12

Sheet Cognos_Office_Connection_Cache
B1: [Modelo Global Result.xlsx]Value Tree 1 - Fx'!A23
B2: Global
B3: VCBR
B4: VCEAA
B5: CORP
B6: ESPA
B7: TURK
B8: VCLATAM
B9: ARTI
B10: ITACA
B11: VCNA
B12: VCOTHERS
... B33: VCNA

Sheet Home

Sheet Summary  - Fx
A1: Cubo
A2: CONS_VC:DFS.200.KPIs
A3: CONS_VC:DFS.100.Profit_and_loss
A4: CONS_VC:DFS.140.Indirect_Cash_Flow
A5: CONS_VC:DFS.180.Gross_Debt
A6: CONS_VC:REV.100.Revenue_Consolidated
A8: Ano
A9: =_xll.SUBNM("CONS_VC:ALL.D.Year","","2025") -> RECALC_0_7_
A11: Mês
A12: =_xll.SUBNM("CONS_VC:ALL.D.Month",,"Total YTD","MEMBER_NAME") -> RECALC_0_9_
A13: =_xll.SUBNM("CONS_VC:ALL.D.Month",,"Year","MEMBER_NAME") -> RECALC_0_10_
A14: =_xll.SUBNM("CONS_VC:ALL.D.Month",,"01","MEMBER_NAME") -> RECALC_0_494_
A16: Versão
A22: Currency
A23: =_xll.SUBNM("CONS_VC:ALL.D.Currency","","BRL Conv.") -> RECALC_0_496_
A24: =_xll.SUBNM("CONS_VC:ALL.D.Currency","","USD Conv.") -> RECALC_0_497_
A25: =_xll.SUBNM("CONS_VC:ALL.D.Currency","","EUR Conv.") -> RECALC_0_498_
A28: Region
A29: =_xll.SUBNM("CONS_VC:ALL.D.Region","","Global") -> RECALC_0_495_
A30: VCBR
A31: VCNA
A32: VCEAA
A33: VCLATAM
A35: Produto
A36: =_xll.SUBNM("CONS_VC:ALL.D.Products","","Total Products") -> RECALC_0_11_
A38: Accounts_PNL
A39: Net Profit
A41: Accounts_ICF
A42: Change in cash
A45: DFS.100.Profil_and_Loss
A46: Global EBITDA Month | B46: Formato
A47: {=_xll.DBR($A$3,$A$9,$A$14,Summary!$L$4,$A$23,$A$29,$A$36,"EBITDA","Total Value")} -> RECALC_1_501_ | B47: ="R$ "& ROUND(A47,0) & " M" -> #VALUE!
A48: {=IFERROR((_xll.DBR($A$3,$A$9,$A$14,Summary!$L$4,$A$23,$A$29,$A$36,"EBITDA","Total Value") - _xll.DBR($A$3,$A$9,$A$14,Summary!$N$4,$A$23,$A$29,$A$36,"EBITDA","Total Value"))/ _xll.DBR($A$3,$A$9,$A$14,Summary!$N$4,$A$23,$A$29,$A$36,"EBITDA","Total Value"),0) &"%" & " vs. Budget"} -> 0% vs. Budget
A50: Global EBITDA YTD | B50: Formato
A51: {=_xll.DBR($A$3,$A$9,$A$12,Summary!$L$4,$A$23,$A$29,$A$36,"EBITDA","Total Value")} -> RECALC_1_522_ | B51: ="R$ "& ROUND(A51,0) & " M" -> #VALUE!
A52: {=IFERROR((_xll.DBR($A$3,$A$9,$A$12,Summary!$L$4,$A$23,$A$29,$A$36,"EBITDA","Total Value") - _xll.DBR($A$3,$A$9,$A$12,Summary!$N$4,$A$23,$A$29,$A$36,"EBITDA","Total Value"))/ _xll.DBR($A$3,$A$9,$A$12,Summary!$N$4,$A$23,$A$29,$A$36,"EBITDA","Total Value"),0) &"%" & " vs. Budget"} -> 0% vs. Budget
A54: Global EBITDA Full Year | B54: Formato
A55: {=_xll.DBR($A$3,$A$9,$A$13,Summary!$L$4,$A$23,$A$29,$A$36,"EBITDA","Total Value")} -> RECALC_1_504_ | B55: ="R$ "& ROUND(A55,0) & " M" -> #VALUE!
A56: {=IFERROR((_xll.DBR($A$3,$A$9,$A$13,Summary!$L$4,$A$23,$A$29,$A$36,"EBITDA","Total Value") - _xll.DBR($A$3,$A$9,$A$13,Summary!$N$4,$A$23,$A$29,$A$36,"EBITDA","Total Value"))/ _xll.DBR($A$3,$A$9,$A$13,Summary!$N$4,$A$23,$A$29,$A$36,"EBITDA","Total Value"),0) &"%" & " vs. Budget"} -> 0% vs. Budget
A58: Regions | B58: Formato
...

Sheet Summary
D2: Summary
D4: Global EBITDA | J4: =_xll.SUBNM("CONS_VC:ALL.D.Version",,"L300","MEMBER_NAME") -> RECALC_0_4_ | L4: =_xll.SUBNM("CONS_VC:ALL.D.Version",,"RF","Descrição") -> RECALC_0_5_ | N4: Budget
I6: Regions EBITDA
D7: Month
D16: YTD
D28: Full Year

Sheet Cement Volumes & Prices - Fx
A1: =_xll.VIEW("CONS_VC:REV.100.Revenue_Consolidated",$A$2,"!","!",$A$9,$A$10,'Cement Volumes & Prices'!$O$3,$A$4,$A$11) -> CONS_VC:REV.100.Revenue_Consolidated:205767106-196713936
A2: ='Cement Volumes & Prices'!$L$3 -> RECALC_0_531_
A4: =_xll.SUBNM("CONS_VC:ALL.D.Market","","Total Market") -> RECALC_0_573_
A9: =_xll.SUBNM("CONS_VC:ALL.D.Currency","Default","BRL","MEMBER_NAME") -> RECALC_0_33_ | C9: Jan | D9: Feb | E9: Mar | F9: Apr | G9: May | H9: Jun | I9: Jul | J9: Aug | K9: Sep | L9: Oct | M9: Nov | N9: Dec
A10: =_xll.SUBNM("CONS_VC:ALL.D.Region","Default","VCBR","MEMBER_NAME") -> RECALC_0_577_ | B10: ='Cement Volumes & Prices'!$S$3 -> RECALC_0_536_ | C10: =_xll.DBRW($A$1,$A$2,C$9,$B10,$A9,$A10,'Cement Volumes & Prices'!$O$3,$A$4,$A11) -> RECALC_1_631_ | D10: =_xll.DBRW($A$1,$A$2,D$9,$B10,$A9,$A10,'Cement Volumes & Prices'!$O$3,$A$4,$A11) -> RECALC_1_783_ | E10: =_xll.DBRW($A$1,$A$2,E$9,$B10,$A9,$A10,'Cement Volumes & Prices'!$O$3,$A$4,$A11) -> RECALC_1_662_ | F10: =_xll.DBRW($A$1,$A$2,F$9,$B10,$A9,$A10,'Cement Volumes & Prices'!$O$3,$A$4,$A11) -> RECALC_1_711_ | G10: =_xll.DBRW($A$1,$A$2,G$9,$B10,$A9,$A10,'Cement Volumes & Prices'!$O$3,$A$4,$A11) -> RECALC_1_785_ | H10: =_xll.DBRW($A$1,$A$2,H$9,$B10,$A9,$A10,'Cement Volumes & Prices'!$O$3,$A$4,$A11) -> RECALC_1_749_ | I10: =_xll.DBRW($A$1,$A$2,I$9,$B10,$A9,$A10,'Cement Volumes & Prices'!$O$3,$A$4,$A11) -> RECALC_1_691_ | J10: =_xll.DBRW($A$1,$A$2,J$9,$B10,$A9,$A10,'Cement Volumes & Prices'!$O$3,$A$4,$A11) -> RECALC_1_731_ | ... N10: =_xll.DBRW($A$1,$A$2,N$9,$B10,$A9,$A10,'Cement Volumes & Prices'!$O$3,$A$4,$A11) -> RECALC_1_730_
A11: =_xll.SUBNM("CONS_VC:REV.M.100.Revenue_Consolidated","Default","Sales Volume [kt]") -> RECALC_0_562_ | B11: ='Cement Volumes & Prices'!$U$3 -> RECALC_0_537_ | C11: =_xll.DBRW($A$1,$A$2,C$9,$B11,$A9,$A10,'Cement Volumes & Prices'!$O$3,$A$4,$A11) -> RECALC_1_647_ | D11: =_xll.DBRW($A$1,$A$2,D$9,$B11,$A9,$A10,'Cement Volumes & Prices'!$O$3,$A$4,$A11) -> RECALC_1_757_ | E11: =_xll.DBRW($A$1,$A$2,E$9,$B11,$A9,$A10,'Cement Volumes & Prices'!$O$3,$A$4,$A11) -> RECALC_1_602_ | F11: =_xll.DBRW($A$1,$A$2,F$9,$B11,$A9,$A10,'Cement Volumes & Prices'!$O$3,$A$4,$A11) -> RECALC_1_714_ | G11: =_xll.DBRW($A$1,$A$2,G$9,$B11,$A9,$A10,'Cement Volumes & Prices'!$O$3,$A$4,$A11) -> RECALC_1_734_ | H11: =_xll.DBRW($A$1,$A$2,H$9,$B11,$A9,$A10,'Cement Volumes & Prices'!$O$3,$A$4,$A11) -> RECALC_1_645_ | I11: =_xll.DBRW($A$1,$A$2,I$9,$B11,$A9,$A10,'Cement Volumes & Prices'!$O$3,$A$4,$A11) -> RECALC_1_614_ | J11: =_xll.DBRW($A$1,$A$2,J$9,$B11,$A9,$A10,'Cement Volumes & Prices'!$O$3,$A$4,$A11) -> RECALC_1_651_ | ... N11: =_xll.DBRW($A$1,$A$2,N$9,$B11,$A9,$A10,'Cement Volumes & Prices'!$O$3,$A$4,$A11) -> RECALC_1_621_
A13: =_xll.SUBNM("CONS_VC:ALL.D.Currency","Default","USD","MEMBER_NAME") -> RECALC_0_561_ | C13: Jan | D13: Feb | E13: Mar | F13: Apr | G13: May | H13: Jun | I13: Jul | J13: Aug | K13: Sep | L13: Oct | M13: Nov | N13: Dec
A14: =_xll.SUBNM("CONS_VC:ALL.D.Region","Default","VCNA","MEMBER_NAME") -> RECALC_0_571_ | B14: ='Cement Volumes & Prices'!$S$3 -> RECALC_0_536_ | C14: =_xll.DBRW($A$1,$A$2,C$9,$B14,$A13,$A14,'Cement Volumes & Prices'!$O$3,$A$4,$A15) -> RECALC_1_637_ | D14: =_xll.DBRW($A$1,$A$2,D$9,$B14,$A13,$A14,'Cement Volumes & Prices'!$O$3,$A$4,$A15) -> RECALC_1_649_ | E14: =_xll.DBRW($A$1,$A$2,E$9,$B14,$A13,$A14,'Cement Volumes & Prices'!$O$3,$A$4,$A15) -> RECALC_1_608_ | F14: =_xll.DBRW($A$1,$A$2,F$9,$B14,$A13,$A14,'Cement Volumes & Prices'!$O$3,$A$4,$A15) -> RECALC_1_673_ | G14: =_xll.DBRW($A$1,$A$2,G$9,$B14,$A13,$A14,'Cement Volumes & Prices'!$O$3,$A$4,$A15) -> RECALC_1_773_ | H14: =_xll.DBRW($A$1,$A$2,H$9,$B14,$A13,$A14,'Cement Volumes & Prices'!$O$3,$A$4,$A15) -> RECALC_1_703_ | I14: =_xll.DBRW($A$1,$A$2,I$9,$B14,$A13,$A14,'Cement Volumes & Prices'!$O$3,$A$4,$A15) -> RECALC_1_716_ | J14: =_xll.DBRW($A$1,$A$2,J$9,$B14,$A13,$A14,'Cement Volumes & Prices'!$O$3,$A$4,$A15) -> RECALC_1_725_ | ... N14: =_xll.DBRW($A$1,$A$2,N$9,$B14,$A13,$A14,'Cement Volumes & Prices'!$O$3,$A$4,$A15) -> RECALC_1_664_
A15: =_xll.SUBNM("CONS_VC:REV.M.100.Revenue_Consolidated","Default","Sales Volume [kt]") -> RECALC_0_562_ | B15: ='Cement Volumes & Prices'!$U$3 -> RECALC_0_537_ | C15: =_xll.DBRW($A$1,$A$2,C$9,$B15,$A13,$A14,'Cement Volumes & Prices'!$O$3,$A$4,$A15) -> RECALC_1_782_ | D15: =_xll.DBRW($A$1,$A$2,D$9,$B15,$A13,$A14,'Cement Volumes & Prices'!$O$3,$A$4,$A15) -> RECALC_1_635_ | E15: =_xll.DBRW($A$1,$A$2,E$9,$B15,$A13,$A14,'Cement Volumes & Prices'!$O$3,$A$4,$A15) -> RECALC_1_619_ | F15: =_xll.DBRW($A$1,$A$2,F$9,$B15,$A13,$A14,'Cement Volumes & Prices'!$O$3,$A$4,$A15) -> RECALC_1_625_ | G15: =_xll.DBRW($A$1,$A$2,G$9,$B15,$A13,$A14,'Cement Volumes & Prices'!$O$3,$A$4,$A15) -> RECALC_1_790_ | H15: =_xll.DBRW($A$1,$A$2,H$9,$B15,$A13,$A14,'Cement Volumes & Prices'!$O$3,$A$4,$A15) -> RECALC_1_661_ | I15: =_xll.DBRW($A$1,$A$2,I$9,$B15,$A13,$A14,'Cement Volumes & Prices'!$O$3,$A$4,$A15) -> RECALC_1_607_ | J15: =_xll.DBRW($A$1,$A$2,J$9,$B15,$A13,$A14,'Cement Volumes & Prices'!$O$3,$A$4,$A15) -> RECALC_1_756_ | ... N15: =_xll.DBRW($A$1,$A$2,N$9,$B15,$A13,$A14,'Cement Volumes & Prices'!$O$3,$A$4,$A15) -> RECALC_1_626_
A17: =_xll.SUBNM("CONS_VC:ALL.D.Currency","Default","EUR","MEMBER_NAME") -> RECALC_0_574_ | C17: Jan | D17: Feb | E17: Mar | F17: Apr | G17: May | H17: Jun | I17: Jul | J17: Aug | K17: Sep | L17: Oct | M17: Nov | N17: Dec
A18: =_xll.SUBNM("CONS_VC:ALL.D.Region","Default","VCEAA","MEMBER_NAME") -> RECALC_0_579_ | B18: ='Cement Volumes & Prices'!$S$3 -> RECALC_0_536_ | C18: =_xll.DBRW($A$1,$A$2,C$9,$B18,$A17,$A18,'Cement Volumes & Prices'!$O$3,$A$4,$A19) -> RECALC_1_692_ | D18: =_xll.DBRW($A$1,$A$2,D$9,$B18,$A17,$A18,'Cement Volumes & Prices'!$O$3,$A$4,$A19) -> RECALC_1_613_ | E18: =_xll.DBRW($A$1,$A$2,E$9,$B18,$A17,$A18,'Cement Volumes & Prices'!$O$3,$A$4,$A19) -> RECALC_1_786_ | F18: =_xll.DBRW($A$1,$A$2,F$9,$B18,$A17,$A18,'Cement Volumes & Prices'!$O$3,$A$4,$A19) -> RECALC_1_776_ | G18: =_xll.DBRW($A$1,$A$2,G$9,$B18,$A17,$A18,'Cement Volumes & Prices'!$O$3,$A$4,$A19) -> RECALC_1_685_ | H18: =_xll.DBRW($A$1,$A$2,H$9,$B18,$A17,$A18,'Cement Volumes & Prices'!$O$3,$A$4,$A19) -> RECALC_1_766_ | I18: =_xll.DBRW($A$1,$A$2,I$9,$B18,$A17,$A18,'Cement Volumes & Prices'!$O$3,$A$4,$A19) -> RECALC_1_609_ | J18: =_xll.DBRW($A$1,$A$2,J$9,$B18,$A17,$A18,'Cement Volumes & Prices'!$O$3,$A$4,$A19) -> RECALC_1_754_ | ... N18: =_xll.DBRW($A$1,$A$2,N$9,$B18,$A17,$A18,'Cement Volumes & Prices'!$O$3,$A$4,$A19) -> RECALC_1_671_
A19: =_xll.SUBNM("CONS_VC:REV.M.100.Revenue_Consolidated","Default","Sales Volume [kt]") -> RECALC_0_562_ | B19: ='Cement Volumes & Prices'!$U$3 -> RECALC_0_537_ | C19: =_xll.DBRW($A$1,$A$2,C$9,$B19,$A17,$A18,'Cement Volumes & Prices'!$O$3,$A$4,$A19) -> RECALC_1_717_ | D19: =_xll.DBRW($A$1,$A$2,D$9,$B19,$A17,$A18,'Cement Volumes & Prices'!$O$3,$A$4,$A19) -> RECALC_1_760_ | E19: =_xll.DBRW($A$1,$A$2,E$9,$B19,$A17,$A18,'Cement Volumes & Prices'!$O$3,$A$4,$A19) -> RECALC_1_615_ | F19: =_xll.DBRW($A$1,$A$2,F$9,$B19,$A17,$A18,'Cement Volumes & Prices'!$O$3,$A$4,$A19) -> RECALC_1_702_ | G19: =_xll.DBRW($A$1,$A$2,G$9,$B19,$A17,$A18,'Cement Volumes & Prices'!$O$3,$A$4,$A19) -> RECALC_1_696_ | H19: =_xll.DBRW($A$1,$A$2,H$9,$B19,$A17,$A18,'Cement Volumes & Prices'!$O$3,$A$4,$A19) -> RECALC_1_745_ | I19: =_xll.DBRW($A$1,$A$2,I$9,$B19,$A17,$A18,'Cement Volumes & Prices'!$O$3,$A$4,$A19) -> RECALC_1_670_ | J19: =_xll.DBRW($A$1,$A$2,J$9,$B19,$A17,$A18,'Cement Volumes & Prices'!$O$3,$A$4,$A19) -> RECALC_1_709_ | ... N19: =_xll.DBRW($A$1,$A$2,N$9,$B19,$A17,$A18,'Cement Volumes & Prices'!$O$3,$A$4,$A19) -> RECALC_1_737_
A21: =_xll.SUBNM("CONS_VC:ALL.D.Currency","Default","USD","MEMBER_NAME") -> RECALC_0_561_ | C21: Jan | D21: Feb | E21: Mar | F21: Apr | G21: May | H21: Jun | I21: Jul | J21: Aug | K21: Sep | L21: Oct | M21: Nov | N21: Dec
A22: =_xll.SUBNM("CONS_VC:ALL.D.Region","Default","VCLATAM Incl. AVEL","MEMBER_NAME") -> RECALC_0_580_ | B22: ='Cement Volumes & Prices'!$S$3 -> RECALC_0_536_ | C22: =_xll.DBRW($A$1,$A$2,C$9,$B22,$A21,$A22,'Cement Volumes & Prices'!$O$3,$A$4,$A23) -> RECALC_1_629_ | D22: =_xll.DBRW($A$1,$A$2,D$9,$B22,$A21,$A22,'Cement Volumes & Prices'!$O$3,$A$4,$A23) -> RECALC_1_656_ | E22: =_xll.DBRW($A$1,$A$2,E$9,$B22,$A21,$A22,'Cement Volumes & Prices'!$O$3,$A$4,$A23) -> RECALC_1_686_ | F22: =_xll.DBRW($A$1,$A$2,F$9,$B22,$A21,$A22,'Cement Volumes & Prices'!$O$3,$A$4,$A23) -> RECALC_1_774_ | G22: =_xll.DBRW($A$1,$A$2,G$9,$B22,$A21,$A22,'Cement Volumes & Prices'!$O$3,$A$4,$A23) -> RECALC_1_699_ | H22: =_xll.DBRW($A$1,$A$2,H$9,$B22,$A21,$A22,'Cement Volumes & Prices'!$O$3,$A$4,$A23) -> RECALC_1_603_ | I22: =_xll.DBRW($A$1,$A$2,I$9,$B22,$A21,$A22,'Cement Volumes & Prices'!$O$3,$A$4,$A23) -> RECALC_1_672_ | J22: =_xll.DBRW($A$1,$A$2,J$9,$B22,$A21,$A22,'Cement Volumes & Prices'!$O$3,$A$4,$A23) -> RECALC_1_761_ | ... N22: =_xll.DBRW($A$1,$A$2,N$9,$B22,$A21,$A22,'Cement Volumes & Prices'!$O$3,$A$4,$A23) -> RECALC_1_679_
A23: =_xll.SUBNM("CONS_VC:REV.M.100.Revenue_Consolidated","Default","Sales Volume [kt]") -> RECALC_0_562_ | B23: ='Cement Volumes & Prices'!$U$3 -> RECALC_0_537_ | C23: =_xll.DBRW($A$1,$A$2,C$9,$B23,$A21,$A22,'Cement Volumes & Prices'!$O$3,$A$4,$A23) -> RECALC_1_689_ | D23: =_xll.DBRW($A$1,$A$2,D$9,$B23,$A21,$A22,'Cement Volumes & Prices'!$O$3,$A$4,$A23) -> RECALC_1_648_ | E23: =_xll.DBRW($A$1,$A$2,E$9,$B23,$A21,$A22,'Cement Volumes & Prices'!$O$3,$A$4,$A23) -> RECALC_1_680_ | F23: =_xll.DBRW($A$1,$A$2,F$9,$B23,$A21,$A22,'Cement Volumes & Prices'!$O$3,$A$4,$A23) -> RECALC_1_750_ | G23: =_xll.DBRW($A$1,$A$2,G$9,$B23,$A21,$A22,'Cement Volumes & Prices'!$O$3,$A$4,$A23) -> RECALC_1_767_ | H23: =_xll.DBRW($A$1,$A$2,H$9,$B23,$A21,$A22,'Cement Volumes & Prices'!$O$3,$A$4,$A23) -> RECALC_1_683_ | I23: =_xll.DBRW($A$1,$A$2,I$9,$B23,$A21,$A22,'Cement Volumes & Prices'!$O$3,$A$4,$A23) -> RECALC_1_688_ | J23: =_xll.DBRW($A$1,$A$2,J$9,$B23,$A21,$A22,'Cement Volumes & Prices'!$O$3,$A$4,$A23) -> RECALC_1_610_ | ... N23: =_xll.DBRW($A$1,$A$2,N$9,$B23,$A21,$A22,'Cement Volumes & Prices'!$O$3,$A$4,$A23) -> RECALC_1_759_
A26: =_xll.SUBNM("CONS_VC:ALL.D.Currency","Default","BRL","MEMBER_NAME") -> RECALC_0_33_ | C26: Jan | D26: Feb | E26: Mar | F26: Apr | G26: May | H26: Jun | I26: Jul | J26: Aug | K26: Sep | L26: Oct | M26: Nov | N26: Dec
A27: =_xll.SUBNM("CONS_VC:ALL.D.Region","Default","VCBR","MEMBER_NAME") -> RECALC_0_577_ | B27: ='Cement Volumes & Prices'!$S$3 -> RECALC_0_536_ | C27: =_xll.DBRW($A$1,$A$2,C$9,$B27,$A26,$A27,'Cement Volumes & Prices'!$O$3,$A$4,$A28) -> RECALC_1_701_ | D27: =_xll.DBRW($A$1,$A$2,D$9,$B27,$A26,$A27,'Cement Volumes & Prices'!$O$3,$A$4,$A28) -> RECALC_1_618_ | E27: =_xll.DBRW($A$1,$A$2,E$9,$B27,$A26,$A27,'Cement Volumes & Prices'!$O$3,$A$4,$A28) -> RECALC_1_634_ | F27: =_xll.DBRW($A$1,$A$2,F$9,$B27,$A26,$A27,'Cement Volumes & Prices'!$O$3,$A$4,$A28) -> RECALC_1_650_ | G27: =_xll.DBRW($A$1,$A$2,G$9,$B27,$A26,$A27,'Cement Volumes & Prices'!$O$3,$A$4,$A28) -> RECALC_1_640_ | H27: =_xll.DBRW($A$1,$A$2,H$9,$B27,$A26,$A27,'Cement Volumes & Prices'!$O$3,$A$4,$A28) -> RECALC_1_605_ | I27: =_xll.DBRW($A$1,$A$2,I$9,$B27,$A26,$A27,'Cement Volumes & Prices'!$O$3,$A$4,$A28) -> RECALC_1_739_ | J27: =_xll.DBRW($A$1,$A$2,J$9,$B27,$A26,$A27,'Cement Volumes & Prices'!$O$3,$A$4,$A28) -> RECALC_1_744_ | ... N27: =_xll.DBRW($A$1,$A$2,N$9,$B27,$A26,$A27,'Cement Volumes & Prices'!$O$3,$A$4,$A28) -> RECALC_1_700_
A28: =_xll.SUBNM("CONS_VC:REV.M.100.Revenue_Consolidated","Default","Price Premium [$/ton]") -> RECALC_0_560_ | B28: ='Cement Volumes & Prices'!$U$3 -> RECALC_0_537_ | C28: =_xll.DBRW($A$1,$A$2,C$9,$B28,$A26,$A27,'Cement Volumes & Prices'!$O$3,$A$4,$A28) -> RECALC_1_636_ | D28: =_xll.DBRW($A$1,$A$2,D$9,$B28,$A26,$A27,'Cement Volumes & Prices'!$O$3,$A$4,$A28) -> RECALC_1_644_ | E28: =_xll.DBRW($A$1,$A$2,E$9,$B28,$A26,$A27,'Cement Volumes & Prices'!$O$3,$A$4,$A28) -> RECALC_1_713_ | F28: =_xll.DBRW($A$1,$A$2,F$9,$B28,$A26,$A27,'Cement Volumes & Prices'!$O$3,$A$4,$A28) -> RECALC_1_715_ | G28: =_xll.DBRW($A$1,$A$2,G$9,$B28,$A26,$A27,'Cement Volumes & Prices'!$O$3,$A$4,$A28) -> RECALC_1_655_ | H28: =_xll.DBRW($A$1,$A$2,H$9,$B28,$A26,$A27,'Cement Volumes & Prices'!$O$3,$A$4,$A28) -> RECALC_1_617_ | I28: =_xll.DBRW($A$1,$A$2,I$9,$B28,$A26,$A27,'Cement Volumes & Prices'!$O$3,$A$4,$A28) -> RECALC_1_752_ | J28: =_xll.DBRW($A$1,$A$2,J$9,$B28,$A26,$A27,'Cement Volumes & Prices'!$O$3,$A$4,$A28) -> RECALC_1_678_ | ... N28: =_xll.DBRW($A$1,$A$2,N$9,$B28,$A26,$A27,'Cement Volumes & Prices'!$O$3,$A$4,$A28) -> RECALC_1_770_
A30: =_xll.SUBNM("CONS_VC:ALL.D.Currency","Default","USD","MEMBER_NAME") -> RECALC_0_561_ | C30: Jan | D30: Feb | E30: Mar | F30: Apr | G30: May | H30: Jun | I30: Jul | J30: Aug | K30: Sep | L30: Oct | M30: Nov | N30: Dec
A31: =_xll.SUBNM("CONS_VC:ALL.D.Region","Default","VCNA","MEMBER_NAME") -> RECALC_0_571_ | B31: ='Cement Volumes & Prices'!$S$3 -> RECALC_0_536_ | C31: =_xll.DBRW($A$1,$A$2,C$9,$B31,$A30,$A31,'Cement Volumes & Prices'!$O$3,$A$4,$A32) -> RECALC_1_708_ | D31: =_xll.DBRW($A$1,$A$2,D$9,$B31,$A30,$A31,'Cement Volumes & Prices'!$O$3,$A$4,$A32) -> RECALC_1_720_ | E31: =_xll.DBRW($A$1,$A$2,E$9,$B31,$A30,$A31,'Cement Volumes & Prices'!$O$3,$A$4,$A32) -> RECALC_1_694_ | F31: =_xll.DBRW($A$1,$A$2,F$9,$B31,$A30,$A31,'Cement Volumes & Prices'!$O$3,$A$4,$A32) -> RECALC_1_657_ | G31: =_xll.DBRW($A$1,$A$2,G$9,$B31,$A30,$A31,'Cement Volumes & Prices'!$O$3,$A$4,$A32) -> RECALC_1_633_ | H31: =_xll.DBRW($A$1,$A$2,H$9,$B31,$A30,$A31,'Cement Volumes & Prices'!$O$3,$A$4,$A32) -> RECALC_1_764_ | I31: =_xll.DBRW($A$1,$A$2,I$9,$B31,$A30,$A31,'Cement Volumes & Prices'!$O$3,$A$4,$A32) -> RECALC_1_627_ | J31: =_xll.DBRW($A$1,$A$2,J$9,$B31,$A30,$A31,'Cement Volumes & Prices'!$O$3,$A$4,$A32) -> RECALC_1_665_ | ... N31: =_xll.DBRW($A$1,$A$2,N$9,$B31,$A30,$A31,'Cement Volumes & Prices'!$O$3,$A$4,$A32) -> RECALC_1_771_
A32: =_xll.SUBNM("CONS_VC:REV.M.100.Revenue_Consolidated","Default","Price Premium [$/ton]") -> RECALC_0_560_ | B32: ='Cement Volumes & Prices'!$U$3 -> RECALC_0_537_ | C32: =_xll.DBRW($A$1,$A$2,C$9,$B32,$A30,$A31,'Cement Volumes & Prices'!$O$3,$A$4,$A32) -> RECALC_1_693_ | D32: =_xll.DBRW($A$1,$A$2,D$9,$B32,$A30,$A31,'Cement Volumes & Prices'!$O$3,$A$4,$A32) -> RECALC_1_722_ | E32: =_xll.DBRW($A$1,$A$2,E$9,$B32,$A30,$A31,'Cement Volumes & Prices'!$O$3,$A$4,$A32) -> RECALC_1_604_ | F32: =_xll.DBRW($A$1,$A$2,F$9,$B32,$A30,$A31,'Cement Volumes & Prices'!$O$3,$A$4,$A32) -> RECALC_1_698_ | G32: =_xll.DBRW($A$1,$A$2,G$9,$B32,$A30,$A31,'Cement Volumes & Prices'!$O$3,$A$4,$A32) -> RECALC_1_630_ | H32: =_xll.DBRW($A$1,$A$2,H$9,$B32,$A30,$A31,'Cement Volumes & Prices'!$O$3,$A$4,$A32) -> RECALC_1_669_ | I32: =_xll.DBRW($A$1,$A$2,I$9,$B32,$A30,$A31,'Cement Volumes & Prices'!$O$3,$A$4,$A32) -> RECALC_1_763_ | J32: =_xll.DBRW($A$1,$A$2,J$9,$B32,$A30,$A31,'Cement Volumes & Prices'!$O$3,$A$4,$A32) -> RECALC_1_624_ | ... N32: =_xll.DBRW($A$1,$A$2,N$9,$B32,$A30,$A31,'Cement Volumes & Prices'!$O$3,$A$4,$A32) -> RECALC_1_781_
A34: =_xll.SUBNM("CONS_VC:ALL.D.Currency","Default","EUR","MEMBER_NAME") -> RECALC_0_574_ | C34: Jan | D34: Feb | E34: Mar | F34: Apr | G34: May | H34: Jun | I34: Jul | J34: Aug | K34: Sep | L34: Oct | M34: Nov | N34: Dec
A35: =_xll.SUBNM("CONS_VC:ALL.D.Region","Default","VCEAA","MEMBER_NAME") -> RECALC_0_579_ | B35: ='Cement Volumes & Prices'!$S$3 -> RECALC_0_536_ | C35: =_xll.DBRW($A$1,$A$2,C$9,$B35,$A34,$A35,'Cement Volumes & Prices'!$O$3,$A$4,$A36) -> RECALC_1_639_ | D35: =_xll.DBRW($A$1,$A$2,D$9,$B35,$A34,$A35,'Cement Volumes & Prices'!$O$3,$A$4,$A36) -> RECALC_1_726_ | E35: =_xll.DBRW($A$1,$A$2,E$9,$B35,$A34,$A35,'Cement Volumes & Prices'!$O$3,$A$4,$A36) -> RECALC_1_710_ | F35: =_xll.DBRW($A$1,$A$2,F$9,$B35,$A34,$A35,'Cement Volumes & Prices'!$O$3,$A$4,$A36) -> RECALC_1_616_ | G35: =_xll.DBRW($A$1,$A$2,G$9,$B35,$A34,$A35,'Cement Volumes & Prices'!$O$3,$A$4,$A36) -> RECALC_1_741_ | H35: =_xll.DBRW($A$1,$A$2,H$9,$B35,$A34,$A35,'Cement Volumes & Prices'!$O$3,$A$4,$A36) -> RECALC_1_652_ | I35: =_xll.DBRW($A$1,$A$2,I$9,$B35,$A34,$A35,'Cement Volumes & Prices'!$O$3,$A$4,$A36) -> RECALC_1_787_ | J35: =_xll.DBRW($A$1,$A$2,J$9,$B35,$A34,$A35,'Cement Volumes & Prices'!$O$3,$A$4,$A36) -> RECALC_1_784_ | ... N35: =_xll.DBRW($A$1,$A$2,N$9,$B35,$A34,$A35,'Cement Volumes & Prices'!$O$3,$A$4,$A36) -> RECALC_1_643_
A36: =_xll.SUBNM("CONS_VC:REV.M.100.Revenue_Consolidated","Default","Price Premium [$/ton]") -> RECALC_0_560_ | B36: ='Cement Volumes & Prices'!$U$3 -> RECALC_0_537_ | C36: =_xll.DBRW($A$1,$A$2,C$9,$B36,$A34,$A35,'Cement Volumes & Prices'!$O$3,$A$4,$A36) -> RECALC_1_732_ | D36: =_xll.DBRW($A$1,$A$2,D$9,$B36,$A34,$A35,'Cement Volumes & Prices'!$O$3,$A$4,$A36) -> RECALC_1_681_ | E36: =_xll.DBRW($A$1,$A$2,E$9,$B36,$A34,$A35,'Cement Volumes & Prices'!$O$3,$A$4,$A36) -> RECALC_1_632_ | F36: =_xll.DBRW($A$1,$A$2,F$9,$B36,$A34,$A35,'Cement Volumes & Prices'!$O$3,$A$4,$A36) -> RECALC_1_733_ | G36: =_xll.DBRW($A$1,$A$2,G$9,$B36,$A34,$A35,'Cement Volumes & Prices'!$O$3,$A$4,$A36) -> RECALC_1_758_ | H36: =_xll.DBRW($A$1,$A$2,H$9,$B36,$A34,$A35,'Cement Volumes & Prices'!$O$3,$A$4,$A36) -> RECALC_1_638_ | I36: =_xll.DBRW($A$1,$A$2,I$9,$B36,$A34,$A35,'Cement Volumes & Prices'!$O$3,$A$4,$A36) -> RECALC_1_677_ | J36: =_xll.DBRW($A$1,$A$2,J$9,$B36,$A34,$A35,'Cement Volumes & Prices'!$O$3,$A$4,$A36) -> RECALC_1_628_ | ... N36: =_xll.DBRW($A$1,$A$2,N$9,$B36,$A34,$A35,'Cement Volumes & Prices'!$O$3,$A$4,$A36) -> RECALC_1_658_
A38: =_xll.SUBNM("CONS_VC:ALL.D.Currency","Default","USD","MEMBER_NAME") -> RECALC_0_561_ | C38: Jan | D38: Feb | E38: Mar | F38: Apr | G38: May | H38: Jun | I38: Jul | J38: Aug | K38: Sep | L38: Oct | M38: Nov | N38: Dec
A39: =_xll.SUBNM("CONS_VC:ALL.D.Region","Default","VCLATAM Incl. AVEL","MEMBER_NAME") -> RECALC_0_580_ | B39: ='Cement Volumes & Prices'!$S$3 -> RECALC_0_536_ | C39: =_xll.DBRW($A$1,$A$2,C$9,$B39,$A38,$A39,'Cement Volumes & Prices'!$O$3,$A$4,$A40) -> RECALC_1_642_ | D39: =_xll.DBRW($A$1,$A$2,D$9,$B39,$A38,$A39,'Cement Volumes & Prices'!$O$3,$A$4,$A40) -> RECALC_1_718_ | E39: =_xll.DBRW($A$1,$A$2,E$9,$B39,$A38,$A39,'Cement Volumes & Prices'!$O$3,$A$4,$A40) -> RECALC_1_676_ | F39: =_xll.DBRW($A$1,$A$2,F$9,$B39,$A38,$A39,'Cement Volumes & Prices'!$O$3,$A$4,$A40) -> RECALC_1_777_ | G39: =_xll.DBRW($A$1,$A$2,G$9,$B39,$A38,$A39,'Cement Volumes & Prices'!$O$3,$A$4,$A40) -> RECALC_1_765_ | H39: =_xll.DBRW($A$1,$A$2,H$9,$B39,$A38,$A39,'Cement Volumes & Prices'!$O$3,$A$4,$A40) -> RECALC_1_740_ | I39: =_xll.DBRW($A$1,$A$2,I$9,$B39,$A38,$A39,'Cement Volumes & Prices'!$O$3,$A$4,$A40) -> RECALC_1_667_ | J39: =_xll.DBRW($A$1,$A$2,J$9,$B39,$A38,$A39,'Cement Volumes & Prices'!$O$3,$A$4,$A40) -> RECALC_1_727_ | ... N39: =_xll.DBRW($A$1,$A$2,N$9,$B39,$A38,$A39,'Cement Volumes & Prices'!$O$3,$A$4,$A40) -> RECALC_1_654_
A40: =_xll.SUBNM("CONS_VC:REV.M.100.Revenue_Consolidated","Default","Price Premium [$/ton]") -> RECALC_0_560_ | B40: ='Cement Volumes & Prices'!$U$3 -> RECALC_0_537_ | C40: =_xll.DBRW($A$1,$A$2,C$9,$B40,$A38,$A39,'Cement Volumes & Prices'!$O$3,$A$4,$A40) -> RECALC_1_653_ | D40: =_xll.DBRW($A$1,$A$2,D$9,$B40,$A38,$A39,'Cement Volumes & Prices'!$O$3,$A$4,$A40) -> RECALC_1_612_ | E40: =_xll.DBRW($A$1,$A$2,E$9,$B40,$A38,$A39,'Cement Volumes & Prices'!$O$3,$A$4,$A40) -> RECALC_1_723_ | F40: =_xll.DBRW($A$1,$A$2,F$9,$B40,$A38,$A39,'Cement Volumes & Prices'!$O$3,$A$4,$A40) -> RECALC_1_779_ | G40: =_xll.DBRW($A$1,$A$2,G$9,$B40,$A38,$A39,'Cement Volumes & Prices'!$O$3,$A$4,$A40) -> RECALC_1_663_ | H40: =_xll.DBRW($A$1,$A$2,H$9,$B40,$A38,$A39,'Cement Volumes & Prices'!$O$3,$A$4,$A40) -> RECALC_1_742_ | I40: =_xll.DBRW($A$1,$A$2,I$9,$B40,$A38,$A39,'Cement Volumes & Prices'!$O$3,$A$4,$A40) -> RECALC_1_719_ | J40: =_xll.DBRW($A$1,$A$2,J$9,$B40,$A38,$A39,'Cement Volumes & Prices'!$O$3,$A$4,$A40) -> RECALC_1_721_ | ... N40: =_xll.DBRW($A$1,$A$2,N$9,$B40,$A38,$A39,'Cement Volumes & Prices'!$O$3,$A$4,$A40) -> RECALC_1_687_

Sheet Cement Volumes & Prices
B3: =O3&" Volumes & Prices – Overview" -> RECALC_0_534_ Volumes & Prices – Overview | K3: Year: | L3: =_xll.SUBNM("CONS_VC:ALL.D.Year","Sys_Picklist","2026","MEMBER_NAME") -> RECALC_0_531_ | N3: Product: | O3: =_xll.SUBNM("CONS_VC:ALL.D.Products","default","Cement Group") -> RECALC_0_534_ | S3: =_xll.SUBNM("CONS_VC:ALL.D.Version","Sys.Report","L300","Descrição") -> RECALC_0_536_ | U3: =_xll.SUBNM("CONS_VC:ALL.D.Version","Sys.Report","RF","Descrição") -> RECALC_0_537_

Sheet EBITDA - Fx
A1: [Begin Format Range]
A2: 0 | B2: Nome do elemento | C2: 123.45679 | D2: 123.45679 | E2: 123.45679 | F2: 123.45679
A3: 1 | B3: Nome do elemento | C3: 123.45679 | D3: 123.45679 | E3: 123.45679 | F3: 123.45679
A4: 2 | B4: Nome do elemento | C4: 123.45679 | D4: 123.45679 | E4: 123.45679 | F4: 123.45679
A5: 3 | B5: Nome do elemento | C5: 123.45679 | D5: 123.45679 | E5: 123.45679 | F5: 123.45679
A6: 4 | B6: Nome do elemento | C6: 123.45679 | D6: 123.45679 | E6: 123.45679 | F6: 123.45679
A7: 5 | B7: Nome do elemento | C7: 123.45679 | D7: 123.45679 | E7: 123.45679 | F7: 123.45679
A8: Default | B8: Nome do elemento | C8: 123.45679 | D8: 123.45679 | E8: 123.45679 | F8: 123.45679
A9: Leaf | B9: Nome do elemento | C9: 123.45679 | D9: 123.45679 | E9: 123.45679 | F9: 123.45679
A10: [End Format Range]
B11: {DRILLDOWNMEMBER({[DFS.D.Accounts_PnL].[DFS.D.Accounts_PnL].[EBITDA]} , {[DFS.D.Accounts_PnL].[DFS.D.Accounts_PnL].[EBITDA]})}
B12: =_xll.TM1RPTVIEW("CONS_VC:DFS.100.Profit_and_Loss:4065595",0,_xll.TM1RPTTITLE("CONS_VC:ALL.D.Year",$B$14),_xll.TM1RPTTITLE("CONS_VC:DFS.M.100.Profit_and_Loss",$B$15),_xll.TM1RPTTITLE("CONS_VC:ALL.D.Version",$B$16),_xll.TM1RPTTITLE("CONS_VC:ALL.D.Currency",EBITDA!$B$5),_xll.TM1RPTTITLE("CONS_VC:ALL.D.Region",$B$18),_xll.TM1RPTTITLE("CONS_VC:ALL.D.Products",$B$19),TM1RPTFMTRNG4065595,TM1RPTFMTIDCOL4065595) -> CONS_VC:DFS.100.Profit_and_Loss:4065595
B13: Year
B14: =_xll.SUBNM("CONS_VC:ALL.D.Year",,"2025") -> RECALC_0_7_
B15: =_xll.SUBNM("CONS_VC:DFS.M.100.Profit_and_Loss",,"Total Value") -> RECALC_0_551_
B16: =_xll.SUBNM("CONS_VC:ALL.D.Version","Sys.Report","Actual","Descrição") -> RECALC_0_539_
B18: =_xll.SUBNM("CONS_VC:ALL.D.Region",,"Global") -> RECALC_0_495_
B19: =_xll.SUBNM("CONS_VC:ALL.D.Products",,"Total Products") -> RECALC_0_11_
B20: =_xll.TM1RPTROW($B$12,"CONS_VC:DFS.D.Accounts_PnL",,,,FALSE,B$11) -> pending__Modelo Global Result.xlsx:EBITDA - Fx:TM1RPTDATARNG:4065595
B22: Quarter View | D22: Q1 | E22: Q2 | F22: Q3 | G22: Q4 | I22: Full Year View | K22: Versão | L22: Actual | M22: L300 | N22: RF | O22: RF | P22: RF | Q22: RF | R22: RF | S22: Actual | T22: RF
A23: =IF(_xll.TM1RPTELISCONSOLIDATED($B$20,EBITDA!$C$6),IF(_xll.TM1RPTELLEV($B$20,EBITDA!$C$6)<=5,_xll.TM1RPTELLEV($B$20,EBITDA!$C$6),"Default"),"Leaf") -> #VALUE! | B23: Actual | C23: 2024 | D23: =_xll.DBRW($B$12,$C$23,D$22,$B23,EBITDA!$B$5,$B$18,$B$19,EBITDA!$C$6,$B$15) -> RECALC_1_575_ | E23: =_xll.DBRW($B$12,$C$23,E$22,$B23,EBITDA!$B$5,$B$18,$B$19,EBITDA!$C$6,$B$15) -> RECALC_1_598_ | F23: =_xll.DBRW($B$12,$C$23,F$22,$B23,EBITDA!$B$5,$B$18,$B$19,EBITDA!$C$6,$B$15) -> RECALC_1_597_ | G23: =_xll.DBRW($B$12,$C$23,G$22,$B23,EBITDA!$B$5,$B$18,$B$19,EBITDA!$C$6,$B$15) -> RECALC_1_594_ | K23: Empresa | L23: Global | M23: Global | N23: VCBR | O23: VCNA | P23: VCEAA | Q23: VCLATAM | R23: VCOTHERS | S23: Fx | T23: Global
B24: L300 | C24: L300 | D24: =_xll.DBRW($B$12,$B$14,D$22,$B24,EBITDA!$B$5,$B$18,$B$19,EBITDA!$C$6,$B$15) -> RECALC_1_570_ | E24: =_xll.DBRW($B$12,$B$14,E$22,$B24,EBITDA!$B$5,$B$18,$B$19,EBITDA!$C$6,$B$15) -> RECALC_1_576_ | F24: =_xll.DBRW($B$12,$B$14,F$22,$B24,EBITDA!$B$5,$B$18,$B$19,EBITDA!$C$6,$B$15) -> RECALC_1_593_ | G24: =_xll.DBRW($B$12,$B$14,G$22,$B24,EBITDA!$B$5,$B$18,$B$19,EBITDA!$C$6,$B$15) -> RECALC_1_592_ | L24: =B14-1 -> #VALUE! | M24: L300 | N24: VCBR | O24: VCNA | P24: VCEA | Q24: VCLATAM | R24: Others | S24: FX | T24: =B14 -> RECALC_0_7_
B25: RF | C25: 2025 | D25: =_xll.DBRW($B$12,$B$14,D$22,$B25,EBITDA!$B$5,$B$18,$B$19,EBITDA!$C$6,$B$15) -> RECALC_1_553_ | E25: =_xll.DBRW($B$12,$B$14,E$22,$B25,EBITDA!$B$5,$B$18,$B$19,EBITDA!$C$6,$B$15) -> RECALC_1_569_ | F25: =_xll.DBRW($B$12,$B$14,F$22,$B25,EBITDA!$B$5,$B$18,$B$19,EBITDA!$C$6,$B$15) -> RECALC_1_556_ | G25: =_xll.DBRW($B$12,$B$14,G$22,$B25,EBITDA!$B$5,$B$18,$B$19,EBITDA!$C$6,$B$15) -> RECALC_1_586_ | L25: =_xll.DBRW($B$12,$B$14,$B$13,L$22,EBITDA!$B$5,L$23,$B$19,EBITDA!$AC$6,$B$15) -> RECALC_1_583_ | M25: =_xll.DBRW($B$12,$B$14,$B$13,M$22,EBITDA!$B$5,M$23,$B$19,EBITDA!$AC$6,$B$15) -> RECALC_1_558_ | N25: =_xll.DBRW($B$12,$B$14,$B$13,N$22,EBITDA!$B$5,N$23,$B$19,EBITDA!$AC$6,$B$15) -> RECALC_1_554_ | O25: =_xll.DBRW($B$12,$B$14,$B$13,O$22,EBITDA!$B$5,O$23,$B$19,EBITDA!$AC$6,$B$15) -> RECALC_1_590_ | P25: =_xll.DBRW($B$12,$B$14,$B$13,P$22,EBITDA!$B$5,P$23,$B$19,EBITDA!$AC$6,$B$15) -> RECALC_1_587_ | Q25: =_xll.DBRW($B$12,$B$14,$B$13,Q$22,EBITDA!$B$5,Q$23,$B$19,EBITDA!$AC$6,$B$15) -> RECALC_1_589_ | R25: =_xll.DBRW($B$12,$B$14,$B$13,R$22,EBITDA!$B$5,R$23,$B$19,EBITDA!$AC$6,$B$15) -> RECALC_1_559_ | S25: =_xll.DBRW($B$12,$B$14,$B$13,S$22,EBITDA!$B$5,S$23,$B$19,EBITDA!$AC$6,$B$15) -> RECALC_1_596_ | T25: =_xll.DBRW($B$12,$B$14,$B$13,T$22,EBITDA!$B$5,T$23,$B$19,EBITDA!$AC$6,$B$15) -> RECALC_1_572_
K26: L300 | N26: =_xll.DBRW($B$12,$B$14,$B$13,$K$26,EBITDA!$B$5,N$23,$B$19,EBITDA!$AC$6,$B$15) -> RECALC_1_582_ | O26: =_xll.DBRW($B$12,$B$14,$B$13,$K$26,EBITDA!$B$5,O$23,$B$19,EBITDA!$AC$6,$B$15) -> RECALC_1_557_ | P26: =_xll.DBRW($B$12,$B$14,$B$13,$K$26,EBITDA!$B$5,P$23,$B$19,EBITDA!$AC$6,$B$15) -> RECALC_1_584_ | Q26: =_xll.DBRW($B$12,$B$14,$B$13,$K$26,EBITDA!$B$5,Q$23,$B$19,EBITDA!$AC$6,$B$15) -> RECALC_1_581_ | R26: =_xll.DBRW($B$12,$B$14,$B$13,$K$26,EBITDA!$B$5,R$23,$B$19,EBITDA!$AC$6,$B$15) -> RECALC_1_591_
N27: =N25-N26 -> #VALUE! | O27: =O25-O26 -> #VALUE! | P27: =P25-P26 -> #VALUE! | Q27: =Q25-Q26 -> #VALUE! | R27: =R25-R26 -> #VALUE!
M29: =T25-M25 -> #VALUE!
B30: EBITDA/Net Revenue (%) | D30: Q1 | E30: Q2 | F30: Q3 | G30: Q4
C31: 2024 | D31: =_xll.DBRW($B$12,$C$23,D$22,$B23,EBITDA!$B$5,$B$18,$B$19,$B30,$B$15) -> RECALC_1_567_ | E31: =_xll.DBRW($B$12,$C$23,E$22,$B23,EBITDA!$B$5,$B$18,$B$19,$B30,$B$15) -> RECALC_1_565_ | F31: =_xll.DBRW($B$12,$C$23,F$22,$B23,EBITDA!$B$5,$B$18,$B$19,$B30,$B$15) -> RECALC_1_555_ | G31: =_xll.DBRW($B$12,$C$23,G$22,$B23,EBITDA!$B$5,$B$18,$B$19,$B30,$B$15) -> RECALC_1_568_
C32: L300 | D32: =_xll.DBRW($B$12,$B$14,D$22,$B24,EBITDA!$B$5,$B$18,$B$19,$B30,$B$15) -> RECALC_1_578_ | E32: =_xll.DBRW($B$12,$B$14,E$22,$B24,EBITDA!$B$5,$B$18,$B$19,$B30,$B$15) -> RECALC_1_566_ | F32: =_xll.DBRW($B$12,$B$14,F$22,$B24,EBITDA!$B$5,$B$18,$B$19,$B30,$B$15) -> RECALC_1_552_ | G32: =_xll.DBRW($B$12,$B$14,G$22,$B24,EBITDA!$B$5,$B$18,$B$19,$B30,$B$15) -> RECALC_1_588_ | L32: 6965 | M32: -87 | N32: =SUM(L32:M32) -> 6878 | O32: =SUM(L32-N32) -> 87
C33: 2025 | D33: =_xll.DBRW($B$12,$B$14,D$22,$B25,EBITDA!$B$5,$B$18,$B$19,$B30,$B$15) -> RECALC_1_595_ | E33: =_xll.DBRW($B$12,$B$14,E$22,$B25,EBITDA!$B$5,$B$18,$B$19,$B30,$B$15) -> RECALC_1_585_ | F33: =_xll.DBRW($B$12,$B$14,F$22,$B25,EBITDA!$B$5,$B$18,$B$19,$B30,$B$15) -> RECALC_1_564_ | G33: =_xll.DBRW($B$12,$B$14,G$22,$B25,EBITDA!$B$5,$B$18,$B$19,$B30,$B$15) -> RECALC_1_563_
L34: -87 | M34: -112 | N34: 163 | O34: 83 | P34: 5 | Q34: -139

Sheet EBITDA
B5: =_xll.SUBNM("CONS_VC:ALL.D.Currency","Default","BRL Conv.") -> RECALC_0_70_
C6: =_xll.SUBNM("CONS_VC:DFS.D.Accounts_PnL","Default","EBITDA") -> RECALC_0_112_ | AC6: =_xll.SUBNM("CONS_VC:DFS.D.Accounts_PnL","Default","EBITDA") -> RECALC_0_112_
C7: QoQ Overview | AC7: Full Year
A26: ="Margin " &'EBITDA - Fx'!B20 -> Margin pending__Modelo Global Result.xlsx:EBITDA - Fx:TM1RPTDATARNG:4065595 | E26: ='EBITDA - Fx'!D31 -> RECALC_1_567_ | F26: ='EBITDA - Fx'!D32 -> RECALC_1_578_ | G26: ='EBITDA - Fx'!D33 -> RECALC_1_595_ | J26: ='EBITDA - Fx'!E31 -> RECALC_1_565_ | K26: ='EBITDA - Fx'!E32 -> RECALC_1_566_ | L26: ='EBITDA - Fx'!E33 -> RECALC_1_585_ | N26: ='EBITDA - Fx'!F31 -> RECALC_1_555_ | O26: ='EBITDA - Fx'!F32 -> RECALC_1_552_ | P26: ='EBITDA - Fx'!F33 -> RECALC_1_564_ | S26: ='EBITDA - Fx'!G31 -> RECALC_1_568_ | T26: ='EBITDA - Fx'!G32 -> RECALC_1_588_ | U26: ='EBITDA - Fx'!G33 -> RECALC_1_563_

Sheet Cash Generation - Fx
A1: =_xll.VIEW("CONS_VC:DFS.140.Indirect_Cash_Flow",$B$2,"!","!",$B$5,$B$6,'Cash Generation'!$C$7,$B$3) -> CONS_VC:DFS.140.Indirect_Cash_Flow:205767106-2015365241
A2: ALL.D.Year | B2: =_xll.SUBNM("CONS_VC:ALL.D.Year","","2025") -> RECALC_0_7_
A3: DFS.M.140.Indirect_Cash_Flow | B3: =_xll.SUBNM("CONS_VC:DFS.M.140.Indirect_Cash_Flow","","Total Value") -> RECALC_0_535_
A4: DFS.D.Accounts_ICF
A5: ALL.D.Currency | B5: =_xll.SUBNM("CONS_VC:ALL.D.Currency","","BRL Conv.") -> RECALC_0_496_
A6: ALL.D.Region | B6: =_xll.SUBNM("CONS_VC:ALL.D.Region","","Global") -> RECALC_0_495_
B8: Q1 | C8: Q2 | D8: Q3 | E8: Q4
A9: Actual | B9: =_xll.DBRW($A$1,$B$2,B$8,$A9,$B$5,$B$6,'Cash Generation'!$C$7,$B$3) -> RECALC_1_549_ | C9: =_xll.DBRW($A$1,$B$2,C$8,$A9,$B$5,$B$6,'Cash Generation'!$C$7,$B$3) -> RECALC_1_547_ | D9: =_xll.DBRW($A$1,$B$2,D$8,$A9,$B$5,$B$6,'Cash Generation'!$C$7,$B$3) -> RECALC_1_540_ | E9: =_xll.DBRW($A$1,$B$2,E$8,$A9,$B$5,$B$6,'Cash Generation'!$C$7,$B$3) -> RECALC_1_546_
A10: L300 | B10: =_xll.DBRW($A$1,$B$2,B$8,$A10,$B$5,$B$6,'Cash Generation'!$C$7,$B$3) -> RECALC_1_545_ | C10: =_xll.DBRW($A$1,$B$2,C$8,$A10,$B$5,$B$6,'Cash Generation'!$C$7,$B$3) -> RECALC_1_543_ | D10: =_xll.DBRW($A$1,$B$2,D$8,$A10,$B$5,$B$6,'Cash Generation'!$C$7,$B$3) -> RECALC_1_550_ | E10: =_xll.DBRW($A$1,$B$2,E$8,$A10,$B$5,$B$6,'Cash Generation'!$C$7,$B$3) -> RECALC_1_548_
A11: RF | B11: =_xll.DBRW($A$1,$B$2,B$8,$A11,$B$5,$B$6,'Cash Generation'!$C$7,$B$3) -> RECALC_1_541_ | C11: =_xll.DBRW($A$1,$B$2,C$8,$A11,$B$5,$B$6,'Cash Generation'!$C$7,$B$3) -> RECALC_1_544_ | D11: =_xll.DBRW($A$1,$B$2,D$8,$A11,$B$5,$B$6,'Cash Generation'!$C$7,$B$3) -> RECALC_1_542_ | E11: =_xll.DBRW($A$1,$B$2,E$8,$A11,$B$5,$B$6,'Cash Generation'!$C$7,$B$3) -> RECALC_1_538_

Sheet Cash Generation
C7: =_xll.SUBNM("CONS_VC:DFS.D.Accounts_ICF","Default","Cash generation before financing") -> RECALC_0_87_ | AC7: EBIT – Full Year
C8: QoQ Overview

Sheet Menu
A1: Cubo
A2: CONS_VC:DFS.200.KPIs
A3: CONS_VC:DFS.100.Profit_and_loss
A4: CONS_VC:DFS.140.Indirect_Cash_Flow
A5: CONS_VC:DFS.180.Gross_Debt
A6: CONS_VC:REV.100.Revenue_Consolidated
A8: Ano
A9: =_xll.SUBNM("CONS_VC:ALL.D.Year","","2025") -> RECALC_0_7_
A11: Mês
A12: =_xll.SUBNM("CONS_VC:ALL.D.Month",,"Total YTD","MEMBER_NAME") -> RECALC_0_9_
A13: =_xll.SUBNM("CONS_VC:ALL.D.Month",,"Year","MEMBER_NAME") -> RECALC_0_10_
A15: Versão
A18: Currency
A19: =_xll.SUBNM("CONS_VC:ALL.D.Currency","","BRL") -> RECALC_0_8_
A21: Region
A22: =_xll.SUBNM("CONS_VC:ALL.D.Region","","VCBR") -> RECALC_0_6_
A24: Produto
A25: =_xll.SUBNM("CONS_VC:ALL.D.Products","","Total Products") -> RECALC_0_11_
A27: Accounts_PNL
A28: Net Profit
A30: DFM.100.Profil_and_Loss
A31: Value

Sheet Planilha3
A1: =_xll.VIEW("CONS_VC:DFS.100.Profit_and_Loss",'Value Tree TESTE'!$F$3,"!",'Value Tree TESTE'!$H$3,'Value Tree TESTE'!$F$4,'Value Tree TESTE'!$H$4,$B$7,"!",$B$3) -> CONS_VC:DFS.100.Profit_and_Loss:2057671061844175
A2: ALL.D.Year
A3: DFS.M.100.Profit_and_Loss | B3: =_xll.SUBNM("CONS_VC:DFS.M.100.Profit_and_Loss","","Value") -> RECALC_0_122_
A4: ALL.D.Version
A5: ALL.D.Currency
A6: ALL.D.Region
A7: ALL.D.Products | B7: =_xll.SUBNM("CONS_VC:ALL.D.Products","","Total Products") -> RECALC_0_11_
B9: Year
A10: Net Profit
A12: =_xll.VIEW("CONS_VC:DFS.140.Indirect_Cash_Flow",$B$13,$B$14,$B$15,$B$16,$B$17,"!","!") -> CONS_VC:DFS.140.Indirect_Cash_Flow:2057671061262658909
A13: ALL.D.Year | B13: =_xll.SUBNM("CONS_VC:ALL.D.Year","","2025") -> RECALC_0_7_
A14: ALL.D.Month | B14: =_xll.SUBNM("CONS_VC:ALL.D.Month","Default","Jan","Desc") -> RECALC_0_45_
A15: ALL.D.Version | B15: =_xll.SUBNM("CONS_VC:ALL.D.Version","","T4") -> RECALC_0_30_
A16: ALL.D.Currency | B16: =_xll.SUBNM("CONS_VC:ALL.D.Currency","","BRL") -> RECALC_0_8_
A17: ALL.D.Region | B17: =_xll.SUBNM("CONS_VC:ALL.D.Region","","VCBR") -> RECALC_0_6_
B19: Total Value | C19: Value | D19: Adjustments
A20: EBITDA | B20: =_xll.DBRW($A$12,$B$13,$B$14,$B$15,$B$16,$B$17,$A20,B$19) -> RECALC_1_428_ | C20: =_xll.DBRW($A$12,$B$13,$B$14,$B$15,$B$16,$B$17,$A20,C$19) -> RECALC_1_460_ | D20: =_xll.DBRW($A$12,$B$13,$B$14,$B$15,$B$16,$B$17,$A20,D$19) -> RECALC_1_392_
A21: Income tax on transactions | B21: =_xll.DBRW($A$12,$B$13,$B$14,$B$15,$B$16,$B$17,$A21,B$19) -> RECALC_1_268_ | C21: =_xll.DBRW($A$12,$B$13,$B$14,$B$15,$B$16,$B$17,$A21,C$19) -> RECALC_1_212_ | D21: =_xll.DBRW($A$12,$B$13,$B$14,$B$15,$B$16,$B$17,$A21,D$19) -> RECALC_1_344_
A22: Working capital | B22: =_xll.DBRW($A$12,$B$13,$B$14,$B$15,$B$16,$B$17,$A22,B$19) -> RECALC_1_335_ | C22: =_xll.DBRW($A$12,$B$13,$B$14,$B$15,$B$16,$B$17,$A22,C$19) -> RECALC_1_258_ | D22: =_xll.DBRW($A$12,$B$13,$B$14,$B$15,$B$16,$B$17,$A22,D$19) -> RECALC_1_438_
A23: Non expansion capex | B23: =_xll.DBRW($A$12,$B$13,$B$14,$B$15,$B$16,$B$17,$A23,B$19) -> RECALC_1_407_ | C23: =_xll.DBRW($A$12,$B$13,$B$14,$B$15,$B$16,$B$17,$A23,C$19) -> RECALC_1_482_ | D23: =_xll.DBRW($A$12,$B$13,$B$14,$B$15,$B$16,$B$17,$A23,D$19) -> RECALC_1_440_
A24: Dividends received | B24: =_xll.DBRW($A$12,$B$13,$B$14,$B$15,$B$16,$B$17,$A24,B$19) -> RECALC_1_474_ | C24: =_xll.DBRW($A$12,$B$13,$B$14,$B$15,$B$16,$B$17,$A24,C$19) -> RECALC_1_437_ | D24: =_xll.DBRW($A$12,$B$13,$B$14,$B$15,$B$16,$B$17,$A24,D$19) -> RECALC_1_316_
A25: Financial Results | B25: =_xll.DBRW($A$12,$B$13,$B$14,$B$15,$B$16,$B$17,$A25,B$19) -> RECALC_1_485_ | C25: =_xll.DBRW($A$12,$B$13,$B$14,$B$15,$B$16,$B$17,$A25,C$19) -> RECALC_1_176_ | D25: =_xll.DBRW($A$12,$B$13,$B$14,$B$15,$B$16,$B$17,$A25,D$19) -> RECALC_1_424_
A26: Debt Amortization | B26: =_xll.DBRW($A$12,$B$13,$B$14,$B$15,$B$16,$B$17,$A26,B$19) -> RECALC_1_373_ | C26: =_xll.DBRW($A$12,$B$13,$B$14,$B$15,$B$16,$B$17,$A26,C$19) -> RECALC_1_224_ | D26: =_xll.DBRW($A$12,$B$13,$B$14,$B$15,$B$16,$B$17,$A26,D$19) -> RECALC_1_315_
A27: Financial Revenue | B27: =_xll.DBRW($A$12,$B$13,$B$14,$B$15,$B$16,$B$17,$A27,B$19) -> RECALC_1_473_ | C27: =_xll.DBRW($A$12,$B$13,$B$14,$B$15,$B$16,$B$17,$A27,C$19) -> RECALC_1_188_ | D27: =_xll.DBRW($A$12,$B$13,$B$14,$B$15,$B$16,$B$17,$A27,D$19) -> RECALC_1_365_
A28: Other Financial Expenses | B28: =_xll.DBRW($A$12,$B$13,$B$14,$B$15,$B$16,$B$17,$A28,B$19) -> RECALC_1_475_ | C28: =_xll.DBRW($A$12,$B$13,$B$14,$B$15,$B$16,$B$17,$A28,C$19) -> RECALC_1_297_ | D28: =_xll.DBRW($A$12,$B$13,$B$14,$B$15,$B$16,$B$17,$A28,D$19) -> RECALC_1_468_
A29: Derivatives settlement | B29: =_xll.DBRW($A$12,$B$13,$B$14,$B$15,$B$16,$B$17,$A29,B$19) -> RECALC_1_251_ | C29: =_xll.DBRW($A$12,$B$13,$B$14,$B$15,$B$16,$B$17,$A29,C$19) -> RECALC_1_226_ | D29: =_xll.DBRW($A$12,$B$13,$B$14,$B$15,$B$16,$B$17,$A29,D$19) -> RECALC_1_304_
A30: Tax on Financial Revenue | B30: =_xll.DBRW($A$12,$B$13,$B$14,$B$15,$B$16,$B$17,$A30,B$19) -> RECALC_1_278_ | C30: =_xll.DBRW($A$12,$B$13,$B$14,$B$15,$B$16,$B$17,$A30,C$19) -> RECALC_1_326_ | D30: =_xll.DBRW($A$12,$B$13,$B$14,$B$15,$B$16,$B$17,$A30,D$19) -> RECALC_1_423_
A31: Other | B31: =_xll.DBRW($A$12,$B$13,$B$14,$B$15,$B$16,$B$17,$A31,B$19) -> RECALC_1_400_ | C31: =_xll.DBRW($A$12,$B$13,$B$14,$B$15,$B$16,$B$17,$A31,C$19) -> RECALC_1_217_ | D31: =_xll.DBRW($A$12,$B$13,$B$14,$B$15,$B$16,$B$17,$A31,D$19) -> RECALC_1_168_
... A44: Funding | B44: =_xll.DBRW($A$12,$B$13,$B$14,$B$15,$B$16,$B$17,$A44,B$19) -> RECALC_1_381_ | C44: =_xll.DBRW($A$12,$B$13,$B$14,$B$15,$B$16,$B$17,$A44,C$19) -> RECALC_1_271_ | D44: =_xll.DBRW($A$12,$B$13,$B$14,$B$15,$B$16,$B$17,$A44,D$19) -> RECALC_1_206_
A45: Change in cash | C45: =_xll.DBRW($A$12,$B$13,$B$14,$B$15,$B$16,$B$17,$A45,C$19) -> RECALC_1_261_ | D45: =_xll.DBRW($A$12,$B$13,$B$14,$B$15,$B$16,$B$17,$A45,D$19) -> RECALC_1_353_
A46: Initial Cash Balance | B46: =_xll.DBRW($A$12,$B$13,$B$14,$B$15,$B$16,$B$17,$A46,B$19) -> RECALC_1_185_ | C46: =_xll.DBRW($A$12,$B$13,$B$14,$B$15,$B$16,$B$17,$A46,C$19) -> RECALC_1_413_ | D46: =_xll.DBRW($A$12,$B$13,$B$14,$B$15,$B$16,$B$17,$A46,D$19) -> RECALC_1_361_
A47: Final Cash Position | B47: =_xll.DBRW($A$12,$B$13,$B$14,$B$15,$B$16,$B$17,$A47,B$19) -> RECALC_1_230_ | C47: =_xll.DBRW($A$12,$B$13,$B$14,$B$15,$B$16,$B$17,$A47,C$19) -> RECALC_1_331_ | D47: =_xll.DBRW($A$12,$B$13,$B$14,$B$15,$B$16,$B$17,$A47,D$19) -> RECALC_1_219_
A48: Final Cash Position Aux | B48: =_xll.DBRW($A$12,$B$13,$B$14,$B$15,$B$16,$B$17,$A48,B$19) -> RECALC_1_355_ | C48: =_xll.DBRW($A$12,$B$13,$B$14,$B$15,$B$16,$B$17,$A48,C$19) -> RECALC_1_254_ | D48: =_xll.DBRW($A$12,$B$13,$B$14,$B$15,$B$16,$B$17,$A48,D$19) -> RECALC_1_457_
A49: Final Debt Position | B49: =_xll.DBRW($A$12,$B$13,$B$14,$B$15,$B$16,$B$17,$A49,B$19) -> RECALC_1_402_ | C49: =_xll.DBRW($A$12,$B$13,$B$14,$B$15,$B$16,$B$17,$A49,C$19) -> RECALC_1_463_ | D49: =_xll.DBRW($A$12,$B$13,$B$14,$B$15,$B$16,$B$17,$A49,D$19) -> RECALC_1_272_
A50: MTM | B50: =_xll.DBRW($A$12,$B$13,$B$14,$B$15,$B$16,$B$17,$A50,B$19) -> RECALC_1_264_ | C50: =_xll.DBRW($A$12,$B$13,$B$14,$B$15,$B$16,$B$17,$A50,C$19) -> RECALC_1_253_ | D50: =_xll.DBRW($A$12,$B$13,$B$14,$B$15,$B$16,$B$17,$A50,D$19) -> RECALC_1_169_
A51: Final Net Debt | B51: =_xll.DBRW($A$12,$B$13,$B$14,$B$15,$B$16,$B$17,$A51,B$19) -> RECALC_1_340_ | C51: =_xll.DBRW($A$12,$B$13,$B$14,$B$15,$B$16,$B$17,$A51,C$19) -> RECALC_1_209_ | D51: =_xll.DBRW($A$12,$B$13,$B$14,$B$15,$B$16,$B$17,$A51,D$19) -> RECALC_1_414_
A52: Adj EBITDA LTM | B52: =_xll.DBRW($A$12,$B$13,$B$14,$B$15,$B$16,$B$17,$A52,B$19) -> RECALC_1_374_ | C52: =_xll.DBRW($A$12,$B$13,$B$14,$B$15,$B$16,$B$17,$A52,C$19) -> RECALC_1_421_ | D52: =_xll.DBRW($A$12,$B$13,$B$14,$B$15,$B$16,$B$17,$A52,D$19) -> RECALC_1_443_
A53: Adjusts LTM | B53: =_xll.DBRW($A$12,$B$13,$B$14,$B$15,$B$16,$B$17,$A53,B$19) -> RECALC_1_358_ | C53: =_xll.DBRW($A$12,$B$13,$B$14,$B$15,$B$16,$B$17,$A53,C$19) -> RECALC_1_229_ | D53: =_xll.DBRW($A$12,$B$13,$B$14,$B$15,$B$16,$B$17,$A53,D$19) -> RECALC_1_493_
A54: Leverage | B54: =_xll.DBRW($A$12,$B$13,$B$14,$B$15,$B$16,$B$17,$A54,B$19) -> RECALC_1_284_ | C54: =_xll.DBRW($A$12,$B$13,$B$14,$B$15,$B$16,$B$17,$A54,C$19) -> RECALC_1_282_ | D54: =_xll.DBRW($A$12,$B$13,$B$14,$B$15,$B$16,$B$17,$A54,D$19) -> RECALC_1_262_
A56: CONS_VC:DFS.200.KPIs
...

Sheet Planilha1
A1: =_xll.VIEW("CONS_VC:DFS.200.KPIs",$B$2,$B$3,$B$4,$B$5,$B$6,$B$7,"!","!") -> CONS_VC:DFS.200.KPIs:205767106-1430385332
A2: ALL.D.Year | B2: =_xll.SUBNM("CONS_VC:ALL.D.Year","","2025") -> RECALC_0_7_
A3: ALL.D.Month | B3: =_xll.SUBNM("CONS_VC:ALL.D.Month","Default","Jan","Desc") -> RECALC_0_45_
A4: ALL.D.Version | B4: =_xll.SUBNM("CONS_VC:ALL.D.Version","","T4") -> RECALC_0_30_
A5: ALL.D.Currency | B5: =_xll.SUBNM("CONS_VC:ALL.D.Currency","Default","BRL","MEMBER_NAME") -> RECALC_0_33_
A6: ALL.D.Region | B6: =_xll.SUBNM("CONS_VC:ALL.D.Region","","VCBR") -> RECALC_0_6_
A7: ALL.D.Products | B7: =_xll.SUBNM("CONS_VC:ALL.D.Products","Default","PROD099 - Others","Código e Descrição") -> RECALC_0_67_
B9: Value | C9: Aux
A10: Production volume (kt) | B10: =_xll.DBRW($A$1,$B$2,$B$3,$B$4,$B$5,$B$6,$B$7,$A10,B$9) -> RECALC_1_296_ | C10: =_xll.DBRW($A$1,$B$2,$B$3,$B$4,$B$5,$B$6,$B$7,$A10,C$9) -> RECALC_1_325_
A11: Thermal Sub. (%) | B11: =_xll.DBRW($A$1,$B$2,$B$3,$B$4,$B$5,$B$6,$B$7,$A11,B$9) -> RECALC_1_389_ | C11: =_xll.DBRW($A$1,$B$2,$B$3,$B$4,$B$5,$B$6,$B$7,$A11,C$9) -> RECALC_1_489_
A12: Thermal C. (kcal/t kk) | B12: =_xll.DBRW($A$1,$B$2,$B$3,$B$4,$B$5,$B$6,$B$7,$A12,B$9) -> RECALC_1_323_ | C12: =_xll.DBRW($A$1,$B$2,$B$3,$B$4,$B$5,$B$6,$B$7,$A12,C$9) -> RECALC_1_246_
A13: Petcoke Price (LMU/t) | B13: =_xll.DBRW($A$1,$B$2,$B$3,$B$4,$B$5,$B$6,$B$7,$A13,B$9) -> RECALC_1_267_ | C13: =_xll.DBRW($A$1,$B$2,$B$3,$B$4,$B$5,$B$6,$B$7,$A13,C$9) -> RECALC_1_306_
A14: CO2 Gross (kg/ton) | B14: =_xll.DBRW($A$1,$B$2,$B$3,$B$4,$B$5,$B$6,$B$7,$A14,B$9) -> RECALC_1_177_ | C14: =_xll.DBRW($A$1,$B$2,$B$3,$B$4,$B$5,$B$6,$B$7,$A14,C$9) -> RECALC_1_270_
A15: CO2 Net (kg/ton) | B15: =_xll.DBRW($A$1,$B$2,$B$3,$B$4,$B$5,$B$6,$B$7,$A15,B$9) -> RECALC_1_470_ | C15: =_xll.DBRW($A$1,$B$2,$B$3,$B$4,$B$5,$B$6,$B$7,$A15,C$9) -> RECALC_1_294_
A16: Power Price (LMU/MWh) | B16: =_xll.DBRW($A$1,$B$2,$B$3,$B$4,$B$5,$B$6,$B$7,$A16,B$9) -> RECALC_1_241_ | C16: =_xll.DBRW($A$1,$B$2,$B$3,$B$4,$B$5,$B$6,$B$7,$A16,C$9) -> RECALC_1_399_
A17: Power Cons. (kWh/t) | B17: =_xll.DBRW($A$1,$B$2,$B$3,$B$4,$B$5,$B$6,$B$7,$A17,B$9) -> RECALC_1_277_ | C17: =_xll.DBRW($A$1,$B$2,$B$3,$B$4,$B$5,$B$6,$B$7,$A17,C$9) -> RECALC_1_431_
A18: Clinker Factor (%) | B18: =_xll.DBRW($A$1,$B$2,$B$3,$B$4,$B$5,$B$6,$B$7,$A18,B$9) -> RECALC_1_210_ | C18: =_xll.DBRW($A$1,$B$2,$B$3,$B$4,$B$5,$B$6,$B$7,$A18,C$9) -> RECALC_1_321_
A19: Cash Cost (LMU/t) | B19: =_xll.DBRW($A$1,$B$2,$B$3,$B$4,$B$5,$B$6,$B$7,$A19,B$9) -> RECALC_1_371_ | C19: =_xll.DBRW($A$1,$B$2,$B$3,$B$4,$B$5,$B$6,$B$7,$A19,C$9) -> RECALC_1_252_
A20: Cement Var. Costs (LMU/t) | B20: =_xll.DBRW($A$1,$B$2,$B$3,$B$4,$B$5,$B$6,$B$7,$A20,B$9) -> RECALC_1_222_ | C20: =_xll.DBRW($A$1,$B$2,$B$3,$B$4,$B$5,$B$6,$B$7,$A20,C$9) -> RECALC_1_337_
A21: Fuel (LMU/t) | B21: =_xll.DBRW($A$1,$B$2,$B$3,$B$4,$B$5,$B$6,$B$7,$A21,B$9) -> RECALC_1_487_ | C21: =_xll.DBRW($A$1,$B$2,$B$3,$B$4,$B$5,$B$6,$B$7,$A21,C$9) -> RECALC_1_202_
... A58: % ROIC | B58: =_xll.DBRW($A$1,$B$2,$B$3,$B$4,$B$5,$B$6,$B$7,$A58,B$9) -> RECALC_1_309_ | C58: =_xll.DBRW($A$1,$B$2,$B$3,$B$4,$B$5,$B$6,$B$7,$A58,C$9) -> RECALC_1_471_

Sheet Planilha2
B2: Cement Net FOB (€/t) | C2: Preço do Cimento | D2: Cobo de Receita | E2: Produto Cimento
B3: SG&A (€M) | C3: ZBB total

Sheet Value Tree TESTE
C1: 9 | M1: IFRS16 adj
A2: Cubo
A3: CONS_VC:DFS.200.KPIs | K3: + | M3: YTD | O3: FY | R3: + | T3: YTD | V3: FY | Y3: + | AA3: YTD | AC3: FY | AF3: - | AH3: YTD | AJ3: FY | AM3: + | AO3: YTD | AQ3: FY
A4: CONS_VC:DFS.100.Profit_and_loss | L4: Net Debt (€M) | S4: Net Rev. (€M) | Z4: Cement Volume (kt) | AG4: Fuel (€/t) | AN4: Thermal Sub. (%)
A5: CONS_VC:DFS.140.Indirect_Cash_Flow | B5: =B7 -> 0 | K5: =A17 -> RECALC_0_5_ | L5: =L7 -> 1 | M5: {=_xll.DBRW('Value Tree TESTE'!A6,A10,A13,K5,A20,A23,"Closing Balance Debt","Total Value")} -> RECALC_1_227_ | N5: =N7 -> 1 | O5: {=_xll.DBRW('Value Tree TESTE'!A6,A10,A14,K5,A20,A23,"Closing Balance Debt","Total Value")} -> RECALC_1_456_ | R5: =A17 -> RECALC_0_5_ | S5: =S7 -> 0 | T5: {=_xll.DBR(A4,A10,A13,R5,A20,A23,"PROD099 - Others","Net Revenue","Value")} -> RECALC_1_305_ | U5: =U7 -> -1 | V5: {=_xll.DBR(A4,A10,A14,R5,A20,A23,"PROD099 - Others","Net Revenue","Value")} -> RECALC_1_288_ | Y5: =A17 -> RECALC_0_5_ | Z5: =Z7 -> 1 | AA5: =_xll.DBRW(A3,A10,A13,Y5,A20,A23,"PROD099 - Others","Volume","Value") -> RECALC_1_425_ | AB5: =AB7 -> 0 | AC5: =_xll.DBRW(A3,A10,A14,Y5,A20,A23,"PROD099 - Others","Volume","Value") -> RECALC_1_426_ | AF5: =A17 -> RECALC_0_5_ | AG5: =AG7 -> #VALUE! | AH5: =_xll.DBRW('Value Tree TESTE'!A3,A10,A13,AF5,A20,A23,"PROD099 - Others","Fuel (LMU/t)","Value") -> RECALC_1_303_ | AI5: =AI7 -> #VALUE! | AJ5: =_xll.DBRW('Value Tree TESTE'!A3,A10,A14,AF5,A20,A23,"PROD099 - Others","Fuel (LMU/t)","Value") -> RECALC_1_386_ | AM5: =A17 -> RECALC_0_5_ | AN5: =AN7 -> #VALUE! | AO5: =_xll.DBRW('Value Tree TESTE'!A3,A10,A13,AM5,A20,A23,"PROD099 - Others","Thermal Sub. (%)","Value") -> RECALC_1_266_ | AP5: =AP7 -> #REF! | AQ5: =_xll.DBRW('Value Tree TESTE'!A3,A10,A14,AM5,A20,A23,"PROD099 - Others","Thermal Sub. (%)","Value") -> RECALC_1_244_ | AS5: 54.4 | AT5: #REF!
A6: CONS_VC:DFS.180.Gross_Debt | B6: =B7 -> 0 | K6: =A18 -> RECALC_0_4_ | L6: =L7 -> 1 | M6: {=_xll.DBRW('Value Tree TESTE'!A6,A10,A13,K6,A20,A23,"Closing Balance Debt","Total Value")} -> RECALC_1_171_ | N6: =N7 -> 1 | O6: {=_xll.DBRW('Value Tree TESTE'!A6,A10,A14,K6,A20,A23,"Closing Balance Debt","Total Value")} -> RECALC_1_260_ | R6: =A18 -> RECALC_0_4_ | S6: =S7 -> 0 | T6: {=_xll.DBR(A4,A10,A13,R6,A20,A23,"PROD099 - Others","Net Revenue","Value")} -> RECALC_1_175_ | U6: =U7 -> -1 | V6: {=_xll.DBR(A4,A10,A14,R6,A20,A23,"PROD099 - Others","Net Revenue","Value")} -> RECALC_1_416_ | Y6: =A18 -> RECALC_0_4_ | Z6: =Z7 -> 1 | AA6: =_xll.DBRW(A3,A10,A13,Y6,A20,A23,"PROD099 - Others","Volume","Value") -> RECALC_1_184_ | AB6: =AB7 -> 0 | AC6: =_xll.DBRW(A3,A10,A14,Y6,A20,A23,"PROD099 - Others","Volume","Value") -> RECALC_1_191_ | AF6: =A18 -> RECALC_0_4_ | AG6: =AG7 -> #VALUE! | AH6: =_xll.DBRW('Value Tree TESTE'!A3,A10,A13,AF6,A20,A23,"PROD099 - Others","Fuel (LMU/t)","Value") -> RECALC_1_276_ | AI6: =AI7 -> #VALUE! | AJ6: =_xll.DBRW('Value Tree TESTE'!A3,A10,A14,AF6,A20,A23,"PROD099 - Others","Fuel (LMU/t)","Value") -> RECALC_1_395_ | AM6: =A18 -> RECALC_0_4_ | AN6: =AN7 -> #VALUE! | AO6: =_xll.DBRW('Value Tree TESTE'!A3,A10,A13,AM6,A20,A23,"PROD099 - Others","Thermal Sub. (%)","Value") -> RECALC_1_320_ | AP6: =AP7 -> #REF! | AQ6: =_xll.DBRW('Value Tree TESTE'!A3,A10,A14,AM6,A20,A23,"PROD099 - Others","Thermal Sub. (%)","Value") -> RECALC_1_376_ | AS6: 54.5 | AT6: #REF!
A7: CONS_VC:REV.100.Revenue_Consolidated | K7: L500 | L7: =IF(K3="+",IF(M5>M7,1,IF(M5>=M6,0,-1)),IF(K3="-",IF(M5<M7,1,IF(M5<=M6,0,-1)))) -> 1 | M7: {=_xll.DBRW('Value Tree TESTE'!A6,A10,A13,K7,A20,A23,"Closing Balance Debt","Total Value")} -> RECALC_1_140_ | N7: =IF(K3="+",IF(O5>O7,1,IF(O5>=O6,0,-1)),IF(K3="-",IF(O5<O7,1,IF(O5<=O6,0,-1)))) -> 1 | O7: {=_xll.DBRW('Value Tree TESTE'!A6,A10,A14,K7,A20,A23,"Closing Balance Debt","Total Value")} -> RECALC_1_141_ | R7: L500 | S7: =IF(R3="+",IF(T5>T7,1,IF(T5>=T6,0,-1)),IF(R3="-",IF(T5<T7,1,IF(T5<=T6,0,-1)))) -> 0 | T7: {=_xll.DBR(A4,A10,A13,R7,A20,A23,"PROD099 - Others","Net Revenue","Value")} -> RECALC_1_78_ | U7: =IF(R3="+",IF(V5>V7,1,IF(V5>=V6,0,-1)),IF(R3="-",IF(V5<V7,1,IF(V5<=V6,0,-1)))) -> -1 | V7: {=_xll.DBR(A4,A10,A14,R7,A20,A23,"PROD099 - Others","Net Revenue","Value")} -> RECALC_1_82_ | Y7: L500 | Z7: =IF(Y3="+",IF(AA5>AA7,1,IF(AA5>=AA6,0,-1)),IF(Y3="-",IF(AA5<AA7,1,IF(AA5<=AA6,0,-1)))) -> 1 | AA7: =_xll.DBRW(A3,A10,A13,Y7,A20,A23,"PROD099 - Others","Volume","Value") -> RECALC_1_145_ | AB7: =IF(Y3="+",IF(AC5>AC7,1,IF(AC5>=AC6,0,-1)),IF(Y3="-",IF(AC5<AC7,1,IF(AC5<=AC6,0,-1)))) -> 0 | AC7: =_xll.DBRW(A3,A10,A14,Y7,A20,A23,"PROD099 - Others","Volume","Value") -> RECALC_1_79_ | AF7: L500 | AG7: =IF(AF3="+",IF(AH5>AH7*(1+IF(AH7>0,$C$4,-$C$4)),0,IF(AH5>=AH6*(1+IF(AH6>0,-$C$4,$C$4)),0,-1)),IF(AF3="-",IF(AH5<AH7*(1+IF(AH7>0,-$C$4,$C$4)),0,IF(AH5<=AH6*(1+IF(AH6>0,$C$4,-$C$4)),0,-1)))) -> #VALUE! | AH7: =_xll.DBRW('Value Tree TESTE'!A3,A10,A13,AF7,A20,A23,"PROD099 - Others","Fuel (LMU/t)","Value") -> RECALC_1_111_ | AI7: =IF(AF3="+",IF(AJ5>AJ7*(1+IF(AJ7>0,$C$4,-$C$4)),0,IF(AJ5>=AJ6*(1+IF(AJ6>0,-$C$4,$C$4)),0,-1)),IF(AF3="-",IF(AJ5<AJ7*(1+IF(AJ7>0,-$C$4,$C$4)),0,IF(AJ5<=AJ6*(1+IF(AJ6>0,$C$4,-$C$4)),0,-1)))) -> #VALUE! | AJ7: =_xll.DBRW('Value Tree TESTE'!A3,A10,A14,AF7,A20,A23,"PROD099 - Others","Fuel (LMU/t)","Value") -> RECALC_1_138_ | AM7: L500 | AN7: =IF(AM3="+",IF(AO5>AO7*(1+IF(AO7>0,$C$4,-$C$4)),1,IF(AO5>=AO6*(1+IF(AO6>0,-$C$4,$C$4)),0,-1)),IF(AM3="-",IF(AO5<AO7*(1+IF(AO7>0,-$C$4,$C$4)),1,IF(AO5<=AO6*(1+IF(AO6>0,$C$4,-$C$4)),0,-1)))) -> #VALUE! | AO7: =_xll.DBRW('Value Tree TESTE'!A3,A10,A13,AM7,A20,A23,"PROD099 - Others","Thermal Sub. (%)","Value") -> RECALC_1_144_ | AP7: =IF(AM3="+",IF(AT5>AQ7*(1+IF(AQ7>0,$C$4,-$C$4)),0,IF(AT5>=AT6*(1+IF(AT6>0,-$C$4,$C$4)),0,-1)),IF(AM3="-",IF(AT5<AQ7*(1+IF(AQ7>0,-$C$4,$C$4)),0,IF(AT5<=AT6*(1+IF(AT6>0,$C$4,-$C$4)),0,-1)))) -> #REF! | AQ7: =_xll.DBRW('Value Tree TESTE'!A3,A10,A14,AM7,A20,A23,"PROD099 - Others","Thermal Sub. (%)","Value") -> RECALC_1_83_
AS8: 5
A9: Ano | D9: + | F9: YTD | H9: FY | K9: + | M9: YTD | O9: FY | R9: + | T9: YTD | V9: FY | Y9: + | AA9: YTD | AC9: FY | AF9: - | AH9: YTD | AJ9: FY | AM9: - | AO9: YTD | AQ9: FY
A10: =_xll.SUBNM("CONS_VC:ALL.D.Year","","2025") -> RECALC_0_7_ | E10: Net Profit (€M) | F10: Net Profit (€M) | L10: EBITDA (€M) | S10: EBITDA Oth. BUs. (€M) | Z10: Cement Net FOB (€/t) | AG10: CO2 Gross (kg/ton) | AN10: Thermal C. (kcal/t kk)
D11: =A17 -> RECALC_0_5_ | E11: =E13 -> #REF! | F11: =_xll.DBRW('Value Tree TESTE'!A4,'Value Tree TESTE'!A10,'Value Tree TESTE'!A13,D11,'Value Tree TESTE'!A20,'Value Tree TESTE'!A23,'Value Tree TESTE'!A26,'Value Tree TESTE'!A29,A36) -> RECALC_1_439_ | G11: =G13 -> #VALUE! | H11: =_xll.DBRW('Value Tree TESTE'!A4,'Value Tree TESTE'!A10,'Value Tree TESTE'!A14,D11,'Value Tree TESTE'!A20,'Value Tree TESTE'!A23,'Value Tree TESTE'!A26,'Value Tree TESTE'!A29,A36) -> RECALC_1_172_ | K11: =A17 -> RECALC_0_5_ | L11: =L13 -> #VALUE! | M11: =_xll.DBRW('Value Tree TESTE'!A3,A10,A13,K11,A20,A23,"PROD099 - Others","EBITDA LTM","Value") -> RECALC_1_388_ | N11: =N13 -> #VALUE! | O11: =_xll.DBRW('Value Tree TESTE'!A3,A10,A14,K11,A20,A23,"PROD099 - Others","EBITDA LTM","Value") -> RECALC_1_446_ | R11: =A17 -> RECALC_0_5_ | S11: =S13 -> #VALUE! | T11: =_xll.DBRW('Value Tree TESTE'!A3,A10,A13,R11,A20,A23,"Total Products","EBITDA LTM","Value")-_xll.DBRW('Value Tree TESTE'!A3,A10,A13,R11,A20,A23,"PRODCE010 - Cement","EBITDA LTM","Value") -> #VALUE! | U11: =U13 -> #VALUE! | V11: =_xll.DBRW('Value Tree TESTE'!A3,A10,A14,R11,A20,A23,"Total Products","EBITDA LTM","Value")-_xll.DBRW('Value Tree TESTE'!A3,A10,A14,R11,A20,A23,"PRODCE010 - Cement","EBITDA LTM","Value") -> #VALUE! | Y11: =A17 -> RECALC_0_5_ | Z11: =Z13 -> #VALUE! | AA11: {=_xll.DBRW(A7,A10,A13,Y11,A20,A23,"PROD099","Total Market","Reference Price [$/ton]")} -> RECALC_1_476_ | AB11: =AB13 -> #VALUE! | AC11: {=_xll.DBRW(A7,A10,A14,Y11,A20,A23,"PROD099","Total Market","Reference Price [$/ton]")} -> RECALC_1_398_ | AF11: =A17 -> RECALC_0_5_ | AG11: =AG13 -> #VALUE! | AH11: =_xll.DBRW('Value Tree TESTE'!A3,A10,A13,AF11,A20,A23,"PROD099 - Others","CO2 Gross (kg/ton)","Value") -> RECALC_1_391_ | AI11: =AI13 -> #VALUE! | AJ11: =_xll.DBRW('Value Tree TESTE'!A3,A10,A14,AF11,A20,A23,"PROD099 - Others","CO2 Gross (kg/ton)","Value") -> RECALC_1_302_ | AM11: =A17 -> RECALC_0_5_ | AN11: =AN13 -> #VALUE! | AO11: =_xll.DBRW(A3,A10,A13,AM11,A20,A23,"PROD099 - Others","Thermal C. (kcal/t kk)","Value") -> RECALC_1_432_ | AP11: =AP13 -> #REF! | AQ11: =_xll.DBRW(A3,A10,A14,AM11,A20,A23,"PROD099 - Others","Thermal C. (kcal/t kk)","Value") -> RECALC_1_237_ | AS11: 812 | AT11: #REF!
A12: Mês | D12: =A18 -> RECALC_0_4_ | E12: =E13 -> #REF! | F12: =_xll.DBRW('Value Tree TESTE'!A4,'Value Tree TESTE'!A10,'Value Tree TESTE'!A13,D12,'Value Tree TESTE'!A20,'Value Tree TESTE'!A23,'Value Tree TESTE'!A26,'Value Tree TESTE'!A29,A36) -> RECALC_1_369_ | G12: =G13 -> #VALUE! | H12: =_xll.DBRW('Value Tree TESTE'!A4,'Value Tree TESTE'!A10,'Value Tree TESTE'!A14,D12,'Value Tree TESTE'!A20,'Value Tree TESTE'!A23,'Value Tree TESTE'!A26,'Value Tree TESTE'!A29,A36) -> RECALC_1_201_ | K12: =A18 -> RECALC_0_4_ | L12: =L13 -> #VALUE! | M12: =_xll.DBRW('Value Tree TESTE'!A3,A10,A13,K12,A20,A23,"PROD099 - Others","EBITDA LTM","Value") -> RECALC_1_225_ | N12: =N13 -> #VALUE! | O12: =_xll.DBRW('Value Tree TESTE'!A3,A10,A14,K12,A20,A23,"PROD099 - Others","EBITDA LTM","Value") -> RECALC_1_377_ | R12: =A18 -> RECALC_0_4_ | S12: =S13 -> #VALUE! | T12: =_xll.DBRW('Value Tree TESTE'!A3,A10,A13,R12,A20,A23,"Total Products","EBITDA LTM","Value")-_xll.DBRW('Value Tree TESTE'!A3,A10,A13,R12,A20,A23,"PRODCE010 - Cement","EBITDA LTM","Value") -> #VALUE! | U12: =U13 -> #VALUE! | V12: =_xll.DBRW('Value Tree TESTE'!A3,A10,A14,R12,A20,A23,"Total Products","EBITDA LTM","Value")-_xll.DBRW('Value Tree TESTE'!A3,A10,A14,R12,A20,A23,"PRODCE010 - Cement","EBITDA LTM","Value") -> #VALUE! | Y12: =A18 -> RECALC_0_4_ | Z12: =Z13 -> #VALUE! | AA12: {=_xll.DBRW(A7,A10,A13,Y12,A20,A23,"PROD099","Total Market","Reference Price [$/ton]")} -> RECALC_1_319_ | AB12: =AB13 -> #VALUE! | AC12: {=_xll.DBRW(A7,A10,A14,Y12,A20,A23,"PROD099","Total Market","Reference Price [$/ton]")} -> RECALC_1_417_ | AF12: =A18 -> RECALC_0_4_ | AG12: =AG13 -> #VALUE! | AH12: =_xll.DBRW('Value Tree TESTE'!A3,A10,A13,AF12,A20,A23,"PROD099 - Others","CO2 Gross (kg/ton)","Value") -> RECALC_1_181_ | AI12: =AI13 -> #VALUE! | AJ12: =_xll.DBRW('Value Tree TESTE'!A3,A10,A14,AF12,A20,A23,"PROD099 - Others","CO2 Gross (kg/ton)","Value") -> RECALC_1_363_ | AM12: =A18 -> RECALC_0_4_ | AN12: =AN13 -> #VALUE! | AO12: =_xll.DBRW(A3,A10,A13,AM12,A20,A23,"PROD099 - Others","Thermal C. (kcal/t kk)","Value") -> RECALC_1_408_ | AP12: =AP13 -> #REF! | AQ12: =_xll.DBRW(A3,A10,A14,AM12,A20,A23,"PROD099 - Others","Thermal C. (kcal/t kk)","Value") -> RECALC_1_214_ | AS12: 810 | AT12: #REF!
