Workbook
Name Current_year: #REF!
Name CurrentForecast: #REF!
Name CurrentForecast: #REF!
Name CurrentMonth: #REF!
Name CurrentMonth: #REF!
Name Currentyear: #REF!
Name CurrentYear: #REF!
Name mes: #REF!
Name Month: #REF!
Name MonthName: #REF!
Name PriorYear: #REF!
Name PriorYear: #REF!

Sheet Value Tree
A2: Cubo
A3: CONS_VC:DFS.200.KPIs | J3: + | L3: YTD | N3: FY | Q3: + | S3: YTD | U3: FY | X3: + | Z3: YTD | AB3: FY | AE3: - | AG3: YTD | AI3: FY | AL3: + | AN3: YTD | AP3: FY
A4: CONS_VC:DFS.100.Profit_and_loss | K4: Net Debt (€M) | R4: Net Rev. (€M) | Y4: Cement Volume (kt) | AF4: Fuel (€/t) | AM4: Thermal Sub. (%)
A5: CONS_VC:DFS.140.Indirect_Cash_Flow | J5: =A17 -> RF | L5: {=_xll.DBRW('Value Tree'!A6,A10,A13,J5,A20,A23,"Closing Balance Debt","Total Value")} -> -1540.8011 | N5: {=_xll.DBRW('Value Tree'!A6,A10,A14,J5,A20,A23,"Closing Balance Debt","Total Value")} -> -1481.8973 | Q5: =A17 -> RF | S5: {=_xll.DBR(A4,A10,A13,Q5,A20,A23,A26,"Net Revenue","Value")} -> 53.485063 | U5: {=_xll.DBR(A4,A10,A14,Q5,A20,A23,A26,"Net Revenue","Value")} -> 1607.961 | X5: =A17 -> RF | Z5: =_xll.DBRW(A3,A10,A13,X5,A20,A23,"Cement Group","Volume","Value") -> 207.21655 | AB5: =_xll.DBRW(A3,A10,A14,X5,A20,A23,"Cement Group","Volume","Value") -> 5974.9683 | AE5: =A17 -> RF | AG5: =_xll.DBRW('Value Tree'!A3,A10,A13,AE5,A20,A23,"Cement Group","Fuel (LMU/t)","Value") -> 0 | AI5: =_xll.DBRW('Value Tree'!A3,A10,A14,AE5,A20,A23,"Cement Group","Fuel (LMU/t)","Value") -> 0 | AL5: =A17 -> RF | AN5: =_xll.DBRW('Value Tree'!A3,A10,A13,AL5,A20,A23,"Cement Group","Thermal Sub. (%)","Value") -> 0 | AP5: =_xll.DBRW('Value Tree'!A3,A10,A14,AL5,A20,A23,"Cement Group","Thermal Sub. (%)","Value") -> 0 | AR5: 54.4 | AS5: #REF!
A6: CONS_VC:DFS.180.Gross_Debt | J6: =A18 -> L300 | L6: {=_xll.DBRW('Value Tree'!A6,A10,A13,J6,A20,A23,"Closing Balance Debt","Total Value")} -> 0 | N6: {=_xll.DBRW('Value Tree'!A6,A10,A14,J6,A20,A23,"Closing Balance Debt","Total Value")} -> 0 | Q6: =A18 -> L300 | S6: {=_xll.DBR(A4,A10,A13,Q6,A20,A23,A26,"Net Revenue","Value")} -> 0 | U6: {=_xll.DBR(A4,A10,A14,Q6,A20,A23,A26,"Net Revenue","Value")} -> 0 | X6: =A18 -> L300 | Z6: =_xll.DBRW(A3,A10,A13,X6,A20,A23,"Cement Group","Volume","Value") -> 0 | AB6: =_xll.DBRW(A3,A10,A14,X6,A20,A23,"Cement Group","Volume","Value") -> 0 | AE6: =A18 -> L300 | AG6: =_xll.DBRW('Value Tree'!A3,A10,A13,AE6,A20,A23,"Cement Group","Fuel (LMU/t)","Value") -> 0 | AI6: =_xll.DBRW('Value Tree'!A3,A10,A14,AE6,A20,A23,"Cement Group","Fuel (LMU/t)","Value") -> 0 | AL6: =A18 -> L300 | AN6: =_xll.DBRW('Value Tree'!A3,A10,A13,AL6,A20,A23,"Cement Group","Thermal Sub. (%)","Value") -> 0 | AP6: =_xll.DBRW('Value Tree'!A3,A10,A14,AL6,A20,A23,"Cement Group","Thermal Sub. (%)","Value") -> 0 | AR6: 54.5 | AS6: #REF!
A7: CONS_VC:REV.100.Revenue_Consolidated | J7: L500 | K7: =IF(J3="+",IF(L5>L7,1,IF(L5>=L6,0,-1)),IF(J3="-",IF(L5<L7,1,IF(L5<=L6,0,-1)))) -> -1 | L7: {=_xll.DBRW('Value Tree'!A6,A10,A13,J7,A20,A23,"Closing Balance Debt","Total Value")} -> 0 | M7: =IF(J3="+",IF(N5>N7,1,IF(N5>=N6,0,-1)),IF(J3="-",IF(N5<N7,1,IF(N5<=N6,0,-1)))) -> -1 | N7: {=_xll.DBRW('Value Tree'!A6,A10,A14,J7,A20,A23,"Closing Balance Debt","Total Value")} -> 0 | Q7: L500 | R7: =IF(Q3="+",IF(S5>S7,1,IF(S5>=S6,0,-1)),IF(Q3="-",IF(S5<S7,1,IF(S5<=S6,0,-1)))) -> 1 | S7: {=_xll.DBR(A4,A10,A13,Q7,A20,A23,A26,"Net Revenue","Value")} -> 0 | T7: =IF(Q3="+",IF(U5>U7,1,IF(U5>=U6,0,-1)),IF(Q3="-",IF(U5<U7,1,IF(U5<=U6,0,-1)))) -> 1 | U7: {=_xll.DBR(A4,A10,A14,Q7,A20,A23,A26,"Net Revenue","Value")} -> 0 | X7: L500 | Y7: =IF(X3="+",IF(Z5>Z7,1,IF(Z5>=Z6,0,-1)),IF(X3="-",IF(Z5<Z7,1,IF(Z5<=Z6,0,-1)))) -> 1 | Z7: =_xll.DBRW(A3,A10,A13,X7,A20,A23,"Cement Group","Volume","Value") -> 0 | AA7: =IF(X3="+",IF(AB5>AB7,1,IF(AB5>=AB6,0,-1)),IF(X3="-",IF(AB5<AB7,1,IF(AB5<=AB6,0,-1)))) -> 1 | AB7: =_xll.DBRW(A3,A10,A14,X7,A20,A23,"Cement Group","Volume","Value") -> 0 | AE7: L500 | AF7: =IF(AE3="+",IF(AG5>AG7*(1+IF(AG7>0,$B$4,-$B$4)),0,IF(AG5>=AG6*(1+IF(AG6>0,-$B$4,$B$4)),0,-1)),IF(AE3="-",IF(AG5<AG7*(1+IF(AG7>0,-$B$4,$B$4)),0,IF(AG5<=AG6*(1+IF(AG6>0,$B$4,-$B$4)),0,-1)))) -> 0 | AG7: =_xll.DBRW('Value Tree'!A3,A10,A13,AE7,A20,A23,"Cement Group","Fuel (LMU/t)","Value") -> 0 | AH7: =IF(AE3="+",IF(AI5>AI7*(1+IF(AI7>0,$B$4,-$B$4)),0,IF(AI5>=AI6*(1+IF(AI6>0,-$B$4,$B$4)),0,-1)),IF(AE3="-",IF(AI5<AI7*(1+IF(AI7>0,-$B$4,$B$4)),0,IF(AI5<=AI6*(1+IF(AI6>0,$B$4,-$B$4)),0,-1)))) -> 0 | AI7: =_xll.DBRW('Value Tree'!A3,A10,A14,AE7,A20,A23,"Cement Group","Fuel (LMU/t)","Value") -> 0 | AL7: L500 | AM7: =IF(AL3="+",IF(AN5>AN7*(1+IF(AN7>0,$B$4,-$B$4)),1,IF(AN5>=AN6*(1+IF(AN6>0,-$B$4,$B$4)),0,-1)),IF(AL3="-",IF(AN5<AN7*(1+IF(AN7>0,-$B$4,$B$4)),1,IF(AN5<=AN6*(1+IF(AN6>0,$B$4,-$B$4)),0,-1)))) -> 0 | AN7: =_xll.DBRW('Value Tree'!A3,A10,A13,AL7,A20,A23,"Cement Group","Thermal Sub. (%)","Value") -> 0 | AO7: =IF(AL3="+",IF(AS5>AP7*(1+IF(AP7>0,$B$4,-$B$4)),0,IF(AS5>=AS6*(1+IF(AS6>0,-$B$4,$B$4)),0,-1)),IF(AL3="-",IF(AS5<AP7*(1+IF(AP7>0,-$B$4,$B$4)),0,IF(AS5<=AS6*(1+IF(AS6>0,$B$4,-$B$4)),0,-1)))) -> #REF! | AP7: =_xll.DBRW('Value Tree'!A3,A10,A14,AL7,A20,A23,"Cement Group","Thermal Sub. (%)","Value") -> 0
AR8: 5
A9: Ano | C9: + | E9: YTD | G9: FY | J9: + | L9: YTD | N9: FY | Q9: + | S9: YTD | U9: FY | X9: + | Z9: YTD | AB9: FY | AE9: - | AG9: YTD | AI9: FY | AL9: - | AN9: YTD | AP9: FY
A10: =_xll.SUBNM("CONS_VC:ALL.D.Year","","2026","MEMBER_NAME") -> 2026 | D10: Net Profit (€M) | K10: EBITDA (€M) | R10: EBITDA Oth. BUs. (€M) | Y10: Cement Net FOB (€/t) | AF10: CO2 Gross (kg/ton) | AM10: Thermal C. (kcal/t kk)
C11: =A17 -> RF | E11: =_xll.DBRW('Value Tree'!A4,'Value Tree'!A10,'Value Tree'!A13,C11,'Value Tree'!A20,'Value Tree'!A23,'Value Tree'!A26,'Value Tree'!A29,A36) -> -25.781941 | G11: =_xll.DBRW(A4,'Value Tree'!A10,'Value Tree'!A14,C11,'Value Tree'!A20,'Value Tree'!A23,'Value Tree'!A26,"Net Profit","Value") -> 112.09072 | J11: =A17 -> RF | L11: =_xll.DBRW(A4,A10,A13,J11,A20,A23,A26,"EBITDA","Value") -> -20.517267 | N11: =_xll.DBRW(A4,A10,A14,J11,A20,A23,A26,"EBITDA","Value") -> 426.1854 | Q11: =A17 -> RF | S11: =_xll.DBRW(A4,A10,A13,Q11,A20,A23,A26,"EBITDA","Value")-_xll.DBRW(A4,A10,A13,Q11,A20,A23,"PRODCE010 - Cement","EBITDA","Value") -> -42.760335 | U11: =_xll.DBRW(A4,A10,A14,Q11,A20,A23,A26,"EBITDA","Value")-_xll.DBRW(A4,A10,A14,Q11,A20,A23,"PRODCE010 - Cement","EBITDA","Value") -> -270.71056 | X11: =A17 -> RF | Z11: =_xll.DBRW(A3,A10,A13,X11,A20,A23,"Cement Group","Price","Value") -> 155.32501 | AB11: =_xll.DBRW(A3,A10,A14,X11,A20,A23,"Cement Group","Price","Value") -> 156.23488 | AE11: =A17 -> RF | AG11: =_xll.DBRW('Value Tree'!A3,A10,A13,AE11,A20,A23,"Cement Group","CO2 Gross (kg/ton)","Value") -> 0 | AI11: =_xll.DBRW('Value Tree'!A3,A10,A14,AE11,A20,A23,"Cement Group","CO2 Gross (kg/ton)","Value") -> 0 | AL11: =A17 -> RF | AN11: =_xll.DBRW(A3,A10,A13,AL11,A20,A23,"Cement Group","Thermal C. (kcal/t kk)","Value") -> 0 | AP11: =_xll.DBRW(A3,A10,A14,AL11,A20,A23,"Cement Group","Thermal C. (kcal/t kk)","Value") -> 0 | AR11: 812 | AS11: #REF!
A12: Mês | C12: =A18 -> L300 | E12: =_xll.DBRW('Value Tree'!A4,'Value Tree'!A10,'Value Tree'!A13,C12,'Value Tree'!A20,'Value Tree'!A23,'Value Tree'!A26,'Value Tree'!A29,A36) -> 0 | G12: =_xll.DBRW('Value Tree'!A4,'Value Tree'!A10,'Value Tree'!A14,C12,'Value Tree'!A20,'Value Tree'!A23,'Value Tree'!A26,'Value Tree'!A29,A36) -> 0 | J12: =A18 -> L300 | L12: =_xll.DBRW(A4,A10,A13,J12,A20,A23,A26,"EBITDA","Value") -> 0 | N12: =_xll.DBRW(A4,A10,A14,J12,A20,A23,A26,"EBITDA","Value") -> 0 | Q12: =A18 -> L300 | S12: =_xll.DBRW(A4,A10,A13,Q12,A20,A23,A26,"EBITDA","Value")-_xll.DBRW(A4,A10,A13,Q12,A20,A23,"PRODCE010 - Cement","EBITDA","Value") -> 0 | U12: =_xll.DBRW(A4,A10,A14,Q12,A20,A23,A26,"EBITDA","Value")-_xll.DBRW(A4,A10,A14,Q12,A20,A23,"PRODCE010 - Cement","EBITDA","Value") -> 0 | X12: =A18 -> L300 | Z12: =_xll.DBRW(A3,A10,A13,X12,A20,A23,"Cement Group","Price","Value") -> 0 | AB12: =_xll.DBRW(A3,A10,A14,X12,A20,A23,"Cement Group","Price","Value") -> 0 | AE12: =A18 -> L300 | AG12: =_xll.DBRW('Value Tree'!A3,A10,A13,AE12,A20,A23,"Cement Group","CO2 Gross (kg/ton)","Value") -> 0 | AI12: =_xll.DBRW('Value Tree'!A3,A10,A14,AE12,A20,A23,"Cement Group","CO2 Gross (kg/ton)","Value") -> 0 | AL12: =A18 -> L300 | AN12: =_xll.DBRW(A3,A10,A13,AL12,A20,A23,"Cement Group","Thermal C. (kcal/t kk)","Value") -> 0 | AP12: =_xll.DBRW(A3,A10,A14,AL12,A20,A23,"Cement Group","Thermal C. (kcal/t kk)","Value") -> 0 | AR12: 810 | AS12: #REF!
A13: =_xll.SUBNM("CONS_VC:ALL.D.Month","SYS.YTD","YTD 01","MEMBER_NAME") -> YTD 01 | C13: L500 | D13: =IF(C9="+",IF(E11>E13,1,IF(E11>=E12,0,-1)),IF(C9="-",IF(E11<E13,1,IF(E11<=E12,0,-1)))) -> -1 | E13: =_xll.DBRW('Value Tree'!A4,'Value Tree'!A10,'Value Tree'!A13,C13,'Value Tree'!A20,'Value Tree'!A23,'Value Tree'!A26,'Value Tree'!A29,A36) -> 0 | F13: =IF(C9="+",IF(G11>G13*(1+IF(G13>0,$B$4,-$B$4)),1,IF(G11>=G12*(1+IF(G12>0,-$B$4,$B$4)),0,-1)),IF(C9="-",IF(G11<G13*(1+IF(G13>0,-$B$4,$B$4)),1,IF(G11<=G12*(1+IF(G12>0,$B$4,-$B$4)),0,-1)))) -> 1 | G13: =_xll.DBRW('Value Tree'!A4,'Value Tree'!A10,'Value Tree'!A14,C13,'Value Tree'!A20,'Value Tree'!A23,'Value Tree'!A26,'Value Tree'!A29,A36) -> 0 | J13: L500 | K13: =IF(J9="+",IF(L11>L13*(1+IF(L13>0,$B$4,-$B$4)),1,IF(L11>=L12*(1+IF(L12>0,-$B$4,$B$4)),0,-1)),IF(J9="-",IF(L11<L13*(1+IF(L13>0,-$B$4,$B$4)),1,IF(L11<=L12*(1+IF(L12>0,$B$4,-$B$4)),0,-1)))) -> -1 | L13: =_xll.DBRW(A4,A10,A13,J13,A20,A23,A26,"EBITDA","Value") -> 0 | M13: =IF(J9="+",IF(N11>N13*(1+IF(N13>0,$B$4,-$B$4)),1,IF(N11>=N12*(1+IF(N12>0,-$B$4,$B$4)),0,-1)),IF(J9="-",IF(N11<N13*(1+IF(N13>0,-$B$4,$B$4)),1,IF(N11<=N12*(1+IF(N12>0,$B$4,-$B$4)),0,-1)))) -> 1 | N13: =_xll.DBRW(A4,A10,A14,J13,A20,A23,A26,"EBITDA","Value") -> 0 | Q13: L500 | R13: =IF(Q9="+",IF(S11>S13,1,IF(S11>=S12,0,-1)),IF(Q9="-",IF(S11<S13,1,IF(S11<=S12,0,-1)))) -> -1 | S13: =_xll.DBRW(A4,A10,A13,Q13,A20,A23,A26,"EBITDA","Value")-_xll.DBRW(A4,A10,A13,Q13,A20,A23,"PRODCE010 - Cement","EBITDA","Value") -> 0 | T13: =IF(Q9="+",IF(U11>U13,1,IF(U11>=U12,0,-1)),IF(Q9="-",IF(U11<U13,1,IF(U11<=U12,0,-1)))) -> -1 | U13: =_xll.DBRW(A4,A10,A14,Q13,A20,A23,A26,"EBITDA","Value")-_xll.DBRW(A4,A10,A14,Q13,A20,A23,"PRODCE010 - Cement","EBITDA","Value") -> 0 | X13: L500 | Y13: =IF(X9="+",IF(Z11>Z13*(1+IF(Z13>0,$B$4,-$B$4)),1,IF(Z11>=Z12*(1+IF(Z12>0,-$B$4,$B$4)),0,-1)),IF(X9="-",IF(Z11<Z13*(1+IF(Z13>0,-$B$4,$B$4)),1,IF(Z11<=Z12*(1+IF(Z12>0,$B$4,-$B$4)),0,-1)))) -> 1 | Z13: =_xll.DBRW(A3,A10,A13,X13,A20,A23,"Cement Group","Price","Value") -> 0 | AA13: =IF(X9="+",IF(AB11>AB13*(1+IF(AB13>0,$B$4,-$B$4)),1,IF(AB11>=AB12*(1+IF(AB12>0,-$B$4,$B$4)),0,-1)),IF(X9="-",IF(AB11<AB13*(1+IF(AB13>0,-$B$4,$B$4)),1,IF(AB11<=AB12*(1+IF(AB12>0,$B$4,-$B$4)),0,-1)))) -> 1 | AB13: =_xll.DBRW(A3,A10,A14,X13,A20,A23,"Cement Group","Price","Value") -> 0 | AE13: L500 | AF13: =IF(AE9="+",IF(AG11>AG13*(1+IF(AG13>0,$B$4,-$B$4)),0,IF(AG11>=AG12*(1+IF(AG12>0,-$B$4,$B$4)),0,-1)),IF(AE9="-",IF(AG11<AG13*(1+IF(AG13>0,-$B$4,$B$4)),0,IF(AG11<=AG12*(1+IF(AG12>0,$B$4,-$B$4)),0,-1)))) -> 0 | AG13: =_xll.DBRW('Value Tree'!A3,A10,A13,AE13,A20,A23,"Cement Group","CO2 Gross (kg/ton)","Value") -> 0 | AH13: =IF(AE9="+",IF(AI11>AI13*(1+IF(AI13>0,$B$4,-$B$4)),0,IF(AI11>=AI12*(1+IF(AI12>0,-$B$4,$B$4)),0,-1)),IF(AE9="-",IF(AI11<AI13*(1+IF(AI13>0,-$B$4,$B$4)),0,IF(AI11<=AI12*(1+IF(AI12>0,$B$4,-$B$4)),0,-1)))) -> 0 | AI13: =_xll.DBRW('Value Tree'!A3,A10,A14,AE13,A20,A23,"Cement Group","CO2 Gross (kg/ton)","Value") -> 0 | AL13: L500 | AM13: =IF(AL9="+",IF(AN11>AN13*(1+IF(AN13>0,$B$4,-$B$4)),0,IF(AN11>=AN12*(1+IF(AN12>0,-$B$4,$B$4)),0,-1)),IF(AL9="-",IF(AN11<AN13*(1+IF(AN13>0,-$B$4,$B$4)),0,IF(AN11<=AN12*(1+IF(AN12>0,$B$4,-$B$4)),0,-1)))) -> 0 | AN13: =_xll.DBRW(A3,A10,A13,AL13,A20,A23,"Cement Group","Thermal C. (kcal/t kk)","Value") -> 0 | AO13: =IF(AL9="+",IF(AS11>AP13*(1+IF(AP13>0,$B$4,-$B$4)),0,IF(AS11>=AS12*(1+IF(AS12>0,-$B$4,$B$4)),0,-1)),IF(AL9="-",IF(AS11<AP13*(1+IF(AP13>0,-$B$4,$B$4)),0,IF(AS11<=AS12*(1+IF(AS12>0,$B$4,-$B$4)),0,-1)))) -> #REF! | AP13: =_xll.DBRW(A3,A10,A14,AL13,A20,A23,"Cement Group","Thermal C. (kcal/t kk)","Value") -> 0
A14: Year
C15: + | E15: YTD | G15: FY | J15: + | L15: YTD | N15: FY | AE15: - | AG15: YTD | AI15: FY | AL15: - | AN15: YTD | AP15: FY
A16: Versão | D16: FCF (€M) | K16: Capex (€M) | AF16: CO2 Net (kg/ton) | AM16: Petcoke Price (USD/t)
A17: =_xll.SUBNM("CONS_VC:ALL.D.Version",,"RF","Descrição") -> RF | C17: =A17 -> RF | E17: =_xll.DBRW('Value Tree'!A5,'Value Tree'!A10,A13,C17,A20,A23,"Cash generation before financing",'Value Tree'!A39) -> -790.52844 | G17: =_xll.DBRW('Value Tree'!A5,'Value Tree'!A10,A14,C17,A20,A23,"Cash generation before financing",'Value Tree'!A39) -> -464.74999 | J17: =A17 -> RF | L17: =_xll.DBRW('Value Tree'!A5,A10,A13,J17,A20,A23,"Expansion Capex",Planilha3!B$19) +_xll.DBRW('Value Tree'!A5,A10,A13,J17,A20,A23,"Non expansion capex",Planilha3!B$19) -> 0 | N17: =_xll.DBRW('Value Tree'!A5,A10,A14,J17,A20,A23,"Expansion Capex",Planilha3!B$19) +_xll.DBRW('Value Tree'!A5,A10,A14,J17,A20,A23,"Non expansion capex",Planilha3!B$19) -> 0 | AE17: =A17 -> RF | AG17: =_xll.DBRW(A3,A10,A13,AE17,A20,A23,"Cement Group","CO2 Net (kg/ton)","Value") -> 0 | AI17: =_xll.DBRW(A3,A10,A14,AE17,A20,A23,"Cement Group","CO2 Net (kg/ton)","Value") -> 0 | AL17: =A17 -> RF | AN17: =_xll.DBRW(A3,A10,A13,AL17,A20,A23,"Cement Group","Petcoke Price (LMU/t)","Value") -> 0 | AP17: =_xll.DBRW(A3,A10,A14,AL17,A20,A23,"Cement Group","Petcoke Price (LMU/t)","Value") -> 0
A18: =_xll.SUBNM("CONS_VC:ALL.D.Version",,"L300","MEMBER_NAME") -> L300 | C18: =A18 -> L300 | E18: =_xll.DBRW('Value Tree'!A5,'Value Tree'!A10,A13,C18,A20,A23,"Cash generation before financing",'Value Tree'!A39) -> 0 | G18: =_xll.DBRW('Value Tree'!A5,'Value Tree'!A10,A14,C18,A20,A23,"Cash generation before financing",'Value Tree'!A39) -> 0 | J18: =A18 -> L300 | L18: =_xll.DBRW('Value Tree'!A5,A10,A13,J18,A20,A23,"Expansion Capex",Planilha3!B$19) +_xll.DBRW('Value Tree'!A5,A10,A13,J18,A20,A23,"Non expansion capex",Planilha3!B$19) -> 0 | N18: =_xll.DBRW('Value Tree'!A5,A10,A14,J18,A20,A23,"Expansion Capex",Planilha3!B$19) +_xll.DBRW('Value Tree'!A5,A10,A14,J18,A20,A23,"Non expansion capex",Planilha3!B$19) -> 0 | AE18: =A18 -> L300 | AG18: =_xll.DBRW(A3,A10,A13,AE18,A20,A23,"Cement Group","CO2 Net (kg/ton)","Value") -> 0 | AI18: =_xll.DBRW(A3,A10,A14,AE18,A20,A23,"Cement Group","CO2 Net (kg/ton)","Value") -> 0 | AL18: =A18 -> L300 | AN18: =_xll.DBRW(A3,A10,A13,AL18,A20,A23,"Cement Group","Petcoke Price (LMU/t)","Value") -> 0 | AP18: =_xll.DBRW(A3,A10,A14,AL18,A20,A23,"Cement Group","Petcoke Price (LMU/t)","Value") -> 0
A19: Currency | C19: L500 | D19: =IF(C15="+",IF(E17>E19,1,IF(E17>=E18,0,-1)),IF(C15="-",IF(E17<E19,1,IF(E17<=E18,0,-1)))) -> -1 | E19: =_xll.DBRW('Value Tree'!A5,'Value Tree'!A10,A13,C19,A20,A23,"Cash generation before financing",'Value Tree'!A39) -> 0 | F19: =IF(C15="+",IF(G17>G19*(1+IF(G19>0,$B$4,-$B$4)),1,IF(G17>=G18*(1+IF(G18>0,-$B$4,$B$4)),0,-1)),IF(C15="-",IF(G17<G19*(1+IF(G19>0,-$B$4,$B$4)),1,IF(G17<=G18*(1+IF(G18>0,$B$4,-$B$4)),0,-1)))) -> -1 | G19: =_xll.DBRW('Value Tree'!A5,'Value Tree'!A10,A14,C19,A20,A23,"Cash generation before financing",'Value Tree'!A39) -> 0 | J19: L500 | K19: =IF(J15="+",IF(L17>L19*(1+IF(L19>0,$B$4,-$B$4)),1,IF(L17>=L18*(1+IF(L18>0,-$B$4,$B$4)),0,-1)),IF(J15="-",IF(L17<L19*(1+IF(L19>0,-$B$4,$B$4)),1,IF(L17<=L18*(1+IF(L18>0,$B$4,-$B$4)),0,-1)))) -> 0 | L19: =_xll.DBRW('Value Tree'!A5,A10,A13,J19,A20,A23,"Expansion Capex",Planilha3!B$19) +_xll.DBRW('Value Tree'!A5,A10,A13,J19,A20,A23,"Non expansion capex",Planilha3!B$19) -> 0 | M19: =IF(J15="+",IF(N17>N19*(1+IF(N19>0,$B$4,-$B$4)),1,IF(N17>=N18*(1+IF(N18>0,-$B$4,$B$4)),0,-1)),IF(J15="-",IF(N17<N19*(1+IF(N19>0,-$B$4,$B$4)),1,IF(N17<=N18*(1+IF(N18>0,$B$4,-$B$4)),0,-1)))) -> 0 | N19: =_xll.DBRW('Value Tree'!A5,A10,A14,J19,A20,A23,"Expansion Capex",Planilha3!B$19) +_xll.DBRW('Value Tree'!A5,A10,A14,J19,A20,A23,"Non expansion capex",Planilha3!B$19) -> 0 | AE19: L500 | AF19: =IF(AE15="+",IF(AG17>AG19*(1+IF(AG19>0,$B$4,-$B$4)),0,IF(AG17>=AG18*(1+IF(AG18>0,-$B$4,$B$4)),0,-1)),IF(AE15="-",IF(AG17<AG19*(1+IF(AG19>0,-$B$4,$B$4)),0,IF(AG17<=AG18*(1+IF(AG18>0,$B$4,-$B$4)),0,-1)))) -> 0 | AG19: =_xll.DBRW(A3,A10,A13,AE19,A20,A23,"Cement Group","CO2 Net (kg/ton)","Value") -> 0 | AH19: =IF(AE15="+",IF(AI17>AI19*(1+IF(AI19>0,$B$4,-$B$4)),0,IF(AI17>=AI18*(1+IF(AI18>0,-$B$4,$B$4)),0,-1)),IF(AE15="-",IF(AI17<AI19*(1+IF(AI19>0,-$B$4,$B$4)),0,IF(AI17<=AI18*(1+IF(AI18>0,$B$4,-$B$4)),0,-1)))) -> 0 | AI19: =_xll.DBRW(A3,A10,A14,AE19,A20,A23,"Cement Group","CO2 Net (kg/ton)","Value") -> 0 | AL19: L500 | AM19: =IF(AL15="+",IF(AN17>AN19*(1+IF(AN19>0,$B$4,-$B$4)),0,IF(AN17>=AN18*(1+IF(AN18>0,-$B$4,$B$4)),0,-1)),IF(AL15="-",IF(AN17<AN19*(1+IF(AN19>0,-$B$4,$B$4)),0,IF(AN17<=AN18*(1+IF(AN18>0,$B$4,-$B$4)),0,-1)))) -> 0 | AN19: =_xll.DBRW(A3,A10,A13,AL19,A20,A23,"Cement Group","Petcoke Price (LMU/t)","Value") -> 0 | AO19: =IF(AL15="+",IF(AP17>AP19*(1+IF(AP19>0,$B$4,-$B$4)),0,IF(AP17>=AP18*(1+IF(AP18>0,-$B$4,$B$4)),0,-1)),IF(AL15="-",IF(AP17<AP19*(1+IF(AP19>0,-$B$4,$B$4)),0,IF(AP17<=AP18*(1+IF(AP18>0,$B$4,-$B$4)),0,-1)))) -> 0 | AP19: =_xll.DBRW(A3,A10,A14,AL19,A20,A23,"Cement Group","Petcoke Price (LMU/t)","Value") -> 0
A20: =_xll.SUBNM("CONS_VC:ALL.D.Currency","","USD","MEMBER_NAME") -> USD
C21: + | E21: YTD | G21: FY | J21: + | L21: YTD | N21: FY | Q21: - | S21: YTD | U21: FY | X21: - | Z21: YTD | AB21: FY | AE21: - | AG21: YTD | AI21: FY | AL21: - | AN21: YTD | AP21: FY
A22: Region | D22: ROIC (%) | K22: ∆ WK Capital (€M) | R22: Cem. Cash Cost (€/t) | Y22: Cement Var. Costs (€/t) | AF22: Power (€/t) | AM22: Power Price (€/MWh)
A23: =_xll.SUBNM("CONS_VC:ALL.D.Region","","VCNA","MEMBER_NAME") -> VCNA | C23: =A17 -> RF | E23: =_xll.DBRW('Value Tree'!A3,A10,A13,C23,A20,A23,A26,"% ROIC","Value") -> 0 | G23: =_xll.DBRW('Value Tree'!A3,A10,A14,C23,A20,A23,A26,"% ROIC","Value") -> 0 | J23: =A17 -> RF | L23: =_xll.DBRW('Value Tree'!A3,A10,A13,J23,A20,A23,A26,"Working Capital Balance","Value") -> 3383.0569 | N23: =_xll.DBRW('Value Tree'!A3,A10,A14,J23,A20,A23,A26,"Working Capital Balance","Value") -> 50032.713 | Q23: =A17 -> RF | S23: =Z23+Z29 -> 0 | U23: =AB23+AB29 -> 0 | X23: =A17 -> RF | Z23: =SUM(AG5,AG23,AG29,AG35) -> 0 | AB23: =SUM(AI5,AI23,AI29,AI35) -> 0 | AE23: =A17 -> RF | AG23: =_xll.DBRW('Value Tree'!A3,A10,A13,AE23,A20,A23,"Cement Group","Power (LMU/t)","Value") -> 0 | AI23: =_xll.DBRW('Value Tree'!A3,A10,A14,AE23,A20,A23,"Cement Group","Power (LMU/t)","Value") -> 0 | AL23: =A17 -> RF | AN23: =_xll.DBRW(A3,A10,A13,AL23,A20,A23,"Cement Group","Power Price (LMU/MWh)","Value") -> 0 | AP23: =_xll.DBRW(A3,A10,A14,AL23,A20,A23,"Cement Group","Power Price (LMU/MWh)","Value") -> 0
C24: =A18 -> L300 | E24: =_xll.DBRW('Value Tree'!A3,A10,A13,C24,A20,A23,A26,"% ROIC","Value") -> 0 | G24: =_xll.DBRW('Value Tree'!A3,A10,A14,C24,A20,A23,A26,"% ROIC","Value") -> 0 | J24: =A18 -> L300 | L24: =_xll.DBRW('Value Tree'!A3,A10,A13,J24,A20,A23,A26,"Working Capital Balance","Value") -> 0 | N24: =_xll.DBRW('Value Tree'!A3,A10,A14,J24,A20,A23,A26,"Working Capital Balance","Value") -> 0 | Q24: =A18 -> L300 | S24: =Z24+Z30 -> 0 | U24: =AB24+AB30 -> 0 | X24: =A18 -> L300 | Z24: =SUM(AG6,AG24,AG30,AG36) -> 0 | AB24: =SUM(AI6,AI24,AI30,AI36) -> 0 | AE24: =A18 -> L300 | AG24: =_xll.DBRW('Value Tree'!A3,A10,A13,AE24,A20,A23,"Cement Group","Power (LMU/t)","Value") -> 0 | AI24: =_xll.DBRW('Value Tree'!A3,A10,A14,AE24,A20,A23,"Cement Group","Power (LMU/t)","Value") -> 0 | AL24: =A18 -> L300 | AN24: =_xll.DBRW(A3,A10,A13,AL24,A20,A23,"Cement Group","Power Price (LMU/MWh)","Value") -> 0 | AP24: =_xll.DBRW(A3,A10,A14,AL24,A20,A23,"Cement Group","Power Price (LMU/MWh)","Value") -> 0
A25: Produto | C25: L500 | D25: =IF(C21="+",IF(E23>E25,1,IF(E23>=E24,0,-1)),IF(C21="-",IF(E23<E25,1,IF(E23<=E24,0,-1)))) -> 0 | E25: =_xll.DBRW('Value Tree'!A3,A10,A13,C25,A20,A23,A26,"% ROIC","Value") -> 0 | F25: =IF(C21="+",IF(G23>G25,1,IF(G23>=G24,0,-1)),IF(C21="-",IF(G23<G25,1,IF(G23<=G24,0,-1)))) -> 0 | G25: =_xll.DBRW('Value Tree'!A3,A10,A14,C25,A20,A23,A26,"% ROIC","Value") -> 0 | J25: L500 | K25: =IF(J21="+",IF(L23>L25*(1+IF(L25>0,$B$4,-$B$4)),1,IF(L23>=L24*(1+IF(L24>0,-$B$4,$B$4)),0,-1)),IF(J21="-",IF(L23<L25*(1+IF(L25>0,-$B$4,$B$4)),1,IF(L23<=L24*(1+IF(L24>0,$B$4,-$B$4)),0,-1)))) -> 1 | L25: =_xll.DBRW('Value Tree'!A3,A10,A13,J25,A20,A23,A26,"Working Capital Balance","Value") -> 0 | M25: =IF(J21="+",IF(N23>N25*(1+IF(N25>0,$B$4,-$B$4)),1,IF(N23>=N24*(1+IF(N24>0,-$B$4,$B$4)),0,-1)),IF(J21="-",IF(N23<N25*(1+IF(N25>0,-$B$4,$B$4)),1,IF(N23<=N24*(1+IF(N24>0,$B$4,-$B$4)),0,-1)))) -> 1 | N25: =_xll.DBRW('Value Tree'!A3,A10,A14,J25,A20,A23,A26,"Working Capital Balance","Value") -> 0 | Q25: L500 | R25: =IF(Q21="+",IF(S23>S25*(1+IF(S25>0,$B$4,-$B$4)),1,IF(S23>=S24*(1+IF(S24>0,-$B$4,$B$4)),0,-1)),IF(Q21="-",IF(S23<S25*(1+IF(S25>0,-$B$4,$B$4)),1,IF(S23<=S24*(1+IF(S24>0,$B$4,-$B$4)),0,-1)))) -> 0 | S25: =Z25+Z31 -> 0 | T25: =IF(Q21="+",IF(U23>U25*(1+IF(U25>0,$B$4,-$B$4)),1,IF(U23>=U24*(1+IF(U24>0,-$B$4,$B$4)),0,-1)),IF(Q21="-",IF(U23<U25*(1+IF(U25>0,-$B$4,$B$4)),1,IF(U23<=U24*(1+IF(U24>0,$B$4,-$B$4)),0,-1)))) -> 0 | U25: =AB25+AB31 -> 0 | X25: L500 | Y25: =IF(X21="+",IF(Z23>Z25*(1+IF(Z25>0,$B$4,-$B$4)),0,IF(Z23>=Z24*(1+IF(Z24>0,-$B$4,$B$4)),0,-1)),IF(X21="-",IF(Z23<Z25*(1+IF(Z25>0,-$B$4,$B$4)),0,IF(Z23<=Z24*(1+IF(Z24>0,$B$4,-$B$4)),0,-1)))) -> 0 | Z25: =SUM(AG7,AG25,AG31,AG37) -> 0 | AA25: =IF(X21="+",IF(AB23>AB25*(1+IF(AB25>0,$B$4,-$B$4)),0,IF(AB23>=AB24*(1+IF(AB24>0,-$B$4,$B$4)),0,-1)),IF(X21="-",IF(AB23<AB25*(1+IF(AB25>0,-$B$4,$B$4)),0,IF(AB23<=AB24*(1+IF(AB24>0,$B$4,-$B$4)),0,-1)))) -> 0 | AB25: =SUM(AI7,AI25,AI31,AI37) -> 0 | AE25: L500 | AF25: =IF(AE21="+",IF(AG23>AG25*(1+IF(AG25>0,$B$4,-$B$4)),0,IF(AG23>=AG24*(1+IF(AG24>0,-$B$4,$B$4)),0,-1)),IF(AE21="-",IF(AG23<AG25*(1+IF(AG25>0,-$B$4,$B$4)),0,IF(AG23<=AG24*(1+IF(AG24>0,$B$4,-$B$4)),0,-1)))) -> 0 | AG25: =_xll.DBRW('Value Tree'!A3,A10,A13,AE25,A20,A23,"Cement Group","Power (LMU/t)","Value") -> 0 | AH25: =IF(AE21="+",IF(AI23>AI25*(1+IF(AI25>0,$B$4,-$B$4)),0,IF(AI23>=AI24*(1+IF(AI24>0,-$B$4,$B$4)),0,-1)),IF(AE21="-",IF(AI23<AI25*(1+IF(AI25>0,-$B$4,$B$4)),0,IF(AI23<=AI24*(1+IF(AI24>0,$B$4,-$B$4)),0,-1)))) -> 0 | AI25: =_xll.DBRW('Value Tree'!A3,A10,A14,AE25,A20,A23,"Cement Group","Power (LMU/t)","Value") -> 0 | AL25: L500 | AM25: =IF(AL21="+",IF(AN23>AN25*(1+IF(AN25>0,$B$4,-$B$4)),0,IF(AN23>=AN24*(1+IF(AN24>0,-$B$4,$B$4)),0,-1)),IF(AL21="-",IF(AN23<AN25*(1+IF(AN25>0,-$B$4,$B$4)),0,IF(AN23<=AN24*(1+IF(AN24>0,$B$4,-$B$4)),0,-1)))) -> 0 | AN25: =_xll.DBRW(A3,A10,A13,AL25,A20,A23,"Cement Group","Power Price (LMU/MWh)","Value") -> 0 | AO25: =IF(AL21="+",IF(AP23>AP25*(1+IF(AP25>0,$B$4,-$B$4)),0,IF(AP23>=AP24*(1+IF(AP24>0,-$B$4,$B$4)),0,-1)),IF(AL21="-",IF(AP23<AP25*(1+IF(AP25>0,-$B$4,$B$4)),0,IF(AP23<=AP24*(1+IF(AP24>0,$B$4,-$B$4)),0,-1)))) -> 0 | AP25: =_xll.DBRW(A3,A10,A14,AL25,A20,A23,"Cement Group","Power Price (LMU/MWh)","Value") -> 0 | AT25: =R25 -> 0
A26: =_xll.SUBNM("CONS_VC:ALL.D.Products","","Total Products") -> Total Products
J27: + | L27: YTD | N27: FY | Q27: - | S27: YTD | U27: FY | X27: - | Z27: YTD | AB27: FY | AE27: - | AG27: YTD | AI27: FY | AL27: - | AN27: YTD | AP27: FY
A28: Accounts_PNL | K28: Income Tax (€M) | R28: Fixed Cost (€M) | Y28: Cement Fix. Costs (€/t) | AF28: Raw Material (€/t) | AM28: Power Cons. (kWh/t)
A29: Net Profit | J29: =A17 -> RF | L29: =_xll.DBRW(A4,A10,A13,J29,A20,A23,A26,"Income Tax","Value") -> -10.00364 | N29: =_xll.DBRW(A4,A10,A14,J29,A20,A23,A26,"Income Tax","Value") -> 38.335251 | Q29: =A17 -> RF | S29: {=_xll.DBRW(A4,A10,A13,Q29,A20,A23,A26,"Fixed Costs","Total Value")} -> -34.8395 | U29: {=_xll.DBRW(A4,A10,A14,Q29,A20,A23,A26,"Fixed Costs","Total Value")} -> -301.22314 | X29: =A17 -> RF | Z29: =_xll.DBRW('Value Tree'!A3,A10,A13,X29,A20,A23,A26,"Cement Fix. Costs (LMU/t)","Value") -> 0 | AB29: =_xll.DBRW('Value Tree'!A3,A10,A14,X29,A20,A23,A26,"Cement Fix. Costs (LMU/t)","Value") -> 0 | AE29: =A17 -> RF | AG29: =_xll.DBRW('Value Tree'!A3,A10,A13,AE29,A20,A23,"Cement Group","Raw Material (LMU/t)","Value") -> 0 | AI29: =_xll.DBRW('Value Tree'!A3,A10,A14,AE29,A20,A23,"Cement Group","Raw Material (LMU/t)","Value") -> 0 | AL29: =A17 -> RF | AN29: =_xll.DBRW(A3,A10,A13,AL29,A20,A23,"Cement Group","Power Cons. (kWh/t)","Value") -> 0 | AP29: =_xll.DBRW(A3,A10,A14,AL29,A20,A23,"Cement Group","Power Cons. (kWh/t)","Value") -> 0
J30: =A18 -> L300 | L30: =_xll.DBRW(A4,A10,A13,J30,A20,A23,A26,"Income Tax","Value") -> 0 | N30: =_xll.DBRW(A4,A10,A14,J30,A20,A23,A26,"Income Tax","Value") -> 0 | Q30: =A18 -> L300 | S30: {=_xll.DBRW(A4,A10,A13,Q30,A20,A23,A26,"Fixed Costs","Total Value")} -> 0 | U30: {=_xll.DBRW(A4,A10,A14,Q30,A20,A23,A26,"Fixed Costs","Total Value")} -> 0 | X30: =A18 -> L300 | Z30: =_xll.DBRW('Value Tree'!A3,A10,A13,X30,A20,A23,A26,"Cement Fix. Costs (LMU/t)","Value") -> 0 | AB30: =_xll.DBRW('Value Tree'!A3,A10,A14,X30,A20,A23,A26,"Cement Fix. Costs (LMU/t)","Value") -> 0 | AE30: =A18 -> L300 | AG30: =_xll.DBRW('Value Tree'!A3,A10,A13,AE30,A20,A23,"Cement Group","Raw Material (LMU/t)","Value") -> 0 | AI30: =_xll.DBRW('Value Tree'!A3,A10,A14,AE30,A20,A23,"Cement Group","Raw Material (LMU/t)","Value") -> 0 | AL30: =A18 -> L300 | AN30: =_xll.DBRW(A3,A10,A13,AL30,A20,A23,"Cement Group","Power Cons. (kWh/t)","Value") -> 0 | AP30: =_xll.DBRW(A3,A10,A14,AL30,A20,A23,"Cement Group","Power Cons. (kWh/t)","Value") -> 0
A31: Accounts_ICF | J31: L500 | K31: =IF(J27="+",IF(L29>L31*(1+IF(L31>0,$B$4,-$B$4)),0,IF(L29>=L30*(1+IF(L30>0,-$B$4,$B$4)),0,-1)),IF(J27="-",IF(L29<L31*(1+IF(L31>0,-$B$4,$B$4)),0,IF(L29<=L30*(1+IF(L30>0,$B$4,-$B$4)),0,-1)))) -> -1 | L31: =_xll.DBRW(A4,A10,A13,J31,A20,A23,A26,"Income Tax","Value") -> 0 | M31: =IF(J27="+",IF(N29>N31*(1+IF(N31>0,$B$4,-$B$4)),0,IF(N29>=N30*(1+IF(N30>0,-$B$4,$B$4)),0,-1)),IF(J27="-",IF(N29<N31*(1+IF(N31>0,-$B$4,$B$4)),0,IF(N29<=N30*(1+IF(N30>0,$B$4,-$B$4)),0,-1)))) -> 0 | N31: =_xll.DBRW(A4,A10,A14,J31,A20,A23,A26,"Income Tax","Value") -> 0 | Q31: L500 | R31: =IF(Q27="+",IF(S29>S31*(1+IF(S31>0,$B$4,-$B$4)),0,IF(S29>=S30*(1+IF(S30>0,-$B$4,$B$4)),0,-1)),IF(Q27="-",IF(S29<S31*(1+IF(S31>0,-$B$4,$B$4)),0,IF(S29<=S30*(1+IF(S30>0,$B$4,-$B$4)),0,-1)))) -> 0 | S31: {=_xll.DBRW(A4,A10,A13,Q31,A20,A23,A26,"Fixed Costs","Total Value")} -> 0 | T31: =IF(Q27="+",IF(U29>U31*(1+IF(U31>0,$B$4,-$B$4)),0,IF(U29>=U30*(1+IF(U30>0,-$B$4,$B$4)),0,-1)),IF(Q27="-",IF(U29<U31*(1+IF(U31>0,-$B$4,$B$4)),0,IF(U29<=U30*(1+IF(U30>0,$B$4,-$B$4)),0,-1)))) -> 0 | U31: {=_xll.DBRW(A4,A10,A14,Q31,A20,A23,A26,"Fixed Costs","Total Value")} -> 0 | X31: L500 | Y31: =IF(X27="+",IF(Z29>Z31*(1+IF(Z31>0,$B$4,-$B$4)),0,IF(Z29>=Z30*(1+IF(Z30>0,-$B$4,$B$4)),0,-1)),IF(X27="-",IF(Z29<Z31*(1+IF(Z31>0,-$B$4,$B$4)),0,IF(Z29<=Z30*(1+IF(Z30>0,$B$4,-$B$4)),0,-1)))) -> 0 | Z31: =_xll.DBRW('Value Tree'!A3,A10,A13,X31,A20,A23,A26,"Cement Fix. Costs (LMU/t)","Value") -> 0 | AA31: =IF(X27="+",IF(AB29>AB31*(1+IF(AB31>0,$B$4,-$B$4)),0,IF(AB29>=AB30*(1+IF(AB30>0,-$B$4,$B$4)),0,-1)),IF(X27="-",IF(AB29<AB31*(1+IF(AB31>0,-$B$4,$B$4)),0,IF(AB29<=AB30*(1+IF(AB30>0,$B$4,-$B$4)),0,-1)))) -> 0 | AB31: =_xll.DBRW('Value Tree'!A3,A10,A14,X31,A20,A23,A26,"Cement Fix. Costs (LMU/t)","Value") -> 0 | AE31: L500 | AF31: =IF(AE27="+",IF(AG29>AG31*(1+IF(AG31>0,$B$4,-$B$4)),0,IF(AG29>=AG30*(1+IF(AG30>0,-$B$4,$B$4)),0,-1)),IF(AE27="-",IF(AG29<AG31*(1+IF(AG31>0,-$B$4,$B$4)),0,IF(AG29<=AG30*(1+IF(AG30>0,$B$4,-$B$4)),0,-1)))) -> 0 | AG31: =_xll.DBRW('Value Tree'!A3,A10,A13,AE31,A20,A23,"Cement Group","Raw Material (LMU/t)","Value") -> 0 | AH31: =IF(AE27="+",IF(AI29>AI31*(1+IF(AI31>0,$B$4,-$B$4)),0,IF(AI29>=AI30*(1+IF(AI30>0,-$B$4,$B$4)),0,-1)),IF(AE27="-",IF(AI29<AI31*(1+IF(AI31>0,-$B$4,$B$4)),0,IF(AI29<=AI30*(1+IF(AI30>0,$B$4,-$B$4)),0,-1)))) -> 0 | AI31: =_xll.DBRW('Value Tree'!A3,A10,A14,AE31,A20,A23,"Cement Group","Raw Material (LMU/t)","Value") -> 0 | AL31: L500 | AM31: =IF(AL27="+",IF(AN29>AN31*(1+IF(AN31>0,$B$4,-$B$4)),0,IF(AN29>=AN30*(1+IF(AN30>0,-$B$4,$B$4)),0,-1)),IF(AL27="-",IF(AN29<AN31*(1+IF(AN31>0,-$B$4,$B$4)),0,IF(AN29<=AN30*(1+IF(AN30>0,$B$4,-$B$4)),0,-1)))) -> 0 | AN31: =_xll.DBRW(A3,A10,A13,AL31,A20,A23,"Cement Group","Power Cons. (kWh/t)","Value") -> 0 | AO31: =IF(AL27="+",IF(AP29>AP31*(1+IF(AP31>0,$B$4,-$B$4)),0,IF(AP29>=AP30*(1+IF(AP30>0,-$B$4,$B$4)),0,-1)),IF(AL27="-",IF(AP29<AP31*(1+IF(AP31>0,-$B$4,$B$4)),0,IF(AP29<=AP30*(1+IF(AP30>0,$B$4,-$B$4)),0,-1)))) -> 0 | AP31: =_xll.DBRW(A3,A10,A14,AL31,A20,A23,"Cement Group","Power Cons. (kWh/t)","Value") -> 0 | AT31: =AF31 -> 0
A32: Change in cash
J33: + | L33: YTD | N33: FY | Q33: - | S33: YTD | U33: FY | X33: - | Z33: YTD | AB33: FY | AE33: - | AG33: YTD | AI33: FY | AL33: - | AN33: YTD | AP33: FY
K34: Fin. Results | R34: SG&A (€M) | Y34: FC+SG&A/Net Sales (%) | AF34: Other Variable (€/t) | AM34: Clinker Factor (%)
A35: DFS.100.Profil_and_Loss | J35: =A17 -> RF | L35: =_xll.DBRW(A5,A10,A13,J35,A20,A23,"Financial Results",Planilha3!B$19) -> -0.81343818 | N35: =_xll.DBRW(A5,A10,A14,J35,A20,A23,"Financial Results",Planilha3!B$19) -> -55.192952 | Q35: =A17 -> RF | S35: =_xll.DBRW(A4,A10,A13,Q35,A20,A23,A26,"Operational Expenses","Value") -> -7.6474137 | U35: =_xll.DBRW('Value Tree'!A4,A10,A14,Q35,A20,A23,A26,"Operational Expenses","Value") -> -107.89134 | X35: =A17 -> RF | Z35: =ABS(IFERROR((S29+S35)/S5,0)) -> 0.79436971 | AB35: =ABS(IFERROR((U29+U35)/U5,0)) -> 0.25443059 | AE35: =A17 -> RF | AG35: =_xll.DBRW(A3,A10,A13,AE35,A20,A23,"Cement Group","Other Variable (LMU/t)","Value") -> 0 | AI35: =_xll.DBRW(A3,A10,A14,AE35,A20,A23,"Cement Group","Other Variable (LMU/t)","Value") -> 0 | AL35: =A17 -> RF | AN35: =_xll.DBRW(A3,A10,A13,AL35,A20,A23,"Cement Group","Clinker Factor (%)","Value") -> 0 | AP35: =_xll.DBRW(A3,A10,A14,AL35,A20,A23,"Cement Group","Clinker Factor (%)","Value") -> 0 | AR35: 75 | AS35: #REF!
A36: Value | J36: =A18 -> L300 | L36: =_xll.DBRW(A5,A10,A13,J36,A20,A23,"Financial Results",Planilha3!B$19) -> 0 | N36: =_xll.DBRW(A5,A10,A14,J36,A20,A23,"Financial Results",Planilha3!B$19) -> 0 | Q36: =A18 -> L300 | S36: =_xll.DBRW(A4,A10,A13,Q36,A20,A23,A26,"Operational Expenses","Value") -> 0 | U36: =_xll.DBRW('Value Tree'!A4,A10,A14,Q36,A20,A23,A26,"Operational Expenses","Value") -> 0 | X36: =A18 -> L300 | Z36: =ABS(IFERROR((S30+S36)/S6,0)) -> 0 | AB36: =ABS(IFERROR((U30+U36)/U6,0)) -> 0 | AE36: =A18 -> L300 | AG36: =_xll.DBRW(A3,A10,A13,AE36,A20,A23,"Cement Group","Other Variable (LMU/t)","Value") -> 0 | AI36: =_xll.DBRW(A3,A10,A14,AE36,A20,A23,"Cement Group","Other Variable (LMU/t)","Value") -> 0 | AL36: =A18 -> L300 | AN36: =_xll.DBRW(A3,A10,A13,AL36,A20,A23,"Cement Group","Clinker Factor (%)","Value") -> 0 | AP36: =_xll.DBRW(A3,A10,A14,AL36,A20,A23,"Cement Group","Clinker Factor (%)","Value") -> 0 | AR36: 75 | AS36: #REF!
J37: L500 | K37: =IF(J33="+",IF(L35>L37*(1+IF(L37>0,$B$4,-$B$4)),0,IF(L35>=L36*(1+IF(L36>0,-$B$4,$B$4)),0,-1)),IF(J33="-",IF(L35<L37*(1+IF(L37>0,-$B$4,$B$4)),0,IF(L35<=L36*(1+IF(L36>0,$B$4,-$B$4)),0,-1)))) -> -1 | L37: =_xll.DBRW(A5,A10,A13,J37,A20,A23,"Financial Results",Planilha3!B$19) -> 0 | M37: =IF(J33="+",IF(N35>N37*(1+IF(N37>0,$B$4,-$B$4)),0,IF(N35>=N36*(1+IF(N36>0,-$B$4,$B$4)),0,-1)),IF(J33="-",IF(N35<N37*(1+IF(N37>0,-$B$4,$B$4)),0,IF(N35<=N36*(1+IF(N36>0,$B$4,-$B$4)),0,-1)))) -> -1 | N37: =_xll.DBRW(A5,A10,A14,J37,A20,A23,"Financial Results",Planilha3!B$19) -> 0 | Q37: L500 | R37: =IF(Q33="+",IF(S35>S37*(1+IF(S37>0,$B$4,-$B$4)),0,IF(S35>=S36*(1+IF(S36>0,-$B$4,$B$4)),0,-1)),IF(Q33="-",IF(S35<S37*(1+IF(S37>0,-$B$4,$B$4)),0,IF(S35<=S36*(1+IF(S36>0,$B$4,-$B$4)),0,-1)))) -> 0 | S37: =_xll.DBRW('Value Tree'!A3,A10,A13,Q37,A20,A23,A26,"ZBB Total","Value") -> 0 | T37: =IF(Q33="+",IF(U35>U37,1,IF(U35>=U36,0,-1)),IF(Q33="-",IF(U35<U37,1,IF(U35<=U36,0,-1)))) -> 1 | U37: =_xll.DBRW('Value Tree'!A3,A10,A14,Q37,A20,A23,A26,"ZBB Total","Value") -> 0 | X37: L500 | Y37: =IF(X33="+",IF(Z35>Z37,1,IF(Z35>=Z36,0,-1)),IF(X33="-",IF(Z35<Z37,1,IF(Z35<=Z36,0,-1)))) -> -1 | Z37: =IFERROR((S30+S36)/S7,0) -> 0 | AA37: =IF(X33="+",IF(AB35>AB37,1,IF(AB35>=AB36,0,-1)),IF(X33="-",IF(AB35<AB37,1,IF(AB35<=AB36,0,-1)))) -> -1 | AB37: =IFERROR((U30+U36)/U7,0) -> 0 | AE37: L500 | AF37: =IF(AE33="+",IF(AG35>AG37*(1+IF(AG37>0,$B$4,-$B$4)),0,IF(AG35>=AG36*(1+IF(AG36>0,-$B$4,$B$4)),0,-1)),IF(AE33="-",IF(AG35<AG37*(1+IF(AG37>0,-$B$4,$B$4)),0,IF(AG35<=AG36*(1+IF(AG36>0,$B$4,-$B$4)),0,-1)))) -> 0 | AG37: =_xll.DBRW(A3,A10,A13,AE37,A20,A23,"Cement Group","Other Variable (LMU/t)","Value") -> 0 | AH37: =IF(AE33="+",IF(AI35>AI37*(1+IF(AI37>0,$B$4,-$B$4)),0,IF(AI35>=AI36*(1+IF(AI36>0,-$B$4,$B$4)),0,-1)),IF(AE33="-",IF(AI35<AI37*(1+IF(AI37>0,-$B$4,$B$4)),0,IF(AI35<=AI36*(1+IF(AI36>0,$B$4,-$B$4)),0,-1)))) -> 0 | AI37: =_xll.DBRW(A3,A10,A14,AE37,A20,A23,"Cement Group","Other Variable (LMU/t)","Value") -> 0 | AL37: L500 | AM37: =IF(AL33="+",IF(AN35>AN37*(1+IF(AN37>0,$B$4,-$B$4)),0,IF(AN35>=AN36*(1+IF(AN36>0,-$B$4,$B$4)),0,-1)),IF(AL33="-",IF(AN35<AN37*(1+IF(AN37>0,-$B$4,$B$4)),0,IF(AN35<=AN36*(1+IF(AN36>0,$B$4,-$B$4)),0,-1)))) -> 0 | AN37: =_xll.DBRW(A3,A10,A13,AL37,A20,A23,"Cement Group","Clinker Factor (%)","Value") -> 0 | AO37: =IF(AL33="+",IF(AS35>AP37*(1+IF(AP37>0,$B$4,-$B$4)),0,IF(AS35>=AS36*(1+IF(AS36>0,-$B$4,$B$4)),0,-1)),IF(AL33="-",IF(AS35<AP37*(1+IF(AP37>0,-$B$4,$B$4)),0,IF(AS35<=AS36*(1+IF(AS36>0,$B$4,-$B$4)),0,-1)))) -> #REF! | AP37: =_xll.DBRW(A3,A10,A14,AL37,A20,A23,"Cement Group","Clinker Factor (%)","Value") -> 0
A38: DFS.M.140.Indirect_Cash_Flow
A39: Total Value
C42: + | E42: Higher is better
C43: - | E43: Lower is better
...

Sheet Menu
A1: Cubo
A2: CONS_VC:DFS.200.KPIs
A3: CONS_VC:DFS.100.Profit_and_loss
A4: CONS_VC:DFS.140.Indirect_Cash_Flow
A5: CONS_VC:DFS.180.Gross_Debt
A6: CONS_VC:REV.100.Revenue_Consolidated
A8: Ano
A9: =_xll.SUBNM("CONS_VC:ALL.D.Year","","2025") -> 2025
A11: Mês
A12: =_xll.SUBNM("CONS_VC:ALL.D.Month",,"Total YTD","MEMBER_NAME") -> Total YTD
A13: =_xll.SUBNM("CONS_VC:ALL.D.Month",,"Year","MEMBER_NAME") -> Year
A15: Versão
A18: Currency
A19: =_xll.SUBNM("CONS_VC:ALL.D.Currency","","BRL") -> BRL
A21: Region
A22: =_xll.SUBNM("CONS_VC:ALL.D.Region","","VCBR") -> VCBR
A24: Produto
A25: =_xll.SUBNM("CONS_VC:ALL.D.Products","","Total Products") -> Total Products
A27: Accounts_PNL
A28: Net Profit
A30: DFM.100.Profil_and_Loss
A31: Value

Sheet Cognos_Office_Connection_Cache

Sheet Planilha3
A1: =_xll.VIEW("CONS_VC:DFS.100.Profit_and_Loss",'Value Tree'!$E$3,"!",'Value Tree'!$G$3,'Value Tree'!$E$4,'Value Tree'!$G$4,$B$7,"!",$B$3) -> CONS_VC:DFS.100.Profit_and_Loss:-1231230054-1315469618
A2: ALL.D.Year
A3: DFS.M.100.Profit_and_Loss | B3: =_xll.SUBNM("CONS_VC:DFS.M.100.Profit_and_Loss","","Value") -> Value
A4: ALL.D.Version
A5: ALL.D.Currency
A6: ALL.D.Region
A7: ALL.D.Products | B7: =_xll.SUBNM("CONS_VC:ALL.D.Products","","Total Products") -> Total Products
B9: Year
A10: Net Profit
A12: =_xll.VIEW("CONS_VC:DFS.140.Indirect_Cash_Flow",$B$13,$B$14,$B$15,$B$16,$B$17,"!","!") -> CONS_VC:DFS.140.Indirect_Cash_Flow:-3297255361808148316
A13: ALL.D.Year | B13: =_xll.SUBNM("CONS_VC:ALL.D.Year","","2025") -> 2025
A14: ALL.D.Month | B14: =_xll.SUBNM("CONS_VC:ALL.D.Month","Default","Jan","Desc") -> Jan
A15: ALL.D.Version | B15: =_xll.SUBNM("CONS_VC:ALL.D.Version","","T4") -> T4
A16: ALL.D.Currency | B16: =_xll.SUBNM("CONS_VC:ALL.D.Currency","","BRL") -> BRL
A17: ALL.D.Region | B17: =_xll.SUBNM("CONS_VC:ALL.D.Region","","VCBR") -> VCBR
B19: Total Value | C19: Value | D19: Adjustments
A20: EBITDA | B20: =_xll.DBRW($A$12,$B$13,$B$14,$B$15,$B$16,$B$17,$A20,B$19) -> 135.51336 | C20: =_xll.DBRW($A$12,$B$13,$B$14,$B$15,$B$16,$B$17,$A20,C$19) -> 135.51336 | D20: =_xll.DBRW($A$12,$B$13,$B$14,$B$15,$B$16,$B$17,$A20,D$19) -> 0
A21: Income tax on transactions | B21: =_xll.DBRW($A$12,$B$13,$B$14,$B$15,$B$16,$B$17,$A21,B$19) -> -26.351264 | C21: =_xll.DBRW($A$12,$B$13,$B$14,$B$15,$B$16,$B$17,$A21,C$19) -> -26.351264 | D21: =_xll.DBRW($A$12,$B$13,$B$14,$B$15,$B$16,$B$17,$A21,D$19) -> 0
A22: Working capital | B22: =_xll.DBRW($A$12,$B$13,$B$14,$B$15,$B$16,$B$17,$A22,B$19) -> -97.235466 | C22: =_xll.DBRW($A$12,$B$13,$B$14,$B$15,$B$16,$B$17,$A22,C$19) -> -97.235466 | D22: =_xll.DBRW($A$12,$B$13,$B$14,$B$15,$B$16,$B$17,$A22,D$19) -> 0
A23: Non expansion capex | B23: =_xll.DBRW($A$12,$B$13,$B$14,$B$15,$B$16,$B$17,$A23,B$19) -> -64.688579 | C23: =_xll.DBRW($A$12,$B$13,$B$14,$B$15,$B$16,$B$17,$A23,C$19) -> -64.688579 | D23: =_xll.DBRW($A$12,$B$13,$B$14,$B$15,$B$16,$B$17,$A23,D$19) -> 0
A24: Dividends received | B24: =_xll.DBRW($A$12,$B$13,$B$14,$B$15,$B$16,$B$17,$A24,B$19) -> 0 | C24: =_xll.DBRW($A$12,$B$13,$B$14,$B$15,$B$16,$B$17,$A24,C$19) -> 0 | D24: =_xll.DBRW($A$12,$B$13,$B$14,$B$15,$B$16,$B$17,$A24,D$19) -> 0
A25: Financial Results | B25: =_xll.DBRW($A$12,$B$13,$B$14,$B$15,$B$16,$B$17,$A25,B$19) -> -3.6362083 | C25: =_xll.DBRW($A$12,$B$13,$B$14,$B$15,$B$16,$B$17,$A25,C$19) -> -3.6362083 | D25: =_xll.DBRW($A$12,$B$13,$B$14,$B$15,$B$16,$B$17,$A25,D$19) -> 0
A26: Debt Amortization | B26: =_xll.DBRW($A$12,$B$13,$B$14,$B$15,$B$16,$B$17,$A26,B$19) -> -0.570196 | C26: =_xll.DBRW($A$12,$B$13,$B$14,$B$15,$B$16,$B$17,$A26,C$19) -> -0.570196 | D26: =_xll.DBRW($A$12,$B$13,$B$14,$B$15,$B$16,$B$17,$A26,D$19) -> 0
A27: Financial Revenue | B27: =_xll.DBRW($A$12,$B$13,$B$14,$B$15,$B$16,$B$17,$A27,B$19) -> 32.409624 | C27: =_xll.DBRW($A$12,$B$13,$B$14,$B$15,$B$16,$B$17,$A27,C$19) -> 32.409624 | D27: =_xll.DBRW($A$12,$B$13,$B$14,$B$15,$B$16,$B$17,$A27,D$19) -> 0
A28: Other Financial Expenses | B28: =_xll.DBRW($A$12,$B$13,$B$14,$B$15,$B$16,$B$17,$A28,B$19) -> -8.5350575 | C28: =_xll.DBRW($A$12,$B$13,$B$14,$B$15,$B$16,$B$17,$A28,C$19) -> -8.5350575 | D28: =_xll.DBRW($A$12,$B$13,$B$14,$B$15,$B$16,$B$17,$A28,D$19) -> 0
A29: Derivatives settlement | B29: =_xll.DBRW($A$12,$B$13,$B$14,$B$15,$B$16,$B$17,$A29,B$19) -> -20.458654 | C29: =_xll.DBRW($A$12,$B$13,$B$14,$B$15,$B$16,$B$17,$A29,C$19) -> -20.458654 | D29: =_xll.DBRW($A$12,$B$13,$B$14,$B$15,$B$16,$B$17,$A29,D$19) -> 0
A30: Tax on Financial Revenue | B30: =_xll.DBRW($A$12,$B$13,$B$14,$B$15,$B$16,$B$17,$A30,B$19) -> -6.4819249 | C30: =_xll.DBRW($A$12,$B$13,$B$14,$B$15,$B$16,$B$17,$A30,C$19) -> -6.4819249 | D30: =_xll.DBRW($A$12,$B$13,$B$14,$B$15,$B$16,$B$17,$A30,D$19) -> 0
A31: Other | B31: =_xll.DBRW($A$12,$B$13,$B$14,$B$15,$B$16,$B$17,$A31,B$19) -> 24.556223 | C31: =_xll.DBRW($A$12,$B$13,$B$14,$B$15,$B$16,$B$17,$A31,C$19) -> 24.556223 | D31: =_xll.DBRW($A$12,$B$13,$B$14,$B$15,$B$16,$B$17,$A31,D$19) -> 0
... A44: Funding | B44: =_xll.DBRW($A$12,$B$13,$B$14,$B$15,$B$16,$B$17,$A44,B$19) -> -1.5730474 | C44: =_xll.DBRW($A$12,$B$13,$B$14,$B$15,$B$16,$B$17,$A44,C$19) -> -1.5730474 | D44: =_xll.DBRW($A$12,$B$13,$B$14,$B$15,$B$16,$B$17,$A44,D$19) -> 0
A45: Change in cash | C45: =_xll.DBRW($A$12,$B$13,$B$14,$B$15,$B$16,$B$17,$A45,C$19) -> -96.577063 | D45: =_xll.DBRW($A$12,$B$13,$B$14,$B$15,$B$16,$B$17,$A45,D$19) -> 0
A46: Initial Cash Balance | B46: =_xll.DBRW($A$12,$B$13,$B$14,$B$15,$B$16,$B$17,$A46,B$19) -> 2906.6917 | C46: =_xll.DBRW($A$12,$B$13,$B$14,$B$15,$B$16,$B$17,$A46,C$19) -> 2906.6917 | D46: =_xll.DBRW($A$12,$B$13,$B$14,$B$15,$B$16,$B$17,$A46,D$19) -> 2906.6917
A47: Final Cash Position | B47: =_xll.DBRW($A$12,$B$13,$B$14,$B$15,$B$16,$B$17,$A47,B$19) -> 5716.8064 | C47: =_xll.DBRW($A$12,$B$13,$B$14,$B$15,$B$16,$B$17,$A47,C$19) -> 2810.1147 | D47: =_xll.DBRW($A$12,$B$13,$B$14,$B$15,$B$16,$B$17,$A47,D$19) -> 2906.6917
A48: Final Cash Position Aux | B48: =_xll.DBRW($A$12,$B$13,$B$14,$B$15,$B$16,$B$17,$A48,B$19) -> 5716.8064 | C48: =_xll.DBRW($A$12,$B$13,$B$14,$B$15,$B$16,$B$17,$A48,C$19) -> 2810.1147 | D48: =_xll.DBRW($A$12,$B$13,$B$14,$B$15,$B$16,$B$17,$A48,D$19) -> 2906.6917
A49: Final Debt Position | B49: =_xll.DBRW($A$12,$B$13,$B$14,$B$15,$B$16,$B$17,$A49,B$19) -> -6017.004 | C49: =_xll.DBRW($A$12,$B$13,$B$14,$B$15,$B$16,$B$17,$A49,C$19) -> -6017.004 | D49: =_xll.DBRW($A$12,$B$13,$B$14,$B$15,$B$16,$B$17,$A49,D$19) -> 0
A50: MTM | B50: =_xll.DBRW($A$12,$B$13,$B$14,$B$15,$B$16,$B$17,$A50,B$19) -> 70.478512 | C50: =_xll.DBRW($A$12,$B$13,$B$14,$B$15,$B$16,$B$17,$A50,C$19) -> 70.478512 | D50: =_xll.DBRW($A$12,$B$13,$B$14,$B$15,$B$16,$B$17,$A50,D$19) -> 0
A51: Final Net Debt | B51: =_xll.DBRW($A$12,$B$13,$B$14,$B$15,$B$16,$B$17,$A51,B$19) -> -229.71909 | C51: =_xll.DBRW($A$12,$B$13,$B$14,$B$15,$B$16,$B$17,$A51,C$19) -> -3136.4108 | D51: =_xll.DBRW($A$12,$B$13,$B$14,$B$15,$B$16,$B$17,$A51,D$19) -> 2906.6917
A52: Adj EBITDA LTM | B52: =_xll.DBRW($A$12,$B$13,$B$14,$B$15,$B$16,$B$17,$A52,B$19) -> 135.51336 | C52: =_xll.DBRW($A$12,$B$13,$B$14,$B$15,$B$16,$B$17,$A52,C$19) -> 135.51336 | D52: =_xll.DBRW($A$12,$B$13,$B$14,$B$15,$B$16,$B$17,$A52,D$19) -> 0
A53: Adjusts LTM | B53: =_xll.DBRW($A$12,$B$13,$B$14,$B$15,$B$16,$B$17,$A53,B$19) -> 0 | C53: =_xll.DBRW($A$12,$B$13,$B$14,$B$15,$B$16,$B$17,$A53,C$19) -> 0 | D53: =_xll.DBRW($A$12,$B$13,$B$14,$B$15,$B$16,$B$17,$A53,D$19) -> 0
A54: Leverage | B54: =_xll.DBRW($A$12,$B$13,$B$14,$B$15,$B$16,$B$17,$A54,B$19) -> -23.144661 | C54: =_xll.DBRW($A$12,$B$13,$B$14,$B$15,$B$16,$B$17,$A54,C$19) -> -23.144661 | D54: =_xll.DBRW($A$12,$B$13,$B$14,$B$15,$B$16,$B$17,$A54,D$19) -> 0
A56: CONS_VC:DFS.200.KPIs
...

Sheet Planilha1
A1: =_xll.VIEW("CONS_VC:DFS.200.KPIs",$B$2,$B$3,$B$4,$B$5,$B$6,$B$7,"!","!") -> CONS_VC:DFS.200.KPIs:340476972643356372
A2: ALL.D.Year | B2: =_xll.SUBNM("CONS_VC:ALL.D.Year","","2025") -> 2025
A3: ALL.D.Month | B3: =_xll.SUBNM("CONS_VC:ALL.D.Month","Default","Jan","Desc") -> Jan
A4: ALL.D.Version | B4: =_xll.SUBNM("CONS_VC:ALL.D.Version","","T4") -> T4
A5: ALL.D.Currency | B5: =_xll.SUBNM("CONS_VC:ALL.D.Currency","Default","BRL","MEMBER_NAME") -> BRL
A6: ALL.D.Region | B6: =_xll.SUBNM("CONS_VC:ALL.D.Region","","VCBR") -> VCBR
A7: ALL.D.Products | B7: =_xll.SUBNM("CONS_VC:ALL.D.Products","Default","PROD099 - Others","Código e Descrição") -> PROD099 - Others
B9: Value | C9: Aux
A10: Production volume (kt) | B10: =_xll.DBRW($A$1,$B$2,$B$3,$B$4,$B$5,$B$6,$B$7,$A10,B$9) -> 100 | C10: =_xll.DBRW($A$1,$B$2,$B$3,$B$4,$B$5,$B$6,$B$7,$A10,C$9) -> 0
A11: Thermal Sub. (%) | B11: =_xll.DBRW($A$1,$B$2,$B$3,$B$4,$B$5,$B$6,$B$7,$A11,B$9) -> 0.1 | C11: =_xll.DBRW($A$1,$B$2,$B$3,$B$4,$B$5,$B$6,$B$7,$A11,C$9) -> 10
A12: Thermal C. (kcal/t kk) | B12: =_xll.DBRW($A$1,$B$2,$B$3,$B$4,$B$5,$B$6,$B$7,$A12,B$9) -> 50 | C12: =_xll.DBRW($A$1,$B$2,$B$3,$B$4,$B$5,$B$6,$B$7,$A12,C$9) -> 5000
A13: Petcoke Price (LMU/t) | B13: =_xll.DBRW($A$1,$B$2,$B$3,$B$4,$B$5,$B$6,$B$7,$A13,B$9) -> 10 | C13: =_xll.DBRW($A$1,$B$2,$B$3,$B$4,$B$5,$B$6,$B$7,$A13,C$9) -> 0
A14: CO2 Gross (kg/ton) | B14: =_xll.DBRW($A$1,$B$2,$B$3,$B$4,$B$5,$B$6,$B$7,$A14,B$9) -> 100 | C14: =_xll.DBRW($A$1,$B$2,$B$3,$B$4,$B$5,$B$6,$B$7,$A14,C$9) -> 10000
A15: CO2 Net (kg/ton) | B15: =_xll.DBRW($A$1,$B$2,$B$3,$B$4,$B$5,$B$6,$B$7,$A15,B$9) -> 100 | C15: =_xll.DBRW($A$1,$B$2,$B$3,$B$4,$B$5,$B$6,$B$7,$A15,C$9) -> 10000
A16: Power Price (LMU/MWh) | B16: =_xll.DBRW($A$1,$B$2,$B$3,$B$4,$B$5,$B$6,$B$7,$A16,B$9) -> 50 | C16: =_xll.DBRW($A$1,$B$2,$B$3,$B$4,$B$5,$B$6,$B$7,$A16,C$9) -> 5000
A17: Power Cons. (kWh/t) | B17: =_xll.DBRW($A$1,$B$2,$B$3,$B$4,$B$5,$B$6,$B$7,$A17,B$9) -> 50 | C17: =_xll.DBRW($A$1,$B$2,$B$3,$B$4,$B$5,$B$6,$B$7,$A17,C$9) -> 5000
A18: Clinker Factor (%) | B18: =_xll.DBRW($A$1,$B$2,$B$3,$B$4,$B$5,$B$6,$B$7,$A18,B$9) -> 0.5 | C18: =_xll.DBRW($A$1,$B$2,$B$3,$B$4,$B$5,$B$6,$B$7,$A18,C$9) -> 50
A19: Cash Cost (LMU/t) | B19: =_xll.DBRW($A$1,$B$2,$B$3,$B$4,$B$5,$B$6,$B$7,$A19,B$9) -> 510 | C19: =_xll.DBRW($A$1,$B$2,$B$3,$B$4,$B$5,$B$6,$B$7,$A19,C$9) -> 51000
A20: Cement Var. Costs (LMU/t) | B20: =_xll.DBRW($A$1,$B$2,$B$3,$B$4,$B$5,$B$6,$B$7,$A20,B$9) -> 360 | C20: =_xll.DBRW($A$1,$B$2,$B$3,$B$4,$B$5,$B$6,$B$7,$A20,C$9) -> 36000
A21: Fuel (LMU/t) | B21: =_xll.DBRW($A$1,$B$2,$B$3,$B$4,$B$5,$B$6,$B$7,$A21,B$9) -> 10 | C21: =_xll.DBRW($A$1,$B$2,$B$3,$B$4,$B$5,$B$6,$B$7,$A21,C$9) -> 1000
... A58: % ROIC | B58: =_xll.DBRW($A$1,$B$2,$B$3,$B$4,$B$5,$B$6,$B$7,$A58,B$9) -> 0 | C58: =_xll.DBRW($A$1,$B$2,$B$3,$B$4,$B$5,$B$6,$B$7,$A58,C$9) -> 0

Sheet Planilha2
B2: Cement Net FOB (€/t) | C2: Preço do Cimento | D2: Cobo de Receita | E2: Produto Cimento
B3: SG&A (€M) | C3: ZBB total
