Workbook
Name ID: "8cf5af60-f32c-4d17-a048-978f4aaf10e7"

Sheet Cons_Region
B1: =_xll.VIEW("CONS_VC_PRD:STG.100.DataBase_Uploads",F12) -> CONS_VC_PRD:STG.100.DataBase_Uploads:1238482367-298299361 | C1: =_xll.VIEW("CONS_VC_PRD:ALL.015.Region_Assumptions") -> CONS_VC_PRD:ALL.015.Region_Assumptions:1238482367-1481494521 | D1: =_xll.VIEW("CONS_VC_PRD:DFS.120.Financial_Results") -> CONS_VC_PRD:DFS.120.Financial_Results:1238482367-1083526962 | K1: Value | L1: N/A | M1: =_xll.SUBNM("CONS_VC_PRD:ALL.D.Version","","T3") -> T3 | N1: PROD099
B2: =_xll.VIEW("CONS_VC_PRD:REV.100.Revenue_Consolidated") -> CONS_VC_PRD:REV.100.Revenue_Consolidated:1238482367-226826383 | C2: =_xll.VIEW("CONS_VC_PRD:ALL.010.Economic_Assumptions") -> CONS_VC_PRD:ALL.010.Economic_Assumptions:1238482367145679083 | D2: =_xll.VIEW("CONS_VC_PRD:DFS.140.Indirect_Cash_Flow") -> CONS_VC_PRD:DFS.140.Indirect_Cash_Flow:1238482367-1117995735 | K2: Total Market | N2: Total Products
B3: =_xll.VIEW("CONS_VC_PRD:DFS.100.Profit_and_Loss") -> CONS_VC_PRD:DFS.100.Profit_and_Loss:123848236720210810 | C3: =_xll.VIEW("CONS_VC_PRD:DFS.160.Working_Capital") -> CONS_VC_PRD:DFS.160.Working_Capital:1238482367-2032607141 | D3: =_xll.VIEW("CONS_VC_PRD:ALL.004.Uploads_Status_Planning") -> CONS_VC_PRD:ALL.004.Uploads_Status_Planning:1238482367-886898250 | G3: Flag
B4: =_xll.VIEW("CONS_VC_PRD:ALL.001.Actual_Control") -> CONS_VC_PRD:ALL.001.Actual_Control:1238482367-2039581856 | C4: =_xll.VIEW("CONS_VC_PRD:DFS.180.Gross_Debt") -> CONS_VC_PRD:DFS.180.Gross_Debt:1238482367-1307852146
C5: =_xll.DBRW(Cons_Region!$B$4,Cons_Region!$F$12,Cons_Region!C15,$M$1,$G$3) -> ACTUAL | D5: =_xll.DBRW(Cons_Region!$B$4,Cons_Region!$F$12,Cons_Region!D15,$M$1,$G$3) | E5: =_xll.DBRW(Cons_Region!$B$4,Cons_Region!$F$12,Cons_Region!E15,$M$1,$G$3) | F5: =_xll.DBRW(Cons_Region!$B$4,Cons_Region!$F$12,Cons_Region!F15,$M$1,$G$3) | G5: =_xll.DBRW(Cons_Region!$B$4,Cons_Region!$F$12,Cons_Region!G15,$M$1,$G$3) | H5: =_xll.DBRW(Cons_Region!$B$4,Cons_Region!$F$12,Cons_Region!H15,$M$1,$G$3) | I5: =_xll.DBRW(Cons_Region!$B$4,Cons_Region!$F$12,Cons_Region!I15,$M$1,$G$3) | J5: =_xll.DBRW(Cons_Region!$B$4,Cons_Region!$F$12,Cons_Region!J15,$M$1,$G$3) | ... N5: =_xll.DBRW(Cons_Region!$B$4,Cons_Region!$F$12,Cons_Region!N15,$M$1,$G$3)
B7: Global Assumptions - Input
C12: =_xll.SUBNM("CONS_VC_PRD:ALL.D.Region","Nível 0","VCBR","MEMBER_NAME") -> VCBR | F12: =_xll.SUBNM("CONS_VC_PRD:ALL.D.Year","SYS_Picklist","2026","MEMBER_NAME") -> 2026 | H12: =_xll.SUBNM("CONS_VC_PRD:ALL.D.Currency","PAX","BRL","Nome alternativo") -> BRL | J12: Input Status: | K12: =_xll.DBRW($D$3,$M$1,$C$12,"Financial_Planning","Status") -> Open
O14: =$F$12+1 -> 2027 | P14: =$F$12+2 -> 2028 | Q14: =$F$12+3 -> 2029 | R14: =$F$12+4 -> 2030 | S14: =$F$12+5 -> 2031
C15: 01 | D15: 02 | E15: 03 | F15: 04 | G15: 05 | H15: 06 | I15: 07 | J15: 08 | K15: 09 | L15: 10 | M15: 11 | N15: 12 | O15: PE | P15: PE | Q15: PE | R15: PE | S15: PE
C16: =$F$12&"."&C15 -> 2026.01 | D16: =$F$12&"."&D15 -> 2026.02 | E16: =$F$12&"."&E15 -> 2026.03 | F16: =$F$12&"."&F15 -> 2026.04 | G16: =$F$12&"."&G15 -> 2026.05 | H16: =$F$12&"."&H15 -> 2026.06 | I16: =$F$12&"."&I15 -> 2026.07 | J16: =$F$12&"."&J15 -> 2026.08 | ... N16: =$F$12&"."&N15 -> 2026.12 | O16: PE | P16: PE | Q16: PE | R16: PE | S16: PE
B17: Begining FX Rate R$/US$ | C17: =_xll.DBRW($C$2,Cons_Region!$F$12,Cons_Region!$C$15,$M$1,$B17,$K$1) -> 0 | D17: =_xll.DBRW($C$2,Cons_Region!$F$12,Cons_Region!$C$15,$M$1,$B17,$K$1) -> 0 | E17: =_xll.DBRW($C$2,Cons_Region!$F$12,Cons_Region!$C$15,$M$1,$B17,$K$1) -> 0 | F17: =_xll.DBRW($C$2,Cons_Region!$F$12,Cons_Region!$C$15,$M$1,$B17,$K$1) -> 0 | G17: =_xll.DBRW($C$2,Cons_Region!$F$12,Cons_Region!$C$15,$M$1,$B17,$K$1) -> 0 | H17: =_xll.DBRW($C$2,Cons_Region!$F$12,Cons_Region!$C$15,$M$1,$B17,$K$1) -> 0 | I17: =_xll.DBRW($C$2,Cons_Region!$F$12,Cons_Region!$C$15,$M$1,$B17,$K$1) -> 0 | J17: =_xll.DBRW($C$2,Cons_Region!$F$12,Cons_Region!$C$15,$M$1,$B17,$K$1) -> 0 | ... N17: =_xll.DBRW($C$2,Cons_Region!$F$12,Cons_Region!$C$15,$M$1,$B17,$K$1) -> 0 | O17: =_xll.DBRW($C$2,$O$14,$O$16,$M$1,$B17,$K$1) -> 0 | P17: =_xll.DBRW($C$2,$O$14,$O$16,$M$1,$B17,$K$1) -> 0 | Q17: =_xll.DBRW($C$2,$O$14,$O$16,$M$1,$B17,$K$1) -> 0 | R17: =_xll.DBRW($C$2,$O$14,$O$16,$M$1,$B17,$K$1) -> 0 | S17: =_xll.DBRW($C$2,$O$14,$O$16,$M$1,$B17,$K$1) -> 0
B18: Average FX Rate R$/US$ | C18: =_xll.DBRW($C$2,Cons_Region!$F$12,Cons_Region!$C$15,$M$1,$B18,$K$1) -> 0 | D18: =_xll.DBRW($C$2,Cons_Region!$F$12,Cons_Region!$C$15,$M$1,$B18,$K$1) -> 0 | E18: =_xll.DBRW($C$2,Cons_Region!$F$12,Cons_Region!$C$15,$M$1,$B18,$K$1) -> 0 | F18: =_xll.DBRW($C$2,Cons_Region!$F$12,Cons_Region!$C$15,$M$1,$B18,$K$1) -> 0 | G18: =_xll.DBRW($C$2,Cons_Region!$F$12,Cons_Region!$C$15,$M$1,$B18,$K$1) -> 0 | H18: =_xll.DBRW($C$2,Cons_Region!$F$12,Cons_Region!$C$15,$M$1,$B18,$K$1) -> 0 | I18: =_xll.DBRW($C$2,Cons_Region!$F$12,Cons_Region!$C$15,$M$1,$B18,$K$1) -> 0 | J18: =_xll.DBRW($C$2,Cons_Region!$F$12,Cons_Region!$C$15,$M$1,$B18,$K$1) -> 0 | ... N18: =_xll.DBRW($C$2,Cons_Region!$F$12,Cons_Region!$C$15,$M$1,$B18,$K$1) -> 0 | O18: =_xll.DBRW($C$2,$O$14,$O$16,$M$1,$B18,$K$1) -> 0 | P18: =_xll.DBRW($C$2,$O$14,$O$16,$M$1,$B18,$K$1) -> 0 | Q18: =_xll.DBRW($C$2,$O$14,$O$16,$M$1,$B18,$K$1) -> 0 | R18: =_xll.DBRW($C$2,$O$14,$O$16,$M$1,$B18,$K$1) -> 0 | S18: =_xll.DBRW($C$2,$O$14,$O$16,$M$1,$B18,$K$1) -> 0
B19: Final FX Rate R$/US$ | C19: =_xll.DBRW($C$2,Cons_Region!$F$12,Cons_Region!$C$15,$M$1,$B19,$K$1) -> 0 | D19: =_xll.DBRW($C$2,Cons_Region!$F$12,Cons_Region!$C$15,$M$1,$B19,$K$1) -> 0 | E19: =_xll.DBRW($C$2,Cons_Region!$F$12,Cons_Region!$C$15,$M$1,$B19,$K$1) -> 0 | F19: =_xll.DBRW($C$2,Cons_Region!$F$12,Cons_Region!$C$15,$M$1,$B19,$K$1) -> 0 | G19: =_xll.DBRW($C$2,Cons_Region!$F$12,Cons_Region!$C$15,$M$1,$B19,$K$1) -> 0 | H19: =_xll.DBRW($C$2,Cons_Region!$F$12,Cons_Region!$C$15,$M$1,$B19,$K$1) -> 0 | I19: =_xll.DBRW($C$2,Cons_Region!$F$12,Cons_Region!$C$15,$M$1,$B19,$K$1) -> 0 | J19: =_xll.DBRW($C$2,Cons_Region!$F$12,Cons_Region!$C$15,$M$1,$B19,$K$1) -> 0 | ... N19: =_xll.DBRW($C$2,Cons_Region!$F$12,Cons_Region!$C$15,$M$1,$B19,$K$1) -> 0 | O19: =_xll.DBRW($C$2,$O$14,$O$16,$M$1,$B19,$K$1) -> 0 | P19: =_xll.DBRW($C$2,$O$14,$O$16,$M$1,$B19,$K$1) -> 0 | Q19: =_xll.DBRW($C$2,$O$14,$O$16,$M$1,$B19,$K$1) -> 0 | R19: =_xll.DBRW($C$2,$O$14,$O$16,$M$1,$B19,$K$1) -> 0 | S19: =_xll.DBRW($C$2,$O$14,$O$16,$M$1,$B19,$K$1) -> 0
B20: Begining FX Rate US$/EUR | C20: =_xll.DBRW($C$2,Cons_Region!$F$12,Cons_Region!$C$15,$M$1,$B20,$K$1) -> 0 | D20: =_xll.DBRW($C$2,Cons_Region!$F$12,Cons_Region!$C$15,$M$1,$B20,$K$1) -> 0 | E20: =_xll.DBRW($C$2,Cons_Region!$F$12,Cons_Region!$C$15,$M$1,$B20,$K$1) -> 0 | F20: =_xll.DBRW($C$2,Cons_Region!$F$12,Cons_Region!$C$15,$M$1,$B20,$K$1) -> 0 | G20: =_xll.DBRW($C$2,Cons_Region!$F$12,Cons_Region!$C$15,$M$1,$B20,$K$1) -> 0 | H20: =_xll.DBRW($C$2,Cons_Region!$F$12,Cons_Region!$C$15,$M$1,$B20,$K$1) -> 0 | I20: =_xll.DBRW($C$2,Cons_Region!$F$12,Cons_Region!$C$15,$M$1,$B20,$K$1) -> 0 | J20: =_xll.DBRW($C$2,Cons_Region!$F$12,Cons_Region!$C$15,$M$1,$B20,$K$1) -> 0 | ... N20: =_xll.DBRW($C$2,Cons_Region!$F$12,Cons_Region!$C$15,$M$1,$B20,$K$1) -> 0 | O20: =_xll.DBRW($C$2,$O$14,$O$16,$M$1,$B20,$K$1) -> 0 | P20: =_xll.DBRW($C$2,$O$14,$O$16,$M$1,$B20,$K$1) -> 0 | Q20: =_xll.DBRW($C$2,$O$14,$O$16,$M$1,$B20,$K$1) -> 0 | R20: =_xll.DBRW($C$2,$O$14,$O$16,$M$1,$B20,$K$1) -> 0 | S20: =_xll.DBRW($C$2,$O$14,$O$16,$M$1,$B20,$K$1) -> 0
B21: Average FX Rate US$/EUR | C21: =_xll.DBRW($C$2,Cons_Region!$F$12,Cons_Region!$C$15,$M$1,$B21,$K$1) -> 5 | D21: =_xll.DBRW($C$2,Cons_Region!$F$12,Cons_Region!$C$15,$M$1,$B21,$K$1) -> 5 | E21: =_xll.DBRW($C$2,Cons_Region!$F$12,Cons_Region!$C$15,$M$1,$B21,$K$1) -> 5 | F21: =_xll.DBRW($C$2,Cons_Region!$F$12,Cons_Region!$C$15,$M$1,$B21,$K$1) -> 5 | G21: =_xll.DBRW($C$2,Cons_Region!$F$12,Cons_Region!$C$15,$M$1,$B21,$K$1) -> 5 | H21: =_xll.DBRW($C$2,Cons_Region!$F$12,Cons_Region!$C$15,$M$1,$B21,$K$1) -> 5 | I21: =_xll.DBRW($C$2,Cons_Region!$F$12,Cons_Region!$C$15,$M$1,$B21,$K$1) -> 5 | J21: =_xll.DBRW($C$2,Cons_Region!$F$12,Cons_Region!$C$15,$M$1,$B21,$K$1) -> 5 | ... N21: =_xll.DBRW($C$2,Cons_Region!$F$12,Cons_Region!$C$15,$M$1,$B21,$K$1) -> 5 | O21: =_xll.DBRW($C$2,$O$14,$O$16,$M$1,$B21,$K$1) -> 0 | P21: =_xll.DBRW($C$2,$O$14,$O$16,$M$1,$B21,$K$1) -> 0 | Q21: =_xll.DBRW($C$2,$O$14,$O$16,$M$1,$B21,$K$1) -> 0 | R21: =_xll.DBRW($C$2,$O$14,$O$16,$M$1,$B21,$K$1) -> 0 | S21: =_xll.DBRW($C$2,$O$14,$O$16,$M$1,$B21,$K$1) -> 0
B22: Final FX Rate US$/EUR | C22: =_xll.DBRW($C$2,Cons_Region!$F$12,Cons_Region!$C$15,$M$1,$B22,$K$1) -> 0 | D22: =_xll.DBRW($C$2,Cons_Region!$F$12,Cons_Region!$C$15,$M$1,$B22,$K$1) -> 0 | E22: =_xll.DBRW($C$2,Cons_Region!$F$12,Cons_Region!$C$15,$M$1,$B22,$K$1) -> 0 | F22: =_xll.DBRW($C$2,Cons_Region!$F$12,Cons_Region!$C$15,$M$1,$B22,$K$1) -> 0 | G22: =_xll.DBRW($C$2,Cons_Region!$F$12,Cons_Region!$C$15,$M$1,$B22,$K$1) -> 0 | H22: =_xll.DBRW($C$2,Cons_Region!$F$12,Cons_Region!$C$15,$M$1,$B22,$K$1) -> 0 | I22: =_xll.DBRW($C$2,Cons_Region!$F$12,Cons_Region!$C$15,$M$1,$B22,$K$1) -> 0 | J22: =_xll.DBRW($C$2,Cons_Region!$F$12,Cons_Region!$C$15,$M$1,$B22,$K$1) -> 0 | ... N22: =_xll.DBRW($C$2,Cons_Region!$F$12,Cons_Region!$C$15,$M$1,$B22,$K$1) -> 0 | O22: =_xll.DBRW($C$2,$O$14,$O$16,$M$1,$B22,$K$1) -> 0 | P22: =_xll.DBRW($C$2,$O$14,$O$16,$M$1,$B22,$K$1) -> 0 | Q22: =_xll.DBRW($C$2,$O$14,$O$16,$M$1,$B22,$K$1) -> 0 | R22: =_xll.DBRW($C$2,$O$14,$O$16,$M$1,$B22,$K$1) -> 0 | S22: =_xll.DBRW($C$2,$O$14,$O$16,$M$1,$B22,$K$1) -> 0
B23: Câmbio Inicial UYU$/US$ | C23: =_xll.DBRW($C$2,Cons_Region!$F$12,Cons_Region!$C$15,$M$1,$B23,$K$1) -> 0 | D23: =_xll.DBRW($C$2,Cons_Region!$F$12,Cons_Region!$C$15,$M$1,$B23,$K$1) -> 0 | E23: =_xll.DBRW($C$2,Cons_Region!$F$12,Cons_Region!$C$15,$M$1,$B23,$K$1) -> 0 | F23: =_xll.DBRW($C$2,Cons_Region!$F$12,Cons_Region!$C$15,$M$1,$B23,$K$1) -> 0 | G23: =_xll.DBRW($C$2,Cons_Region!$F$12,Cons_Region!$C$15,$M$1,$B23,$K$1) -> 0 | H23: =_xll.DBRW($C$2,Cons_Region!$F$12,Cons_Region!$C$15,$M$1,$B23,$K$1) -> 0 | I23: =_xll.DBRW($C$2,Cons_Region!$F$12,Cons_Region!$C$15,$M$1,$B23,$K$1) -> 0 | J23: =_xll.DBRW($C$2,Cons_Region!$F$12,Cons_Region!$C$15,$M$1,$B23,$K$1) -> 0 | ... N23: =_xll.DBRW($C$2,Cons_Region!$F$12,Cons_Region!$C$15,$M$1,$B23,$K$1) -> 0 | O23: =_xll.DBRW($C$2,$O$14,$O$16,$M$1,$B23,$K$1) -> 0 | P23: =_xll.DBRW($C$2,$O$14,$O$16,$M$1,$B23,$K$1) -> 0 | Q23: =_xll.DBRW($C$2,$O$14,$O$16,$M$1,$B23,$K$1) -> 0 | R23: =_xll.DBRW($C$2,$O$14,$O$16,$M$1,$B23,$K$1) -> 0 | S23: =_xll.DBRW($C$2,$O$14,$O$16,$M$1,$B23,$K$1) -> 0
B24: Câmbio Médio UYU$/US$ | C24: =_xll.DBRW($C$2,Cons_Region!$F$12,Cons_Region!$C$15,$M$1,$B24,$K$1) -> 0 | D24: =_xll.DBRW($C$2,Cons_Region!$F$12,Cons_Region!$C$15,$M$1,$B24,$K$1) -> 0 | E24: =_xll.DBRW($C$2,Cons_Region!$F$12,Cons_Region!$C$15,$M$1,$B24,$K$1) -> 0 | F24: =_xll.DBRW($C$2,Cons_Region!$F$12,Cons_Region!$C$15,$M$1,$B24,$K$1) -> 0 | G24: =_xll.DBRW($C$2,Cons_Region!$F$12,Cons_Region!$C$15,$M$1,$B24,$K$1) -> 0 | H24: =_xll.DBRW($C$2,Cons_Region!$F$12,Cons_Region!$C$15,$M$1,$B24,$K$1) -> 0 | I24: =_xll.DBRW($C$2,Cons_Region!$F$12,Cons_Region!$C$15,$M$1,$B24,$K$1) -> 0 | J24: =_xll.DBRW($C$2,Cons_Region!$F$12,Cons_Region!$C$15,$M$1,$B24,$K$1) -> 0 | ... N24: =_xll.DBRW($C$2,Cons_Region!$F$12,Cons_Region!$C$15,$M$1,$B24,$K$1) -> 0 | O24: =_xll.DBRW($C$2,$O$14,$O$16,$M$1,$B24,$K$1) -> 0 | P24: =_xll.DBRW($C$2,$O$14,$O$16,$M$1,$B24,$K$1) -> 0 | Q24: =_xll.DBRW($C$2,$O$14,$O$16,$M$1,$B24,$K$1) -> 0 | R24: =_xll.DBRW($C$2,$O$14,$O$16,$M$1,$B24,$K$1) -> 0 | S24: =_xll.DBRW($C$2,$O$14,$O$16,$M$1,$B24,$K$1) -> 0
B25: Câmbio Final UYU$/US$ | C25: =_xll.DBRW($C$2,Cons_Region!$F$12,Cons_Region!$C$15,$M$1,$B25,$K$1) -> 0 | D25: =_xll.DBRW($C$2,Cons_Region!$F$12,Cons_Region!$C$15,$M$1,$B25,$K$1) -> 0 | E25: =_xll.DBRW($C$2,Cons_Region!$F$12,Cons_Region!$C$15,$M$1,$B25,$K$1) -> 0 | F25: =_xll.DBRW($C$2,Cons_Region!$F$12,Cons_Region!$C$15,$M$1,$B25,$K$1) -> 0 | G25: =_xll.DBRW($C$2,Cons_Region!$F$12,Cons_Region!$C$15,$M$1,$B25,$K$1) -> 0 | H25: =_xll.DBRW($C$2,Cons_Region!$F$12,Cons_Region!$C$15,$M$1,$B25,$K$1) -> 0 | I25: =_xll.DBRW($C$2,Cons_Region!$F$12,Cons_Region!$C$15,$M$1,$B25,$K$1) -> 0 | J25: =_xll.DBRW($C$2,Cons_Region!$F$12,Cons_Region!$C$15,$M$1,$B25,$K$1) -> 0 | ... N25: =_xll.DBRW($C$2,Cons_Region!$F$12,Cons_Region!$C$15,$M$1,$B25,$K$1) -> 0 | O25: =_xll.DBRW($C$2,$O$14,$O$16,$M$1,$B25,$K$1) -> 0 | P25: =_xll.DBRW($C$2,$O$14,$O$16,$M$1,$B25,$K$1) -> 0 | Q25: =_xll.DBRW($C$2,$O$14,$O$16,$M$1,$B25,$K$1) -> 0 | R25: =_xll.DBRW($C$2,$O$14,$O$16,$M$1,$B25,$K$1) -> 0 | S25: =_xll.DBRW($C$2,$O$14,$O$16,$M$1,$B25,$K$1) -> 0
B26: Câmbio Inicial ARS$/US$ | C26: =_xll.DBRW($C$2,Cons_Region!$F$12,Cons_Region!$C$15,$M$1,$B26,$K$1) -> 0 | D26: =_xll.DBRW($C$2,Cons_Region!$F$12,Cons_Region!$C$15,$M$1,$B26,$K$1) -> 0 | E26: =_xll.DBRW($C$2,Cons_Region!$F$12,Cons_Region!$C$15,$M$1,$B26,$K$1) -> 0 | F26: =_xll.DBRW($C$2,Cons_Region!$F$12,Cons_Region!$C$15,$M$1,$B26,$K$1) -> 0 | G26: =_xll.DBRW($C$2,Cons_Region!$F$12,Cons_Region!$C$15,$M$1,$B26,$K$1) -> 0 | H26: =_xll.DBRW($C$2,Cons_Region!$F$12,Cons_Region!$C$15,$M$1,$B26,$K$1) -> 0 | I26: =_xll.DBRW($C$2,Cons_Region!$F$12,Cons_Region!$C$15,$M$1,$B26,$K$1) -> 0 | J26: =_xll.DBRW($C$2,Cons_Region!$F$12,Cons_Region!$C$15,$M$1,$B26,$K$1) -> 0 | ... N26: =_xll.DBRW($C$2,Cons_Region!$F$12,Cons_Region!$C$15,$M$1,$B26,$K$1) -> 0 | O26: =_xll.DBRW($C$2,$O$14,$O$16,$M$1,$B26,$K$1) -> 0 | P26: =_xll.DBRW($C$2,$O$14,$O$16,$M$1,$B26,$K$1) -> 0 | Q26: =_xll.DBRW($C$2,$O$14,$O$16,$M$1,$B26,$K$1) -> 0 | R26: =_xll.DBRW($C$2,$O$14,$O$16,$M$1,$B26,$K$1) -> 0 | S26: =_xll.DBRW($C$2,$O$14,$O$16,$M$1,$B26,$K$1) -> 0
B27: Câmbio Médio ARS$/US$ | C27: =_xll.DBRW($C$2,Cons_Region!$F$12,Cons_Region!$C$15,$M$1,$B27,$K$1) -> 0 | D27: =_xll.DBRW($C$2,Cons_Region!$F$12,Cons_Region!$C$15,$M$1,$B27,$K$1) -> 0 | E27: =_xll.DBRW($C$2,Cons_Region!$F$12,Cons_Region!$C$15,$M$1,$B27,$K$1) -> 0 | F27: =_xll.DBRW($C$2,Cons_Region!$F$12,Cons_Region!$C$15,$M$1,$B27,$K$1) -> 0 | G27: =_xll.DBRW($C$2,Cons_Region!$F$12,Cons_Region!$C$15,$M$1,$B27,$K$1) -> 0 | H27: =_xll.DBRW($C$2,Cons_Region!$F$12,Cons_Region!$C$15,$M$1,$B27,$K$1) -> 0 | I27: =_xll.DBRW($C$2,Cons_Region!$F$12,Cons_Region!$C$15,$M$1,$B27,$K$1) -> 0 | J27: =_xll.DBRW($C$2,Cons_Region!$F$12,Cons_Region!$C$15,$M$1,$B27,$K$1) -> 0 | ... N27: =_xll.DBRW($C$2,Cons_Region!$F$12,Cons_Region!$C$15,$M$1,$B27,$K$1) -> 0 | O27: =_xll.DBRW($C$2,$O$14,$O$16,$M$1,$B27,$K$1) -> 0 | P27: =_xll.DBRW($C$2,$O$14,$O$16,$M$1,$B27,$K$1) -> 0 | Q27: =_xll.DBRW($C$2,$O$14,$O$16,$M$1,$B27,$K$1) -> 0 | R27: =_xll.DBRW($C$2,$O$14,$O$16,$M$1,$B27,$K$1) -> 0 | S27: =_xll.DBRW($C$2,$O$14,$O$16,$M$1,$B27,$K$1) -> 0
B28: Câmbio Final ARS$/US$ | C28: =_xll.DBRW($C$2,Cons_Region!$F$12,Cons_Region!$C$15,$M$1,$B28,$K$1) -> 0 | D28: =_xll.DBRW($C$2,Cons_Region!$F$12,Cons_Region!$C$15,$M$1,$B28,$K$1) -> 0 | E28: =_xll.DBRW($C$2,Cons_Region!$F$12,Cons_Region!$C$15,$M$1,$B28,$K$1) -> 0 | F28: =_xll.DBRW($C$2,Cons_Region!$F$12,Cons_Region!$C$15,$M$1,$B28,$K$1) -> 0 | G28: =_xll.DBRW($C$2,Cons_Region!$F$12,Cons_Region!$C$15,$M$1,$B28,$K$1) -> 0 | H28: =_xll.DBRW($C$2,Cons_Region!$F$12,Cons_Region!$C$15,$M$1,$B28,$K$1) -> 0 | I28: =_xll.DBRW($C$2,Cons_Region!$F$12,Cons_Region!$C$15,$M$1,$B28,$K$1) -> 0 | J28: =_xll.DBRW($C$2,Cons_Region!$F$12,Cons_Region!$C$15,$M$1,$B28,$K$1) -> 0 | ... N28: =_xll.DBRW($C$2,Cons_Region!$F$12,Cons_Region!$C$15,$M$1,$B28,$K$1) -> 0 | O28: =_xll.DBRW($C$2,$O$14,$O$16,$M$1,$B28,$K$1) -> 0 | P28: =_xll.DBRW($C$2,$O$14,$O$16,$M$1,$B28,$K$1) -> 0 | Q28: =_xll.DBRW($C$2,$O$14,$O$16,$M$1,$B28,$K$1) -> 0 | R28: =_xll.DBRW($C$2,$O$14,$O$16,$M$1,$B28,$K$1) -> 0 | S28: =_xll.DBRW($C$2,$O$14,$O$16,$M$1,$B28,$K$1) -> 0
... B30: American CPI | C30: =_xll.DBRW($C$2,Cons_Region!$F$12,Cons_Region!$C$15,$M$1,$B30,$K$1) -> 0 | D30: =_xll.DBRW($C$2,Cons_Region!$F$12,Cons_Region!$C$15,$M$1,$B30,$K$1) -> 0 | E30: =_xll.DBRW($C$2,Cons_Region!$F$12,Cons_Region!$C$15,$M$1,$B30,$K$1) -> 0 | F30: =_xll.DBRW($C$2,Cons_Region!$F$12,Cons_Region!$C$15,$M$1,$B30,$K$1) -> 0 | G30: =_xll.DBRW($C$2,Cons_Region!$F$12,Cons_Region!$C$15,$M$1,$B30,$K$1) -> 0 | H30: =_xll.DBRW($C$2,Cons_Region!$F$12,Cons_Region!$C$15,$M$1,$B30,$K$1) -> 0 | I30: =_xll.DBRW($C$2,Cons_Region!$F$12,Cons_Region!$C$15,$M$1,$B30,$K$1) -> 0 | J30: =_xll.DBRW($C$2,Cons_Region!$F$12,Cons_Region!$C$15,$M$1,$B30,$K$1) -> 0 | ... N30: =_xll.DBRW($C$2,Cons_Region!$F$12,Cons_Region!$C$15,$M$1,$B30,$K$1) -> 0 | O30: =_xll.DBRW($C$2,$O$14,$O$16,$M$1,$B30,$K$1) -> 0 | P30: =_xll.DBRW($C$2,$O$14,$O$16,$M$1,$B30,$K$1) -> 0 | Q30: =_xll.DBRW($C$2,$O$14,$O$16,$M$1,$B30,$K$1) -> 0 | R30: =_xll.DBRW($C$2,$O$14,$O$16,$M$1,$B30,$K$1) -> 0 | S30: =_xll.DBRW($C$2,$O$14,$O$16,$M$1,$B30,$K$1) -> 0
B31: Number of Days | C31: =_xll.DBRW($C$2,Cons_Region!$F$12,C$15,$M$1,$B31,$K$1) -> 31 | D31: =_xll.DBRW($C$2,Cons_Region!$F$12,D$15,$M$1,$B31,$K$1) -> 28 | E31: =_xll.DBRW($C$2,Cons_Region!$F$12,E$15,$M$1,$B31,$K$1) -> 31 | F31: =_xll.DBRW($C$2,Cons_Region!$F$12,F$15,$M$1,$B31,$K$1) -> 30 | G31: =_xll.DBRW($C$2,Cons_Region!$F$12,G$15,$M$1,$B31,$K$1) -> 31 | H31: =_xll.DBRW($C$2,Cons_Region!$F$12,H$15,$M$1,$B31,$K$1) -> 30 | I31: =_xll.DBRW($C$2,Cons_Region!$F$12,I$15,$M$1,$B31,$K$1) -> 31 | J31: =_xll.DBRW($C$2,Cons_Region!$F$12,J$15,$M$1,$B31,$K$1) -> 31 | ... N31: =_xll.DBRW($C$2,Cons_Region!$F$12,N$15,$M$1,$B31,$K$1) -> 31 | O31: =_xll.DBRW($C$2,$O$14,$O$16,$M$1,$B31,$K$1) -> 0 | P31: =_xll.DBRW($C$2,$O$14,$O$16,$M$1,$B31,$K$1) -> 0 | Q31: =_xll.DBRW($C$2,$O$14,$O$16,$M$1,$B31,$K$1) -> 0 | R31: =_xll.DBRW($C$2,$O$14,$O$16,$M$1,$B31,$K$1) -> 0 | S31: =_xll.DBRW($C$2,$O$14,$O$16,$M$1,$B31,$K$1) -> 0
B34: NET REVENUES
O36: =$F$12+1 -> 2027 | P36: =$F$12+2 -> 2028 | Q36: =$F$12+3 -> 2029 | R36: =$F$12+4 -> 2030 | S36: =$F$12+5 -> 2031
C37: =$F$12&"."&C15 -> 2026.01 | D37: =$F$12&"."&D15 -> 2026.02 | E37: =$F$12&"."&E15 -> 2026.03 | F37: =$F$12&"."&F15 -> 2026.04 | G37: =$F$12&"."&G15 -> 2026.05 | H37: =$F$12&"."&H15 -> 2026.06 | I37: =$F$12&"."&I15 -> 2026.07 | J37: =$F$12&"."&J15 -> 2026.08 | ... N37: =$F$12&"."&N15 -> 2026.12 | O37: PE | P37: PE | Q37: PE | R37: PE | S37: PE
B38: % Operational Tax | C38: =_xll.DBRW($B$2,Cons_Region!$F$12,Cons_Region!C$15,$M$1,Cons_Region!$H$12,Cons_Region!$C$12,$N$2,$K$2,$B$38) -> 0 | D38: =_xll.DBRW($B$2,Cons_Region!$F$12,Cons_Region!D$15,$M$1,Cons_Region!$H$12,Cons_Region!$C$12,$N$2,$K$2,$B$38) -> 0.3246 | E38: =_xll.DBRW($B$2,Cons_Region!$F$12,Cons_Region!E$15,$M$1,Cons_Region!$H$12,Cons_Region!$C$12,$N$2,$K$2,$B$38) -> 0.3331 | F38: =_xll.DBRW($B$2,Cons_Region!$F$12,Cons_Region!F$15,$M$1,Cons_Region!$H$12,Cons_Region!$C$12,$N$2,$K$2,$B$38) -> 0.3356 | G38: =_xll.DBRW($B$2,Cons_Region!$F$12,Cons_Region!G$15,$M$1,Cons_Region!$H$12,Cons_Region!$C$12,$N$2,$K$2,$B$38) -> 0.3349 | H38: =_xll.DBRW($B$2,Cons_Region!$F$12,Cons_Region!H$15,$M$1,Cons_Region!$H$12,Cons_Region!$C$12,$N$2,$K$2,$B$38) -> 0.3303 | I38: =_xll.DBRW($B$2,Cons_Region!$F$12,Cons_Region!I$15,$M$1,Cons_Region!$H$12,Cons_Region!$C$12,$N$2,$K$2,$B$38) -> 0.3308 | J38: =_xll.DBRW($B$2,Cons_Region!$F$12,Cons_Region!J$15,$M$1,Cons_Region!$H$12,Cons_Region!$C$12,$N$2,$K$2,$B$38) -> 0.3269 | ... N38: =_xll.DBRW($B$2,Cons_Region!$F$12,Cons_Region!N$15,$M$1,Cons_Region!$H$12,Cons_Region!$C$12,$N$2,$K$2,$B$38) -> 0.3524 | O38: =_xll.DBRW($B$2,O36,Cons_Region!O$15,$M$1,Cons_Region!$H$12,Cons_Region!$C$12,$N$2,$K$2,$B$38) -> 0 | P38: =_xll.DBRW($B$2,P36,Cons_Region!P$15,$M$1,Cons_Region!$H$12,Cons_Region!$C$12,$N$2,$K$2,$B$38) -> 0 | Q38: =_xll.DBRW($B$2,Q36,Cons_Region!Q$15,$M$1,Cons_Region!$H$12,Cons_Region!$C$12,$N$2,$K$2,$B$38) -> 0 | R38: =_xll.DBRW($B$2,R36,Cons_Region!R$15,$M$1,Cons_Region!$H$12,Cons_Region!$C$12,$N$2,$K$2,$B$38) -> 0 | S38: =_xll.DBRW($B$2,S36,Cons_Region!S$15,$M$1,Cons_Region!$H$12,Cons_Region!$C$12,$N$2,$K$2,$B$38) -> 0
B39: Gross Revenue [$MM] | C39: =_xll.DBRW($B$2,Cons_Region!$F$12,Cons_Region!C$15,$M$1,Cons_Region!$H$12,Cons_Region!$C$12,$N$2,$K$2,$B$39) -> 0 | D39: =_xll.DBRW($B$2,Cons_Region!$F$12,Cons_Region!D$15,$M$1,Cons_Region!$H$12,Cons_Region!$C$12,$N$2,$K$2,$B$39) -> 1595.2141 | E39: =_xll.DBRW($B$2,Cons_Region!$F$12,Cons_Region!E$15,$M$1,Cons_Region!$H$12,Cons_Region!$C$12,$N$2,$K$2,$B$39) -> 1894.3089 | F39: =_xll.DBRW($B$2,Cons_Region!$F$12,Cons_Region!F$15,$M$1,Cons_Region!$H$12,Cons_Region!$C$12,$N$2,$K$2,$B$39) -> 1765.3017 | G39: =_xll.DBRW($B$2,Cons_Region!$F$12,Cons_Region!G$15,$M$1,Cons_Region!$H$12,Cons_Region!$C$12,$N$2,$K$2,$B$39) -> 1910.8408 | H39: =_xll.DBRW($B$2,Cons_Region!$F$12,Cons_Region!H$15,$M$1,Cons_Region!$H$12,Cons_Region!$C$12,$N$2,$K$2,$B$39) -> 1969.8936 | I39: =_xll.DBRW($B$2,Cons_Region!$F$12,Cons_Region!I$15,$M$1,Cons_Region!$H$12,Cons_Region!$C$12,$N$2,$K$2,$B$39) -> 2129.565 | J39: =_xll.DBRW($B$2,Cons_Region!$F$12,Cons_Region!J$15,$M$1,Cons_Region!$H$12,Cons_Region!$C$12,$N$2,$K$2,$B$39) -> 2150.9372 | ... N39: =_xll.DBRW($B$2,Cons_Region!$F$12,Cons_Region!N$15,$M$1,Cons_Region!$H$12,Cons_Region!$C$12,$N$2,$K$2,$B$39) -> 1664.1683 | O39: =_xll.DBRW($B$2,O$36,Cons_Region!O$15,$M$1,Cons_Region!$H$12,Cons_Region!$C$12,$N$2,$K$2,$B$39) -> 0 | P39: =_xll.DBRW($B$2,P$36,Cons_Region!P$15,$M$1,Cons_Region!$H$12,Cons_Region!$C$12,$N$2,$K$2,$B$39) -> 0 | Q39: =_xll.DBRW($B$2,Q$36,Cons_Region!Q$15,$M$1,Cons_Region!$H$12,Cons_Region!$C$12,$N$2,$K$2,$B$39) -> 0 | R39: =_xll.DBRW($B$2,R$36,Cons_Region!R$15,$M$1,Cons_Region!$H$12,Cons_Region!$C$12,$N$2,$K$2,$B$39) -> 0 | S39: =_xll.DBRW($B$2,S$36,Cons_Region!S$15,$M$1,Cons_Region!$H$12,Cons_Region!$C$12,$N$2,$K$2,$B$39) -> 0
B40: Net Revenue [$MM] | C40: =_xll.DBRW($B$2,Cons_Region!$F$12,Cons_Region!C$15,$M$1,Cons_Region!$H$12,Cons_Region!$C$12,$N$2,$K$2,$B$40) -> 0 | D40: =_xll.DBRW($B$2,Cons_Region!$F$12,Cons_Region!D$15,$M$1,Cons_Region!$H$12,Cons_Region!$C$12,$N$2,$K$2,$B$40) -> 1204.2987 | E40: =_xll.DBRW($B$2,Cons_Region!$F$12,Cons_Region!E$15,$M$1,Cons_Region!$H$12,Cons_Region!$C$12,$N$2,$K$2,$B$40) -> 1420.9804 | F40: =_xll.DBRW($B$2,Cons_Region!$F$12,Cons_Region!F$15,$M$1,Cons_Region!$H$12,Cons_Region!$C$12,$N$2,$K$2,$B$40) -> 1321.7294 | G40: =_xll.DBRW($B$2,Cons_Region!$F$12,Cons_Region!G$15,$M$1,Cons_Region!$H$12,Cons_Region!$C$12,$N$2,$K$2,$B$40) -> 1431.4486 | H40: =_xll.DBRW($B$2,Cons_Region!$F$12,Cons_Region!H$15,$M$1,Cons_Region!$H$12,Cons_Region!$C$12,$N$2,$K$2,$B$40) -> 1480.789 | I40: =_xll.DBRW($B$2,Cons_Region!$F$12,Cons_Region!I$15,$M$1,Cons_Region!$H$12,Cons_Region!$C$12,$N$2,$K$2,$B$40) -> 1600.2142 | J40: =_xll.DBRW($B$2,Cons_Region!$F$12,Cons_Region!J$15,$M$1,Cons_Region!$H$12,Cons_Region!$C$12,$N$2,$K$2,$B$40) -> 1621.0244 | ... N40: =_xll.DBRW($B$2,Cons_Region!$F$12,Cons_Region!N$15,$M$1,Cons_Region!$H$12,Cons_Region!$C$12,$N$2,$K$2,$B$40) -> 1230.5297 | O40: =_xll.DBRW($B$2,O$36,Cons_Region!O$15,$M$1,Cons_Region!$H$12,Cons_Region!$C$12,$N$2,$K$2,$B$39) -> 0 | P40: =_xll.DBRW($B$2,P$36,Cons_Region!P$15,$M$1,Cons_Region!$H$12,Cons_Region!$C$12,$N$2,$K$2,$B$39) -> 0 | Q40: =_xll.DBRW($B$2,Q$36,Cons_Region!Q$15,$M$1,Cons_Region!$H$12,Cons_Region!$C$12,$N$2,$K$2,$B$39) -> 0 | R40: =_xll.DBRW($B$2,R$36,Cons_Region!R$15,$M$1,Cons_Region!$H$12,Cons_Region!$C$12,$N$2,$K$2,$B$39) -> 0 | S40: =_xll.DBRW($B$2,S$36,Cons_Region!S$15,$M$1,Cons_Region!$H$12,Cons_Region!$C$12,$N$2,$K$2,$B$39) -> 0
B44: CONTRIBUTION MARGIN
O46: =$F$12+1 -> 2027 | P46: =$F$12+2 -> 2028 | Q46: =$F$12+3 -> 2029 | R46: =$F$12+4 -> 2030 | S46: =$F$12+5 -> 2031
C47: =$F$12&"."&C$15 -> 2026.01 | D47: =$F$12&"."&D$15 -> 2026.02 | E47: =$F$12&"."&E$15 -> 2026.03 | F47: =$F$12&"."&F$15 -> 2026.04 | G47: =$F$12&"."&G$15 -> 2026.05 | H47: =$F$12&"."&H$15 -> 2026.06 | I47: =$F$12&"."&I$15 -> 2026.07 | J47: =$F$12&"."&J$15 -> 2026.08 | ... N47: =$F$12&"."&N$15 -> 2026.12 | O47: PE | P47: PE | Q47: PE | R47: PE | S47: PE
A48: EXP.010.001 | B48: Final Variable Sales Expenses | C48: =_xll.DBRW($B$1,Cons_Region!$F$12,Cons_Region!C$15,$M$1,Cons_Region!$H$12,Cons_Region!$C$12,$N$2,$A48,$L$1,$K$1) -> 0 | D48: =_xll.DBRW($B$1,Cons_Region!$F$12,Cons_Region!D$15,$M$1,Cons_Region!$H$12,Cons_Region!$C$12,$N$2,$A48,$L$1,$K$1) -> 168.802 | E48: =_xll.DBRW($B$1,Cons_Region!$F$12,Cons_Region!E$15,$M$1,Cons_Region!$H$12,Cons_Region!$C$12,$N$2,$A48,$L$1,$K$1) -> 205.1198 | F48: =_xll.DBRW($B$1,Cons_Region!$F$12,Cons_Region!F$15,$M$1,Cons_Region!$H$12,Cons_Region!$C$12,$N$2,$A48,$L$1,$K$1) -> 199.2509 | G48: =_xll.DBRW($B$1,Cons_Region!$F$12,Cons_Region!G$15,$M$1,Cons_Region!$H$12,Cons_Region!$C$12,$N$2,$A48,$L$1,$K$1) -> 216.5219 | H48: =_xll.DBRW($B$1,Cons_Region!$F$12,Cons_Region!H$15,$M$1,Cons_Region!$H$12,Cons_Region!$C$12,$N$2,$A48,$L$1,$K$1) -> 222.5475 | I48: =_xll.DBRW($B$1,Cons_Region!$F$12,Cons_Region!I$15,$M$1,Cons_Region!$H$12,Cons_Region!$C$12,$N$2,$A48,$L$1,$K$1) -> 237.5144 | J48: =_xll.DBRW($B$1,Cons_Region!$F$12,Cons_Region!J$15,$M$1,Cons_Region!$H$12,Cons_Region!$C$12,$N$2,$A48,$L$1,$K$1) -> 239.9574 | ... N48: =_xll.DBRW($B$1,Cons_Region!$F$12,Cons_Region!N$15,$M$1,Cons_Region!$H$12,Cons_Region!$C$12,$N$2,$A48,$L$1,$K$1) -> 185.971 | O48: =_xll.DBRW($B$1,O$36,Cons_Region!O$15,$M$1,Cons_Region!$H$12,Cons_Region!$C$12,$N$2,$A48,$L$1,$K$1) -> 0 | P48: =_xll.DBRW($B$1,P$36,Cons_Region!P$15,$M$1,Cons_Region!$H$12,Cons_Region!$C$12,$N$2,$A48,$L$1,$K$1) -> 0 | Q48: =_xll.DBRW($B$1,Q$36,Cons_Region!Q$15,$M$1,Cons_Region!$H$12,Cons_Region!$C$12,$N$2,$A48,$L$1,$K$1) -> 0 | R48: =_xll.DBRW($B$1,R$36,Cons_Region!R$15,$M$1,Cons_Region!$H$12,Cons_Region!$C$12,$N$2,$A48,$L$1,$K$1) -> 0 | S48: =_xll.DBRW($B$1,S$36,Cons_Region!S$15,$M$1,Cons_Region!$H$12,Cons_Region!$C$12,$N$2,$A48,$L$1,$K$1) -> 0
A49: CST.010.001 | B49: Other Variable Costs | C49: =_xll.DBRW($B$1,Cons_Region!$F$12,Cons_Region!C$15,$M$1,Cons_Region!$H$12,Cons_Region!$C$12,$N$2,$A49,$L$1,$K$1) -> 0 | D49: =_xll.DBRW($B$1,Cons_Region!$F$12,Cons_Region!D$15,$M$1,Cons_Region!$H$12,Cons_Region!$C$12,$N$2,$A49,$L$1,$K$1) -> 598.8773 | E49: =_xll.DBRW($B$1,Cons_Region!$F$12,Cons_Region!E$15,$M$1,Cons_Region!$H$12,Cons_Region!$C$12,$N$2,$A49,$L$1,$K$1) -> 675.2484 | F49: =_xll.DBRW($B$1,Cons_Region!$F$12,Cons_Region!F$15,$M$1,Cons_Region!$H$12,Cons_Region!$C$12,$N$2,$A49,$L$1,$K$1) -> 594.5248 | G49: =_xll.DBRW($B$1,Cons_Region!$F$12,Cons_Region!G$15,$M$1,Cons_Region!$H$12,Cons_Region!$C$12,$N$2,$A49,$L$1,$K$1) -> 612.4205 | H49: =_xll.DBRW($B$1,Cons_Region!$F$12,Cons_Region!H$15,$M$1,Cons_Region!$H$12,Cons_Region!$C$12,$N$2,$A49,$L$1,$K$1) -> 629.7126 | I49: =_xll.DBRW($B$1,Cons_Region!$F$12,Cons_Region!I$15,$M$1,Cons_Region!$H$12,Cons_Region!$C$12,$N$2,$A49,$L$1,$K$1) -> 680.9529 | J49: =_xll.DBRW($B$1,Cons_Region!$F$12,Cons_Region!J$15,$M$1,Cons_Region!$H$12,Cons_Region!$C$12,$N$2,$A49,$L$1,$K$1) -> 694.0405 | ... N49: =_xll.DBRW($B$1,Cons_Region!$F$12,Cons_Region!N$15,$M$1,Cons_Region!$H$12,Cons_Region!$C$12,$N$2,$A49,$L$1,$K$1) -> 530.3109 | O49: =_xll.DBRW($B$1,O$36,Cons_Region!O$15,$M$1,Cons_Region!$H$12,Cons_Region!$C$12,$N$2,$A49,$L$1,$K$1) -> 0 | P49: =_xll.DBRW($B$1,P$36,Cons_Region!P$15,$M$1,Cons_Region!$H$12,Cons_Region!$C$12,$N$2,$A49,$L$1,$K$1) -> 0 | Q49: =_xll.DBRW($B$1,Q$36,Cons_Region!Q$15,$M$1,Cons_Region!$H$12,Cons_Region!$C$12,$N$2,$A49,$L$1,$K$1) -> 0 | R49: =_xll.DBRW($B$1,R$36,Cons_Region!R$15,$M$1,Cons_Region!$H$12,Cons_Region!$C$12,$N$2,$A49,$L$1,$K$1) -> 0 | S49: =_xll.DBRW($B$1,S$36,Cons_Region!S$15,$M$1,Cons_Region!$H$12,Cons_Region!$C$12,$N$2,$A49,$L$1,$K$1) -> 0
A50: CST.020.001 | B50: Fixed Costs | C50: =_xll.DBRW($B$1,Cons_Region!$F$12,Cons_Region!C$15,$M$1,Cons_Region!$H$12,Cons_Region!$C$12,$N$2,$A50,$L$1,$K$1) -> 0 | D50: =_xll.DBRW($B$1,Cons_Region!$F$12,Cons_Region!D$15,$M$1,Cons_Region!$H$12,Cons_Region!$C$12,$N$2,$A50,$L$1,$K$1) -> 174.4091 | E50: =_xll.DBRW($B$1,Cons_Region!$F$12,Cons_Region!E$15,$M$1,Cons_Region!$H$12,Cons_Region!$C$12,$N$2,$A50,$L$1,$K$1) -> 212.3951 | F50: =_xll.DBRW($B$1,Cons_Region!$F$12,Cons_Region!F$15,$M$1,Cons_Region!$H$12,Cons_Region!$C$12,$N$2,$A50,$L$1,$K$1) -> 193.3931 | G50: =_xll.DBRW($B$1,Cons_Region!$F$12,Cons_Region!G$15,$M$1,Cons_Region!$H$12,Cons_Region!$C$12,$N$2,$A50,$L$1,$K$1) -> 189.3711 | H50: =_xll.DBRW($B$1,Cons_Region!$F$12,Cons_Region!H$15,$M$1,Cons_Region!$H$12,Cons_Region!$C$12,$N$2,$A50,$L$1,$K$1) -> 189.6201 | I50: =_xll.DBRW($B$1,Cons_Region!$F$12,Cons_Region!I$15,$M$1,Cons_Region!$H$12,Cons_Region!$C$12,$N$2,$A50,$L$1,$K$1) -> 181.5719 | J50: =_xll.DBRW($B$1,Cons_Region!$F$12,Cons_Region!J$15,$M$1,Cons_Region!$H$12,Cons_Region!$C$12,$N$2,$A50,$L$1,$K$1) -> 175.1754 | ... N50: =_xll.DBRW($B$1,Cons_Region!$F$12,Cons_Region!N$15,$M$1,Cons_Region!$H$12,Cons_Region!$C$12,$N$2,$A50,$L$1,$K$1) -> 152.984 | O50: =_xll.DBRW($B$1,O$36,Cons_Region!O$15,$M$1,Cons_Region!$H$12,Cons_Region!$C$12,$N$2,$A50,$L$1,$K$1) -> 0 | P50: =_xll.DBRW($B$1,P$36,Cons_Region!P$15,$M$1,Cons_Region!$H$12,Cons_Region!$C$12,$N$2,$A50,$L$1,$K$1) -> 0 | Q50: =_xll.DBRW($B$1,Q$36,Cons_Region!Q$15,$M$1,Cons_Region!$H$12,Cons_Region!$C$12,$N$2,$A50,$L$1,$K$1) -> 0 | R50: =_xll.DBRW($B$1,R$36,Cons_Region!R$15,$M$1,Cons_Region!$H$12,Cons_Region!$C$12,$N$2,$A50,$L$1,$K$1) -> 0 | S50: =_xll.DBRW($B$1,S$36,Cons_Region!S$15,$M$1,Cons_Region!$H$12,Cons_Region!$C$12,$N$2,$A50,$L$1,$K$1) -> 0
A51: EXP.020.001 | B51: Operating Expenses | C51: =_xll.DBRW($B$1,Cons_Region!$F$12,Cons_Region!C$15,$M$1,Cons_Region!$H$12,Cons_Region!$C$12,$N$2,$A51,$L$1,$K$1) -> 0 | D51: =_xll.DBRW($B$1,Cons_Region!$F$12,Cons_Region!D$15,$M$1,Cons_Region!$H$12,Cons_Region!$C$12,$N$2,$A51,$L$1,$K$1) -> 117.0107 | E51: =_xll.DBRW($B$1,Cons_Region!$F$12,Cons_Region!E$15,$M$1,Cons_Region!$H$12,Cons_Region!$C$12,$N$2,$A51,$L$1,$K$1) -> 124.1856 | F51: =_xll.DBRW($B$1,Cons_Region!$F$12,Cons_Region!F$15,$M$1,Cons_Region!$H$12,Cons_Region!$C$12,$N$2,$A51,$L$1,$K$1) -> 129.2842 | G51: =_xll.DBRW($B$1,Cons_Region!$F$12,Cons_Region!G$15,$M$1,Cons_Region!$H$12,Cons_Region!$C$12,$N$2,$A51,$L$1,$K$1) -> 147.9149 | H51: =_xll.DBRW($B$1,Cons_Region!$F$12,Cons_Region!H$15,$M$1,Cons_Region!$H$12,Cons_Region!$C$12,$N$2,$A51,$L$1,$K$1) -> 130.73 | I51: =_xll.DBRW($B$1,Cons_Region!$F$12,Cons_Region!I$15,$M$1,Cons_Region!$H$12,Cons_Region!$C$12,$N$2,$A51,$L$1,$K$1) -> 123.315 | J51: =_xll.DBRW($B$1,Cons_Region!$F$12,Cons_Region!J$15,$M$1,Cons_Region!$H$12,Cons_Region!$C$12,$N$2,$A51,$L$1,$K$1) -> 128.4872 | ... N51: =_xll.DBRW($B$1,Cons_Region!$F$12,Cons_Region!N$15,$M$1,Cons_Region!$H$12,Cons_Region!$C$12,$N$2,$A51,$L$1,$K$1) -> 123.5418 | O51: =_xll.DBRW($B$1,O$36,Cons_Region!O$15,$M$1,Cons_Region!$H$12,Cons_Region!$C$12,$N$2,$A51,$L$1,$K$1) -> 0 | P51: =_xll.DBRW($B$1,P$36,Cons_Region!P$15,$M$1,Cons_Region!$H$12,Cons_Region!$C$12,$N$2,$A51,$L$1,$K$1) -> 0 | Q51: =_xll.DBRW($B$1,Q$36,Cons_Region!Q$15,$M$1,Cons_Region!$H$12,Cons_Region!$C$12,$N$2,$A51,$L$1,$K$1) -> 0 | R51: =_xll.DBRW($B$1,R$36,Cons_Region!R$15,$M$1,Cons_Region!$H$12,Cons_Region!$C$12,$N$2,$A51,$L$1,$K$1) -> 0 | S51: =_xll.DBRW($B$1,S$36,Cons_Region!S$15,$M$1,Cons_Region!$H$12,Cons_Region!$C$12,$N$2,$A51,$L$1,$K$1) -> 0
A52: OOR.010.001 | B52: Other | C52: =_xll.DBRW($B$1,Cons_Region!$F$12,Cons_Region!C$15,$M$1,Cons_Region!$H$12,Cons_Region!$C$12,$N$2,$A52,$L$1,$K$1) -> 0 | D52: =_xll.DBRW($B$1,Cons_Region!$F$12,Cons_Region!D$15,$M$1,Cons_Region!$H$12,Cons_Region!$C$12,$N$2,$A52,$L$1,$K$1) -> 0 | E52: =_xll.DBRW($B$1,Cons_Region!$F$12,Cons_Region!E$15,$M$1,Cons_Region!$H$12,Cons_Region!$C$12,$N$2,$A52,$L$1,$K$1) -> 0 | F52: =_xll.DBRW($B$1,Cons_Region!$F$12,Cons_Region!F$15,$M$1,Cons_Region!$H$12,Cons_Region!$C$12,$N$2,$A52,$L$1,$K$1) -> 0 | G52: =_xll.DBRW($B$1,Cons_Region!$F$12,Cons_Region!G$15,$M$1,Cons_Region!$H$12,Cons_Region!$C$12,$N$2,$A52,$L$1,$K$1) -> 0 | H52: =_xll.DBRW($B$1,Cons_Region!$F$12,Cons_Region!H$15,$M$1,Cons_Region!$H$12,Cons_Region!$C$12,$N$2,$A52,$L$1,$K$1) -> 0 | I52: =_xll.DBRW($B$1,Cons_Region!$F$12,Cons_Region!I$15,$M$1,Cons_Region!$H$12,Cons_Region!$C$12,$N$2,$A52,$L$1,$K$1) -> 0 | J52: =_xll.DBRW($B$1,Cons_Region!$F$12,Cons_Region!J$15,$M$1,Cons_Region!$H$12,Cons_Region!$C$12,$N$2,$A52,$L$1,$K$1) -> 0 | ... N52: =_xll.DBRW($B$1,Cons_Region!$F$12,Cons_Region!N$15,$M$1,Cons_Region!$H$12,Cons_Region!$C$12,$N$2,$A52,$L$1,$K$1) -> 0 | O52: =_xll.DBRW($B$1,O$36,Cons_Region!O$15,$M$1,Cons_Region!$H$12,Cons_Region!$C$12,$N$2,$A52,$L$1,$K$1) -> 0 | P52: =_xll.DBRW($B$1,P$36,Cons_Region!P$15,$M$1,Cons_Region!$H$12,Cons_Region!$C$12,$N$2,$A52,$L$1,$K$1) -> 0 | Q52: =_xll.DBRW($B$1,Q$36,Cons_Region!Q$15,$M$1,Cons_Region!$H$12,Cons_Region!$C$12,$N$2,$A52,$L$1,$K$1) -> 0 | R52: =_xll.DBRW($B$1,R$36,Cons_Region!R$15,$M$1,Cons_Region!$H$12,Cons_Region!$C$12,$N$2,$A52,$L$1,$K$1) -> 0 | S52: =_xll.DBRW($B$1,S$36,Cons_Region!S$15,$M$1,Cons_Region!$H$12,Cons_Region!$C$12,$N$2,$A52,$L$1,$K$1) -> 0
A53: DRE.099.004 | B53: EBITDA | C53: =_xll.DBRW($B$3,Cons_Region!$F$12,Cons_Region!C$15,$M$1,Cons_Region!$H$12,Cons_Region!$C$12,$N$2,$A53,$K$1) -> 0 | D53: =_xll.DBRW($B$3,Cons_Region!$F$12,Cons_Region!D$15,$M$1,Cons_Region!$H$12,Cons_Region!$C$12,$N$2,$A53,$K$1) -> 164.97952 | E53: =_xll.DBRW($B$3,Cons_Region!$F$12,Cons_Region!E$15,$M$1,Cons_Region!$H$12,Cons_Region!$C$12,$N$2,$A53,$K$1) -> 211.55466 | F53: =_xll.DBRW($B$3,Cons_Region!$F$12,Cons_Region!F$15,$M$1,Cons_Region!$H$12,Cons_Region!$C$12,$N$2,$A53,$K$1) -> 218.04976 | G53: =_xll.DBRW($B$3,Cons_Region!$F$12,Cons_Region!G$15,$M$1,Cons_Region!$H$12,Cons_Region!$C$12,$N$2,$A53,$K$1) -> 280.17124 | H53: =_xll.DBRW($B$3,Cons_Region!$F$12,Cons_Region!H$15,$M$1,Cons_Region!$H$12,Cons_Region!$C$12,$N$2,$A53,$K$1) -> 316.88202 | I53: =_xll.DBRW($B$3,Cons_Region!$F$12,Cons_Region!I$15,$M$1,Cons_Region!$H$12,Cons_Region!$C$12,$N$2,$A53,$K$1) -> 391.21588 | J53: =_xll.DBRW($B$3,Cons_Region!$F$12,Cons_Region!J$15,$M$1,Cons_Region!$H$12,Cons_Region!$C$12,$N$2,$A53,$K$1) -> 391.12058 | ... N53: =_xll.DBRW($B$3,Cons_Region!$F$12,Cons_Region!N$15,$M$1,Cons_Region!$H$12,Cons_Region!$C$12,$N$2,$A53,$K$1) -> 274.94186 | O53: =_xll.DBRW($B$3,O$14,Cons_Region!O$15,$M$1,Cons_Region!$H$12,Cons_Region!$C$12,$N$2,$A53,$K$1) -> 0 | P53: =_xll.DBRW($B$3,P$14,Cons_Region!P$15,$M$1,Cons_Region!$H$12,Cons_Region!$C$12,$N$2,$A53,$K$1) -> 0 | Q53: =_xll.DBRW($B$3,Q$14,Cons_Region!Q$15,$M$1,Cons_Region!$H$12,Cons_Region!$C$12,$N$2,$A53,$K$1) -> 0 | R53: =_xll.DBRW($B$3,R$14,Cons_Region!R$15,$M$1,Cons_Region!$H$12,Cons_Region!$C$12,$N$2,$A53,$K$1) -> 0 | S53: =_xll.DBRW($B$3,S$14,Cons_Region!S$15,$M$1,Cons_Region!$H$12,Cons_Region!$C$12,$N$2,$A53,$K$1) -> 0
B56: Operating Profit
...

Sheet Opening
C1: =_xll.VIEW("CONS_VC_PRD:STG.100.DataBase_Uploads",G13) -> CONS_VC_PRD:STG.100.DataBase_Uploads:12384823671237949904 | E1: =_xll.VIEW("CONS_VC_PRD:ALL.015.Region_Assumptions") -> CONS_VC_PRD:ALL.015.Region_Assumptions:1238482367336302825 | F1: =_xll.VIEW("CONS_VC_PRD:DFS.120.Financial_Results") -> CONS_VC_PRD:DFS.120.Financial_Results:1238482367756964870 | M1: Value | N1: N/A | O1: =_xll.SUBNM("CONS_VC_PRD:ALL.D.Version","","T3") -> T3 | P1: PROD099
C2: =_xll.VIEW("CONS_VC_PRD:REV.100.Revenue_Consolidated") -> CONS_VC_PRD:REV.100.Revenue_Consolidated:12384823671892466621 | E2: =_xll.VIEW("CONS_VC_PRD:ALL.010.Economic_Assumptions") -> CONS_VC_PRD:ALL.010.Economic_Assumptions:12384823671117458081 | F2: =_xll.VIEW("CONS_VC_PRD:DFS.140.Indirect_Cash_Flow") -> CONS_VC_PRD:DFS.140.Indirect_Cash_Flow:12384823672022746056 | M2: Total Market | P2: Total Products
C3: =_xll.VIEW("CONS_VC_PRD:DFS.100.Profit_and_Loss") -> CONS_VC_PRD:DFS.100.Profit_and_Loss:1238482367-656224029 | E3: =_xll.VIEW("CONS_VC_PRD:DFS.160.Working_Capital") -> CONS_VC_PRD:DFS.160.Working_Capital:12384823671881473188 | F3: =_xll.VIEW("CONS_VC_PRD:ALL.004.Uploads_Status_Planning") -> CONS_VC_PRD:ALL.004.Uploads_Status_Planning:1238482367629058957 | I3: Flag
C4: =_xll.VIEW("CONS_VC_PRD:ALL.001.Actual_Control") -> CONS_VC_PRD:ALL.001.Actual_Control:1238482367343083193 | E4: =_xll.VIEW("CONS_VC_PRD:DFS.180.Gross_Debt") -> CONS_VC_PRD:DFS.180.Gross_Debt:12384823671210914551
E5: =_xll.DBRW(Opening!$C$4,Opening!$G$13,Opening!E11,$O$1,$I$3) -> ACTUAL | F5: =_xll.DBRW(Opening!$C$4,Opening!$G$13,Opening!F11,$O$1,$I$3) | G5: =_xll.DBRW(Opening!$C$4,Opening!$G$13,Opening!G11,$O$1,$I$3) | H5: =_xll.DBRW(Opening!$C$4,Opening!$G$13,Opening!H11,$O$1,$I$3) | I5: =_xll.DBRW(Opening!$C$4,Opening!$G$13,Opening!I11,$O$1,$I$3) | J5: =_xll.DBRW(Opening!$C$4,Opening!$G$13,Opening!J11,$O$1,$I$3) | K5: =_xll.DBRW(Opening!$C$4,Opening!$G$13,Opening!K11,$O$1,$I$3) | L5: =_xll.DBRW(Opening!$C$4,Opening!$G$13,Opening!L11,$O$1,$I$3) | ... P5: =_xll.DBRW(Opening!$C$4,Opening!$G$13,Opening!P11,$O$1,$I$3)
C7: Dre - Other OP. Results
E11: 01 | F11: 02 | G11: 03 | H11: 04 | I11: 05 | J11: 06 | K11: 07 | L11: 08 | M11: 09 | N11: 10 | O11: 11 | P11: 12
D13: =_xll.SUBNM("CONS_VC_PRD:ALL.D.Region","Nível 0","ESPA","MEMBER_NAME") -> ESPA | G13: =_xll.SUBNM("CONS_VC_PRD:ALL.D.Year","SYS_Picklist","2026","MEMBER_NAME") -> 2026 | I13: =_xll.SUBNM("CONS_VC_PRD:ALL.D.Currency","PAX","EUR","Nome alternativo") -> EUR | K13: Input Status: | L13: =_xll.DBRW($F$3,$O$1,$D$13,"Financial_Planning","Status") -> Open
Q15: =$G$13+1 -> 2027 | R15: =$G$13+2 -> 2028 | S15: =$G$13+3 -> 2029 | T15: =$G$13+4 -> 2030 | U15: =$G$13+5 -> 2031
E16: =$G$13&"."&E$11 -> 2026.01 | F16: =$G$13&"."&F$11 -> 2026.02 | G16: =$G$13&"."&G$11 -> 2026.03 | H16: =$G$13&"."&H$11 -> 2026.04 | I16: =$G$13&"."&I$11 -> 2026.05 | J16: =$G$13&"."&J$11 -> 2026.06 | K16: =$G$13&"."&K$11 -> 2026.07 | L16: =$G$13&"."&L$11 -> 2026.08 | ... P16: =$G$13&"."&P$11 -> 2026.12 | Q16: PE | R16: PE | S16: PE | T16: PE | U16: PE
A17: OOR.010.001 | B17: Total Accounts Line | C17: Other | D17: Total Accounts Line | E17: =_xll.DBRW($C$1,Opening!$G$13,Opening!E$11,$O$1,Opening!$I$13,Opening!$D$13,$P$1,$A17,$D17,$M$1) -> 0 | F17: =_xll.DBRW($C$1,Opening!$G$13,Opening!F$11,$O$1,Opening!$I$13,Opening!$D$13,$P$1,$A17,$D17,$M$1) -> 0 | G17: =_xll.DBRW($C$1,Opening!$G$13,Opening!G$11,$O$1,Opening!$I$13,Opening!$D$13,$P$1,$A17,$D17,$M$1) -> 0 | H17: =_xll.DBRW($C$1,Opening!$G$13,Opening!H$11,$O$1,Opening!$I$13,Opening!$D$13,$P$1,$A17,$D17,$M$1) -> 0 | I17: =_xll.DBRW($C$1,Opening!$G$13,Opening!I$11,$O$1,Opening!$I$13,Opening!$D$13,$P$1,$A17,$D17,$M$1) -> 0 | J17: =_xll.DBRW($C$1,Opening!$G$13,Opening!J$11,$O$1,Opening!$I$13,Opening!$D$13,$P$1,$A17,$D17,$M$1) -> 0 | K17: =_xll.DBRW($C$1,Opening!$G$13,Opening!K$11,$O$1,Opening!$I$13,Opening!$D$13,$P$1,$A17,$D17,$M$1) -> 0 | L17: =_xll.DBRW($C$1,Opening!$G$13,Opening!L$11,$O$1,Opening!$I$13,Opening!$D$13,$P$1,$A17,$D17,$M$1) -> 0 | ... P17: =_xll.DBRW($C$1,Opening!$G$13,Opening!P$11,$O$1,Opening!$I$13,Opening!$D$13,$P$1,$A17,$D17,$M$1) -> 0 | Q17: =_xll.DBRW($C$1,Q$15,$Q$16,$O$1,Opening!$I$13,Opening!$D$13,$P$1,$A17,$D17,$M$1) -> 0 | R17: =_xll.DBRW($C$1,R$15,$Q$16,$O$1,Opening!$I$13,Opening!$D$13,$P$1,$A17,$D17,$M$1) -> 0 | S17: =_xll.DBRW($C$1,S$15,$Q$16,$O$1,Opening!$I$13,Opening!$D$13,$P$1,$A17,$D17,$M$1) -> 0 | T17: =_xll.DBRW($C$1,T$15,$Q$16,$O$1,Opening!$I$13,Opening!$D$13,$P$1,$A17,$D17,$M$1) -> 0 | U17: =_xll.DBRW($C$1,U$15,$Q$16,$O$1,Opening!$I$13,Opening!$D$13,$P$1,$A17,$D17,$M$1) -> 0
A18: OOR.010.001 | B18: ACL.OOR.010.001.01 | C18: Other | D18: Other Op. Results - Asset Write-off | E18: =_xll.DBRW($C$1,Opening!$G$13,Opening!E$11,$O$1,Opening!$I$13,Opening!$D$13,$P$1,$A18,$B18,$M$1) -> 0 | F18: =_xll.DBRW($C$1,Opening!$G$13,Opening!F$11,$O$1,Opening!$I$13,Opening!$D$13,$P$1,$A18,$B18,$M$1) -> 0 | G18: =_xll.DBRW($C$1,Opening!$G$13,Opening!G$11,$O$1,Opening!$I$13,Opening!$D$13,$P$1,$A18,$B18,$M$1) -> 0 | H18: =_xll.DBRW($C$1,Opening!$G$13,Opening!H$11,$O$1,Opening!$I$13,Opening!$D$13,$P$1,$A18,$B18,$M$1) -> 0 | I18: =_xll.DBRW($C$1,Opening!$G$13,Opening!I$11,$O$1,Opening!$I$13,Opening!$D$13,$P$1,$A18,$B18,$M$1) -> 0 | J18: =_xll.DBRW($C$1,Opening!$G$13,Opening!J$11,$O$1,Opening!$I$13,Opening!$D$13,$P$1,$A18,$B18,$M$1) -> 0 | K18: =_xll.DBRW($C$1,Opening!$G$13,Opening!K$11,$O$1,Opening!$I$13,Opening!$D$13,$P$1,$A18,$B18,$M$1) -> 0 | L18: =_xll.DBRW($C$1,Opening!$G$13,Opening!L$11,$O$1,Opening!$I$13,Opening!$D$13,$P$1,$A18,$B18,$M$1) -> 0 | ... P18: =_xll.DBRW($C$1,Opening!$G$13,Opening!P$11,$O$1,Opening!$I$13,Opening!$D$13,$P$1,$A18,$B18,$M$1) -> 0 | Q18: =_xll.DBRW($C$1,Q$15,$Q$16,$O$1,Opening!$I$13,Opening!$D$13,$P$1,$A18,$B18,$M$1) -> 0 | R18: =_xll.DBRW($C$1,R$15,$Q$16,$O$1,Opening!$I$13,Opening!$D$13,$P$1,$A18,$B18,$M$1) -> 0 | S18: =_xll.DBRW($C$1,S$15,$Q$16,$O$1,Opening!$I$13,Opening!$D$13,$P$1,$A18,$B18,$M$1) -> 0 | T18: =_xll.DBRW($C$1,T$15,$Q$16,$O$1,Opening!$I$13,Opening!$D$13,$P$1,$A18,$B18,$M$1) -> 0 | U18: =_xll.DBRW($C$1,U$15,$Q$16,$O$1,Opening!$I$13,Opening!$D$13,$P$1,$A18,$B18,$M$1) -> 0
A19: OOR.010.001 | B19: ACL.OOR.010.001.02 | C19: Other | D19: Slow moving | E19: =_xll.DBRW($C$1,Opening!$G$13,Opening!E$11,$O$1,Opening!$I$13,Opening!$D$13,$P$1,$A19,$B19,$M$1) -> 0 | F19: =_xll.DBRW($C$1,Opening!$G$13,Opening!F$11,$O$1,Opening!$I$13,Opening!$D$13,$P$1,$A19,$B19,$M$1) -> 0 | G19: =_xll.DBRW($C$1,Opening!$G$13,Opening!G$11,$O$1,Opening!$I$13,Opening!$D$13,$P$1,$A19,$B19,$M$1) -> 0 | H19: =_xll.DBRW($C$1,Opening!$G$13,Opening!H$11,$O$1,Opening!$I$13,Opening!$D$13,$P$1,$A19,$B19,$M$1) -> 0 | I19: =_xll.DBRW($C$1,Opening!$G$13,Opening!I$11,$O$1,Opening!$I$13,Opening!$D$13,$P$1,$A19,$B19,$M$1) -> 0 | J19: =_xll.DBRW($C$1,Opening!$G$13,Opening!J$11,$O$1,Opening!$I$13,Opening!$D$13,$P$1,$A19,$B19,$M$1) -> 0 | K19: =_xll.DBRW($C$1,Opening!$G$13,Opening!K$11,$O$1,Opening!$I$13,Opening!$D$13,$P$1,$A19,$B19,$M$1) -> 0 | L19: =_xll.DBRW($C$1,Opening!$G$13,Opening!L$11,$O$1,Opening!$I$13,Opening!$D$13,$P$1,$A19,$B19,$M$1) -> 0 | ... P19: =_xll.DBRW($C$1,Opening!$G$13,Opening!P$11,$O$1,Opening!$I$13,Opening!$D$13,$P$1,$A19,$B19,$M$1) -> 0 | Q19: =_xll.DBRW($C$1,Q$15,$Q$16,$O$1,Opening!$I$13,Opening!$D$13,$P$1,$A19,$B19,$M$1) -> 0 | R19: =_xll.DBRW($C$1,R$15,$Q$16,$O$1,Opening!$I$13,Opening!$D$13,$P$1,$A19,$B19,$M$1) -> 0 | S19: =_xll.DBRW($C$1,S$15,$Q$16,$O$1,Opening!$I$13,Opening!$D$13,$P$1,$A19,$B19,$M$1) -> 0 | T19: =_xll.DBRW($C$1,T$15,$Q$16,$O$1,Opening!$I$13,Opening!$D$13,$P$1,$A19,$B19,$M$1) -> 0 | U19: =_xll.DBRW($C$1,U$15,$Q$16,$O$1,Opening!$I$13,Opening!$D$13,$P$1,$A19,$B19,$M$1) -> 0
A20: OOR.010.001 | B20: ACL.OOR.010.001.03 | C20: Other | D20: Clinker | E20: =_xll.DBRW($C$1,Opening!$G$13,Opening!E$11,$O$1,Opening!$I$13,Opening!$D$13,$P$1,$A20,$B20,$M$1) -> 0 | F20: =_xll.DBRW($C$1,Opening!$G$13,Opening!F$11,$O$1,Opening!$I$13,Opening!$D$13,$P$1,$A20,$B20,$M$1) -> 0 | G20: =_xll.DBRW($C$1,Opening!$G$13,Opening!G$11,$O$1,Opening!$I$13,Opening!$D$13,$P$1,$A20,$B20,$M$1) -> 0 | H20: =_xll.DBRW($C$1,Opening!$G$13,Opening!H$11,$O$1,Opening!$I$13,Opening!$D$13,$P$1,$A20,$B20,$M$1) -> 0 | I20: =_xll.DBRW($C$1,Opening!$G$13,Opening!I$11,$O$1,Opening!$I$13,Opening!$D$13,$P$1,$A20,$B20,$M$1) -> 0 | J20: =_xll.DBRW($C$1,Opening!$G$13,Opening!J$11,$O$1,Opening!$I$13,Opening!$D$13,$P$1,$A20,$B20,$M$1) -> 0 | K20: =_xll.DBRW($C$1,Opening!$G$13,Opening!K$11,$O$1,Opening!$I$13,Opening!$D$13,$P$1,$A20,$B20,$M$1) -> 0 | L20: =_xll.DBRW($C$1,Opening!$G$13,Opening!L$11,$O$1,Opening!$I$13,Opening!$D$13,$P$1,$A20,$B20,$M$1) -> 0 | ... P20: =_xll.DBRW($C$1,Opening!$G$13,Opening!P$11,$O$1,Opening!$I$13,Opening!$D$13,$P$1,$A20,$B20,$M$1) -> 0 | Q20: =_xll.DBRW($C$1,Q$15,$Q$16,$O$1,Opening!$I$13,Opening!$D$13,$P$1,$A20,$B20,$M$1) -> 0 | R20: =_xll.DBRW($C$1,R$15,$Q$16,$O$1,Opening!$I$13,Opening!$D$13,$P$1,$A20,$B20,$M$1) -> 0 | S20: =_xll.DBRW($C$1,S$15,$Q$16,$O$1,Opening!$I$13,Opening!$D$13,$P$1,$A20,$B20,$M$1) -> 0 | T20: =_xll.DBRW($C$1,T$15,$Q$16,$O$1,Opening!$I$13,Opening!$D$13,$P$1,$A20,$B20,$M$1) -> 0 | U20: =_xll.DBRW($C$1,U$15,$Q$16,$O$1,Opening!$I$13,Opening!$D$13,$P$1,$A20,$B20,$M$1) -> 0
A21: OOR.010.001 | B21: ACL.OOR.010.001.04 | C21: Other | D21: Contingencies | E21: =_xll.DBRW($C$1,Opening!$G$13,Opening!E$11,$O$1,Opening!$I$13,Opening!$D$13,$P$1,$A21,$B21,$M$1) -> 0 | F21: =_xll.DBRW($C$1,Opening!$G$13,Opening!F$11,$O$1,Opening!$I$13,Opening!$D$13,$P$1,$A21,$B21,$M$1) -> 0 | G21: =_xll.DBRW($C$1,Opening!$G$13,Opening!G$11,$O$1,Opening!$I$13,Opening!$D$13,$P$1,$A21,$B21,$M$1) -> 0 | H21: =_xll.DBRW($C$1,Opening!$G$13,Opening!H$11,$O$1,Opening!$I$13,Opening!$D$13,$P$1,$A21,$B21,$M$1) -> 0 | I21: =_xll.DBRW($C$1,Opening!$G$13,Opening!I$11,$O$1,Opening!$I$13,Opening!$D$13,$P$1,$A21,$B21,$M$1) -> 0 | J21: =_xll.DBRW($C$1,Opening!$G$13,Opening!J$11,$O$1,Opening!$I$13,Opening!$D$13,$P$1,$A21,$B21,$M$1) -> 0 | K21: =_xll.DBRW($C$1,Opening!$G$13,Opening!K$11,$O$1,Opening!$I$13,Opening!$D$13,$P$1,$A21,$B21,$M$1) -> 0 | L21: =_xll.DBRW($C$1,Opening!$G$13,Opening!L$11,$O$1,Opening!$I$13,Opening!$D$13,$P$1,$A21,$B21,$M$1) -> 0 | ... P21: =_xll.DBRW($C$1,Opening!$G$13,Opening!P$11,$O$1,Opening!$I$13,Opening!$D$13,$P$1,$A21,$B21,$M$1) -> 0 | Q21: =_xll.DBRW($C$1,Q$15,$Q$16,$O$1,Opening!$I$13,Opening!$D$13,$P$1,$A21,$B21,$M$1) -> 0 | R21: =_xll.DBRW($C$1,R$15,$Q$16,$O$1,Opening!$I$13,Opening!$D$13,$P$1,$A21,$B21,$M$1) -> 0 | S21: =_xll.DBRW($C$1,S$15,$Q$16,$O$1,Opening!$I$13,Opening!$D$13,$P$1,$A21,$B21,$M$1) -> 0 | T21: =_xll.DBRW($C$1,T$15,$Q$16,$O$1,Opening!$I$13,Opening!$D$13,$P$1,$A21,$B21,$M$1) -> 0 | U21: =_xll.DBRW($C$1,U$15,$Q$16,$O$1,Opening!$I$13,Opening!$D$13,$P$1,$A21,$B21,$M$1) -> 0
A22: OOR.010.001 | B22: ACL.OOR.010.001.05 | C22: Other | D22: Non-recurring Expenses | E22: =_xll.DBRW($C$1,Opening!$G$13,Opening!E$11,$O$1,Opening!$I$13,Opening!$D$13,$P$1,$A22,$B22,$M$1) -> 0 | F22: =_xll.DBRW($C$1,Opening!$G$13,Opening!F$11,$O$1,Opening!$I$13,Opening!$D$13,$P$1,$A22,$B22,$M$1) -> 0 | G22: =_xll.DBRW($C$1,Opening!$G$13,Opening!G$11,$O$1,Opening!$I$13,Opening!$D$13,$P$1,$A22,$B22,$M$1) -> 0 | H22: =_xll.DBRW($C$1,Opening!$G$13,Opening!H$11,$O$1,Opening!$I$13,Opening!$D$13,$P$1,$A22,$B22,$M$1) -> 0 | I22: =_xll.DBRW($C$1,Opening!$G$13,Opening!I$11,$O$1,Opening!$I$13,Opening!$D$13,$P$1,$A22,$B22,$M$1) -> 0 | J22: =_xll.DBRW($C$1,Opening!$G$13,Opening!J$11,$O$1,Opening!$I$13,Opening!$D$13,$P$1,$A22,$B22,$M$1) -> 0 | K22: =_xll.DBRW($C$1,Opening!$G$13,Opening!K$11,$O$1,Opening!$I$13,Opening!$D$13,$P$1,$A22,$B22,$M$1) -> 0 | L22: =_xll.DBRW($C$1,Opening!$G$13,Opening!L$11,$O$1,Opening!$I$13,Opening!$D$13,$P$1,$A22,$B22,$M$1) -> 0 | ... P22: =_xll.DBRW($C$1,Opening!$G$13,Opening!P$11,$O$1,Opening!$I$13,Opening!$D$13,$P$1,$A22,$B22,$M$1) -> 0 | Q22: =_xll.DBRW($C$1,Q$15,$Q$16,$O$1,Opening!$I$13,Opening!$D$13,$P$1,$A22,$B22,$M$1) -> 0 | R22: =_xll.DBRW($C$1,R$15,$Q$16,$O$1,Opening!$I$13,Opening!$D$13,$P$1,$A22,$B22,$M$1) -> 0 | S22: =_xll.DBRW($C$1,S$15,$Q$16,$O$1,Opening!$I$13,Opening!$D$13,$P$1,$A22,$B22,$M$1) -> 0 | T22: =_xll.DBRW($C$1,T$15,$Q$16,$O$1,Opening!$I$13,Opening!$D$13,$P$1,$A22,$B22,$M$1) -> 0 | U22: =_xll.DBRW($C$1,U$15,$Q$16,$O$1,Opening!$I$13,Opening!$D$13,$P$1,$A22,$B22,$M$1) -> 0
A23: OOR.010.001 | B23: ACL.OOR.010.001.06 | C23: Other | D23: Gain on assets | E23: =_xll.DBRW($C$1,Opening!$G$13,Opening!E$11,$O$1,Opening!$I$13,Opening!$D$13,$P$1,$A23,$B23,$M$1) -> 0 | F23: =_xll.DBRW($C$1,Opening!$G$13,Opening!F$11,$O$1,Opening!$I$13,Opening!$D$13,$P$1,$A23,$B23,$M$1) -> 0 | G23: =_xll.DBRW($C$1,Opening!$G$13,Opening!G$11,$O$1,Opening!$I$13,Opening!$D$13,$P$1,$A23,$B23,$M$1) -> 0 | H23: =_xll.DBRW($C$1,Opening!$G$13,Opening!H$11,$O$1,Opening!$I$13,Opening!$D$13,$P$1,$A23,$B23,$M$1) -> 0 | I23: =_xll.DBRW($C$1,Opening!$G$13,Opening!I$11,$O$1,Opening!$I$13,Opening!$D$13,$P$1,$A23,$B23,$M$1) -> 0 | J23: =_xll.DBRW($C$1,Opening!$G$13,Opening!J$11,$O$1,Opening!$I$13,Opening!$D$13,$P$1,$A23,$B23,$M$1) -> 0 | K23: =_xll.DBRW($C$1,Opening!$G$13,Opening!K$11,$O$1,Opening!$I$13,Opening!$D$13,$P$1,$A23,$B23,$M$1) -> 0 | L23: =_xll.DBRW($C$1,Opening!$G$13,Opening!L$11,$O$1,Opening!$I$13,Opening!$D$13,$P$1,$A23,$B23,$M$1) -> 0 | ... P23: =_xll.DBRW($C$1,Opening!$G$13,Opening!P$11,$O$1,Opening!$I$13,Opening!$D$13,$P$1,$A23,$B23,$M$1) -> 0 | Q23: =_xll.DBRW($C$1,Q$15,$Q$16,$O$1,Opening!$I$13,Opening!$D$13,$P$1,$A23,$B23,$M$1) -> 0 | R23: =_xll.DBRW($C$1,R$15,$Q$16,$O$1,Opening!$I$13,Opening!$D$13,$P$1,$A23,$B23,$M$1) -> 0 | S23: =_xll.DBRW($C$1,S$15,$Q$16,$O$1,Opening!$I$13,Opening!$D$13,$P$1,$A23,$B23,$M$1) -> 0 | T23: =_xll.DBRW($C$1,T$15,$Q$16,$O$1,Opening!$I$13,Opening!$D$13,$P$1,$A23,$B23,$M$1) -> 0 | U23: =_xll.DBRW($C$1,U$15,$Q$16,$O$1,Opening!$I$13,Opening!$D$13,$P$1,$A23,$B23,$M$1) -> 0
A24: OOR.010.001 | B24: ACL.OOR.010.001.07 | C24: Other | D24: Tax benefits | E24: =_xll.DBRW($C$1,Opening!$G$13,Opening!E$11,$O$1,Opening!$I$13,Opening!$D$13,$P$1,$A24,$B24,$M$1) -> 0 | F24: =_xll.DBRW($C$1,Opening!$G$13,Opening!F$11,$O$1,Opening!$I$13,Opening!$D$13,$P$1,$A24,$B24,$M$1) -> 0 | G24: =_xll.DBRW($C$1,Opening!$G$13,Opening!G$11,$O$1,Opening!$I$13,Opening!$D$13,$P$1,$A24,$B24,$M$1) -> 0 | H24: =_xll.DBRW($C$1,Opening!$G$13,Opening!H$11,$O$1,Opening!$I$13,Opening!$D$13,$P$1,$A24,$B24,$M$1) -> 0 | I24: =_xll.DBRW($C$1,Opening!$G$13,Opening!I$11,$O$1,Opening!$I$13,Opening!$D$13,$P$1,$A24,$B24,$M$1) -> 0 | J24: =_xll.DBRW($C$1,Opening!$G$13,Opening!J$11,$O$1,Opening!$I$13,Opening!$D$13,$P$1,$A24,$B24,$M$1) -> 0 | K24: =_xll.DBRW($C$1,Opening!$G$13,Opening!K$11,$O$1,Opening!$I$13,Opening!$D$13,$P$1,$A24,$B24,$M$1) -> 0 | L24: =_xll.DBRW($C$1,Opening!$G$13,Opening!L$11,$O$1,Opening!$I$13,Opening!$D$13,$P$1,$A24,$B24,$M$1) -> 0 | ... P24: =_xll.DBRW($C$1,Opening!$G$13,Opening!P$11,$O$1,Opening!$I$13,Opening!$D$13,$P$1,$A24,$B24,$M$1) -> 0 | Q24: =_xll.DBRW($C$1,Q$15,$Q$16,$O$1,Opening!$I$13,Opening!$D$13,$P$1,$A24,$B24,$M$1) -> 0 | R24: =_xll.DBRW($C$1,R$15,$Q$16,$O$1,Opening!$I$13,Opening!$D$13,$P$1,$A24,$B24,$M$1) -> 0 | S24: =_xll.DBRW($C$1,S$15,$Q$16,$O$1,Opening!$I$13,Opening!$D$13,$P$1,$A24,$B24,$M$1) -> 0 | T24: =_xll.DBRW($C$1,T$15,$Q$16,$O$1,Opening!$I$13,Opening!$D$13,$P$1,$A24,$B24,$M$1) -> 0 | U24: =_xll.DBRW($C$1,U$15,$Q$16,$O$1,Opening!$I$13,Opening!$D$13,$P$1,$A24,$B24,$M$1) -> 0
A25: OOR.010.001 | B25: ACL.OOR.010.001.08 | C25: Other | D25: Other Op. Results - Machadinho | E25: =_xll.DBRW($C$1,Opening!$G$13,Opening!E$11,$O$1,Opening!$I$13,Opening!$D$13,$P$1,$A25,$B25,$M$1) -> 0 | F25: =_xll.DBRW($C$1,Opening!$G$13,Opening!F$11,$O$1,Opening!$I$13,Opening!$D$13,$P$1,$A25,$B25,$M$1) -> 0 | G25: =_xll.DBRW($C$1,Opening!$G$13,Opening!G$11,$O$1,Opening!$I$13,Opening!$D$13,$P$1,$A25,$B25,$M$1) -> 0 | H25: =_xll.DBRW($C$1,Opening!$G$13,Opening!H$11,$O$1,Opening!$I$13,Opening!$D$13,$P$1,$A25,$B25,$M$1) -> 0 | I25: =_xll.DBRW($C$1,Opening!$G$13,Opening!I$11,$O$1,Opening!$I$13,Opening!$D$13,$P$1,$A25,$B25,$M$1) -> 0 | J25: =_xll.DBRW($C$1,Opening!$G$13,Opening!J$11,$O$1,Opening!$I$13,Opening!$D$13,$P$1,$A25,$B25,$M$1) -> 0 | K25: =_xll.DBRW($C$1,Opening!$G$13,Opening!K$11,$O$1,Opening!$I$13,Opening!$D$13,$P$1,$A25,$B25,$M$1) -> 0 | L25: =_xll.DBRW($C$1,Opening!$G$13,Opening!L$11,$O$1,Opening!$I$13,Opening!$D$13,$P$1,$A25,$B25,$M$1) -> 0 | ... P25: =_xll.DBRW($C$1,Opening!$G$13,Opening!P$11,$O$1,Opening!$I$13,Opening!$D$13,$P$1,$A25,$B25,$M$1) -> 0 | Q25: =_xll.DBRW($C$1,Q$15,$Q$16,$O$1,Opening!$I$13,Opening!$D$13,$P$1,$A25,$B25,$M$1) -> 0 | R25: =_xll.DBRW($C$1,R$15,$Q$16,$O$1,Opening!$I$13,Opening!$D$13,$P$1,$A25,$B25,$M$1) -> 0 | S25: =_xll.DBRW($C$1,S$15,$Q$16,$O$1,Opening!$I$13,Opening!$D$13,$P$1,$A25,$B25,$M$1) -> 0 | T25: =_xll.DBRW($C$1,T$15,$Q$16,$O$1,Opening!$I$13,Opening!$D$13,$P$1,$A25,$B25,$M$1) -> 0 | U25: =_xll.DBRW($C$1,U$15,$Q$16,$O$1,Opening!$I$13,Opening!$D$13,$P$1,$A25,$B25,$M$1) -> 0
A26: OOR.010.001 | B26: ACL.OOR.010.001.09 | C26: Other | D26: MOTZ | E26: =_xll.DBRW($C$1,Opening!$G$13,Opening!E$11,$O$1,Opening!$I$13,Opening!$D$13,$P$1,$A26,$B26,$M$1) -> 0 | F26: =_xll.DBRW($C$1,Opening!$G$13,Opening!F$11,$O$1,Opening!$I$13,Opening!$D$13,$P$1,$A26,$B26,$M$1) -> 0 | G26: =_xll.DBRW($C$1,Opening!$G$13,Opening!G$11,$O$1,Opening!$I$13,Opening!$D$13,$P$1,$A26,$B26,$M$1) -> 0 | H26: =_xll.DBRW($C$1,Opening!$G$13,Opening!H$11,$O$1,Opening!$I$13,Opening!$D$13,$P$1,$A26,$B26,$M$1) -> 0 | I26: =_xll.DBRW($C$1,Opening!$G$13,Opening!I$11,$O$1,Opening!$I$13,Opening!$D$13,$P$1,$A26,$B26,$M$1) -> 0 | J26: =_xll.DBRW($C$1,Opening!$G$13,Opening!J$11,$O$1,Opening!$I$13,Opening!$D$13,$P$1,$A26,$B26,$M$1) -> 0 | K26: =_xll.DBRW($C$1,Opening!$G$13,Opening!K$11,$O$1,Opening!$I$13,Opening!$D$13,$P$1,$A26,$B26,$M$1) -> 0 | L26: =_xll.DBRW($C$1,Opening!$G$13,Opening!L$11,$O$1,Opening!$I$13,Opening!$D$13,$P$1,$A26,$B26,$M$1) -> 0 | ... P26: =_xll.DBRW($C$1,Opening!$G$13,Opening!P$11,$O$1,Opening!$I$13,Opening!$D$13,$P$1,$A26,$B26,$M$1) -> 0 | Q26: =_xll.DBRW($C$1,Q$15,$Q$16,$O$1,Opening!$I$13,Opening!$D$13,$P$1,$A26,$B26,$M$1) -> 0 | R26: =_xll.DBRW($C$1,R$15,$Q$16,$O$1,Opening!$I$13,Opening!$D$13,$P$1,$A26,$B26,$M$1) -> 0 | S26: =_xll.DBRW($C$1,S$15,$Q$16,$O$1,Opening!$I$13,Opening!$D$13,$P$1,$A26,$B26,$M$1) -> 0 | T26: =_xll.DBRW($C$1,T$15,$Q$16,$O$1,Opening!$I$13,Opening!$D$13,$P$1,$A26,$B26,$M$1) -> 0 | U26: =_xll.DBRW($C$1,U$15,$Q$16,$O$1,Opening!$I$13,Opening!$D$13,$P$1,$A26,$B26,$M$1) -> 0
A27: OOR.010.001 | B27: ACL.OOR.010.001.10 | C27: Other | D27: Non Op. Taxes | E27: =_xll.DBRW($C$1,Opening!$G$13,Opening!E$11,$O$1,Opening!$I$13,Opening!$D$13,$P$1,$A27,$B27,$M$1) -> 0 | F27: =_xll.DBRW($C$1,Opening!$G$13,Opening!F$11,$O$1,Opening!$I$13,Opening!$D$13,$P$1,$A27,$B27,$M$1) -> 0 | G27: =_xll.DBRW($C$1,Opening!$G$13,Opening!G$11,$O$1,Opening!$I$13,Opening!$D$13,$P$1,$A27,$B27,$M$1) -> 0 | H27: =_xll.DBRW($C$1,Opening!$G$13,Opening!H$11,$O$1,Opening!$I$13,Opening!$D$13,$P$1,$A27,$B27,$M$1) -> 0 | I27: =_xll.DBRW($C$1,Opening!$G$13,Opening!I$11,$O$1,Opening!$I$13,Opening!$D$13,$P$1,$A27,$B27,$M$1) -> 0 | J27: =_xll.DBRW($C$1,Opening!$G$13,Opening!J$11,$O$1,Opening!$I$13,Opening!$D$13,$P$1,$A27,$B27,$M$1) -> 0 | K27: =_xll.DBRW($C$1,Opening!$G$13,Opening!K$11,$O$1,Opening!$I$13,Opening!$D$13,$P$1,$A27,$B27,$M$1) -> 0 | L27: =_xll.DBRW($C$1,Opening!$G$13,Opening!L$11,$O$1,Opening!$I$13,Opening!$D$13,$P$1,$A27,$B27,$M$1) -> 0 | ... P27: =_xll.DBRW($C$1,Opening!$G$13,Opening!P$11,$O$1,Opening!$I$13,Opening!$D$13,$P$1,$A27,$B27,$M$1) -> 0 | Q27: =_xll.DBRW($C$1,Q$15,$Q$16,$O$1,Opening!$I$13,Opening!$D$13,$P$1,$A27,$B27,$M$1) -> 0 | R27: =_xll.DBRW($C$1,R$15,$Q$16,$O$1,Opening!$I$13,Opening!$D$13,$P$1,$A27,$B27,$M$1) -> 0 | S27: =_xll.DBRW($C$1,S$15,$Q$16,$O$1,Opening!$I$13,Opening!$D$13,$P$1,$A27,$B27,$M$1) -> 0 | T27: =_xll.DBRW($C$1,T$15,$Q$16,$O$1,Opening!$I$13,Opening!$D$13,$P$1,$A27,$B27,$M$1) -> 0 | U27: =_xll.DBRW($C$1,U$15,$Q$16,$O$1,Opening!$I$13,Opening!$D$13,$P$1,$A27,$B27,$M$1) -> 0
A28: OOR.010.001 | B28: ACL.OOR.010.001.11 | C28: Other | D28: Other products | E28: =_xll.DBRW($C$1,Opening!$G$13,Opening!E$11,$O$1,Opening!$I$13,Opening!$D$13,$P$1,$A28,$B28,$M$1) -> 0 | F28: =_xll.DBRW($C$1,Opening!$G$13,Opening!F$11,$O$1,Opening!$I$13,Opening!$D$13,$P$1,$A28,$B28,$M$1) -> 0 | G28: =_xll.DBRW($C$1,Opening!$G$13,Opening!G$11,$O$1,Opening!$I$13,Opening!$D$13,$P$1,$A28,$B28,$M$1) -> 0 | H28: =_xll.DBRW($C$1,Opening!$G$13,Opening!H$11,$O$1,Opening!$I$13,Opening!$D$13,$P$1,$A28,$B28,$M$1) -> 0 | I28: =_xll.DBRW($C$1,Opening!$G$13,Opening!I$11,$O$1,Opening!$I$13,Opening!$D$13,$P$1,$A28,$B28,$M$1) -> 0 | J28: =_xll.DBRW($C$1,Opening!$G$13,Opening!J$11,$O$1,Opening!$I$13,Opening!$D$13,$P$1,$A28,$B28,$M$1) -> 0 | K28: =_xll.DBRW($C$1,Opening!$G$13,Opening!K$11,$O$1,Opening!$I$13,Opening!$D$13,$P$1,$A28,$B28,$M$1) -> 0 | L28: =_xll.DBRW($C$1,Opening!$G$13,Opening!L$11,$O$1,Opening!$I$13,Opening!$D$13,$P$1,$A28,$B28,$M$1) -> 0 | ... P28: =_xll.DBRW($C$1,Opening!$G$13,Opening!P$11,$O$1,Opening!$I$13,Opening!$D$13,$P$1,$A28,$B28,$M$1) -> 0 | Q28: =_xll.DBRW($C$1,Q$15,$Q$16,$O$1,Opening!$I$13,Opening!$D$13,$P$1,$A28,$B28,$M$1) -> 0 | R28: =_xll.DBRW($C$1,R$15,$Q$16,$O$1,Opening!$I$13,Opening!$D$13,$P$1,$A28,$B28,$M$1) -> 0 | S28: =_xll.DBRW($C$1,S$15,$Q$16,$O$1,Opening!$I$13,Opening!$D$13,$P$1,$A28,$B28,$M$1) -> 0 | T28: =_xll.DBRW($C$1,T$15,$Q$16,$O$1,Opening!$I$13,Opening!$D$13,$P$1,$A28,$B28,$M$1) -> 0 | U28: =_xll.DBRW($C$1,U$15,$Q$16,$O$1,Opening!$I$13,Opening!$D$13,$P$1,$A28,$B28,$M$1) -> 0
A29: OOR.010.001 | B29: ACL.OOR.010.001.12 | C29: Other | D29: Non-recurring Revenues | E29: =_xll.DBRW($C$1,Opening!$G$13,Opening!E$11,$O$1,Opening!$I$13,Opening!$D$13,$P$1,$A29,$B29,$M$1) -> 0 | F29: =_xll.DBRW($C$1,Opening!$G$13,Opening!F$11,$O$1,Opening!$I$13,Opening!$D$13,$P$1,$A29,$B29,$M$1) -> 0 | G29: =_xll.DBRW($C$1,Opening!$G$13,Opening!G$11,$O$1,Opening!$I$13,Opening!$D$13,$P$1,$A29,$B29,$M$1) -> 0 | H29: =_xll.DBRW($C$1,Opening!$G$13,Opening!H$11,$O$1,Opening!$I$13,Opening!$D$13,$P$1,$A29,$B29,$M$1) -> 0 | I29: =_xll.DBRW($C$1,Opening!$G$13,Opening!I$11,$O$1,Opening!$I$13,Opening!$D$13,$P$1,$A29,$B29,$M$1) -> 0 | J29: =_xll.DBRW($C$1,Opening!$G$13,Opening!J$11,$O$1,Opening!$I$13,Opening!$D$13,$P$1,$A29,$B29,$M$1) -> 0 | K29: =_xll.DBRW($C$1,Opening!$G$13,Opening!K$11,$O$1,Opening!$I$13,Opening!$D$13,$P$1,$A29,$B29,$M$1) -> 0 | L29: =_xll.DBRW($C$1,Opening!$G$13,Opening!L$11,$O$1,Opening!$I$13,Opening!$D$13,$P$1,$A29,$B29,$M$1) -> 0 | ... P29: =_xll.DBRW($C$1,Opening!$G$13,Opening!P$11,$O$1,Opening!$I$13,Opening!$D$13,$P$1,$A29,$B29,$M$1) -> 0 | Q29: =_xll.DBRW($C$1,Q$15,$Q$16,$O$1,Opening!$I$13,Opening!$D$13,$P$1,$A29,$B29,$M$1) -> 0 | R29: =_xll.DBRW($C$1,R$15,$Q$16,$O$1,Opening!$I$13,Opening!$D$13,$P$1,$A29,$B29,$M$1) -> 0 | S29: =_xll.DBRW($C$1,S$15,$Q$16,$O$1,Opening!$I$13,Opening!$D$13,$P$1,$A29,$B29,$M$1) -> 0 | T29: =_xll.DBRW($C$1,T$15,$Q$16,$O$1,Opening!$I$13,Opening!$D$13,$P$1,$A29,$B29,$M$1) -> 0 | U29: =_xll.DBRW($C$1,U$15,$Q$16,$O$1,Opening!$I$13,Opening!$D$13,$P$1,$A29,$B29,$M$1) -> 0
... A33: OOR.010.001 | B33: N/A | C33: Other | D33: N/A | E33: =_xll.DBRW($C$1,Opening!$G$13,Opening!E$11,$O$1,Opening!$I$13,Opening!$D$13,$P$1,$A33,$B33,$M$1) -> 0 | F33: =_xll.DBRW($C$1,Opening!$G$13,Opening!F$11,$O$1,Opening!$I$13,Opening!$D$13,$P$1,$A33,$B33,$M$1) -> 0 | G33: =_xll.DBRW($C$1,Opening!$G$13,Opening!G$11,$O$1,Opening!$I$13,Opening!$D$13,$P$1,$A33,$B33,$M$1) -> 0 | H33: =_xll.DBRW($C$1,Opening!$G$13,Opening!H$11,$O$1,Opening!$I$13,Opening!$D$13,$P$1,$A33,$B33,$M$1) -> 0 | I33: =_xll.DBRW($C$1,Opening!$G$13,Opening!I$11,$O$1,Opening!$I$13,Opening!$D$13,$P$1,$A33,$B33,$M$1) -> 0 | J33: =_xll.DBRW($C$1,Opening!$G$13,Opening!J$11,$O$1,Opening!$I$13,Opening!$D$13,$P$1,$A33,$B33,$M$1) -> 0 | K33: =_xll.DBRW($C$1,Opening!$G$13,Opening!K$11,$O$1,Opening!$I$13,Opening!$D$13,$P$1,$A33,$B33,$M$1) -> 0 | L33: =_xll.DBRW($C$1,Opening!$G$13,Opening!L$11,$O$1,Opening!$I$13,Opening!$D$13,$P$1,$A33,$B33,$M$1) -> 0 | ... P33: =_xll.DBRW($C$1,Opening!$G$13,Opening!P$11,$O$1,Opening!$I$13,Opening!$D$13,$P$1,$A33,$B33,$M$1) -> 0 | Q33: =_xll.DBRW($C$1,Q$15,$Q$16,$O$1,Opening!$I$13,Opening!$D$13,$P$1,$A33,$B33,$M$1) -> 0 | R33: =_xll.DBRW($C$1,R$15,$Q$16,$O$1,Opening!$I$13,Opening!$D$13,$P$1,$A33,$B33,$M$1) -> 0 | S33: =_xll.DBRW($C$1,S$15,$Q$16,$O$1,Opening!$I$13,Opening!$D$13,$P$1,$A33,$B33,$M$1) -> 0 | T33: =_xll.DBRW($C$1,T$15,$Q$16,$O$1,Opening!$I$13,Opening!$D$13,$P$1,$A33,$B33,$M$1) -> 0 | U33: =_xll.DBRW($C$1,U$15,$Q$16,$O$1,Opening!$I$13,Opening!$D$13,$P$1,$A33,$B33,$M$1) -> 0
C36: DRE - OTHER NON OP. RESULTS
Q37: =$G$13+1 -> 2027 | R37: =$G$13+2 -> 2028 | S37: =$G$13+3 -> 2029 | T37: =$G$13+4 -> 2030 | U37: =$G$13+5 -> 2031
E38: =$G$13&"."&E$11 -> 2026.01 | F38: =$G$13&"."&F$11 -> 2026.02 | G38: =$G$13&"."&G$11 -> 2026.03 | H38: =$G$13&"."&H$11 -> 2026.04 | I38: =$G$13&"."&I$11 -> 2026.05 | J38: =$G$13&"."&J$11 -> 2026.06 | K38: =$G$13&"."&K$11 -> 2026.07 | L38: =$G$13&"."&L$11 -> 2026.08 | ... P38: =$G$13&"."&P$11 -> 2026.12 | Q38: PE | R38: PE | S38: PE | T38: PE | U38: PE
