Workbook
Name ID: "277ba13c-b6eb-4d47-83fa-9baf228cb385"
Name ID: "6b59bacb-47d2-463d-bb42-950ec78108a7"
Name ID: "4a87d370-8f7f-491d-80f0-a1aa34e613de"

Sheet Cognos_Office_Connection_Cache

Sheet Home

Sheet Summary  - Fx
A1: Cubo
A2: CONS_VC:DFS.200.KPIs
A3: CONS_VC:DFS.100.Profit_and_loss
A4: CONS_VC:DFS.140.Indirect_Cash_Flow
A5: CONS_VC:DFS.180.Gross_Debt
A6: CONS_VC:REV.100.Revenue_Consolidated
A8: Ano | F8: Regions | G8: Formato
F9: VCBR
F10: {=_xll.DBRW($A$3,Summary!$S$6,Summary!$U$6,Summary!$K$6,$A$23,$A$30,$A$36,"EBITDA","Total Value")} -> #VALUE! | G10: =Summary!$K$6 -> #N/A
A11: Mês | F11: {=_xll.DBRW($A$3,Summary!$S$6,Summary!$U$6,Summary!$M$6,$A$23,$A$30,$A$36,"EBITDA","Total Value")} -> #VALUE! | G11: =Summary!$M$6 -> #N/A
A12: =_xll.SUBNM("CONS_VC:ALL.D.Month",,"Total YTD","MEMBER_NAME") -> Total YTD | F12: =IFERROR((F10-F11)/F11,0) -> 0 | G12: =Summary!$O$6 -> #N/A
A13: =_xll.SUBNM("CONS_VC:ALL.D.Month",,"Year","MEMBER_NAME") -> Year
F14: VCBR
F15: {=_xll.DBRW($A$3,Summary!$S$6,$A$12,Summary!$K$6,$A$23,$A$30,$A$36,"EBITDA","Total Value")} -> #VALUE! | G15: L300
A16: Versão | F16: {=_xll.DBRW($A$3,Summary!$S$6,$A$12,Summary!$M$6,$A$23,$A$30,$A$36,"EBITDA","Total Value")} -> #VALUE! | G16: RF
A17: =Summary!$K$6 -> #N/A | F17: =IFERROR((F15-F16)/F16,0) -> 0
A18: =Summary!$M$6 -> #N/A
A19: =Summary!$O$6 -> #N/A | F19: VCBR
F20: {=_xll.DBRW($A$3,Summary!$S$6,$A$13,Summary!$K$6,$A$23,$A$30,$A$36,"EBITDA","Total Value")} -> #VALUE! | G20: L300
F21: {=_xll.DBRW($A$3,Summary!$S$6,$A$13,Summary!$M$6,$A$23,$A$30,$A$36,"EBITDA","Total Value")} -> #VALUE! | G21: RF
A22: Currency | F22: {=_xll.DBRW($A$3,Summary!$S$6,$A$13,Summary!$M$6,$A$23,$A$30,$A$36,G22,"Total Value")} -> #VALUE! | G22: EBITDA Econômico
A23: =_xll.SUBNM("CONS_VC:ALL.D.Currency","","BRL Conv.") -> BRL Conv.
A24: =_xll.SUBNM("CONS_VC:ALL.D.Currency","","USD Conv.") -> USD Conv. | F24: VCNA
A25: =_xll.SUBNM("CONS_VC:ALL.D.Currency","","EUR Conv.") -> EUR Conv. | F25: {=_xll.DBRW($A$3,Summary!$S$6,Summary!$U$6,Summary!$K$6,$A$24,$A$31,$A$36,"EBITDA","Total Value")} -> #VALUE! | G25: L300
F26: {=_xll.DBRW($A$3,Summary!$S$6,Summary!$U$6,Summary!$M$6,$A$24,$A$31,$A$36,"EBITDA","Total Value")} -> #VALUE! | G26: RF
F27: =IFERROR((F25-F26)/F26,0) -> 0
A28: Region
A29: =Summary!$D$6 -> #N/A | F29: VCNA
A30: VCBR | F30: {=_xll.DBRW($A$3,Summary!$S$6,$A$12,Summary!$K$6,$A$24,$A$31,$A$36,"EBITDA","Total Value")} -> #VALUE! | G30: L300
A31: VCNA | F31: {=_xll.DBRW($A$3,Summary!$S$6,$A$12,Summary!$M$6,$A$24,$A$31,$A$36,"EBITDA","Total Value")} -> #VALUE! | G31: RF
A32: VCEAA | F32: =IFERROR((F30-F31)/F31,0) -> 0
A33: VCLATAM
F34: VCNA
A35: Produto | F35: {=_xll.DBRW($A$3,Summary!$S$6,$A$13,Summary!$K$6,$A$24,$A$31,$A$36,"EBITDA","Total Value")} -> #VALUE! | G35: L300
A36: =_xll.SUBNM("CONS_VC:ALL.D.Products","","Total Products") -> Total Products | F36: {=_xll.DBRW($A$3,Summary!$S$6,$A$13,Summary!$M$6,$A$24,$A$31,$A$36,"EBITDA","Total Value")} -> #VALUE! | G36: RF
F37: {=_xll.DBRW($A$3,Summary!$S$6,$A$13,Summary!$M$6,$A$24,$A$31,$A$36,G37,"Total Value")} -> #VALUE! | G37: EBITDA Econômico
A38: Accounts_PNL | F38: =IFERROR((F36-F37)/F37,0) -> 0
A39: Net Profit
F40: VCEA
A41: Accounts_ICF | F41: {=_xll.DBRW($A$3,Summary!$S$6,Summary!$U$6,Summary!$K$6,$A$25,$A$32,$A$36,"EBITDA","Total Value")} -> #VALUE! | G41: L300
...

Sheet Summary
B1: Summary - Regions EBITDA
D6: =_xll.SUBNM("CONS_VC_PRD:ALL.D.Region","","Global") -> #N/A | K6: =_xll.SUBNM("CONS_VC_PRD:ALL.D.Version","Sys.Report","Actual","Descrição") -> #N/A | M6: =_xll.SUBNM("CONS_VC_PRD:ALL.D.Version","Sys.Report","RF","Descrição") -> #N/A | O6: =_xll.SUBNM("CONS_VC_PRD:ALL.D.Version","Sys.Report","Actual","Descrição") -> #N/A | S6: =_xll.SUBNM("CONS_VC_PRD:ALL.D.Year","SYS_Picklist","2025","ÏD do Membro") -> #N/A | U6: =_xll.SUBNM("CONS_VC_PRD:ALL.D.Month","sys_picklist","Jan","DESC") -> #N/A
D8: Month
J9: VCBR (BRL)
F12: ='Summary - Fx'!B47 -> #VALUE!
G14: ='Summary - Fx'!A48 -> 0% vs. Budget
J15: VCNA (USD)
D17: YTD
F22: ='Summary - Fx'!B51 -> #VALUE! | J22: VCEA (EUR)
G24: ='Summary - Fx'!A52 -> 0% vs. Budget
D27: Full Year
J30: VCLatam (USD)
F33: ='Summary - Fx'!B56 -> #VALUE!
G35: ='Summary - Fx'!A57 -> 0% vs. Budget

Sheet EBITDA - Fx
A2: CONS_VC:DFS.100.Profit_and_Loss
B3: =_xll.SUBNM("CONS_VC:ALL.D.Month","SYS_YTD",EBITDA!$N$6,"ID do membro") -> #VALUE!
A4: =_xll.SUBNM("CONS_VC:ALL.D.Year",,"2025") -> 2025
A5: =_xll.SUBNM("CONS_VC:DFS.M.100.Profit_and_Loss",,"Total Value") -> Total Value
A6: =_xll.SUBNM("CONS_VC:ALL.D.Version","Sys.Report","Actual","Descrição") -> Actual
D7: =EBITDA!C6 -> #N/A
A9: =_xll.SUBNM("CONS_VC:ALL.D.Products",,"Total Products") -> Total Products
A12: Quarter View | C12: =EBITDA!$N$6 -> #N/A | D12: ="YTD "&$B$3 -> #VALUE! | H12: Full Year View | J12: Versão | K12: =EBITDA!$AI$6 -> #N/A | L12: L300 | M12: =EBITDA!$AM$6 -> #N/A | N12: =EBITDA!$AM$6 -> #N/A | O12: =EBITDA!$AM$6 -> #N/A | P12: =EBITDA!$AM$6 -> #N/A | Q12: =EBITDA!$AM$6 -> #N/A | R12: =EBITDA!$AI$6 -> #N/A | S12: =EBITDA!$AM$6 -> #N/A
A13: =EBITDA!$AI$6 -> #N/A | B13: =$A$4-1 -> 2024 | C13: =_xll.DBRW($A$2,$B$13,C$12,$A13,EBITDA!$X$6,EBITDA!$R$6,$A$9,$D$7,$A$5) -> #VALUE! | D13: =_xll.DBRW($A$2,$B$13,D$12,$A13,EBITDA!$X$6,EBITDA!$R$6,$A$9,$D$7,$A$5) -> #VALUE! | J13: Empresa | K13: Global | L13: Global | M13: VCBR | N13: VCNA | O13: VCEAA | P13: VCLATAM | Q13: VCOTHERS | R13: Fx | S13: Global
A14: =EBITDA!$AK$6 -> #N/A | B14: =$A$4 -> 2025 | C14: =_xll.DBRW($A$2,$A$4,C$12,$A14,EBITDA!$X$6,EBITDA!$R$6,$A$9,$D$7,$A$5) -> #VALUE! | D14: =_xll.DBRW($A$2,$A$4,D$12,$A14,EBITDA!$X$6,EBITDA!$R$6,$A$9,$D$7,$A$5) -> #VALUE! | K14: =A4-1 -> 2024 | L14: L300 | M14: VCBR | N14: VCNA | O14: VCEA | P14: VCLATAM | Q14: Others | R14: FX | S14: Flash
A15: =EBITDA!$AM$6 -> #N/A | B15: 2025 | C15: =_xll.DBRW($A$2,$A$4,C$12,$A15,EBITDA!$X$6,EBITDA!$R$6,$A$9,$D$7,$A$5) -> #VALUE! | D15: =_xll.DBRW($A$2,$A$4,D$12,$A15,EBITDA!$X$6,EBITDA!$R$6,$A$9,$D$7,$A$5) -> #VALUE! | K15: =_xll.DBRW($A$2,$K$14,EBITDA!$N$6,K$12,EBITDA!$X$6,K$13,$A$9,$D$7,$A$5) -> #VALUE! | L15: =_xll.DBRW($A$2,$A$4,EBITDA!$N$6,L$12,EBITDA!$X$6,L$13,$A$9,$D$7,$A$5) -> #VALUE! | M15: =_xll.DBRW($A$2,$A$4,EBITDA!$N$6,M$12,EBITDA!$X$6,M$13,$A$9,$D$7,$A$5) -> #VALUE! | N15: =_xll.DBRW($A$2,$A$4,EBITDA!$N$6,N$12,EBITDA!$X$6,N$13,$A$9,$D$7,$A$5) -> #VALUE! | O15: =_xll.DBRW($A$2,$A$4,EBITDA!$N$6,O$12,EBITDA!$X$6,O$13,$A$9,$D$7,$A$5) -> #VALUE! | P15: =_xll.DBRW($A$2,$A$4,EBITDA!$N$6,P$12,EBITDA!$X$6,P$13,$A$9,$D$7,$A$5) -> #VALUE! | Q15: =_xll.DBRW($A$2,$A$4,EBITDA!$N$6,Q$12,EBITDA!$X$6,Q$13,$A$9,$D$7,$A$5) -> #VALUE! | R15: =_xll.DBRW($A$2,$A$4,EBITDA!$N$6,R$12,EBITDA!$X$6,R$13,$A$9,$D$7,$A$5) -> #VALUE! | S15: =_xll.DBRW($A$2,$A$4,EBITDA!$N$6,S$12,EBITDA!$X$6,S$13,$A$9,$D$7,$A$5) -> #VALUE!
J16: =EBITDA!AK6 -> #N/A | M16: =_xll.DBRW($A$2,$A$4,EBITDA!$N$6,$J$16,EBITDA!$X$6,M$13,$A$9,$D$7,$A$5) -> #VALUE! | N16: =_xll.DBRW($A$2,$A$4,EBITDA!$N$6,$J$16,EBITDA!$X$6,N$13,$A$9,$D$7,$A$5) -> #VALUE! | O16: =_xll.DBRW($A$2,$A$4,EBITDA!$N$6,$J$16,EBITDA!$X$6,O$13,$A$9,$D$7,$A$5) -> #VALUE! | P16: =_xll.DBRW($A$2,$A$4,EBITDA!$N$6,$J$16,EBITDA!$X$6,P$13,$A$9,$D$7,$A$5) -> #VALUE! | Q16: =_xll.DBRW($A$2,$A$4,EBITDA!$N$6,$J$16,EBITDA!$X$6,Q$13,$A$9,$D$7,$A$5) -> #VALUE!
A20: EBITDA/Net Revenue (%) | C20: Q1 | D20: Q2
A21: =EBITDA!$AI$6 -> #N/A | B21: =$A$4-1 -> 2024 | C21: =_xll.DBRW($A$2,$B$13,C$12,$A13,EBITDA!$X$6,EBITDA!$R$6,$A$9,$A20,$A$5) -> #VALUE! | D21: =_xll.DBRW($A$2,$B$13,D$12,$A13,EBITDA!$X$6,EBITDA!$R$6,$A$9,$A20,$A$5) -> #VALUE!
A22: =EBITDA!$AK$6 -> #N/A | B22: =$A$4 -> 2025 | C22: =_xll.DBRW($A$2,$A$4,C$12,$A14,EBITDA!$X$6,EBITDA!$R$6,$A$9,$A20,$A$5) -> #VALUE! | D22: =_xll.DBRW($A$2,$A$4,D$12,$A14,EBITDA!$X$6,EBITDA!$R$6,$A$9,$A20,$A$5) -> #VALUE!
A23: =EBITDA!$AM$6 -> #N/A | B23: 2025 | C23: =_xll.DBRW($A$2,$A$4,C$12,$A15,EBITDA!$X$6,EBITDA!$R$6,$A$9,$A20,$A$5) -> #VALUE! | D23: =_xll.DBRW($A$2,$A$4,D$12,$A15,EBITDA!$X$6,EBITDA!$R$6,$A$9,$A20,$A$5) -> #VALUE!

Sheet EBITDA
B1: Account Analysis by Region
C6: =_xll.SUBNM("CONS_VC_PRD:DFS.D.Accounts_PnL","Default","EBITDA") -> #N/A | J6: =_xll.SUBNM("CONS_VC_PRD:ALL.D.Year","SYS_Picklist","2025","ÏD do Membro") -> #N/A | N6: =_xll.SUBNM("CONS_VC_PRD:ALL.D.Month","SYS_Picklist","Nov","Desc") -> #N/A | R6: =_xll.SUBNM("CONS_VC_PRD:ALL.D.Region","Default","Global") -> #N/A | X6: =_xll.SUBNM("CONS_VC_PRD:ALL.D.Currency","Default","BRL Conv.") -> #N/A | AI6: =_xll.SUBNM("CONS_VC_PRD:ALL.D.Version","Sys.Report","Actual","Descrição") -> #N/A | AK6: =_xll.SUBNM("CONS_VC_PRD:ALL.D.Version","Sys.Report","L300","Descrição") -> #N/A | AM6: =_xll.SUBNM("CONS_VC_PRD:ALL.D.Version","Sys.Report","RF","Descrição") -> #N/A
C8: =C6 -> #N/A | AB8: =C6&" Bridge" -> #N/A
A26: ="Margin "&$C$6 &'EBITDA - Fx'!A10 -> #N/A | D26: ='EBITDA - Fx'!C21 -> #VALUE! | E26: ='EBITDA - Fx'!C22 -> #VALUE! | F26: ='EBITDA - Fx'!C23 -> #VALUE! | I26: ='EBITDA - Fx'!D21 -> #VALUE! | J26: ='EBITDA - Fx'!D22 -> #VALUE! | K26: ='EBITDA - Fx'!D23 -> #VALUE! | M26: ='EBITDA - Fx'!E21 -> 0 | N26: ='EBITDA - Fx'!E22 -> 0 | O26: ='EBITDA - Fx'!E23 -> 0 | R26: ='EBITDA - Fx'!F21 -> 0 | S26: ='EBITDA - Fx'!F22 -> 0 | T26: ='EBITDA - Fx'!F23 -> 0

Sheet Monthly Global - Fx
A1: CONS_VC:DFS.100.Profit_and_Loss
A2: ='Monthly Global'!M3 -> #N/A
A3: ='Monthly Global'!O3 -> #N/A
E4: ='Monthly Global'!$Q$3 -> Actual | F4: ='Monthly Global'!$S$3 -> L300 | G4: Delta
A5: Total Products | C5: BRL CONV. | D5: Global | E5: =_xll.DBRW($A$1,$A$2,$A$3,E$4,$C5,$D5,$A$5,$A$6,$A$7) -> #VALUE! | F5: =_xll.DBRW($A$1,$A$2,$A$3,F$4,$C5,$D5,$A$5,$A$6,$A$7) -> #VALUE! | G5: =IFERROR(IF(E5>F5,ABS(E5/F5-1),-ABS(E5/F5-1)),0) -> 0 | I5: =C5& " | " &TEXT(E5,"#.##0") & " | " & TEXT(F5,"#.##0") & " | " & IF(G5>0,"▲ ", IF(G5<0,"▼ ","▬ ")) & TEXT(G5,"#.##0") -> #VALUE!
A6: ='Monthly Global'!D3 -> #N/A | C6: USD | D6: VCNA | E6: =_xll.DBRW($A$1,$A$2,$A$3,E$4,$C6,$D6,$A$5,$A$6,$A$7) -> #VALUE! | F6: =_xll.DBRW($A$1,$A$2,$A$3,F$4,$C6,$D6,$A$5,$A$6,$A$7) -> #VALUE! | G6: =IFERROR(IF(E6>F6,ABS(E6/F6-1),-ABS(E6/F6-1)),0) -> 0 | I6: =C6& " | " &TEXT(E6,"#.##0") & " | " & TEXT(F6,"#.##0") & " | " & IF(G6>0,"▲ ", IF(G6<0,"▼ ","▬ ")) & TEXT(G6,"#.##0") -> #VALUE!
A7: Total Value | C7: BRL | D7: VCBR - VCBR | E7: =_xll.DBRW($A$1,$A$2,$A$3,E$4,$C7,$D7,$A$5,$A$6,$A$7) -> #VALUE! | F7: =_xll.DBRW($A$1,$A$2,$A$3,F$4,$C7,$D7,$A$5,$A$6,$A$7) -> #VALUE! | G7: =IFERROR(IF(E7>F7,ABS(E7/F7-1),-ABS(E7/F7-1)),0) -> 0 | I7: =C7& " | " &TEXT(E7,"#.##0") & " | " & TEXT(F7,"#.##0") & " | " & IF(G7>0,"▲ ", IF(G7<0,"▼ ","▬ ")) & TEXT(G7,"#.##0") -> #VALUE!
C8: EUR | D8: ESPA - Spain | E8: =_xll.DBRW($A$1,$A$2,$A$3,E$4,$C8,$D8,$A$5,$A$6,$A$7) -> #VALUE! | F8: =_xll.DBRW($A$1,$A$2,$A$3,F$4,$C8,$D8,$A$5,$A$6,$A$7) -> #VALUE! | G8: =IFERROR(IF(E8>F8,ABS(E8/F8-1),-ABS(E8/F8-1)),0) -> 0 | I8: =C8& " | " &TEXT(E8,"#.##0") & " | " & TEXT(F8,"#.##0") & " | " & IF(G8>0,"▲ ", IF(G8<0,"▼ ","▬ ")) & TEXT(G8,"#.##0") -> #VALUE!
C9: EUR | D9: TURK - Turkey | E9: =_xll.DBRW($A$1,$A$2,$A$3,E$4,$C9,$D9,$A$5,$A$6,$A$7) -> #VALUE! | F9: =_xll.DBRW($A$1,$A$2,$A$3,F$4,$C9,$D9,$A$5,$A$6,$A$7) -> #VALUE! | G9: =IFERROR(IF(E9>F9,ABS(E9/F9-1),-ABS(E9/F9-1)),0) -> 0 | I9: =C9& " | " &TEXT(E9,"#.##0") & " | " & TEXT(F9,"#.##0") & " | " & IF(G9>0,"▲ ", IF(G9<0,"▼ ","▬ ")) & TEXT(G9,"#.##0") -> #VALUE!
C10: BOB | D10: ARTI - Artigas | E10: =_xll.DBRW($A$1,$A$2,$A$3,E$4,$C10,$D10,$A$5,$A$6,$A$7) -> #VALUE! | F10: =_xll.DBRW($A$1,$A$2,$A$3,F$4,$C10,$D10,$A$5,$A$6,$A$7) -> #VALUE! | G10: =IFERROR(IF(E10>F10,ABS(E10/F10-1),-ABS(E10/F10-1)),0) -> 0 | I10: =C10& " | " &TEXT(E10,"#.##0") & " | " & TEXT(F10,"#.##0") & " | " & IF(G10>0,"▲ ", IF(G10<0,"▼ ","▬ ")) & TEXT(G10,"#.##0") -> #VALUE!
C11: UYU | D11: ITACA - Itacamba | E11: =_xll.DBRW($A$1,$A$2,$A$3,E$4,$C11,$D11,$A$5,$A$6,$A$7) -> #VALUE! | F11: =_xll.DBRW($A$1,$A$2,$A$3,F$4,$C11,$D11,$A$5,$A$6,$A$7) -> #VALUE! | G11: =IFERROR(IF(E11>F11,ABS(E11/F11-1),-ABS(E11/F11-1)),0) -> 0 | I11: =C11& " | " &TEXT(E11,"#.##0") & " | " & TEXT(F11,"#.##0") & " | " & IF(G11>0,"▲ ", IF(G11<0,"▼ ","▬ ")) & TEXT(G11,"#.##0") -> #VALUE!

Sheet Monthly Global
A2: Month Analysis
D3: =_xll.SUBNM("CONS_VC_PRD:DFS.D.Accounts_PnL","Default","EBITDA") -> #N/A | M3: =_xll.SUBNM("CONS_VC_PRD:ALL.D.Year","SYS_Picklist","2025","ÏD do Membro") -> #N/A | O3: =_xll.SUBNM("CONS_VC_PRD:ALL.D.Month","SYS_Picklist","Nov","Desc") -> #N/A | Q3: Actual | S3: L300

Sheet Monthly VOL | PRICES - Fx
A1: CONS_VC:REV.100.Revenue_Consolidated
A2: ='Monthly VOL | PRICES'!M3 -> #N/A
A3: ='Monthly VOL | PRICES'!O3 -> #N/A | E3: Sales Volume [kt] | F3: Sales Volume [kt] | H3: Price Premium [$/ton] | I3: Price Premium [$/ton]
E4: ='Monthly VOL | PRICES'!$Q$3 -> Actual | F4: ='Monthly VOL | PRICES'!$S$3 -> L300 | G4: Delta | H4: ='Monthly VOL | PRICES'!$Q$3 -> Actual | I4: ='Monthly VOL | PRICES'!$S$3 -> L300 | J4: Delta
A5: ='Monthly VOL | PRICES'!D3 -> #N/A | C5: BRL CONV. | D5: Global | E5: =_xll.DBRW($A$1,$A$2,$A$3,E$4,$C5,$D5,$A$5,$A$8,$E$3) -> #VALUE! | F5: =_xll.DBRW($A$1,$A$2,$A$3,F$4,$C5,$D5,$A$5,$A$8,$F$3) -> #VALUE! | G5: =IFERROR((F5/E5)-1,"-") -> - | H5: =_xll.DBRW($A$1,$A$2,$A$3,H$4,$C5,$D5,$A$5,$A$8,$H$3) -> #VALUE! | I5: =_xll.DBRW($A$1,$A$2,$A$3,I$4,$C5,$D5,$A$5,$A$8,$I$3) -> #VALUE! | J5: =IFERROR((I5/H5)-1,"-") -> - | L5: =IFERROR(IF(ROUND(G5,4)>0,"▲ ",IF(ROUND(G5,4)<0,"▼ ","▬ ")) & TEXT(G5,"0,00%") & " | " & IF(ROUND(J5,4)>0,"▲ ",IF(ROUND(J5,4)<0,"▼ ","▬ ")) & TEXT(J5,"0,00%"),"▬ 0,00% | ▬ 0,00%") -> ▬ 0,00% | ▬ 0,00%
A6: =_xll.SUBNM("CONS_VC:DFS.D.Accounts_PnL","Default","EBITDA") -> EBITDA | C6: USD | D6: VCNA | E6: =_xll.DBRW($A$1,$A$2,$A$3,E$4,$C6,$D6,$A$5,$A$8,$E$3) -> #VALUE! | F6: =_xll.DBRW($A$1,$A$2,$A$3,F$4,$C6,$D6,$A$5,$A$8,$F$3) -> #VALUE! | G6: =IFERROR((F6/E6)-1,"-") -> - | H6: =_xll.DBRW($A$1,$A$2,$A$3,H$4,$C6,$D6,$A$5,$A$8,$E$3) -> #VALUE! | I6: =_xll.DBRW($A$1,$A$2,$A$3,I$4,$C6,$D6,$A$5,$A$8,$F$3) -> #VALUE! | J6: =IFERROR((I6/H6)-1,"-") -> - | L6: =IFERROR(IF(ROUND(G6,4)>0,"▲ ",IF(ROUND(G6,4)<0,"▼ ","▬ ")) & TEXT(G6,"0,00%") & " | " & IF(ROUND(J6,4)>0,"▲ ",IF(ROUND(J6,4)<0,"▼ ","▬ ")) & TEXT(J6,"0,00%"),"▬ 0,00% | ▬ 0,00%") -> ▬ 0,00% | ▬ 0,00%
A7: Total Value | C7: BRL | D7: VCBR - VCBR | E7: =_xll.DBRW($A$1,$A$2,$A$3,E$4,$C7,$D7,$A$5,$A$8,$E$3) -> #VALUE! | F7: =_xll.DBRW($A$1,$A$2,$A$3,F$4,$C7,$D7,$A$5,$A$8,$F$3) -> #VALUE! | G7: =IFERROR((F7/E7)-1,"-") -> - | H7: =_xll.DBRW($A$1,$A$2,$A$3,H$4,$C7,$D7,$A$5,$A$8,$E$3) -> #VALUE! | I7: =_xll.DBRW($A$1,$A$2,$A$3,I$4,$C7,$D7,$A$5,$A$8,$F$3) -> #VALUE! | J7: =IFERROR((I7/H7)-1,"-") -> - | L7: =IFERROR(IF(ROUND(G7,4)>0,"▲ ",IF(ROUND(G7,4)<0,"▼ ","▬ ")) & TEXT(G7,"0,00%") & " | " & IF(ROUND(J7,4)>0,"▲ ",IF(ROUND(J7,4)<0,"▼ ","▬ ")) & TEXT(J7,"0,00%"),"▬ 0,00% | ▬ 0,00%") -> ▬ 0,00% | ▬ 0,00%
A8: {='Monthly VOL | PRICES'!I3:J3} -> #N/A | B8: 0 | C8: EUR | D8: ESPA - Spain | E8: =_xll.DBRW($A$1,$A$2,$A$3,E$4,$C8,$D8,$A$5,$A$8,$E$3) -> #VALUE! | F8: =_xll.DBRW($A$1,$A$2,$A$3,F$4,$C8,$D8,$A$5,$A$8,$F$3) -> #VALUE! | G8: =IFERROR((F8/E8)-1,"-") -> - | H8: =_xll.DBRW($A$1,$A$2,$A$3,H$4,$C8,$D8,$A$5,$A$8,$E$3) -> #VALUE! | I8: =_xll.DBRW($A$1,$A$2,$A$3,I$4,$C8,$D8,$A$5,$A$8,$F$3) -> #VALUE! | J8: =IFERROR((I8/H8)-1,"-") -> - | L8: =IFERROR(IF(ROUND(G8,4)>0,"▲ ",IF(ROUND(G8,4)<0,"▼ ","▬ ")) & TEXT(G8,"0,00%") & " | " & IF(ROUND(J8,4)>0,"▲ ",IF(ROUND(J8,4)<0,"▼ ","▬ ")) & TEXT(J8,"0,00%"),"▬ 0,00% | ▬ 0,00%") -> ▬ 0,00% | ▬ 0,00%
C9: EUR | D9: TURK - Turkey | E9: =_xll.DBRW($A$1,$A$2,$A$3,E$4,$C9,$D9,$A$5,$A$8,$E$3) -> #VALUE! | F9: =_xll.DBRW($A$1,$A$2,$A$3,F$4,$C9,$D9,$A$5,$A$8,$F$3) -> #VALUE! | G9: =IFERROR((F9/E9)-1,"-") -> - | H9: =_xll.DBRW($A$1,$A$2,$A$3,H$4,$C9,$D9,$A$5,$A$8,$E$3) -> #VALUE! | I9: =_xll.DBRW($A$1,$A$2,$A$3,I$4,$C9,$D9,$A$5,$A$8,$F$3) -> #VALUE! | J9: =IFERROR((I9/H9)-1,"-") -> - | L9: =IFERROR(IF(ROUND(G9,4)>0,"▲ ",IF(ROUND(G9,4)<0,"▼ ","▬ ")) & TEXT(G9,"0,00%") & " | " & IF(ROUND(J9,4)>0,"▲ ",IF(ROUND(J9,4)<0,"▼ ","▬ ")) & TEXT(J9,"0,00%"),"▬ 0,00% | ▬ 0,00%") -> ▬ 0,00% | ▬ 0,00%
C10: UYU | D10: ARTI - Artigas | E10: =_xll.DBRW($A$1,$A$2,$A$3,E$4,$C10,$D10,$A$5,$A$8,$E$3) -> #VALUE! | F10: =_xll.DBRW($A$1,$A$2,$A$3,F$4,$C10,$D10,$A$5,$A$8,$F$3) -> #VALUE! | G10: =IFERROR((F10/E10)-1,"-") -> - | H10: =_xll.DBRW($A$1,$A$2,$A$3,H$4,$C10,$D10,$A$5,$A$8,$E$3) -> #VALUE! | I10: =_xll.DBRW($A$1,$A$2,$A$3,I$4,$C10,$D10,$A$5,$A$8,$F$3) -> #VALUE! | J10: =IFERROR((I10/H10)-1,"-") -> - | L10: =IFERROR(IF(ROUND(G10,4)>0,"▲ ",IF(ROUND(G10,4)<0,"▼ ","▬ ")) & TEXT(G10,"0,00%") & " | " & IF(ROUND(J10,4)>0,"▲ ",IF(ROUND(J10,4)<0,"▼ ","▬ ")) & TEXT(J10,"0,00%"),"▬ 0,00% | ▬ 0,00%") -> ▬ 0,00% | ▬ 0,00%
C11: BOB | D11: ITACA - Itacamba | E11: =_xll.DBRW($A$1,$A$2,$A$3,E$4,$C11,$D11,$A$5,$A$8,$E$3) -> #VALUE! | F11: =_xll.DBRW($A$1,$A$2,$A$3,F$4,$C11,$D11,$A$5,$A$8,$F$3) -> #VALUE! | G11: =IFERROR((F11/E11)-1,"-") -> - | H11: =_xll.DBRW($A$1,$A$2,$A$3,H$4,$C11,$D11,$A$5,$A$8,$E$3) -> #VALUE! | I11: =_xll.DBRW($A$1,$A$2,$A$3,I$4,$C11,$D11,$A$5,$A$8,$F$3) -> #VALUE! | J11: =IFERROR((I11/H11)-1,"-") -> - | L11: =IFERROR(IF(ROUND(G11,4)>0,"▲ ",IF(ROUND(G11,4)<0,"▼ ","▬ ")) & TEXT(G11,"0,00%") & " | " & IF(ROUND(J11,4)>0,"▲ ",IF(ROUND(J11,4)<0,"▼ ","▬ ")) & TEXT(J11,"0,00%"),"▬ 0,00% | ▬ 0,00%") -> ▬ 0,00% | ▬ 0,00%
C12: CAD | D12: VCNA | E12: =_xll.DBRW($A$1,$A$2,$A$3,E$4,$C12,$D12,$A$5,$A$8,$E$3) -> #VALUE! | F12: =_xll.DBRW($A$1,$A$2,$A$3,F$4,$C12,$D12,$A$5,$A$8,$F$3) -> #VALUE! | G12: =IFERROR((F12/E12)-1,"-") -> - | H12: =_xll.DBRW($A$1,$A$2,$A$3,H$4,$C12,$D12,$A$5,$A$8,$E$3) -> #VALUE! | I12: =_xll.DBRW($A$1,$A$2,$A$3,I$4,$C12,$D12,$A$5,$A$8,$F$3) -> #VALUE! | J12: =IFERROR((I12/H12)-1,"-") -> - | L12: =IFERROR(IF(ROUND(G12,4)>0,"▲ ",IF(ROUND(G12,4)<0,"▼ ","▬ ")) & TEXT(G12,"0,00%") & " | " & IF(ROUND(J12,4)>0,"▲ ",IF(ROUND(J12,4)<0,"▼ ","▬ ")) & TEXT(J12,"0,00%"),"▬ 0,00% | ▬ 0,00%") -> ▬ 0,00% | ▬ 0,00%

Sheet Monthly VOL | PRICES
A2: Month Analysis
D3: =_xll.SUBNM("CONS_VC_PRD:ALL.D.Products","Products","PRODCE010 - Cement","Código e Descrição") -> #N/A | I3: =_xll.SUBNM("CONS_VC_PRD:ALL.D.Market","Default","Total Market","ID do membro") -> #N/A | M3: =_xll.SUBNM("CONS_VC_PRD:ALL.D.Year","SYS_Picklist","2025","ÏD do Membro") -> #N/A | O3: =_xll.SUBNM("CONS_VC_PRD:ALL.D.Month","SYS_Picklist","Nov","Desc") -> #N/A | Q3: Actual | S3: L300

Sheet Vol | Price (product ) - Fx
A1: CONS_VC:REV.100.Revenue_Consolidated
A2: CONS_VC:DFS.100.Profit_and_Loss | M2: EBITDA
A3: ='Vol | Price (product)'!$N$6 -> #N/A | B3: =_xll.SUBNM("CONS_VC:ALL.D.Month","SYS_YTD",$A$4,"ID do membro") -> #VALUE! | C3: Sales Volume [kt] | D3: =$A$4 -> #N/A | E3: ="YTD "&$B$3 -> #VALUE! | H3: Price Premium [$/ton] | I3: =$A$4 -> #N/A | J3: ="YTD "&$B$3 -> #VALUE! | M3: Total Products | N3: =$A$4 -> #N/A | O3: ="YTD "&$B$3 -> #VALUE!
A4: ='Vol | Price (product)'!$S$6 -> #N/A | C4: ='Vol | Price (product)'!$AI6 -> #N/A | D4: =_xll.DBRW($A$1,$A$3,D$3,$C4,$A$7,$A$6,$B$5,$A$8,$C$3) -> #VALUE! | E4: =_xll.DBRW($A$1,$A$3,E$3,$C4,$A$7,$A$6,$B$5,$A$8,$C$3) -> #VALUE! | H4: ='Vol | Price (product)'!$AI6 -> #N/A | I4: =_xll.DBRW($A$1,$A$3,I$3,$H4,$A$7,$A$6,$B$5,$A$8,$H$3) -> #VALUE! | J4: =_xll.DBRW($A$1,$A$3,J$3,$H4,$A$7,$A$6,$B$5,$A$8,$H$3) -> #VALUE! | M4: ='Vol | Price (product)'!$AI6 -> #N/A | N4: =_xll.DBRW($A$2,$A$3,N$3,$M4,$A$7,$A$6,$M$3,$M$2,$A$9) -> #VALUE! | O4: =_xll.DBRW($A$2,$A$3,O$3,$M4,$A$7,$A$6,$M$3,$M$2,$A$9) -> #VALUE!
A5: Version | B5: ='Vol | Price (product)'!B9 -> #N/A | C5: ='Vol | Price (product)'!$AK6 -> #N/A | D5: =_xll.DBRW($A$1,$A$3,D$3,$C5,$A$7,$A$6,$B$5,$A$8,$C$3) -> #VALUE! | E5: =_xll.DBRW($A$1,$A$3,E$3,$C5,$A$7,$A$6,$B$5,$A$8,$C$3) -> #VALUE! | H5: ='Vol | Price (product)'!$AK6 -> #N/A | I5: =_xll.DBRW($A$1,$A$3,I$3,$H5,$A$7,$A$6,$B$5,$A$8,$H$3) -> #VALUE! | J5: =_xll.DBRW($A$1,$A$3,J$3,$H5,$A$7,$A$6,$B$5,$A$8,$H$3) -> #VALUE! | M5: ='Vol | Price (product)'!$AK6 -> #N/A | N5: =_xll.DBRW($A$2,$A$3,N$3,$M5,$A$7,$A$6,$M$3,$M$2,$A$9) -> #VALUE! | O5: =_xll.DBRW($A$2,$A$3,O$3,$M5,$A$7,$A$6,$M$3,$M$2,$A$9) -> #VALUE!
A6: ='Vol | Price (product)'!G6 -> #N/A
A7: ='Vol | Price (product)'!X6 -> #N/A
A8: ='Vol | Price (product)'!$AD$6 -> #N/A
A9: Total Value | C9: Sales Volume [kt] | D9: =$A$4 -> #N/A | E9: ="YTD "&$B$3 -> #VALUE! | H9: Price Premium [$/ton] | I9: =$A$4 -> #N/A | J9: ="YTD "&$B$3 -> #VALUE!
C10: ='Vol | Price (product)'!$AI6 -> #N/A | D10: =_xll.DBRW($A$1,$A$3,D$3,$C10,$A$7,$A$6,$B$11,$A$8,$C$9) -> #VALUE! | E10: =_xll.DBRW($A$1,$A$3,E$3,$C10,$A$7,$A$6,$B$11,$A$8,$C$9) -> #VALUE! | H10: ='Vol | Price (product)'!$AI6 -> #N/A | I10: =_xll.DBRW($A$1,$A$3,I$9,$H10,$A$7,$A$6,$B$11,$A$8,$H$9) -> #VALUE! | J10: =_xll.DBRW($A$1,$A$3,J$9,$H10,$A$7,$A$6,$B$11,$A$8,$H$9) -> #VALUE!
B11: ='Vol | Price (product)'!B19 -> #N/A | C11: ='Vol | Price (product)'!$AK6 -> #N/A | D11: =_xll.DBRW($A$1,$A$3,D$3,$C11,$A$7,$A$6,$B$11,$A$8,$C$9) -> #VALUE! | E11: =_xll.DBRW($A$1,$A$3,E$3,$C11,$A$7,$A$6,$B$11,$A$8,$C$9) -> #VALUE! | H11: ='Vol | Price (product)'!$AK6 -> #N/A | I11: =_xll.DBRW($A$1,$A$3,I$9,$H11,$A$7,$A$6,$B$11,$A$8,$H$9) -> #VALUE! | J11: =_xll.DBRW($A$1,$A$3,J$9,$H11,$A$7,$A$6,$B$11,$A$8,$H$9) -> #VALUE!
C15: Sales Volume [kt] | D15: =$A$4 -> #N/A | E15: ="YTD "&$B$3 -> #VALUE! | H15: Price Premium [$/ton] | I15: =$A$4 -> #N/A | J15: ="YTD "&$B$3 -> #VALUE!
C16: =$C10 -> #N/A | D16: =_xll.DBRW($A$1,$A$3,D$3,$C16,$A$7,$A$6,$B$17,$A$8,$C$15) -> #VALUE! | E16: =_xll.DBRW($A$1,$A$3,E$3,$C16,$A$7,$A$6,$B$17,$A$8,$C$15) -> #VALUE! | H16: ='Vol | Price (product)'!$AI6 -> #N/A | I16: =_xll.DBRW($A$1,$A$3,I$15,$H16,$A$7,$A$6,$B$17,$A$8,$H$15) -> #VALUE! | J16: =_xll.DBRW($A$1,$A$3,J$15,$H16,$A$7,$A$6,$B$17,$A$8,$H$15) -> #VALUE!
B17: ='Vol | Price (product)'!B28 -> #N/A | C17: =$C11 -> #N/A | D17: =_xll.DBRW($A$1,$A$3,D$3,$C17,$A$7,$A$6,$B$17,$A$8,$C$15) -> #VALUE! | E17: =_xll.DBRW($A$1,$A$3,E$3,$C17,$A$7,$A$6,$B$17,$A$8,$C$15) -> #VALUE! | H17: ='Vol | Price (product)'!$AK6 -> #N/A | I17: =_xll.DBRW($A$1,$A$3,I$15,$H17,$A$7,$A$6,$B$17,$A$8,$H$15) -> #VALUE! | J17: =_xll.DBRW($A$1,$A$3,J$15,$H17,$A$7,$A$6,$B$17,$A$8,$H$15) -> #VALUE!

Sheet Vol | Price  (product)
B1: Volume | Price
G6: =_xll.SUBNM("CONS_VC_PRD:ALL.D.Region","DEFAuLT","VCBR - VCBR","Código e Descrição" ) -> #N/A | N6: =_xll.SUBNM("CONS_VC_PRD:ALL.D.Year","SYS_Picklist","2025","ÏD do Membro") -> #N/A | S6: =_xll.SUBNM("CONS_VC_PRD:ALL.D.Month","SYS_Picklist","Nov","Desc") -> #N/A | X6: =_xll.SUBNM("CONS_VC_PRD:ALL.D.Currency","Default","BRL","Código e Descrição") -> #N/A | AD6: =_xll.SUBNM("CONS_VC_PRD:ALL.D.Market","Default","Total Market","ID do membro") -> #N/A | AI6: =_xll.SUBNM("CONS_VC_PRD:ALL.D.Version","Sys.Report","Actual","Descrição") -> #N/A | AK6: =_xll.SUBNM("CONS_VC_PRD:ALL.D.Version","Sys.Report","L300","Descrição") -> #N/A
G8: Sales Volumes | AB8: ="FOB Price " &( X6 ) -> #N/A | AK8: ="EBITDA " &( X6 ) -> #N/A
B9: =_xll.SUBNM("CONS_VC_PRD:ALL.D.Products","Products","PRODCE010 - Cement","Código e Descrição") -> #N/A
B19: =_xll.SUBNM("CONS_VC_PRD:ALL.D.Products","Products","PRODRM010 - Ready Mix","Código e Descrição") -> #N/A
B28: =_xll.SUBNM("CONS_VC_PRD:ALL.D.Products","Products","PRODAG010 - Aggregates","Código e Descrição") -> #N/A

Sheet Cement | Region - Fx
A1: CONS_VC:REV.100.Revenue_Consolidated | C1: ='Cement | Region'!G6 -> #N/A
A2: CONS_VC:DFS.100.Profit_and_Loss | M2: EBITDA
A3: ='Cement | Region'!$Z$6 -> #N/A | B3: =_xll.SUBNM("CONS_VC:ALL.D.Month","SYS_YTD",$A$4,"ID do membro") -> #VALUE! | C3: Sales Volume [kt] | D3: =$A$4 -> #N/A | E3: ="YTD "&$B$3 -> #VALUE! | I3: Price Premium [$/ton] | J3: =$A$4 -> #N/A | K3: ="YTD "&$B$3 -> #VALUE! | M3: Total Products | N3: =$A$4 -> #N/A | O3: ="YTD "&$B$3 -> #VALUE!
A4: ='Cement | Region'!$AD$6 -> #N/A | C4: ='Cement | Region'!$AI$6 -> #N/A | D4: =_xll.DBRW($A$1,$A$3,D$3,$C4,$B$6,$B$5,$C$1,$A$8,$C$3) -> #VALUE! | E4: =_xll.DBRW($A$1,$A$3,E$3,$C4,$B$6,$B$5,$C$1,$A$8,$C$3) -> #VALUE! | I4: ='Cement | Region'!$AI$6 -> #N/A | J4: =_xll.DBRW($A$1,$A$3,J$3,$I4,$B$6,$B$5,$C$1,$A$8,$I$3) -> #VALUE! | K4: =_xll.DBRW($A$1,$A$3,K$3,$I4,$B$6,$B$5,$C$1,$A$8,$I$3) -> #VALUE! | M4: ='Cement | Region'!$AI$6 -> #N/A | N4: =_xll.DBRW($A$2,$A$3,N$3,$M4,$B$6,$B$5,$M$3,$M$2,$A$9) -> #VALUE! | O4: =_xll.DBRW($A$2,$A$3,O$3,$M4,$B$6,$B$5,$M$3,$M$2,$A$9) -> #VALUE!
A5: Version | B5: ='Cement | Region'!$B$9 -> #N/A | C5: ='Cement | Region'!$AK$6 -> #N/A | D5: =_xll.DBRW($A$1,$A$3,D$3,$C5,$B$6,$B$5,$C$1,$A$8,$C$3) -> #VALUE! | E5: =_xll.DBRW($A$1,$A$3,E$3,$C5,$B$6,$B$5,$C$1,$A$8,$C$3) -> #VALUE! | I5: ='Cement | Region'!$AK$6 -> #N/A | J5: =_xll.DBRW($A$1,$A$3,J$3,$I5,$B$6,$B$5,$C$1,$A$8,$I$3) -> #VALUE! | K5: =_xll.DBRW($A$1,$A$3,K$3,$I5,$B$6,$B$5,$C$1,$A$8,$I$3) -> #VALUE! | M5: ='Cement | Region'!$AK$6 -> #N/A | N5: =_xll.DBRW($A$2,$A$3,N$3,$M5,$B$6,$B$5,$M$3,$M$2,$A$9) -> #VALUE! | O5: =_xll.DBRW($A$2,$A$3,O$3,$M5,$B$6,$B$5,$M$3,$M$2,$A$9) -> #VALUE!
B6: ='Cement | Region'!B12 -> #N/A
A8: ='Cement | Region'!$P$6 -> #N/A | M8: EBITDA
A9: Total Value | C9: Sales Volume [kt] | D9: =$A$4 -> #N/A | E9: ="YTD "&$B$3 -> #VALUE! | I9: Price Premium [$/ton] | J9: =$A$4 -> #N/A | K9: ="YTD "&$B$3 -> #VALUE! | M9: Total Products | N9: =$A$4 -> #N/A | O9: ="YTD "&$B$3 -> #VALUE!
C10: ='Cement | Region'!$AI$6 -> #N/A | D10: =_xll.DBRW($A$1,$A$3,D$9,$C10,$B$12,$B$11,$C$1,$A$8,$C$9) -> #VALUE! | E10: =_xll.DBRW($A$1,$A$3,E$9,$C10,$B$12,$B$11,$C$1,$A$8,$C$9) -> #VALUE! | I10: ='Cement | Region'!$AI$6 -> #N/A | J10: =_xll.DBRW($A$1,$A$3,J$9,$I10,$B$12,$B$11,$C$1,$A$8,$I$9) -> #VALUE! | K10: =_xll.DBRW($A$1,$A$3,K$9,$I10,$B$12,$B$11,$C$1,$A$8,$I$9) -> #VALUE! | M10: ='Cement | Region'!$AI$6 -> #N/A | N10: =_xll.DBRW($A$2,$A$3,N$9,$M10,$B$12,$B$11,$M$9,$M$8,$A$9) -> #VALUE! | O10: =_xll.DBRW($A$2,$A$3,O$9,$M10,$B$12,$B$11,$M$9,$M$8,$A$9) -> #VALUE!
B11: ='Cement | Region'!B19 -> #N/A | C11: ='Cement | Region'!$AK$6 -> #N/A | D11: =_xll.DBRW($A$1,$A$3,D$9,$C11,$B$12,$B$11,$C$1,$A$8,$C$9) -> #VALUE! | E11: =_xll.DBRW($A$1,$A$3,E$9,$C11,$B$12,$B$11,$C$1,$A$8,$C$9) -> #VALUE! | I11: ='Cement | Region'!$AK$6 -> #N/A | J11: =_xll.DBRW($A$1,$A$3,J$9,$I11,$B$12,$B$11,$C$1,$A$8,$I$9) -> #VALUE! | K11: =_xll.DBRW($A$1,$A$3,K$9,$I11,$B$12,$B$11,$C$1,$A$8,$I$9) -> #VALUE! | M11: ='Cement | Region'!$AK$6 -> #N/A | N11: =_xll.DBRW($A$2,$A$3,N$9,$M11,$B$12,$B$11,$M$9,$M$8,$A$9) -> #VALUE! | O11: =_xll.DBRW($A$2,$A$3,O$9,$M11,$B$12,$B$11,$M$9,$M$8,$A$9) -> #VALUE!
B12: ='Cement | Region'!B22 -> #N/A
M14: EBITDA
C15: Sales Volume [kt] | D15: =$A$4 -> #N/A | E15: ="YTD "&$B$3 -> #VALUE! | I15: Price Premium [$/ton] | J15: =$A$4 -> #N/A | K15: ="YTD "&$B$3 -> #VALUE! | M15: Total Products | N15: =$A$4 -> #N/A | O15: ="YTD "&$B$3 -> #VALUE!
C16: ='Cement | Region'!$AI$6 -> #N/A | D16: =_xll.DBRW($A$1,$A$3,D$15,$C16,$B$18,$B$17,$C$1,$A$8,$C$15) -> #VALUE! | E16: =_xll.DBRW($A$1,$A$3,E$15,$C16,$B$18,$B$17,$C$1,$A$8,$C$15) -> #VALUE! | I16: ='Cement | Region'!$AI$6 -> #N/A | J16: =_xll.DBRW($A$1,$A$3,J$15,$I16,$B$18,$B$17,$C$1,$A$8,$I$15) -> #VALUE! | K16: =_xll.DBRW($A$1,$A$3,K$15,$I16,$B$18,$B$17,$C$1,$A$8,$I$15) -> #VALUE! | M16: ='Cement | Region'!$AI$6 -> #N/A | N16: =_xll.DBRW($A$2,$A$3,N$15,$M16,$B$18,$B$17,$M$15,$M$14,$A$9) -> #VALUE! | O16: =_xll.DBRW($A$2,$A$3,O$15,$M16,$B$18,$B$17,$M$15,$M$14,$A$9) -> #VALUE!
B17: ='Cement | Region'!B28 -> #N/A | C17: ='Cement | Region'!$AK$6 -> #N/A | D17: =_xll.DBRW($A$1,$A$3,D$15,$C17,$B$18,$B$17,$C$1,$A$8,$C$15) -> #VALUE! | E17: =_xll.DBRW($A$1,$A$3,E$15,$C17,$B$18,$B$17,$C$1,$A$8,$C$15) -> #VALUE! | I17: ='Cement | Region'!$AK$6 -> #N/A | J17: =_xll.DBRW($A$1,$A$3,J$15,$I17,$B$18,$B$17,$C$1,$A$8,$I$15) -> #VALUE! | K17: =_xll.DBRW($A$1,$A$3,K$15,$I17,$B$18,$B$17,$C$1,$A$8,$I$15) -> #VALUE! | M17: ='Cement | Region'!$AK$6 -> #N/A | N17: =_xll.DBRW($A$2,$A$3,N$15,$M17,$B$18,$B$17,$M$15,$M$14,$A$9) -> #VALUE! | O17: =_xll.DBRW($A$2,$A$3,O$15,$M17,$B$18,$B$17,$M$15,$M$14,$A$9) -> #VALUE!
B18: ='Cement | Region'!B31 -> #N/A

Sheet Cement | Region
B1: Volume | Price
G6: =_xll.SUBNM("CONS_VC_PRD:ALL.D.Products","Products","PRODCE010 - Cement","Código e Descrição") -> #N/A | P6: =_xll.SUBNM("CONS_VC_PRD:ALL.D.Market","Default","Total Market","ID do membro") -> #N/A | Z6: =_xll.SUBNM("CONS_VC_PRD:ALL.D.Year","SYS_Picklist","2025","ÏD do Membro") -> #N/A | AD6: =_xll.SUBNM("CONS_VC_PRD:ALL.D.Month","SYS_Picklist","Nov","Desc") -> #N/A | AI6: =_xll.SUBNM("CONS_VC_PRD:ALL.D.Version","Sys.Report","Actual","Descrição") -> #N/A | AK6: =_xll.SUBNM("CONS_VC_PRD:ALL.D.Version","Sys.Report","L300","Descrição") -> #N/A
G8: Sales Volumes | AB8: ="FOB Price " &( X6 ) -> FOB Price | AK8: ="EBITDA " &( X6 ) -> EBITDA
B9: =_xll.SUBNM("CONS_VC_PRD:ALL.D.Region","DEFAuLT","VCEAA - VCEAA","Código e Descrição" ) -> #N/A
B12: =_xll.SUBNM("CONS_VC_PRD:ALL.D.Currency","Default","USD","Código e Descrição") -> #N/A
B19: =_xll.SUBNM("CONS_VC_PRD:ALL.D.Region","DEFAuLT","ESPA - Spain","Código e Descrição" ) -> #N/A
B22: =_xll.SUBNM("CONS_VC_PRD:ALL.D.Currency","Default","EUR","Código e Descrição") -> #N/A
B28: =_xll.SUBNM("CONS_VC_PRD:ALL.D.Region","DEFAuLT","TURK - Turkey","Código e Descrição" ) -> #N/A
B31: =_xll.SUBNM("CONS_VC_PRD:ALL.D.Currency","Default","TRY","Código e Descrição") -> #N/A
